File: g12-mi1_05.txt
#Acq. time (s)=	60
#Accumulations=	5
#Range=	Off
#Autofocus=	Off
#Macrospot=	Off
#AutoExposure=	Off
#Spike filter=	Multiple accum.
#Delay time (s)=	0
#Binning=	1
#Readout mode=	Signal
#DeNoise=	Off
#ICS correction=	Off
#Dark correction=	Off
#Inst. Process=	Off
#Instrument=	LabRAM HR Evol
#Detector=	Andor CCD
#Objective=	x100 LWD
#Grating=	1800 gr/mm
#ND Filter=	100%
#Laser (nm)=	532
#Spectro (cm-¹)=	1240.03
#Hole=	49.98
#Range=	Visible
#AFM=	Off
#StageXY=	Marzhauser
#StageZ=	Marzhauser
#X (µm)=	717.1
#Y (µm)=	-1004.6
#Z (µm)=	135.1
#Project=
#Sample=
#Site=
#Title=	g12-mi1
#Remark=
#Date=	28.03.2022 19:41
#Acquired=	28.03.2022 19:41:16
1454.82	680
1454.29	647.25
1453.76	661
1453.23	664.75
1452.7	635
1452.17	656.25
1451.65	678.5
1451.12	660.75
1450.59	654
1450.06	662.5
1449.53	674.5
1449	661
1448.47	671
1447.94	655.5
1447.41	668.25
1446.88	663.25
1446.36	632.5
1445.83	644.5
1445.3	663.25
1444.77	670
1444.24	664
1443.71	660
1443.18	658
1442.65	661.25
1442.12	649
1441.59	661.25
1441.06	644.25
1440.53	694.5
1440	635.25
1439.47	654.25
1438.94	652.25
1438.41	634
1437.88	670
1437.35	629.75
1436.82	622
1436.29	616
1435.76	636.5
1435.23	620
1434.7	643.75
1434.17	628
1433.64	640.5
1433.11	643
1432.58	608.5
1432.05	591
1431.52	613.25
1430.99	621.5
1430.46	597
1429.93	612.5
1429.4	606
1428.87	616
1428.34	632.25
1427.81	603.25
1427.27	588.5
1426.74	620.25
1426.21	584
1425.68	607.75
1425.15	594
1424.62	601.75
1424.09	589
1423.56	582.5
1423.03	594.5
1422.49	576.5
1421.96	582.75
1421.43	580.5
1420.9	586.25
1420.37	610.5
1419.84	600
1419.3	592.5
1418.77	588.75
1418.24	592
1417.71	592.25
1417.18	599.25
1416.65	568.75
1416.11	616.25
1415.58	570.75
1415.05	600
1414.52	585
1413.99	577.75
1413.45	575
1412.92	580.75
1412.39	597.5
1411.86	603.5
1411.32	581.25
1410.79	611
1410.26	634.5
1409.73	640.5
1409.19	593.75
1408.66	574
1408.13	561.25
1407.6	585
1407.06	584.75
1406.53	573
1406	569.75
1405.46	562.5
1404.93	580.25
1404.4	582.5
1403.87	582
1403.33	586
1402.8	580.5
1402.27	575
1401.73	557.5
1401.2	571.75
1400.67	581.5
1400.13	562.5
1399.6	588.25
1399.07	569.25
1398.53	587.5
1398	571.25
1397.46	600.75
1396.93	582.5
1396.4	594
1395.86	592.5
1395.33	556
1394.8	575.75
1394.26	585.5
1393.73	530.75
1393.19	562
1392.66	572.75
1392.13	583.25
1391.59	560.75
1391.06	556
1390.52	626.5
1389.99	653
1389.45	870.5
1388.92	1288
1388.38	1363
1387.85	782
1387.32	590
1386.78	587
1386.25	588.5
1385.71	581.5
1385.18	585
1384.64	571.5
1384.11	582
1383.57	576
1383.04	602.25
1382.5	589.5
1381.97	553.5
1381.43	598.25
1380.9	611.5
1380.36	580.5
1379.82	576.25
1379.29	583
1378.75	592.25
1378.22	547
1377.68	575.75
1377.15	591
1376.61	577
1376.08	550.25
1375.54	579.5
1375	580
1374.47	576
1373.93	558.5
1373.4	587
1372.86	544.75
1372.33	583.5
1371.79	555
1371.25	576.5
1370.72	604
1370.18	547.25
1369.64	600.25
1369.11	550.5
1368.57	559.25
1368.03	565.5
1367.5	577.25
1366.96	557
1366.43	580
1365.89	611.5
1365.35	590.5
1364.82	557
1364.28	562
1363.74	578
1363.2	583.25
1362.67	578
1362.13	568.5
1361.59	574.25
1361.06	556.75
1360.52	583.5
1359.98	574
1359.45	588.75
1358.91	590
1358.37	549.75
1357.83	579.5
1357.3	572.25
1356.76	572.5
1356.22	576.5
1355.68	560
1355.15	562
1354.61	584.5
1354.07	568.5
1353.53	552
1352.99	562.5
1352.46	586.25
1351.92	557.5
1351.38	562.25
1350.84	548
1350.31	556.5
1349.77	576.75
1349.23	599.75
1348.69	580
1348.15	563.5
1347.61	546.75
1347.08	568.25
1346.54	568.5
1346	560.5
1345.46	589.75
1344.92	560
1344.38	552.25
1343.84	575.5
1343.3	566.25
1342.77	548.25
1342.23	583.25
1341.69	578.75
1341.15	568.5
1340.61	573
1340.07	550
1339.53	576.5
1338.99	550
1338.45	572.25
1337.92	564
1337.38	581.75
1336.84	571.25
1336.3	563.75
1335.76	561.25
1335.22	578
1334.68	560.75
1334.14	550
1333.6	555.5
1333.06	551.75
1332.52	570.25
1331.98	576.5
1331.44	572.5
1330.9	544.5
1330.36	552.25
1329.82	582.25
1329.28	539.25
1328.74	550.5
1328.2	552.25
1327.66	562.5
1327.12	561
1326.58	557.5
1326.04	581.25
1325.5	558.5
1324.96	556.25
1324.42	557.5
1323.88	573.5
1323.34	580
1322.8	573.25
1322.25	561.5
1321.71	573.25
1321.17	555.25
1320.63	571.5
1320.09	589
1319.55	584.5
1319.01	609.25
1318.47	589
1317.93	567
1317.39	585.25
1316.85	598
1316.3	597.25
1315.76	595.5
1315.22	547.25
1314.68	593
1314.14	601
1313.6	589
1313.06	572.5
1312.51	617
1311.97	617.25
1311.43	592.75
1310.89	603.5
1310.35	615
1309.81	574.25
1309.26	610.25
1308.72	604.75
1308.18	596.5
1307.64	591.5
1307.1	610
1306.55	627.75
1306.01	625.25
1305.47	621.25
1304.93	642.25
1304.39	649.75
1303.84	634
1303.3	639.75
1302.76	641.5
1302.22	669
1301.67	629.75
1301.13	644.5
1300.59	638.25
1300.04	662.5
1299.5	630
1298.96	645.5
1298.42	625.5
1297.87	655
1297.33	657.75
1296.79	644.5
1296.24	684.25
1295.7	649.25
1295.16	667
1294.61	665.25
1294.07	657.5
1293.53	637.5
1292.98	634
1292.44	650
1291.9	642
1291.35	653
1290.81	637
1290.27	657.75
1289.72	618
1289.18	642.5
1288.63	647.5
1288.09	646
1287.55	674.25
1287	729.75
1286.46	1021.5
1285.92	1171.25
1285.37	934
1284.83	668
1284.28	670
1283.74	646
1283.19	610.25
1282.65	623.5
1282.1	616.5
1281.56	614
1281.02	606.25
1280.47	616.75
1279.93	637.75
1279.38	643.5
1278.84	639
1278.29	596
1277.75	621.5
1277.2	615
1276.66	613.5
1276.11	628.75
1275.57	596.5
1275.02	612.75
1274.48	643.5
1273.93	616.5
1273.39	612.25
1272.84	661.75
1272.3	606.75
1271.75	613.75
1271.21	623.75
1270.66	657
1270.11	651
1269.57	638.5
1269.02	652.75
1268.48	618.5
1267.93	642.5
1267.39	666.75
1266.84	657.75
1266.3	688
1265.75	712
1265.2	671.25
1264.66	646.25
1264.11	684.5
1263.57	652.25
1263.02	647.25
1262.47	678.5
1261.93	668.75
1261.38	651.5
1260.83	662.75
1260.29	691.5
1259.74	669.25
1259.19	706.75
1258.65	664.75
1258.1	675.5
1257.55	668
1257.01	722.25
1256.46	701
1255.91	728.5
1255.37	714
1254.82	705.5
1254.27	699
1253.73	717.5
1253.18	714.75
1252.63	725
1252.08	735.25
1251.54	743.5
1250.99	759
1250.44	756.75
1249.9	708.75
1249.35	755.25
1248.8	757
1248.25	753
1247.71	760.25
1247.16	743.25
1246.61	787
1246.06	775.5
1245.51	771
1244.97	762.5
1244.42	781.5
1243.87	783
1243.32	810.75
1242.77	813
1242.23	800.5
1241.68	831.5
1241.13	820.5
1240.58	861.25
1240.03	865.25
1239.48	867.75
1238.94	913
1238.39	877.75
1237.84	937
1237.29	927.75
1236.74	982.5
1236.19	1017.5
1235.65	1023.5
1235.1	1016.25
1234.55	1071.25
1234	1114.25
1233.45	1163.25
1232.9	1132
1232.35	1158.25
1231.8	1185.75
1231.25	1205
1230.7	1163.25
1230.16	1210.5
1229.61	1198
1229.06	1218.25
1228.51	1166.75
1227.96	1169.25
1227.41	1142.5
1226.86	1159
1226.31	1127.5
1225.76	1066
1225.21	1037.5
1224.66	1026
1224.11	989.5
1223.56	962.75
1223.01	960
1222.46	917.75
1221.91	905.25
1221.36	883
1220.81	893.5
1220.26	833.5
1219.71	869.25
1219.16	821.25
1218.61	830.5
1218.06	833.75
1217.51	822.5
1216.96	775
1216.41	796.5
1215.86	802.5
1215.31	777.75
1214.76	762
1214.21	750.5
1213.65	762
1213.1	744.5
1212.55	748.75
1212	736.25
1211.45	724.5
1210.9	742
1210.35	692
1209.8	711.75
1209.25	714.5
1208.7	701.5
1208.15	716.5
1207.59	703.25
1207.04	710.75
1206.49	694.25
1205.94	659
1205.39	710.75
1204.84	692.25
1204.29	669
1203.73	664.75
1203.18	685.25
1202.63	692
1202.08	681.75
1201.53	644.5
1200.97	673.25
1200.42	722
1199.87	718.75
1199.32	679.5
1198.77	683.25
1198.21	699.5
1197.66	691.75
1197.11	696.5
1196.56	702.5
1196	711.25
1195.45	670
1194.9	694.5
1194.35	727.75
1193.79	735.75
1193.24	704.25
1192.69	735
1192.14	747.75
1191.58	744.25
1191.03	773.75
1190.48	767
1189.92	797.5
1189.37	801.5
1188.82	797.75
1188.26	801
1187.71	818.5
1187.16	848.75
1186.61	833
1186.05	851
1185.5	823
1184.95	826
1184.39	834.25
1183.84	833
1183.28	786.5
1182.73	794.5
1182.18	838
1181.62	803.5
1181.07	824.25
1180.52	780
1179.96	786.75
1179.41	805.5
1178.86	777.75
1178.3	796
1177.75	813.75
1177.19	772.5
1176.64	796
1176.09	805
1175.53	780
1174.98	787.75
1174.42	796.25
1173.87	764.5
1173.31	846.25
1172.76	826.75
1172.2	854.5
1171.65	866
1171.09	893.5
1170.54	895.5
1169.99	926.75
1169.43	975.25
1168.87	965.5
1168.32	1042.75
1167.76	1069
1167.21	1106
1166.66	1171.5
1166.1	1307
1165.55	1380.5
1164.99	1476.5
1164.43	1576.5
1163.88	1690
1163.32	1886.75
1162.77	2034.75
1162.21	2166.25
1161.66	2332
1161.1	2451.75
1160.54	2528
1159.99	2571.5
1159.43	2598.75
1158.88	2541.5
1158.32	2538
1157.77	2437.25
1157.21	2320.25
1156.65	2174.75
1156.1	1965.75
1155.54	1881.25
1154.99	1707
1154.43	1616.5
1153.87	1511
1153.32	1361.75
1152.76	1333.75
1152.2	1268.75
1151.65	1190
1151.09	1149.75
1150.54	1107
1149.98	1094
1149.42	1032
1148.86	1032.75
1148.31	1019.5
1147.75	979.25
1147.19	937.5
1146.64	924.25
1146.08	960
1145.52	898
1144.97	885
1144.41	888.75
1143.85	876.5
1143.29	861
1142.74	818.75
1142.18	863.75
1141.62	853.25
1141.06	850.25
1140.51	827
1139.95	820.75
1139.39	819.5
1138.83	806.5
1138.28	789.5
1137.72	774
1137.16	802.5
1136.6	800.5
1136.04	776.25
1135.49	767.5
1134.93	769.25
1134.37	822.5
1133.81	757.75
1133.26	781
1132.7	766.5
1132.14	804.25
1131.58	777.25
1131.02	772
1130.46	753
1129.91	781
1129.35	781.75
1128.79	779.75
1128.23	772.5
1127.67	791.25
1127.11	795.75
1126.55	780
1125.99	805.75
1125.44	801.5
1124.88	802.75
1124.32	807
1123.76	796.5
1123.2	822.25
1122.64	779.5
1122.08	790.5
1121.52	810.75
1120.96	791
1120.4	823.5
1119.84	792.75
1119.28	803
1118.72	865.5
1118.16	843.5
1117.6	882.5
1117.05	851
1116.49	868.75
1115.93	906.5
1115.37	914.75
1114.81	942
1114.25	943.25
1113.69	971.75
1113.13	932.5
1112.57	977.25
1112.01	962.5
1111.45	907.25
1110.89	925.5
1110.32	935
1109.77	909.25
1109.2	911
1108.64	864.75
1108.08	878.75
1107.52	837.75
1106.96	827
1106.4	839
1105.84	837.25
1105.28	824.25
1104.72	782.5
1104.16	829.25
1103.6	800.5
1103.04	816
1102.48	778.25
1101.92	807.75
1101.35	785.5
1100.79	805.75
1100.23	760.5
1099.67	779
1099.11	774
1098.55	754
1097.99	738.75
1097.42	783
1096.86	771.75
1096.3	768.25
1095.74	749.25
1095.18	781.25
1094.62	772.25
1094.05	763.75
1093.49	756.75
1092.93	782.5
1092.37	782.75
1091.81	801.25
1091.24	792.5
1090.68	753
1090.12	798.5
1089.56	800
1089	804
1088.43	800
1087.87	819
1087.31	831.5
1086.75	853.25
1086.18	885.5
1085.62	933.25
1085.06	902.5
1084.5	973.75
1083.93	1026
1083.37	1036.25
1082.81	1076
1082.25	1101.75
1081.68	1073.25
1081.12	1095
1080.56	1019
1079.99	1034.5
1079.43	993
1078.87	942.75
1078.3	917.75
1077.74	901.75
1077.18	863.75
1076.61	849
1076.05	844.25
1075.49	851.5
1074.92	811.5
1074.36	799.25
1073.8	814.5
1073.23	808.25
1072.67	780.25
1072.11	789.25
1071.54	832.25
1070.98	837
1070.41	801.5
1069.85	758
1069.28	819.5
1068.72	765
1068.16	785.5
1067.59	846.25
1067.03	841
1066.46	817
1065.9	838.75
1065.33	794.5
1064.77	828
1064.21	832.5
1063.64	793
1063.08	788.75
1062.51	808.75
1061.95	803.5
1061.38	791
1060.82	791.75
1060.25	738.75
1059.69	777
1059.12	770.25
1058.56	771
1057.99	762.75
1057.43	782.25
1056.86	765.75
1056.3	769.75
1055.73	781
1055.17	747
1054.6	758.75
1054.04	774.75
1053.47	777.5
1052.9	797.75
1052.34	763
1051.77	804.25
1051.21	827.25
1050.64	801
1050.07	781
1049.51	809
1048.94	829
1048.38	848.75
1047.81	853.5
1047.24	900.75
1046.68	874.25
1046.11	885
1045.55	898
1044.98	868.25
1044.41	891.5
1043.85	903.25
1043.28	896.5
1042.71	891.5
1042.15	829
1041.58	834.5
1041.02	817.25
1040.45	822.5
1039.88	809.75
1039.31	783
1038.75	782.25
1038.18	804.75
1037.61	757.5
1037.05	782
1036.48	773
1035.91	774.5
1035.34	729.5
1034.78	722.25
1034.21	718
1033.64	714
1033.08	712.5
1032.51	720
1031.94	732
1031.37	743
1030.81	729.5
1030.24	710.5
1029.67	732.75
1029.1	706
1028.53	707
1027.97	713
1027.4	698.75
1026.83	669
1026.26	692.25
1025.69	715.75
1025.13	708
1024.56	695.5
1023.99	686.5
1023.42	696
1022.85	719.75
1022.29	724.25
1021.72	679.25
1021.15	710
1020.58	696.75
1020.01	678.5
1019.44	725.5
1018.87	702
1018.31	707.25
1017.74	714
1017.17	723.5
1016.6	709
1016.31	739.75