File: Testing/Hickernall_HORIBA/g15-mi1_01.txt
#Acq. time (s)=	75
#Accumulations=	5
#Range=	Off
#Autofocus=	Off
#Macrospot=	Off
#AutoExposure=	Off
#Spike filter=	Multiple accum.
#Delay time (s)=	0
#Binning=	1
#Readout mode=	Signal
#DeNoise=	Off
#ICS correction=	Off
#Dark correction=	Off
#Inst. Process=	Off
#Instrument=	LabRAM HR Evol
#Detector=	Andor CCD
#Objective=	x100 LWD
#Grating=	1800 gr/mm
#ND Filter=	100%
#Laser (nm)=	532
#Spectro (cm-¹)=	1240.02
#Hole=	49.98
#Range=	Visible
#AFM=	Off
#StageXY=	Marzhauser
#StageZ=	Marzhauser
#X (µm)=	-5511.2
#Y (µm)=	-1274.8
#Z (µm)=	-325.9
#Project=
#Sample=
#Site=
#Title=	g15-mi1
#Remark=
#Date=	06.05.2022 08:14
#Acquired=	06.05.2022 08:14:50
1454.81	2641
1454.28	2603
1453.75	2630
1453.22	2616
1452.69	2648.5
1452.16	2628.5
1451.64	2562.25
1451.11	2654.25
1450.58	2633.75
1450.05	2564
1449.52	2630.25
1448.99	2672
1448.46	2608.5
1447.93	2601.25
1447.4	2581.5
1446.88	2665.5
1446.35	2567.5
1445.82	2639.25
1445.29	2610.75
1444.76	2634
1444.23	2583.75
1443.7	2616.25
1443.17	2567.75
1442.64	2629.25
1442.11	2594.5
1441.58	2600.75
1441.05	2592.75
1440.52	2549
1439.99	2589.75
1439.46	2579.25
1438.93	2615.5
1438.4	2559.5
1437.87	2635
1437.34	2614.25
1436.81	2586.75
1436.28	2576.5
1435.75	2630.25
1435.22	2586.5
1434.69	2598.75
1434.16	2605
1433.63	2541.75
1433.1	2558.75
1432.57	2543.75
1432.04	2564
1431.51	2546.5
1430.98	2555.75
1430.45	2551.5
1429.92	2518
1429.39	2505.75
1428.86	2553
1428.33	2572.5
1427.8	2549
1427.26	2557.5
1426.73	2587.25
1426.2	2548.25
1425.67	2516.25
1425.14	2550.5
1424.61	2548.5
1424.08	2599
1423.55	2519.25
1423.02	2485.25
1422.49	2558.25
1421.95	2608.5
1421.42	2508.25
1420.89	2552
1420.36	2554.25
1419.83	2595
1419.3	2530
1418.76	2482.25
1418.23	2537
1417.7	2529.25
1417.17	2473.5
1416.64	2517.5
1416.1	2545.25
1415.57	2527.5
1415.04	2515.5
1414.51	2520.5
1413.98	2525.75
1413.44	2517.25
1412.91	2523.5
1412.38	2514
1411.85	2534
1411.32	2568.5
1410.78	2532.5
1410.25	2497.75
1409.72	2508
1409.18	2498
1408.65	2513.25
1408.12	2488.5
1407.59	2544.25
1407.05	2556.5
1406.52	2532.25
1405.99	2539.25
1405.46	2543.75
1404.92	2531.75
1404.39	2541.25
1403.86	2554
1403.32	2464.25
1402.79	2516
1402.26	2519.25
1401.72	2471.75
1401.19	2524.25
1400.66	2512
1400.12	2528.5
1399.59	2530.5
1399.06	2467.75
1398.52	2513.75
1397.99	2501.5
1397.46	2464
1396.92	2494.75
1396.39	2483.25
1395.85	2405.5
1395.32	2458.25
1394.79	2492
1394.25	2474.25
1393.72	2505.75
1393.18	2519.25
1392.65	2511
1392.12	2449.75
1391.58	2504.5
1391.05	2464.25
1390.51	2489.25
1389.98	2527
1389.44	2580.5
1388.91	2537.5
1388.38	2482.75
1387.84	2481
1387.31	2511
1386.77	2488.5
1386.24	2469
1385.7	2453.25
1385.17	2536.25
1384.63	2548.25
1384.1	2472.25
1383.56	2473.75
1383.03	2541
1382.49	2549.25
1381.96	2558.5
1381.42	2488.5
1380.89	2515.75
1380.35	2544.5
1379.82	2506.75
1379.28	2567.25
1378.74	2525
1378.21	2558
1377.67	2519.25
1377.14	2503.25
1376.6	2501.5
1376.07	2523.5
1375.53	2480.25
1374.99	2517.75
1374.46	2492.75
1373.92	2483.5
1373.39	2493.5
1372.85	2465.5
1372.32	2494
1371.78	2515.5
1371.24	2464.25
1370.71	2465
1370.17	2499.25
1369.63	2481
1369.1	2484.5
1368.56	2458
1368.03	2465.5
1367.49	2420.5
1366.95	2448.5
1366.42	2489.75
1365.88	2511.25
1365.34	2462.25
1364.81	2451.5
1364.27	2451.75
1363.73	2436.25
1363.19	2425
1362.66	2480
1362.12	2440.5
1361.58	2474.75
1361.05	2496.75
1360.51	2482.75
1359.97	2490.5
1359.44	2398.25
1358.9	2450
1358.36	2478
1357.82	2518.25
1357.29	2363
1356.75	2454.5
1356.21	2482.5
1355.67	2438.25
1355.14	2378.5
1354.6	2458.25
1354.06	2410.5
1353.52	2420.25
1352.99	2432.25
1352.45	2417.75
1351.91	2443.5
1351.37	2367.25
1350.83	2440
1350.3	2465.25
1349.76	2392.5
1349.22	2461
1348.68	2365.5
1348.14	2406.75
1347.6	2408.5
1347.06	2446.75
1346.53	2361
1345.99	2398
1345.45	2452.25
1344.91	2429
1344.37	2407
1343.83	2384.5
1343.3	2408
1342.76	2454.5
1342.22	2413.25
1341.68	2399
1341.14	2425
1340.6	2369.75
1340.06	2427.75
1339.52	2388.75
1338.98	2436.25
1338.45	2507.5
1337.91	2376.75
1337.37	2399.5
1336.83	2360
1336.29	2396
1335.75	2395.5
1335.21	2352
1334.67	2439.5
1334.13	2422.75
1333.59	2403.5
1333.05	2345.5
1332.51	2445.75
1331.97	2393.25
1331.43	2302.75
1330.89	2422.75
1330.35	2327.75
1329.81	2370.75
1329.27	2359
1328.73	2373
1328.19	2349
1327.65	2411.25
1327.11	2441
1326.57	2371
1326.03	2390.75
1325.49	2375
1324.95	2346.5
1324.41	2338
1323.87	2333.75
1323.33	2394.25
1322.79	2425.5
1322.25	2373.5
1321.71	2370.25
1321.16	2408
1320.62	2350.25
1320.08	2323.25
1319.54	2384
1319	2336.5
1318.46	2363.5
1317.92	2310.25
1317.38	2346.75
1316.84	2352.25
1316.29	2381.25
1315.75	2339
1315.21	2316
1314.67	2373.5
1314.13	2416
1313.59	2343.75
1313.05	2282
1312.5	2344
1311.96	2392.75
1311.42	2338.75
1310.88	2323.75
1310.34	2352.5
1309.8	2355.25
1309.25	2353.25
1308.71	2341
1308.17	2305.5
1307.63	2363
1307.09	2302
1306.54	2293.5
1306	2323.25
1305.46	2312
1304.92	2371.75
1304.38	2301
1303.83	2313.25
1303.29	2360.25
1302.75	2332.25
1302.21	2315.75
1301.66	2316.5
1301.12	2349.75
1300.58	2333.5
1300.04	2298.75
1299.49	2342
1298.95	2331.25
1298.41	2371.75
1297.86	2297.5
1297.32	2306.75
1296.78	2389
1296.23	2337
1295.69	2319
1295.15	2280.75
1294.6	2345.75
1294.06	2302.25
1293.52	2339.5
1292.97	2307.5
1292.43	2317
1291.89	2330.25
1291.34	2332.25
1290.8	2337.5
1290.26	2318.5
1289.71	2298.75
1289.17	2376
1288.63	2307.5
1288.08	2317.5
1287.54	2335
1286.99	2331.25
1286.45	2277
1285.9	2347.25
1285.36	2343.5
1284.82	2298.75
1284.27	2299.25
1283.73	2310.25
1283.19	2299.25
1282.64	2272.25
1282.1	2329.5
1281.55	2329.75
1281.01	2319.5
1280.46	2300.25
1279.92	2278.75
1279.37	2350.5
1278.83	2296.25
1278.28	2311.25
1277.74	2307.25
1277.19	2349.25
1276.65	2315
1276.1	2291
1275.56	2266.5
1275.01	2319
1274.47	2296.5
1273.92	2345
1273.38	2313.5
1272.83	2384.75
1272.29	2299.5
1271.74	2303.25
1271.2	2343.25
1270.65	2363.75
1270.11	2324.75
1269.56	2346.75
1269.01	2312.75
1268.47	2267
1267.92	2327.25
1267.38	2312.5
1266.83	2306.5
1266.29	2361
1265.74	2293.25
1265.19	2273.25
1264.65	2292.25
1264.1	2341.75
1263.55	2350.75
1263.01	2303.5
1262.46	2287.5
1261.92	2349.75
1261.37	2340.75
1260.82	2265
1260.28	2282.5
1259.73	2338.75
1259.18	2399
1258.64	2281.75
1258.09	2308
1257.55	2329
1257	2350
1256.45	2273.5
1255.9	2340.75
1255.36	2346.25
1254.81	2292.5
1254.26	2309.5
1253.72	2366.25
1253.17	2330.75
1252.62	2374.5
1252.07	2339.25
1251.53	2367
1250.98	2323.5
1250.43	2292.5
1249.89	2339.5
1249.34	2323.25
1248.79	2325
1248.24	2374.75
1247.7	2341.25
1247.15	2330.5
1246.6	2325.75
1246.05	2363.75
1245.5	2323.25
1244.96	2309.25
1244.41	2351
1243.86	2351.5
1243.31	2359.5
1242.77	2303
1242.22	2347.75
1241.67	2391.75
1241.12	2310.5
1240.57	2373.75
1240.02	2402
1239.48	2361.75
1238.93	2353.5
1238.38	2362.25
1237.83	2354.5
1237.28	2398.75
1236.73	2344.5
1236.18	2318.75
1235.64	2358.5
1235.09	2345.25
1234.54	2362
1233.99	2354.5
1233.44	2394.75
1232.89	2374.5
1232.34	2365.25
1231.79	2326.25
1231.24	2338.25
1230.69	2373.5
1230.15	2372.5
1229.6	2409
1229.05	2351.75
1228.5	2351.25
1227.95	2383.75
1227.4	2323.25
1226.85	2357.25
1226.3	2355
1225.75	2396.5
1225.2	2289.75
1224.65	2342.25
1224.1	2378.5
1223.55	2328.75
1223	2381.75
1222.45	2387.5
1221.9	2395.75
1221.35	2317
1220.8	2367
1220.25	2366.75
1219.7	2340
1219.15	2355.5
1218.6	2345
1218.05	2397.5
1217.5	2392.5
1216.95	2367.75
1216.4	2318
1215.85	2400
1215.3	2323.75
1214.75	2324.75
1214.2	2352.25
1213.65	2355.75
1213.09	2372.75
1212.54	2374.75
1211.99	2372.75
1211.44	2357.25
1210.89	2377.25
1210.34	2340.75
1209.79	2342.5
1209.24	2304.25
1208.69	2394.75
1208.14	2366
1207.58	2326.25
1207.03	2285.5
1206.48	2311.75
1205.93	2376.5
1205.38	2419.25
1204.83	2363
1204.27	2375.75
1203.72	2355.25
1203.17	2389.25
1202.62	2396.5
1202.07	2405
1201.52	2363.25
1200.96	2353.25
1200.41	2348.5
1199.86	2404.5
1199.31	2366.75
1198.76	2351
1198.2	2342
1197.65	2421.75
1197.1	2369.5
1196.55	2353.5
1196	2354.25
1195.44	2348.25
1194.89	2337
1194.34	2421.25
1193.78	2416.5
1193.23	2415.5
1192.68	2389.5
1192.13	2344.75
1191.57	2356.25
1191.02	2443
1190.47	2370.75
1189.91	2375.5
1189.36	2401.5
1188.81	2402.5
1188.26	2440
1187.7	2369.5
1187.15	2400.75
1186.6	2450.75
1186.04	2445.5
1185.49	2381
1184.94	2366
1184.38	2426.75
1183.83	2401.25
1183.28	2397
1182.72	2451.75
1182.17	2442.5
1181.61	2422
1181.06	2399
1180.51	2427.5
1179.95	2432.5
1179.4	2448.5
1178.85	2397.5
1178.29	2439.5
1177.74	2427.25
1177.18	2414
1176.63	2434.25
1176.07	2461.25
1175.52	2437.5
1174.97	2437.25
1174.41	2430.25
1173.86	2464.5
1173.3	2441.5
1172.75	2416.5
1172.19	2440.75
1171.64	2439.5
1171.09	2467
1170.53	2519.75
1169.97	2464.5
1169.42	2464.5
1168.86	2500
1168.31	2452
1167.76	2411.5
1167.2	2466.75
1166.65	2477.25
1166.09	2444
1165.53	2430
1164.98	2522.5
1164.42	2480.25
1163.87	2452.75
1163.31	2503.25
1162.76	2492.75
1162.2	2543.75
1161.65	2475.75
1161.09	2433
1160.54	2528.75
1159.98	2495.75
1159.42	2451.25
1158.87	2506
1158.31	2545
1157.76	2527.75
1157.2	2543.25
1156.65	2580.75
1156.09	2539.25
1155.53	2534
1154.98	2538.25
1154.42	2528
1153.86	2573.5
1153.31	2498.5
1152.75	2567.75
1152.19	2605
1151.64	2617.75
1151.08	2648
1150.52	2575
1149.97	2575.5
1149.41	2707.75
1148.86	2597.25
1148.3	2587.25
1147.74	2624
1147.18	2647
1146.63	2613.25
1146.07	2623.75
1145.51	2686.5
1144.96	2649.5
1144.4	2654.25
1143.84	2683.75
1143.28	2683
1142.73	2684.5
1142.17	2674
1141.61	2692.5
1141.06	2727.25
1140.5	2755.5
1139.94	2735.5
1139.38	2699.25
1138.83	2700
1138.27	2757
1137.71	2709.25
1137.15	2748
1136.59	2708.5
1136.04	2753.5
1135.48	2765.5
1134.92	2738.5
1134.36	2740.25
1133.8	2743.25
1133.25	2757.5
1132.69	2693.5
1132.13	2755.5
1131.57	2775.25
1131.01	2790.25
1130.45	2782.25
1129.9	2767
1129.34	2775.25
1128.78	2824.75
1128.22	2771.25
1127.66	2795
1127.1	2795
1126.54	2791
1125.98	2856.5
1125.43	2829
1124.87	2832.5
1124.31	2838.25
1123.75	2769.25
1123.19	2852.75
1122.63	2787.75
1122.07	2781.75
1121.51	2808.75
1120.95	2816
1120.39	2891
1119.83	2788
1119.27	2803.75
1118.72	2841
1118.15	2782
1117.6	2780.5
1117.04	2809
1116.48	2796.25
1115.92	2846.5
1115.36	2768.75
1114.8	2793.5
1114.24	2840.75
1113.68	2815.75
1113.12	2844.5
1112.56	2820
1112	2825.5
1111.44	2816.75
1110.88	2744
1110.32	2848
1109.76	2776
1109.19	2755
1108.64	2755.25
1108.07	2768.25
1107.51	2761
1106.95	2755.25
1106.39	2749
1105.83	2822.75
1105.27	2790
1104.71	2749
1104.15	2727.25
1103.59	2719.25
1103.03	2758.25
1102.47	2693
1101.91	2721
1101.34	2716
1100.78	2664.75
1100.22	2690.5
1099.66	2677.25
1099.1	2739.5
1098.54	2730.75
1097.98	2692.25
1097.41	2653
1096.85	2736
1096.29	2687.25
1095.73	2721.25
1095.17	2658
1094.61	2681.5
1094.04	2643.5
1093.48	2664
1092.92	2662.75
1092.36	2701.25
1091.8	2698.25
1091.23	2672.5
1090.67	2656.75
1090.11	2661.5
1089.55	2585.5
1088.99	2570.25
1088.42	2576.25
1087.86	2602.5
1087.3	2597.5
1086.74	2607.25
1086.17	2615.25
1085.61	2584
1085.05	2596.75
1084.49	2550.5
1083.92	2506.75
1083.36	2650.75
1082.8	2541.75
1082.23	2546
1081.67	2616
1081.11	2586.25
1080.55	2579.5
1079.98	2518.75
1079.42	2551.25
1078.86	2561
1078.29	2503.25
1077.73	2502
1077.17	2583
1076.6	2587.5
1076.04	2537
1075.48	2526.25
1074.91	2487.75
1074.35	2487.75
1073.79	2455
1073.22	2511.75
1072.66	2506
1072.09	2522.25
1071.53	2495.75
1070.97	2532.5
1070.4	2507.25
1069.84	2487
1069.27	2410.75
1068.71	2478.5
1068.15	2431
1067.58	2448.25
1067.02	2462.5
1066.45	2462.75
1065.89	2454.5
1065.32	2470.75
1064.76	2493.25
1064.19	2500
1063.63	2422.5
1063.07	2506.5
1062.5	2445.75
1061.94	2496
1061.37	2541
1060.81	2493.5
1060.24	2498.25
1059.68	2514.5
1059.11	2526.75
1058.55	2460.75
1057.98	2505.75
1057.42	2554
1056.85	2509
1056.29	2415
1055.72	2516.75
1055.16	2505
1054.59	2475.5
1054.03	2464.25
1053.46	2536.75
1052.89	2584.75
1052.33	2485.75
1051.76	2481.75
1051.2	2504.25
1050.63	2513.25
1050.06	2483
1049.5	2477
1048.93	2532.5
1048.37	2525.25
1047.8	2501.25
1047.24	2527.25
1046.67	2485.25
1046.1	2516.25
1045.54	2443
1044.97	2432.5
1044.4	2430.75
1043.84	2427.75
1043.27	2498
1042.7	2466.75
1042.14	2461.75
1041.57	2508.25
1041.01	2503.25
1040.44	2472.5
1039.87	2489.75
1039.3	2448.75
1038.74	2467.5
1038.17	2491.5
1037.6	2489.5
1037.04	2489
1036.47	2477.25
1035.9	2465
1035.34	2492.25
1034.77	2458
1034.2	2474.25
1033.63	2510.5
1033.07	2500.75
1032.5	2435
1031.93	2475.75
1031.36	2451.5
1030.8	2441.5
1030.23	2429
1029.66	2450
1029.09	2511.25
1028.52	2466.5
1027.96	2500.75
1027.39	2464.25
1026.82	2523.25
1026.25	2451.25
1025.68	2486
1025.12	2460.25
1024.55	2459.5
1023.98	2403.25
1023.41	2441.5
1022.84	2460.5
1022.28	2476.25
1021.71	2406.25
1021.14	2488.75
1020.57	2493.25
1020	2408.25
1019.43	2484
1018.86	2477.5
1018.3	2470.25
1017.73	2465
1017.16	2480.75
1016.59	2443.75
1016.3	2462.25