File: Testing/Hickernall_HORIBA/g15-mi1incl_01.txt
#Acq. time (s)=	30
#Accumulations=	3
#Range=	Off
#Autofocus=	Off
#Macrospot=	Off
#AutoExposure=	Off
#Spike filter=	Multiple accum.
#Delay time (s)=	0
#Binning=	1
#Readout mode=	Signal
#DeNoise=	Off
#ICS correction=	Off
#Dark correction=	Off
#Inst. Process=	Off
#Instrument=	LabRAM HR Evol
#Detector=	Andor CCD
#Objective=	x100 LWD
#Grating=	1800 gr/mm
#ND Filter=	100%
#Laser (nm)=	532
#Spectro (cm-¹)=	1240.02
#Hole=	49.98
#Range=	Visible
#AFM=	Off
#StageXY=	Marzhauser
#StageZ=	Marzhauser
#X (µm)=	-5516.7
#Y (µm)=	-1264.3
#Z (µm)=	-324.5
#Project=
#Sample=
#Site=
#Title=	g15-mi1incl
#Remark=
#Date=	06.05.2022 08:28
#Acquired=	06.05.2022 08:28:27
1454.81	4184
1454.28	4252
1453.75	4303
1453.22	4192
1452.69	4188.5
1452.16	4240
1451.64	4125
1451.11	4206
1450.58	4183
1450.05	4102.5
1449.52	4260
1448.99	4222
1448.46	4173
1447.93	4178
1447.4	4215
1446.88	4218.5
1446.35	4256.5
1445.82	4260
1445.29	4144
1444.76	4197.5
1444.23	4218
1443.7	4222
1443.17	4157
1442.64	4195.5
1442.11	4185
1441.58	4174.5
1441.05	4189.5
1440.52	4143
1439.99	4230
1439.46	4166
1438.93	4098
1438.4	4114.5
1437.87	4150.5
1437.34	4173
1436.81	4228
1436.28	4168
1435.75	4126
1435.22	4171.5
1434.69	4274.5
1434.16	4084.5
1433.63	4131.5
1433.1	4122.5
1432.57	4199.5
1432.04	4125
1431.51	4158
1430.98	4090
1430.45	4161
1429.92	4160.5
1429.39	4160.5
1428.86	4196.5
1428.33	4091
1427.8	4056
1427.26	4108.5
1426.73	4148.5
1426.2	4178.5
1425.67	4082.5
1425.14	4109
1424.61	4134.5
1424.08	4119
1423.55	4078.5
1423.02	4049
1422.49	4169.5
1421.95	4174
1421.42	4218
1420.89	4119
1420.36	4115.5
1419.83	4127.5
1419.3	4183.5
1418.76	4168.5
1418.23	4058
1417.7	4240
1417.17	4118.5
1416.64	3965
1416.1	4184
1415.57	4084
1415.04	4091.5
1414.51	4108.5
1413.98	4073.5
1413.44	4112.5
1412.91	4160
1412.38	4083.5
1411.85	4163.5
1411.32	4141
1410.78	4204.5
1410.25	4012
1409.72	4067
1409.18	4087
1408.65	4135.5
1408.12	4016
1407.59	4067
1407.05	4109.5
1406.52	4100
1405.99	4061.5
1405.46	4084
1404.92	3984.5
1404.39	4167
1403.86	4027.5
1403.32	4030
1402.79	3940
1402.26	4115
1401.72	4031.5
1401.19	4048.5
1400.66	4077.5
1400.12	4027.5
1399.59	4065.5
1399.06	4058.5
1398.52	3993.5
1397.99	4101.5
1397.46	4078
1396.92	4056.5
1396.39	4059.5
1395.85	4173.5
1395.32	4048.5
1394.79	3990.5
1394.25	3962
1393.72	4091
1393.18	3962
1392.65	4001
1392.12	4018.5
1391.58	4035
1391.05	4155
1390.51	4072.5
1389.98	4067
1389.44	4151
1388.91	4060
1388.38	4089.5
1387.84	4065
1387.31	4024.5
1386.77	4108.5
1386.24	3997.5
1385.7	3992
1385.17	3995
1384.63	4019.5
1384.1	4025
1383.56	3876
1383.03	4084.5
1382.49	4080
1381.96	4036
1381.42	4032
1380.89	3910
1380.35	4004
1379.82	3912
1379.28	4080
1378.74	4031
1378.21	3993
1377.67	4108.5
1377.14	3985
1376.6	4011
1376.07	4031.5
1375.53	3967
1374.99	3927
1374.46	3965
1373.92	4033.5
1373.39	3989
1372.85	3956
1372.32	3873
1371.78	3975
1371.24	3993
1370.71	3947
1370.17	3962.5
1369.63	3859
1369.1	3987
1368.56	4004
1368.03	3976
1367.49	3988.5
1366.95	3994.5
1366.42	3890
1365.88	4020
1365.34	3990
1364.81	4091.5
1364.27	3985
1363.73	3924
1363.19	4032.5
1362.66	4031
1362.12	4016.5
1361.58	3967
1361.05	3927
1360.51	4080.5
1359.97	4057.5
1359.44	3879.5
1358.9	3982.5
1358.36	3853
1357.82	4025
1357.29	3822
1356.75	3887
1356.21	3930
1355.67	4030
1355.14	3911
1354.6	3847
1354.06	3921.5
1353.52	3960
1352.99	3789
1352.45	3960.5
1351.91	3964
1351.37	4023.5
1350.83	3963
1350.3	3995.5
1349.76	3956.5
1349.22	3951.5
1348.68	3879
1348.14	3960.5
1347.6	4021
1347.06	3965
1346.53	3929
1345.99	3910
1345.45	3984
1344.91	3912.5
1344.37	3914
1343.83	3772
1343.3	3969.5
1342.76	3889.5
1342.22	3945
1341.68	3880
1341.14	3936
1340.6	3905
1340.06	3922.5
1339.52	3852
1338.98	3833
1338.45	4023
1337.91	3765
1337.37	3904
1336.83	3854.5
1336.29	3881
1335.75	3957
1335.21	3895.5
1334.67	3843
1334.13	3953
1333.59	3920
1333.05	3859.5
1332.51	3927.5
1331.97	3845
1331.43	3816.5
1330.89	3890
1330.35	3843
1329.81	3878
1329.27	3943
1328.73	3705.5
1328.19	3867.5
1327.65	3842
1327.11	3877.5
1326.57	3778
1326.03	3853.5
1325.49	3862
1324.95	3875.5
1324.41	3812
1323.87	3751.5
1323.33	3727
1322.79	3741
1322.25	3809
1321.71	3821
1321.16	3827.5
1320.62	3878
1320.08	3754
1319.54	3779.5
1319	3843
1318.46	3872.5
1317.92	3784.5
1317.38	3752
1316.84	3825.5
1316.29	3799
1315.75	3826.5
1315.21	3718
1314.67	3846
1314.13	3803
1313.59	3816.5
1313.05	3806
1312.5	3809
1311.96	3900
1311.42	3723
1310.88	3798.5
1310.34	3817.5
1309.8	3830.5
1309.25	3767
1308.71	3747.5
1308.17	3740.5
1307.63	3796.5
1307.09	3823
1306.54	3710.5
1306	3775.5
1305.46	3783
1304.92	3875.5
1304.38	3694
1303.83	3786
1303.29	3744
1302.75	3684
1302.21	3727
1301.66	3730
1301.12	3798.5
1300.58	3681
1300.04	3734
1299.49	3716
1298.95	3746
1298.41	3712.5
1297.86	3846.5
1297.32	3718
1296.78	3813
1296.23	3772
1295.69	3735
1295.15	3695
1294.6	3694
1294.06	3770
1293.52	3755
1292.97	3734.5
1292.43	3793.5
1291.89	3656
1291.34	3752
1290.8	3714.5
1290.26	3780
1289.71	3782
1289.17	3810
1288.63	3698
1288.08	3688.5
1287.54	3830
1286.99	3820
1286.45	3662
1285.9	3754.5
1285.36	3770
1284.82	3672
1284.27	3719.5
1283.73	3741
1283.19	3785.5
1282.64	3717.5
1282.1	3727
1281.55	3708.5
1281.01	3748
1280.46	3715
1279.92	3773.5
1279.37	3793.5
1278.83	3798
1278.28	3644.5
1277.74	3700.5
1277.19	3777
1276.65	3679.5
1276.1	3725.5
1275.56	3735
1275.01	3699
1274.47	3723.5
1273.92	3709
1273.38	3613
1272.83	3757.5
1272.29	3747.5
1271.74	3771.5
1271.2	3771
1270.65	3670.5
1270.11	3686
1269.56	3726
1269.01	3671.5
1268.47	3697
1267.92	3676
1267.38	3651
1266.83	3708
1266.29	3619
1265.74	3710.5
1265.19	3686.5
1264.65	3662
1264.1	3796
1263.55	3783.5
1263.01	3685
1262.46	3705.5
1261.92	3687
1261.37	3763.5
1260.82	3757
1260.28	3742.5
1259.73	3701
1259.18	3830.5
1258.64	3807
1258.09	3680
1257.55	3751
1257	3746
1256.45	3779
1255.9	3657.5
1255.36	3829
1254.81	3696
1254.26	3612.5
1253.72	3706
1253.17	3717.5
1252.62	3838.5
1252.07	3776.5
1251.53	3769
1250.98	3749
1250.43	3743
1249.89	3754
1249.34	3707.5
1248.79	3727.5
1248.24	3817
1247.7	3773.5
1247.15	3743
1246.6	3779
1246.05	3767.5
1245.5	3756.5
1244.96	3606
1244.41	3745
1243.86	3732
1243.31	3699
1242.77	3756.5
1242.22	3693.5
1241.67	3780.5
1241.12	3758.5
1240.57	3729
1240.02	3813.5
1239.48	3775
1238.93	3753
1238.38	3736
1237.83	3722.5
1237.28	3772
1236.73	3744
1236.18	3668.5
1235.64	3740
1235.09	3743.5
1234.54	3798
1233.99	3738
1233.44	3740
1232.89	3808.5
1232.34	3852
1231.79	3725
1231.24	3810
1230.69	3782
1230.15	3776
1229.6	3746
1229.05	3720
1228.5	3686
1227.95	3780
1227.4	3766
1226.85	3730
1226.3	3806
1225.75	3766.5
1225.2	3770.5
1224.65	3815
1224.1	3808
1223.55	3723.5
1223	3769
1222.45	3787
1221.9	3727.5
1221.35	3682
1220.8	3685
1220.25	3729
1219.7	3819
1219.15	3787.5
1218.6	3756.5
1218.05	3792.5
1217.5	3834.5
1216.95	3891
1216.4	3774
1215.85	3652
1215.3	3786
1214.75	3771
1214.2	3686.5
1213.65	3735
1213.09	3788
1212.54	3815
1211.99	3653
1211.44	3801
1210.89	3731
1210.34	3753
1209.79	3755
1209.24	3677.5
1208.69	3748
1208.14	3713
1207.58	3763.5
1207.03	3654
1206.48	3557
1205.93	3783.5
1205.38	3730
1204.83	3692.5
1204.27	3723
1203.72	3752
1203.17	3671.5
1202.62	3707.5
1202.07	3857
1201.52	3659
1200.96	3713
1200.41	3695
1199.86	3720.5
1199.31	3733.5
1198.76	3732
1198.2	3688
1197.65	3702
1197.1	3726
1196.55	3742
1196	3776
1195.44	3715
1194.89	3654
1194.34	3704
1193.78	3610
1193.23	3749
1192.68	3728
1192.13	3766.5
1191.57	3719
1191.02	3798
1190.47	3828
1189.91	3707.5
1189.36	3686
1188.81	3811
1188.26	3832.5
1187.7	3757.5
1187.15	3797
1186.6	3823
1186.04	3781.5
1185.49	3741.5
1184.94	3776
1184.38	3786
1183.83	3881
1183.28	3715.5
1182.72	3871.5
1182.17	3718
1181.61	3870
1181.06	3758
1180.51	3765
1179.95	3853.5
1179.4	3860.5
1178.85	3725.5
1178.29	3804
1177.74	3792.5
1177.18	3902
1176.63	3833.5
1176.07	3822
1175.52	3871.5
1174.97	3874.5
1174.41	3769.5
1173.86	3746
1173.3	3845.5
1172.75	3828.5
1172.19	3906.5
1171.64	3799.5
1171.09	3751
1170.53	3778
1169.97	3887.5
1169.42	3892.5
1168.86	3931.5
1168.31	3897
1167.76	3842
1167.2	3843
1166.65	3949
1166.09	3867
1165.53	3918.5
1164.98	3926.5
1164.42	3883
1163.87	3784
1163.31	3942
1162.76	3827
1162.2	4008.5
1161.65	3881
1161.09	3856
1160.54	3895
1159.98	3982.5
1159.42	3906
1158.87	3922
1158.31	3974
1157.76	3989
1157.2	4035.5
1156.65	3953
1156.09	3891
1155.53	4063
1154.98	3984.5
1154.42	4047
1153.86	3971
1153.31	4082
1152.75	3999
1152.19	4024.5
1151.64	4009.5
1151.08	4002
1150.52	3985
1149.97	4032.5
1149.41	4074.5
1148.86	4057
1148.3	4065.5
1147.74	4073
1147.18	4135.5
1146.63	4139.5
1146.07	4084
1145.51	4063.5
1144.96	4193.5
1144.4	4046
1143.84	4111.5
1143.28	4172.5
1142.73	4185
1142.17	4165
1141.61	4213
1141.06	4180
1140.5	4218
1139.94	4273.5
1139.38	4112.5
1138.83	4149.5
1138.27	4189.5
1137.71	4331
1137.15	4196
1136.59	4274
1136.04	4271
1135.48	4361.5
1134.92	4215.5
1134.36	4300
1133.8	4345.5
1133.25	4343
1132.69	4257.5
1132.13	4267.5
1131.57	4389
1131.01	4367.5
1130.45	4350.5
1129.9	4272.5
1129.34	4388.5
1128.78	4269
1128.22	4351.5
1127.66	4329
1127.1	4399.5
1126.54	4311
1125.98	4311.5
1125.43	4380
1124.87	4355
1124.31	4416
1123.75	4271
1123.19	4317
1122.63	4492
1122.07	4401
1121.51	4316.5
1120.95	4450.5
1120.39	4481.5
1119.83	4422
1119.27	4365
1118.72	4347
1118.15	4408.5
1117.6	4393.5
1117.04	4349
1116.48	4480.5
1115.92	4427
1115.36	4384.5
1114.8	4401.5
1114.24	4355
1113.68	4432
1113.12	4322
1112.56	4367.5
1112	4537
1111.44	4406.5
1110.88	4378
1110.32	4406
1109.76	4305.5
1109.19	4333.5
1108.64	4373.5
1108.07	4242
1107.51	4338.5
1106.95	4380
1106.39	4386.5
1105.83	4274.5
1105.27	4194
1104.71	4333.5
1104.15	4261
1103.59	4363
1103.03	4345
1102.47	4354
1101.91	4227.5
1101.34	4237
1100.78	4178.5
1100.22	4269
1099.66	4232.5
1099.1	4225.5
1098.54	4286
1097.98	4239.5
1097.41	4236
1096.85	4251
1096.29	4259.5
1095.73	4242
1095.17	4119.5
1094.61	4222.5
1094.04	4179.5
1093.48	4161.5
1092.92	4145
1092.36	4194.5
1091.8	4231
1091.23	4161
1090.67	4176.5
1090.11	4170
1089.55	4152.5
1088.99	4075
1088.42	4057
1087.86	4058.5
1087.3	4103
1086.74	4024
1086.17	4081
1085.61	4153
1085.05	4062.5
1084.49	3970
1083.92	4052
1083.36	4162
1082.8	4060
1082.23	4064.5
1081.67	4021
1081.11	4199
1080.55	3976.5
1079.98	3951
1079.42	3981.5
1078.86	4010.5
1078.29	3976
1077.73	3989
1077.17	3947
1076.6	3890.5
1076.04	4002
1075.48	3932.5
1074.91	3943.5
1074.35	3999.5
1073.79	4001.5
1073.22	3879.5
1072.66	3978
1072.09	3972
1071.53	3858.5
1070.97	3866
1070.4	3817
1069.84	3905.5
1069.27	4008
1068.71	3868
1068.15	3936
1067.58	3898.5
1067.02	3844
1066.45	3935
1065.89	3932
1065.32	3868.5
1064.76	3812.5
1064.19	3899
1063.63	3923
1063.07	3892
1062.5	3800
1061.94	3849
1061.37	3924
1060.81	3914
1060.24	3839.5
1059.68	3864
1059.11	3862
1058.55	3878.5
1057.98	3874
1057.42	3893
1056.85	3962
1056.29	3926.5
1055.72	3850
1055.16	3937
1054.59	3868.5
1054.03	3929
1053.46	3897.5
1052.89	3941.5
1052.33	3854.5
1051.76	3816
1051.2	3956
1050.63	3949
1050.06	3757
1049.5	3932
1048.93	3937
1048.37	3911
1047.8	3957
1047.24	3807.5
1046.67	3920.5
1046.1	3913.5
1045.54	3881.5
1044.97	3909.5
1044.4	3918
1043.84	3870
1043.27	3862
1042.7	3811
1042.14	3927
1041.57	3876
1041.01	3889.5
1040.44	3935
1039.87	3886.5
1039.3	3749
1038.74	3874
1038.17	3803
1037.6	3860.5
1037.04	3835
1036.47	3822.5
1035.9	3864
1035.34	3884.5
1034.77	3934
1034.2	3760
1033.63	3878
1033.07	3868
1032.5	3798
1031.93	3868
1031.36	3838.5
1030.8	3757
1030.23	3915.5
1029.66	3815
1029.09	3825.5
1028.52	3853
1027.96	3748.5
1027.39	3801
1026.82	3862
1026.25	3804.5
1025.68	3811
1025.12	3818.5
1024.55	3857.5
1023.98	3844
1023.41	3720.5
1022.84	3787
1022.28	3847
1021.71	3835.5
1021.14	3800.5
1020.57	3840
1020	3800
1019.43	3797
1018.86	3788
1018.3	3845.5
1017.73	3856
1017.16	3854
1016.59	3840
1016.3	3803