File: Testing/Hickernall_HORIBA/g15-mi1_02.txt
#Acq. time (s)=	75
#Accumulations=	5
#Range=	Off
#Autofocus=	Off
#Macrospot=	Off
#AutoExposure=	Off
#Spike filter=	Multiple accum.
#Delay time (s)=	0
#Binning=	1
#Readout mode=	Signal
#DeNoise=	Off
#ICS correction=	Off
#Dark correction=	Off
#Inst. Process=	Off
#Instrument=	LabRAM HR Evol
#Detector=	Andor CCD
#Objective=	x100 LWD
#Grating=	1800 gr/mm
#ND Filter=	100%
#Laser (nm)=	532
#Spectro (cm-¹)=	1240.02
#Hole=	49.98
#Range=	Visible
#AFM=	Off
#StageXY=	Marzhauser
#StageZ=	Marzhauser
#X (µm)=	-5510.6
#Y (µm)=	-1273.4
#Z (µm)=	-324
#Project=
#Sample=
#Site=
#Title=	g15-mi1
#Remark=
#Date=	06.05.2022 08:21
#Acquired=	06.05.2022 08:21:36
1454.81	3386.75
1454.28	3350.5
1453.75	3476.25
1453.22	3419.75
1452.69	3377.25
1452.16	3305.25
1451.64	3414.5
1451.11	3420
1450.58	3370
1450.05	3333.25
1449.52	3371
1448.99	3424
1448.46	3386.75
1447.93	3357.25
1447.4	3338.25
1446.88	3375.5
1446.35	3330.25
1445.82	3387.25
1445.29	3343.75
1444.76	3351.75
1444.23	3343.75
1443.7	3368
1443.17	3353.5
1442.64	3400.5
1442.11	3333.25
1441.58	3300.25
1441.05	3363
1440.52	3339.75
1439.99	3361
1439.46	3269
1438.93	3291.5
1438.4	3285
1437.87	3322.5
1437.34	3393.25
1436.81	3366.25
1436.28	3266
1435.75	3395.25
1435.22	3387.25
1434.69	3299.75
1434.16	3326.75
1433.63	3244.75
1433.1	3338.75
1432.57	3306
1432.04	3299.75
1431.51	3231.25
1430.98	3326.5
1430.45	3348.5
1429.92	3307.5
1429.39	3260.75
1428.86	3334.25
1428.33	3349
1427.8	3293.25
1427.26	3271
1426.73	3327.25
1426.2	3296.75
1425.67	3322.5
1425.14	3275.75
1424.61	3354.75
1424.08	3338.25
1423.55	3345.25
1423.02	3319.25
1422.49	3270.75
1421.95	3344.5
1421.42	3298.25
1420.89	3322.5
1420.36	3287
1419.83	3316.5
1419.3	3281.25
1418.76	3259.5
1418.23	3277.25
1417.7	3307
1417.17	3305.75
1416.64	3198.75
1416.1	3277.5
1415.57	3259.5
1415.04	3263.5
1414.51	3176.5
1413.98	3233.75
1413.44	3300.5
1412.91	3344.25
1412.38	3248
1411.85	3266.5
1411.32	3293
1410.78	3286.25
1410.25	3276.5
1409.72	3261.5
1409.18	3339
1408.65	3339
1408.12	3223
1407.59	3196.5
1407.05	3298.75
1406.52	3295.75
1405.99	3241.5
1405.46	3221.5
1404.92	3211.75
1404.39	3273
1403.86	3245.25
1403.32	3251
1402.79	3305.25
1402.26	3315.75
1401.72	3264.75
1401.19	3217.75
1400.66	3164
1400.12	3293.5
1399.59	3322
1399.06	3209.5
1398.52	3219.75
1397.99	3201.75
1397.46	3299
1396.92	3222
1396.39	3231.75
1395.85	3196.25
1395.32	3227.75
1394.79	3206.75
1394.25	3175.5
1393.72	3214.5
1393.18	3247.75
1392.65	3252.75
1392.12	3212.75
1391.58	3274.5
1391.05	3196
1390.51	3212.5
1389.98	3233.25
1389.44	3264
1388.91	3236.25
1388.38	3283.75
1387.84	3186
1387.31	3221.25
1386.77	3231.75
1386.24	3169.5
1385.7	3256.25
1385.17	3233.75
1384.63	3246
1384.1	3204
1383.56	3250.5
1383.03	3249
1382.49	3308
1381.96	3237
1381.42	3290.5
1380.89	3304.75
1380.35	3339.75
1379.82	3239.25
1379.28	3223.75
1378.74	3293.5
1378.21	3325.75
1377.67	3290
1377.14	3337.25
1376.6	3274
1376.07	3228
1375.53	3258.75
1374.99	3197.75
1374.46	3234
1373.92	3254
1373.39	3302.5
1372.85	3169.75
1372.32	3255
1371.78	3223
1371.24	3238.5
1370.71	3191.25
1370.17	3119
1369.63	3211
1369.1	3221.75
1368.56	3223
1368.03	3161.25
1367.49	3236.5
1366.95	3182.75
1366.42	3154
1365.88	3172
1365.34	3141
1364.81	3213.75
1364.27	3166.75
1363.73	3172.75
1363.19	3166.5
1362.66	3167.5
1362.12	3187.25
1361.58	3179.5
1361.05	3209.5
1360.51	3208.25
1359.97	3167
1359.44	3137.5
1358.9	3174.5
1358.36	3171.25
1357.82	3207
1357.29	3146
1356.75	3141
1356.21	3208.75
1355.67	3209.75
1355.14	3158.25
1354.6	3198.5
1354.06	3125.25
1353.52	3157.25
1352.99	3198.25
1352.45	3163
1351.91	3208.5
1351.37	3130.5
1350.83	3142.5
1350.3	3084.5
1349.76	3121.25
1349.22	3176.5
1348.68	3168.25
1348.14	3109.5
1347.6	3133.75
1347.06	3160.75
1346.53	3105.5
1345.99	3101.75
1345.45	3112.5
1344.91	3129.25
1344.37	3132.75
1343.83	3116.5
1343.3	3090.5
1342.76	3158.25
1342.22	3113.5
1341.68	3078.5
1341.14	3114.75
1340.6	3122.75
1340.06	3146.75
1339.52	3062.25
1338.98	3107.25
1338.45	3108
1337.91	3124.25
1337.37	3106.25
1336.83	3091.25
1336.29	3148.25
1335.75	3107.75
1335.21	3118.5
1334.67	3122.25
1334.13	3062.75
1333.59	3071.25
1333.05	3025.5
1332.51	3102.25
1331.97	3102.75
1331.43	3065.75
1330.89	3042.25
1330.35	3037.25
1329.81	3105.5
1329.27	3120.5
1328.73	3038.75
1328.19	2985.25
1327.65	3076.25
1327.11	3045
1326.57	3072.75
1326.03	3059.25
1325.49	3080.75
1324.95	3103.75
1324.41	3031.5
1323.87	3011.75
1323.33	3029
1322.79	3067.5
1322.25	3037.5
1321.71	3104
1321.16	3025
1320.62	3037.5
1320.08	3058
1319.54	3059.5
1319	3039.75
1318.46	3108.5
1317.92	3032.75
1317.38	3002
1316.84	3054.75
1316.29	3050.25
1315.75	3069
1315.21	3029
1314.67	3080
1314.13	3046.5
1313.59	2999.5
1313.05	2974
1312.5	3062.5
1311.96	3061.5
1311.42	3070.25
1310.88	3029.25
1310.34	3076.5
1309.8	3009.25
1309.25	3073.5
1308.71	2964
1308.17	3040.25
1307.63	3075.25
1307.09	3089.5
1306.54	3025
1306	3029.25
1305.46	2969
1304.92	3043.75
1304.38	2995
1303.83	3000.5
1303.29	3018.25
1302.75	2972.25
1302.21	2990
1301.66	3006
1301.12	3071.75
1300.58	3041.25
1300.04	3040.25
1299.49	2979
1298.95	3026.75
1298.41	3017
1297.86	2929.75
1297.32	2981.5
1296.78	3044.75
1296.23	2994.25
1295.69	2980
1295.15	2981.25
1294.6	3037.5
1294.06	2965
1293.52	2949
1292.97	2957
1292.43	3018.25
1291.89	2934.5
1291.34	2987.75
1290.8	2973
1290.26	3017.5
1289.71	3019
1289.17	2949.75
1288.63	2963.75
1288.08	3011
1287.54	3048.75
1286.99	3005.5
1286.45	2981.5
1285.9	3021.25
1285.36	2987.5
1284.82	2955.75
1284.27	2993
1283.73	3015.5
1283.19	2981.25
1282.64	3013.5
1282.1	3012.25
1281.55	2966.5
1281.01	2997
1280.46	2975
1279.92	2959.25
1279.37	3000.75
1278.83	2976.5
1278.28	2951.5
1277.74	2926.25
1277.19	2999.25
1276.65	3010
1276.1	2980.75
1275.56	2979.75
1275.01	2923
1274.47	3034.25
1273.92	2966.5
1273.38	2998.5
1272.83	3001.25
1272.29	2992.25
1271.74	3014
1271.2	2958.25
1270.65	3033.5
1270.11	2953
1269.56	2997
1269.01	2892
1268.47	3024.5
1267.92	2986
1267.38	3007.25
1266.83	2941.75
1266.29	2960.75
1265.74	2970.5
1265.19	3028.25
1264.65	2924
1264.1	2989
1263.55	3026.5
1263.01	2932.5
1262.46	2953.75
1261.92	2968.75
1261.37	2998.75
1260.82	3018.25
1260.28	2976
1259.73	3034
1259.18	3037.5
1258.64	3006.5
1258.09	2975.25
1257.55	2984
1257	3023.5
1256.45	2963.75
1255.9	2975
1255.36	3002
1254.81	3034.75
1254.26	2980
1253.72	3008.25
1253.17	2944.25
1252.62	2953.25
1252.07	2945.75
1251.53	2988
1250.98	2990.5
1250.43	3018.75
1249.89	2959.5
1249.34	2980.75
1248.79	3003.5
1248.24	3101
1247.7	2989
1247.15	2972.25
1246.6	3066.25
1246.05	3036
1245.5	3039
1244.96	2988.75
1244.41	2979.25
1243.86	3025.25
1243.31	3035.5
1242.77	2943.25
1242.22	3017.25
1241.67	3011
1241.12	2998.25
1240.57	2968.25
1240.02	3108.25
1239.48	3052
1238.93	3032
1238.38	2984.5
1237.83	3071.25
1237.28	3056
1236.73	2993.75
1236.18	2988.75
1235.64	3057.75
1235.09	3030.75
1234.54	3065.75
1233.99	2948.25
1233.44	3108.5
1232.89	3016.5
1232.34	3060
1231.79	3035
1231.24	3100.25
1230.69	3020.75
1230.15	3101.5
1229.6	2988.75
1229.05	3004.75
1228.5	3099.25
1227.95	3075.5
1227.4	3036.25
1226.85	3044.25
1226.3	3032.5
1225.75	3053
1225.2	3010.25
1224.65	3022.25
1224.1	3036.75
1223.55	3010.5
1223	3069.75
1222.45	3057.75
1221.9	2968.75
1221.35	3064
1220.8	3082.5
1220.25	3063.75
1219.7	3078
1219.15	2960.5
1218.6	3037.5
1218.05	3083.75
1217.5	3078
1216.95	2977
1216.4	2960
1215.85	3093.75
1215.3	3051.5
1214.75	3061.75
1214.2	3051.75
1213.65	3015.5
1213.09	3082.25
1212.54	3036.25
1211.99	2998.5
1211.44	3019.5
1210.89	3038.5
1210.34	2978.75
1209.79	3033.5
1209.24	3021.75
1208.69	3030
1208.14	3024.75
1207.58	3014.5
1207.03	3013.25
1206.48	3028
1205.93	3077
1205.38	3026.5
1204.83	3052.5
1204.27	3014.75
1203.72	3090
1203.17	3010
1202.62	3000.25
1202.07	3081.25
1201.52	3040.75
1200.96	3056
1200.41	3077.25
1199.86	3013.75
1199.31	3067
1198.76	3015
1198.2	3009.25
1197.65	3059.75
1197.1	3035.75
1196.55	3045.5
1196	3032.5
1195.44	3040.25
1194.89	3021.25
1194.34	3031.25
1193.78	3044
1193.23	3030.5
1192.68	3060
1192.13	3016
1191.57	3044.25
1191.02	3143.5
1190.47	3006.5
1189.91	3067.5
1189.36	3090
1188.81	3132.75
1188.26	3089.75
1187.7	3050.25
1187.15	3076
1186.6	3111
1186.04	3144
1185.49	3127.75
1184.94	3094
1184.38	3141.75
1183.83	3125.5
1183.28	3144
1182.72	3132.25
1182.17	3151.25
1181.61	3097.5
1181.06	3070.75
1180.51	3073
1179.95	3142.25
1179.4	3095.75
1178.85	3053.5
1178.29	3093
1177.74	3077.75
1177.18	3086.75
1176.63	3128.25
1176.07	3134
1175.52	3100.5
1174.97	3100.5
1174.41	3100
1173.86	3131
1173.3	3166.75
1172.75	3164.25
1172.19	3133.25
1171.64	3141.5
1171.09	3161.25
1170.53	3127.75
1169.97	3112.5
1169.42	3091.75
1168.86	3117
1168.31	3109
1167.76	3106.25
1167.2	3149.5
1166.65	3157.5
1166.09	3117.75
1165.53	3150.75
1164.98	3193.25
1164.42	3163.75
1163.87	3194.25
1163.31	3113.75
1162.76	3146.5
1162.2	3192.25
1161.65	3113.5
1161.09	3178.5
1160.54	3173.25
1159.98	3196
1159.42	3193
1158.87	3244
1158.31	3242.25
1157.76	3216.75
1157.2	3246.75
1156.65	3194.25
1156.09	3274.5
1155.53	3245.25
1154.98	3225.5
1154.42	3271
1153.86	3247.75
1153.31	3316.75
1152.75	3203.5
1152.19	3266
1151.64	3293.75
1151.08	3302.5
1150.52	3234.25
1149.97	3239
1149.41	3345
1148.86	3277.75
1148.3	3252
1147.74	3313.5
1147.18	3330
1146.63	3313
1146.07	3343.25
1145.51	3307.75
1144.96	3349
1144.4	3329.75
1143.84	3335.75
1143.28	3377.25
1142.73	3384.5
1142.17	3325.75
1141.61	3344
1141.06	3407
1140.5	3338.5
1139.94	3377.25
1139.38	3372.25
1138.83	3416.75
1138.27	3396
1137.71	3397.5
1137.15	3403.75
1136.59	3408.75
1136.04	3450.25
1135.48	3489.75
1134.92	3402.25
1134.36	3429.75
1133.8	3463
1133.25	3433.75
1132.69	3436.75
1132.13	3480
1131.57	3488.5
1131.01	3405.5
1130.45	3423.5
1129.9	3484.25
1129.34	3484.75
1128.78	3477.5
1128.22	3437
1127.66	3480.5
1127.1	3485.75
1126.54	3486
1125.98	3522.5
1125.43	3564.75
1124.87	3488.75
1124.31	3455.75
1123.75	3456.75
1123.19	3520.25
1122.63	3475.75
1122.07	3406.5
1121.51	3454.5
1120.95	3440.25
1120.39	3492
1119.83	3456
1119.27	3478.5
1118.72	3507.5
1118.15	3514
1117.6	3427.5
1117.04	3485.5
1116.48	3514.25
1115.92	3497.25
1115.36	3510.5
1114.8	3553.75
1114.24	3438
1113.68	3479.5
1113.12	3493.25
1112.56	3429.75
1112	3521.25
1111.44	3452.25
1110.88	3451.5
1110.32	3508
1109.76	3460.75
1109.19	3460
1108.64	3381.25
1108.07	3427.5
1107.51	3486.75
1106.95	3447
1106.39	3389
1105.83	3411.5
1105.27	3450.5
1104.71	3412.25
1104.15	3365.75
1103.59	3386
1103.03	3373.25
1102.47	3343.5
1101.91	3323.25
1101.34	3399.75
1100.78	3398
1100.22	3353.5
1099.66	3333.75
1099.1	3368.5
1098.54	3405.25
1097.98	3364.5
1097.41	3319.75
1096.85	3386
1096.29	3350.75
1095.73	3340.75
1095.17	3307
1094.61	3301.25
1094.04	3319.75
1093.48	3374
1092.92	3328
1092.36	3309
1091.8	3246.75
1091.23	3299.75
1090.67	3194
1090.11	3333
1089.55	3290.25
1088.99	3265.25
1088.42	3274.5
1087.86	3253
1087.3	3250.75
1086.74	3225
1086.17	3217.25
1085.61	3176.5
1085.05	3220
1084.49	3260
1083.92	3316
1083.36	3257.75
1082.8	3163
1082.23	3229.25
1081.67	3225.5
1081.11	3244.25
1080.55	3128
1079.98	3186
1079.42	3220.25
1078.86	3142.5
1078.29	3117
1077.73	3183.5
1077.17	3198.25
1076.6	3188.5
1076.04	3098
1075.48	3094.5
1074.91	3197.75
1074.35	3151.5
1073.79	3125.5
1073.22	3104.75
1072.66	3147.25
1072.09	3069.5
1071.53	3071.5
1070.97	3165.25
1070.4	3092.5
1069.84	3137.75
1069.27	3083.75
1068.71	3117
1068.15	3087
1067.58	3100.25
1067.02	3072
1066.45	3117.5
1065.89	3036
1065.32	3095.25
1064.76	3098.25
1064.19	3160.25
1063.63	3152.75
1063.07	3112.75
1062.5	3143.75
1061.94	3117
1061.37	3167.25
1060.81	3196
1060.24	3127.25
1059.68	3131.75
1059.11	3126.5
1058.55	3110.75
1057.98	3153.5
1057.42	3158.25
1056.85	3160.5
1056.29	3156.5
1055.72	3187.75
1055.16	3174
1054.59	3181
1054.03	3125.5
1053.46	3192.5
1052.89	3127.5
1052.33	3166.5
1051.76	3151
1051.2	3131.5
1050.63	3104.5
1050.06	3118.75
1049.5	3097.25
1048.93	3192.5
1048.37	3183
1047.8	3103.75
1047.24	3146.75
1046.67	3139.25
1046.1	3182.25
1045.54	3127.75
1044.97	3109.25
1044.4	3084
1043.84	3168.5
1043.27	3137
1042.7	3115.25
1042.14	3137.25
1041.57	3134.25
1041.01	3060.5
1040.44	3055.25
1039.87	3145.25
1039.3	3159.75
1038.74	3067.75
1038.17	3045
1037.6	3165.5
1037.04	3082
1036.47	3113.75
1035.9	3132.75
1035.34	3101.5
1034.77	3037.25
1034.2	3049
1033.63	3125.5
1033.07	3090.5
1032.5	3115
1031.93	3062.75
1031.36	3157.25
1030.8	3085.5
1030.23	3035.5
1029.66	3111.25
1029.09	3072.5
1028.52	3083.25
1027.96	3037.5
1027.39	3048.75
1026.82	3055.5
1026.25	3067.75
1025.68	3048.75
1025.12	3109
1024.55	3129.25
1023.98	3068.75
1023.41	3011
1022.84	3052.75
1022.28	3095.25
1021.71	3061.75
1021.14	3065.5
1020.57	3100
1020	3040.75
1019.43	2985.75
1018.86	3101.25
1018.3	3039.5
1017.73	3041
1017.16	3081.5
1016.59	3060.75
1016.3	3022.25