File: Testing/Hickernall_HORIBA/g36-mi1_02.txt
#Acq. time (s)=	75
#Accumulations=	5
#Range=	Off
#Autofocus=	Off
#Macrospot=	Off
#AutoExposure=	Off
#Spike filter=	Multiple accum.
#Delay time (s)=	0
#Binning=	1
#Readout mode=	Signal
#DeNoise=	Off
#ICS correction=	Off
#Dark correction=	Off
#Inst. Process=	Off
#Instrument=	LabRAM HR Evol
#Detector=	Andor CCD
#Objective=	x100 LWD
#Grating=	1800 gr/mm
#ND Filter=	100%
#Laser (nm)=	532
#Spectro (cm-¹)=	1240.02
#Hole=	49.98
#Range=	Visible
#AFM=	Off
#StageXY=	Marzhauser
#StageZ=	Marzhauser
#X (µm)=	-15775.7
#Y (µm)=	-1015.7
#Z (µm)=	-316.3
#Project=
#Sample=
#Site=
#Title=	g36-mi1
#Remark=
#Date=	06.05.2022 09:04
#Acquired=	06.05.2022 09:04:56
1454.81	943.25
1454.28	918.5
1453.75	934.5
1453.22	928.5
1452.69	925.75
1452.16	940.5
1451.64	933.5
1451.11	921.75
1450.58	917.25
1450.05	931.75
1449.52	911.25
1448.99	933.75
1448.46	937
1447.93	922.5
1447.4	928.5
1446.88	882
1446.35	906.5
1445.82	953.75
1445.29	926.5
1444.76	920.5
1444.23	945.5
1443.7	944.5
1443.17	933.5
1442.64	942.5
1442.11	887.25
1441.58	916.25
1441.05	902.5
1440.52	929
1439.99	919.25
1439.46	902.25
1438.93	895
1438.4	892.25
1437.87	902
1437.34	894
1436.81	938
1436.28	903
1435.75	893.5
1435.22	909.75
1434.69	928.25
1434.16	905.75
1433.63	902.5
1433.1	918.5
1432.57	872.5
1432.04	894.75
1431.51	896
1430.98	894.5
1430.45	874.5
1429.92	912.5
1429.39	893.5
1428.86	890
1428.33	930.25
1427.8	877.25
1427.26	864.75
1426.73	915.25
1426.2	891.25
1425.67	883.25
1425.14	879.25
1424.61	888.5
1424.08	916.25
1423.55	866
1423.02	911.5
1422.49	872.75
1421.95	887.75
1421.42	891
1420.89	875.25
1420.36	894.25
1419.83	880.5
1419.3	883
1418.76	878.5
1418.23	877.75
1417.7	875.75
1417.17	889.25
1416.64	871.75
1416.1	897.75
1415.57	897
1415.04	883.5
1414.51	867.75
1413.98	874.75
1413.44	887
1412.91	880.75
1412.38	893.75
1411.85	879
1411.32	936.75
1410.78	879.75
1410.25	887
1409.72	875.25
1409.18	877.5
1408.65	910.75
1408.12	873.5
1407.59	906.75
1407.05	864.75
1406.52	900.75
1405.99	890.75
1405.46	898.75
1404.92	868.5
1404.39	872
1403.86	870.25
1403.32	876
1402.79	917.75
1402.26	883.5
1401.72	840
1401.19	841.75
1400.66	898
1400.12	879.75
1399.59	856.25
1399.06	892.5
1398.52	878
1397.99	886
1397.46	912.75
1396.92	881.25
1396.39	879.75
1395.85	876.5
1395.32	888.75
1394.79	848.25
1394.25	842.75
1393.72	909.25
1393.18	883.75
1392.65	867.75
1392.12	855.5
1391.58	869.5
1391.05	863.5
1390.51	869.25
1389.98	885.5
1389.44	900.75
1388.91	952.75
1388.38	944
1387.84	962.5
1387.31	936.5
1386.77	865.5
1386.24	870.5
1385.7	861.5
1385.17	894.75
1384.63	897.75
1384.1	901.5
1383.56	899.25
1383.03	869.75
1382.49	915.25
1381.96	865.5
1381.42	864.25
1380.89	826
1380.35	888.75
1379.82	860
1379.28	885.25
1378.74	857.75
1378.21	893.75
1377.67	861.25
1377.14	918.75
1376.6	868
1376.07	859.5
1375.53	885
1374.99	893.75
1374.46	877.75
1373.92	816
1373.39	872.5
1372.85	860.5
1372.32	873.25
1371.78	844
1371.24	869.5
1370.71	872.5
1370.17	862
1369.63	868
1369.1	877
1368.56	880.5
1368.03	866.75
1367.49	901.75
1366.95	883.25
1366.42	866.5
1365.88	870.5
1365.34	857
1364.81	877.75
1364.27	887.5
1363.73	865.75
1363.19	878.25
1362.66	859.75
1362.12	859.5
1361.58	904.25
1361.05	901.5
1360.51	881.75
1359.97	853.25
1359.44	854.25
1358.9	896.75
1358.36	847
1357.82	895
1357.29	858
1356.75	890
1356.21	877
1355.67	858
1355.14	895.25
1354.6	851.25
1354.06	859.25
1353.52	870.75
1352.99	851.5
1352.45	853.75
1351.91	880.75
1351.37	871.75
1350.83	841
1350.3	856.75
1349.76	849.25
1349.22	893
1348.68	856.75
1348.14	836.5
1347.6	912
1347.06	873.5
1346.53	859.25
1345.99	861
1345.45	872
1344.91	885.75
1344.37	861.5
1343.83	869.5
1343.3	850.5
1342.76	856.5
1342.22	856
1341.68	866.75
1341.14	851.5
1340.6	896.25
1340.06	846.75
1339.52	853.75
1338.98	876
1338.45	847.25
1337.91	856.75
1337.37	828.25
1336.83	859.75
1336.29	879.75
1335.75	857.5
1335.21	868.25
1334.67	851.75
1334.13	886.25
1333.59	880.5
1333.05	873.75
1332.51	853
1331.97	856.5
1331.43	853.75
1330.89	869.5
1330.35	841
1329.81	842.25
1329.27	817.25
1328.73	861
1328.19	884
1327.65	819.25
1327.11	847.25
1326.57	872
1326.03	871.5
1325.49	883.5
1324.95	872.5
1324.41	842.5
1323.87	892.5
1323.33	873.75
1322.79	851.5
1322.25	828.75
1321.71	850.5
1321.16	870
1320.62	875.5
1320.08	878
1319.54	867.5
1319	846
1318.46	860.5
1317.92	881.75
1317.38	869.25
1316.84	903.5
1316.29	862.25
1315.75	901
1315.21	857.75
1314.67	886
1314.13	848.75
1313.59	881.5
1313.05	859.25
1312.5	879.25
1311.96	883.25
1311.42	864
1310.88	856.5
1310.34	859
1309.8	892.5
1309.25	884.5
1308.71	913
1308.17	912
1307.63	909
1307.09	875.75
1306.54	896.5
1306	859.75
1305.46	883
1304.92	897.75
1304.38	893
1303.83	870.75
1303.29	880.25
1302.75	870
1302.21	878
1301.66	868
1301.12	906.25
1300.58	898.25
1300.04	896.5
1299.49	857.75
1298.95	897
1298.41	895.25
1297.86	902.25
1297.32	898.5
1296.78	905
1296.23	844.5
1295.69	895.5
1295.15	910.25
1294.6	900.25
1294.06	885
1293.52	895.75
1292.97	902.5
1292.43	909.25
1291.89	894.5
1291.34	901.25
1290.8	862
1290.26	866.5
1289.71	903
1289.17	902.25
1288.63	916.25
1288.08	908.5
1287.54	917.5
1286.99	860
1286.45	919.5
1285.9	921
1285.36	997.75
1284.82	968
1284.27	891.5
1283.73	874.75
1283.19	884
1282.64	874.75
1282.1	887
1281.55	893.75
1281.01	884.75
1280.46	903.5
1279.92	873.75
1279.37	909
1278.83	871.25
1278.28	888.25
1277.74	907.5
1277.19	909.75
1276.65	880
1276.1	909
1275.56	840.25
1275.01	875.5
1274.47	866.75
1273.92	890
1273.38	890.75
1272.83	919.75
1272.29	894.25
1271.74	871.5
1271.2	857
1270.65	900
1270.11	873.5
1269.56	876.5
1269.01	899.75
1268.47	883.25
1267.92	886.5
1267.38	904.25
1266.83	874.25
1266.29	919
1265.74	902.25
1265.19	897.75
1264.65	884.25
1264.1	880.75
1263.55	870.25
1263.01	905.75
1262.46	886.5
1261.92	900
1261.37	909
1260.82	884.75
1260.28	900.5
1259.73	870.25
1259.18	944
1258.64	931.5
1258.09	909
1257.55	931.5
1257	929.75
1256.45	943.5
1255.9	912.5
1255.36	943
1254.81	963.25
1254.26	973.5
1253.72	935
1253.17	960.75
1252.62	917.5
1252.07	950.5
1251.53	921
1250.98	920.25
1250.43	964
1249.89	932.25
1249.34	966.75
1248.79	945.5
1248.24	981
1247.7	937.25
1247.15	934
1246.6	972
1246.05	967.25
1245.5	1003.25
1244.96	945.5
1244.41	928.5
1243.86	974.5
1243.31	954.25
1242.77	959.75
1242.22	969
1241.67	971
1241.12	992.5
1240.57	991.75
1240.02	986.25
1239.48	979.75
1238.93	992
1238.38	1000.25
1237.83	1000.75
1237.28	986.75
1236.73	1029
1236.18	1006.75
1235.64	1048.75
1235.09	1053.25
1234.54	1094.5
1233.99	1092.5
1233.44	1131.5
1232.89	1112
1232.34	1096
1231.79	1106.75
1231.24	1101.75
1230.69	1128
1230.15	1149.25
1229.6	1148
1229.05	1123.25
1228.5	1143
1227.95	1135.75
1227.4	1102.25
1226.85	1113
1226.3	1090.25
1225.75	1080.5
1225.2	1085.5
1224.65	1078.5
1224.1	1038.25
1223.55	1064.75
1223	1028.25
1222.45	1042.75
1221.9	1053.25
1221.35	1054
1220.8	1047
1220.25	991.25
1219.7	1005.75
1219.15	1007.25
1218.6	1000
1218.05	1003.25
1217.5	998.25
1216.95	1013.25
1216.4	1023.75
1215.85	988
1215.3	972.25
1214.75	1007.75
1214.2	986.75
1213.65	959
1213.09	993
1212.54	975.25
1211.99	971.25
1211.44	962
1210.89	1017.75
1210.34	982.25
1209.79	975.75
1209.24	955
1208.69	974.25
1208.14	964.25
1207.58	942.75
1207.03	961.75
1206.48	996
1205.93	968
1205.38	997
1204.83	975.25
1204.27	985.25
1203.72	970.25
1203.17	953
1202.62	957.25
1202.07	978.5
1201.52	999.5
1200.96	992
1200.41	949.5
1199.86	950.75
1199.31	955.25
1198.76	968.5
1198.2	964.25
1197.65	1002.5
1197.1	992
1196.55	971.25
1196	979
1195.44	967
1194.89	1003.25
1194.34	1002.25
1193.78	964.5
1193.23	1026.75
1192.68	1005
1192.13	959
1191.57	1017.25
1191.02	999.5
1190.47	1060
1189.91	1022.75
1189.36	1017
1188.81	1057
1188.26	1028.75
1187.7	1081.5
1187.15	1030.5
1186.6	1057.25
1186.04	1092.5
1185.49	1056.25
1184.94	1101.75
1184.38	1115.75
1183.83	1098.75
1183.28	1092.25
1182.72	1087
1182.17	1054.75
1181.61	1069.5
1181.06	1025.5
1180.51	1057.25
1179.95	1065
1179.4	1063.5
1178.85	1083.25
1178.29	1034.75
1177.74	1069.75
1177.18	1066.75
1176.63	1022.5
1176.07	1047
1175.52	1052.5
1174.97	1052.25
1174.41	1018.5
1173.86	1060.5
1173.3	1051.75
1172.75	1032.25
1172.19	1073
1171.64	1083.5
1171.09	1082.75
1170.53	1044.25
1169.97	1090.75
1169.42	1089.25
1168.86	1100.75
1168.31	1062.5
1167.76	1068.75
1167.2	1097
1166.65	1154.5
1166.09	1106.75
1165.53	1133.25
1164.98	1154.5
1164.42	1172.75
1163.87	1165.75
1163.31	1197.5
1162.76	1191.75
1162.2	1270
1161.65	1275
1161.09	1329.25
1160.54	1287.5
1159.98	1342.25
1159.42	1360
1158.87	1329
1158.31	1348.25
1157.76	1371
1157.2	1326.5
1156.65	1300.25
1156.09	1312.5
1155.53	1253.75
1154.98	1283.75
1154.42	1213.5
1153.86	1203.75
1153.31	1225.25
1152.75	1176.25
1152.19	1177.5
1151.64	1160
1151.08	1178.25
1150.52	1138.5
1149.97	1140.5
1149.41	1154.5
1148.86	1107
1148.3	1124
1147.74	1131.5
1147.18	1199.25
1146.63	1114.5
1146.07	1101
1145.51	1127
1144.96	1098.25
1144.4	1130.75
1143.84	1083.5
1143.28	1105.25
1142.73	1171.5
1142.17	1134.25
1141.61	1116.25
1141.06	1118.75
1140.5	1113.5
1139.94	1135.25
1139.38	1114.75
1138.83	1140
1138.27	1135.5
1137.71	1107.5
1137.15	1112.5
1136.59	1107.75
1136.04	1145.5
1135.48	1127.75
1134.92	1101
1134.36	1116.75
1133.8	1124.25
1133.25	1134.75
1132.69	1109.25
1132.13	1085
1131.57	1141.5
1131.01	1123
1130.45	1096
1129.9	1140.5
1129.34	1129.5
1128.78	1091
1128.22	1116
1127.66	1131.75
1127.1	1134
1126.54	1127.25
1125.98	1126.75
1125.43	1157.25
1124.87	1140.25
1124.31	1144.25
1123.75	1147.5
1123.19	1160.25
1122.63	1176.5
1122.07	1155.75
1121.51	1144.5
1120.95	1155.5
1120.39	1144.75
1119.83	1140.5
1119.27	1117.25
1118.72	1142.5
1118.15	1146.25
1117.6	1166.75
1117.04	1178
1116.48	1173
1115.92	1223.25
1115.36	1157.25
1114.8	1209.75
1114.24	1248.5
1113.68	1208.5
1113.12	1218.25
1112.56	1255.75
1112	1252.75
1111.44	1248.5
1110.88	1215
1110.32	1203.75
1109.76	1193
1109.19	1188.75
1108.64	1163.25
1108.07	1195.25
1107.51	1191.5
1106.95	1168.5
1106.39	1154
1105.83	1168
1105.27	1138.75
1104.71	1145.5
1104.15	1156.25
1103.59	1112.25
1103.03	1175.25
1102.47	1166.5
1101.91	1129.25
1101.34	1094.75
1100.78	1145
1100.22	1116.5
1099.66	1129.25
1099.1	1128.25
1098.54	1146.5
1097.98	1121
1097.41	1107
1096.85	1137.25
1096.29	1142.25
1095.73	1149.25
1095.17	1129.75
1094.61	1152
1094.04	1144.25
1093.48	1120.5
1092.92	1145.25
1092.36	1156.25
1091.8	1160.75
1091.23	1191.75
1090.67	1148.25
1090.11	1159.5
1089.55	1132.25
1088.99	1183.25
1088.42	1214.5
1087.86	1225.75
1087.3	1217.5
1086.74	1277
1086.17	1273.5
1085.61	1312.5
1085.05	1346.5
1084.49	1415.5
1083.92	1430.5
1083.36	1544.75
1082.8	1549.75
1082.23	1597.75
1081.67	1629.25
1081.11	1659.75
1080.55	1633
1079.98	1642.25
1079.42	1520.5
1078.86	1474.25
1078.29	1438.5
1077.73	1323.25
1077.17	1317
1076.6	1288.75
1076.04	1280.5
1075.48	1197.5
1074.91	1229
1074.35	1220.25
1073.79	1182
1073.22	1190.25
1072.66	1192.25
1072.09	1205.75
1071.53	1147.5
1070.97	1190.5
1070.4	1184.25
1069.84	1186.5
1069.27	1187
1068.71	1170.25
1068.15	1167.75
1067.58	1117.25
1067.02	1125.75
1066.45	1168.25
1065.89	1156.25
1065.32	1114.75
1064.76	1104
1064.19	1139.5
1063.63	1146
1063.07	1132.5
1062.5	1141
1061.94	1171.25
1061.37	1115.75
1060.81	1154
1060.24	1100.5
1059.68	1117.75
1059.11	1109
1058.55	1118.75
1057.98	1097.25
1057.42	1160.75
1056.85	1101.75
1056.29	1109.25
1055.72	1158.75
1055.16	1132
1054.59	1111.75
1054.03	1127
1053.46	1142
1052.89	1082.25
1052.33	1140.25
1051.76	1127
1051.2	1115.25
1050.63	1118.5
1050.06	1132.75
1049.5	1120.25
1048.93	1152.25
1048.37	1161.25
1047.8	1141.25
1047.24	1158
1046.67	1144.5
1046.1	1178.5
1045.54	1230.75
1044.97	1185.5
1044.4	1198
1043.84	1172
1043.27	1228.5
1042.7	1162
1042.14	1177.5
1041.57	1146
1041.01	1114.75
1040.44	1176.25
1039.87	1138.25
1039.3	1137.75
1038.74	1120.5
1038.17	1111
1037.6	1125.5
1037.04	1137.75
1036.47	1145.5
1035.9	1102
1035.34	1125.75
1034.77	1130.5
1034.2	1118.25
1033.63	1101.75
1033.07	1133.25
1032.5	1097
1031.93	1075.25
1031.36	1130.25
1030.8	1117.25
1030.23	1078.5
1029.66	1110
1029.09	1127.5
1028.52	1097.25
1027.96	1120.75
1027.39	1136.5
1026.82	1114.75
1026.25	1112.25
1025.68	1087.5
1025.12	1107.25
1024.55	1072
1023.98	1104
1023.41	1098.25
1022.84	1113
1022.28	1131.25
1021.71	1085
1021.14	1112.25
1020.57	1131.75
1020	1141
1019.43	1124
1018.86	1112.25
1018.3	1106.75
1017.73	1123.75
1017.16	1142.75
1016.59	1121.5
1016.3	1110