File: Testing/Hickernall_HORIBA/g36-mi1_03.txt
#Acq. time (s)=	75
#Accumulations=	5
#Range=	Off
#Autofocus=	Off
#Macrospot=	Off
#AutoExposure=	Off
#Spike filter=	Multiple accum.
#Delay time (s)=	0
#Binning=	1
#Readout mode=	Signal
#DeNoise=	Off
#ICS correction=	Off
#Dark correction=	Off
#Inst. Process=	Off
#Instrument=	LabRAM HR Evol
#Detector=	Andor CCD
#Objective=	x100 LWD
#Grating=	1800 gr/mm
#ND Filter=	100%
#Laser (nm)=	532
#Spectro (cm-¹)=	1240.02
#Hole=	49.98
#Range=	Visible
#AFM=	Off
#StageXY=	Marzhauser
#StageZ=	Marzhauser
#X (µm)=	-15775.7
#Y (µm)=	-1015.7
#Z (µm)=	-314.6
#Project=
#Sample=
#Site=
#Title=	g36-mi1
#Remark=
#Date=	06.05.2022 09:11
#Acquired=	06.05.2022 09:11:33
1454.81	905.5
1454.28	903
1453.75	896.75
1453.22	888.5
1452.69	895
1452.16	886.25
1451.64	890.5
1451.11	907
1450.58	891.25
1450.05	880.5
1449.52	869.5
1448.99	927.5
1448.46	886
1447.93	886
1447.4	887.25
1446.88	903.25
1446.35	884.25
1445.82	891
1445.29	855.5
1444.76	862
1444.23	885
1443.7	901.5
1443.17	873
1442.64	885.75
1442.11	877.25
1441.58	885
1441.05	884.75
1440.52	895.25
1439.99	890.5
1439.46	858.5
1438.93	863.5
1438.4	911
1437.87	865
1437.34	847.25
1436.81	875.25
1436.28	867.75
1435.75	855.25
1435.22	867.5
1434.69	882.5
1434.16	856
1433.63	864.5
1433.1	874.25
1432.57	869.5
1432.04	846.5
1431.51	844.25
1430.98	889.25
1430.45	848.75
1429.92	849
1429.39	845
1428.86	851.25
1428.33	864
1427.8	880.5
1427.26	845.75
1426.73	841.5
1426.2	837.5
1425.67	852.25
1425.14	842.5
1424.61	854.5
1424.08	853.75
1423.55	834
1423.02	820.5
1422.49	852.5
1421.95	832
1421.42	826.25
1420.89	839.5
1420.36	873.5
1419.83	823.25
1419.3	863
1418.76	833.75
1418.23	828.75
1417.7	820.75
1417.17	861
1416.64	875.75
1416.1	857.5
1415.57	833.75
1415.04	854.75
1414.51	819.5
1413.98	839.75
1413.44	842
1412.91	850.5
1412.38	847
1411.85	821.75
1411.32	852.25
1410.78	859.5
1410.25	848
1409.72	820.5
1409.18	880.75
1408.65	855.25
1408.12	839.25
1407.59	841
1407.05	840.5
1406.52	831.25
1405.99	856.25
1405.46	846.5
1404.92	834
1404.39	828.5
1403.86	845.75
1403.32	824.75
1402.79	829.5
1402.26	845.75
1401.72	846.25
1401.19	828.25
1400.66	842.75
1400.12	846.25
1399.59	813
1399.06	824
1398.52	818
1397.99	830.75
1397.46	851.25
1396.92	860
1396.39	813
1395.85	831
1395.32	829.75
1394.79	823.25
1394.25	809
1393.72	837.5
1393.18	866.25
1392.65	795.75
1392.12	834.5
1391.58	859
1391.05	829
1390.51	863
1389.98	878.5
1389.44	856
1388.91	906.25
1388.38	971.25
1387.84	1002.5
1387.31	874.25
1386.77	845.75
1386.24	842
1385.7	862
1385.17	857.25
1384.63	835.75
1384.1	842.5
1383.56	829.25
1383.03	837.5
1382.49	878.5
1381.96	848.5
1381.42	885.5
1380.89	864.25
1380.35	855.25
1379.82	850
1379.28	840.75
1378.74	832.25
1378.21	833.25
1377.67	873
1377.14	806.5
1376.6	887.5
1376.07	834.25
1375.53	847.25
1374.99	833
1374.46	818.5
1373.92	830.75
1373.39	835.25
1372.85	810.25
1372.32	838.75
1371.78	858.5
1371.24	814
1370.71	830.25
1370.17	846.25
1369.63	855.25
1369.1	836.25
1368.56	810.5
1368.03	840
1367.49	837
1366.95	808.75
1366.42	783.5
1365.88	848.5
1365.34	859
1364.81	844
1364.27	862.25
1363.73	842
1363.19	793
1362.66	847.25
1362.12	844.25
1361.58	862
1361.05	820.5
1360.51	828.5
1359.97	868.75
1359.44	823
1358.9	822.25
1358.36	809
1357.82	849.75
1357.29	833
1356.75	855
1356.21	833.5
1355.67	855.75
1355.14	839.25
1354.6	832
1354.06	845
1353.52	819.5
1352.99	823.5
1352.45	846.25
1351.91	833.5
1351.37	846.25
1350.83	838
1350.3	808
1349.76	799
1349.22	851.25
1348.68	853.75
1348.14	791.25
1347.6	809.25
1347.06	841.25
1346.53	824.5
1345.99	826
1345.45	823.5
1344.91	860
1344.37	838
1343.83	818.75
1343.3	778.75
1342.76	815.75
1342.22	833
1341.68	809
1341.14	843.75
1340.6	822.25
1340.06	822
1339.52	813.5
1338.98	811.25
1338.45	834.75
1337.91	791
1337.37	832.25
1336.83	828.75
1336.29	816.75
1335.75	820.25
1335.21	811.5
1334.67	826
1334.13	810.75
1333.59	843.5
1333.05	815.25
1332.51	782.5
1331.97	806.25
1331.43	832
1330.89	794.5
1330.35	836
1329.81	800
1329.27	818.25
1328.73	837.75
1328.19	808.25
1327.65	803.5
1327.11	842.5
1326.57	819
1326.03	834
1325.49	839.25
1324.95	817.5
1324.41	819.75
1323.87	778
1323.33	788.75
1322.79	818
1322.25	820.5
1321.71	780.75
1321.16	815.25
1320.62	826.25
1320.08	835
1319.54	824.75
1319	809.25
1318.46	846.5
1317.92	843.75
1317.38	820.75
1316.84	833.25
1316.29	821
1315.75	794.75
1315.21	823
1314.67	849.25
1314.13	845.75
1313.59	869
1313.05	829
1312.5	831.5
1311.96	831
1311.42	863.25
1310.88	831.5
1310.34	844.25
1309.8	846.25
1309.25	827
1308.71	824
1308.17	844.5
1307.63	876.25
1307.09	864.25
1306.54	853.5
1306	812.25
1305.46	839.75
1304.92	840.25
1304.38	853.75
1303.83	844.25
1303.29	852
1302.75	851.5
1302.21	876.75
1301.66	841.25
1301.12	872.5
1300.58	850.5
1300.04	864.25
1299.49	839.75
1298.95	884.25
1298.41	856.75
1297.86	878
1297.32	887.5
1296.78	847.75
1296.23	828.75
1295.69	852.5
1295.15	863.5
1294.6	857.25
1294.06	832.75
1293.52	855.5
1292.97	852.25
1292.43	842.75
1291.89	880.25
1291.34	843.25
1290.8	886
1290.26	844.5
1289.71	858.25
1289.17	821.25
1288.63	850.25
1288.08	831
1287.54	849.25
1286.99	868.25
1286.45	896.25
1285.9	901.5
1285.36	951
1284.82	942.75
1284.27	875.5
1283.73	808
1283.19	858.75
1282.64	839
1282.1	856.5
1281.55	841
1281.01	829
1280.46	838.5
1279.92	864.25
1279.37	856.5
1278.83	833.75
1278.28	848.75
1277.74	796.5
1277.19	834
1276.65	839.75
1276.1	840.75
1275.56	823.5
1275.01	850.5
1274.47	841.75
1273.92	873
1273.38	844
1272.83	861
1272.29	838.5
1271.74	822
1271.2	833
1270.65	855.5
1270.11	859.25
1269.56	861
1269.01	827
1268.47	857.25
1267.92	835.75
1267.38	863.75
1266.83	861.75
1266.29	842.5
1265.74	855
1265.19	899.5
1264.65	846
1264.1	860.25
1263.55	838.5
1263.01	865.5
1262.46	873.5
1261.92	850.25
1261.37	884
1260.82	863
1260.28	869.5
1259.73	900.5
1259.18	892.25
1258.64	881.75
1258.09	853.25
1257.55	861.25
1257	908.5
1256.45	890.5
1255.9	864.75
1255.36	863
1254.81	880
1254.26	904.75
1253.72	865.5
1253.17	910.25
1252.62	884.25
1252.07	896.5
1251.53	875.25
1250.98	864
1250.43	902.5
1249.89	922.25
1249.34	927.75
1248.79	900
1248.24	937.5
1247.7	915.75
1247.15	891.75
1246.6	939.25
1246.05	894.25
1245.5	918.75
1244.96	923.75
1244.41	902.25
1243.86	900.25
1243.31	910.25
1242.77	922.75
1242.22	897.5
1241.67	938.5
1241.12	934.5
1240.57	949.5
1240.02	971.5
1239.48	967.25
1238.93	975.5
1238.38	1008.25
1237.83	972
1237.28	989.25
1236.73	987.25
1236.18	972
1235.64	1014.75
1235.09	1035.75
1234.54	1029.75
1233.99	1026.75
1233.44	1081.75
1232.89	1072.5
1232.34	1076.5
1231.79	1055
1231.24	1081.25
1230.69	1144
1230.15	1100.25
1229.6	1080.25
1229.05	1100.75
1228.5	1088.25
1227.95	1108.5
1227.4	1067.5
1226.85	1061.5
1226.3	1118
1225.75	1071.5
1225.2	1069.5
1224.65	1063
1224.1	1043.5
1223.55	1031.25
1223	1005.25
1222.45	1012
1221.9	1016.75
1221.35	1006
1220.8	995.25
1220.25	969.25
1219.7	1000.25
1219.15	987.75
1218.6	961
1218.05	943
1217.5	963
1216.95	973
1216.4	964.75
1215.85	954.5
1215.3	962.25
1214.75	993
1214.2	983.5
1213.65	912.25
1213.09	948
1212.54	970.25
1211.99	949
1211.44	936
1210.89	959.75
1210.34	965
1209.79	912.75
1209.24	926.5
1208.69	966
1208.14	935.25
1207.58	932.75
1207.03	942.75
1206.48	940.25
1205.93	957.5
1205.38	919
1204.83	940.25
1204.27	962.5
1203.72	957
1203.17	914
1202.62	947.5
1202.07	967.25
1201.52	942
1200.96	950.25
1200.41	951.25
1199.86	954.5
1199.31	992.5
1198.76	954
1198.2	937.75
1197.65	951.75
1197.1	985.5
1196.55	959
1196	958
1195.44	1007.5
1194.89	975.75
1194.34	962.25
1193.78	975.5
1193.23	953.5
1192.68	971.75
1192.13	974.25
1191.57	983.75
1191.02	992.5
1190.47	1036
1189.91	990
1189.36	1009
1188.81	1038
1188.26	1036.5
1187.7	1032.75
1187.15	1031.25
1186.6	1062.75
1186.04	1038
1185.49	1066
1184.94	1038.75
1184.38	1033.75
1183.83	1063.25
1183.28	1057.25
1182.72	1102.25
1182.17	1035.5
1181.61	1061.25
1181.06	1047.75
1180.51	1051.25
1179.95	1031.5
1179.4	1043.5
1178.85	989
1178.29	1030
1177.74	1022.5
1177.18	1017.5
1176.63	1018
1176.07	996.5
1175.52	1026.5
1174.97	1036
1174.41	1042.25
1173.86	1004.5
1173.3	1054
1172.75	1066.5
1172.19	1043.75
1171.64	1047
1171.09	1069
1170.53	1055.25
1169.97	1069.25
1169.42	1066
1168.86	1024.75
1168.31	1083
1167.76	1099
1167.2	1023.25
1166.65	1120
1166.09	1137.5
1165.53	1165.75
1164.98	1134
1164.42	1185.25
1163.87	1150.25
1163.31	1168.5
1162.76	1251.25
1162.2	1294.5
1161.65	1259.5
1161.09	1268.5
1160.54	1275
1159.98	1369.75
1159.42	1354.25
1158.87	1384.75
1158.31	1380.75
1157.76	1393.75
1157.2	1352
1156.65	1326.25
1156.09	1295
1155.53	1338.25
1154.98	1286.25
1154.42	1228
1153.86	1203.25
1153.31	1242
1152.75	1171.5
1152.19	1177.5
1151.64	1191.75
1151.08	1159.25
1150.52	1165.25
1149.97	1126
1149.41	1128.5
1148.86	1143.5
1148.3	1166.25
1147.74	1103.75
1147.18	1137.75
1146.63	1118.75
1146.07	1124.5
1145.51	1114
1144.96	1140.75
1144.4	1131.5
1143.84	1101.75
1143.28	1148
1142.73	1126.5
1142.17	1122.25
1141.61	1087.25
1141.06	1117
1140.5	1132.5
1139.94	1131.25
1139.38	1141
1138.83	1105
1138.27	1148.25
1137.71	1114.25
1137.15	1126
1136.59	1099
1136.04	1108.25
1135.48	1149.75
1134.92	1111
1134.36	1129
1133.8	1126.75
1133.25	1099.75
1132.69	1113
1132.13	1137
1131.57	1122.5
1131.01	1121.5
1130.45	1139.25
1129.9	1103.5
1129.34	1126.25
1128.78	1112.75
1128.22	1132.5
1127.66	1132
1127.1	1138
1126.54	1123.5
1125.98	1145.5
1125.43	1157.5
1124.87	1163
1124.31	1116.75
1123.75	1156.5
1123.19	1146.75
1122.63	1158.25
1122.07	1122.25
1121.51	1145.25
1120.95	1151
1120.39	1135
1119.83	1134.5
1119.27	1167.5
1118.72	1144.25
1118.15	1189.25
1117.6	1156.5
1117.04	1169.75
1116.48	1152.75
1115.92	1179.75
1115.36	1207.25
1114.8	1189.75
1114.24	1186.5
1113.68	1222.25
1113.12	1217
1112.56	1191.5
1112	1231.75
1111.44	1286.5
1110.88	1194
1110.32	1224.75
1109.76	1182.75
1109.19	1188.25
1108.64	1195.25
1108.07	1209.5
1107.51	1201.5
1106.95	1161.75
1106.39	1187.75
1105.83	1125.75
1105.27	1144.75
1104.71	1155.25
1104.15	1164.5
1103.59	1177.25
1103.03	1115.75
1102.47	1172
1101.91	1137.25
1101.34	1134
1100.78	1155.5
1100.22	1119.5
1099.66	1138.25
1099.1	1154
1098.54	1137.5
1097.98	1104.75
1097.41	1175
1096.85	1119
1096.29	1137.25
1095.73	1128
1095.17	1138
1094.61	1151
1094.04	1144.5
1093.48	1141.25
1092.92	1125
1092.36	1137.25
1091.8	1142
1091.23	1159.75
1090.67	1126
1090.11	1143
1089.55	1198
1088.99	1178.5
1088.42	1190.75
1087.86	1204.25
1087.3	1266.75
1086.74	1240.75
1086.17	1288.5
1085.61	1324.25
1085.05	1361.75
1084.49	1379.75
1083.92	1437
1083.36	1528.75
1082.8	1591
1082.23	1626.5
1081.67	1726.25
1081.11	1748.75
1080.55	1692
1079.98	1653.5
1079.42	1569.75
1078.86	1517.25
1078.29	1451
1077.73	1349.5
1077.17	1327.25
1076.6	1306.5
1076.04	1301.5
1075.48	1257
1074.91	1215
1074.35	1230.5
1073.79	1191
1073.22	1187.75
1072.66	1217.25
1072.09	1196
1071.53	1206.25
1070.97	1176.75
1070.4	1164
1069.84	1178.25
1069.27	1147.5
1068.71	1186.5
1068.15	1159.75
1067.58	1098.5
1067.02	1135
1066.45	1147
1065.89	1165
1065.32	1185.5
1064.76	1149
1064.19	1173
1063.63	1103.5
1063.07	1161.5
1062.5	1131.25
1061.94	1126.5
1061.37	1134.75
1060.81	1161.25
1060.24	1112.5
1059.68	1125.75
1059.11	1136.25
1058.55	1101.5
1057.98	1143.75
1057.42	1089.5
1056.85	1097.25
1056.29	1110.75
1055.72	1095
1055.16	1120.75
1054.59	1130
1054.03	1101
1053.46	1112.75
1052.89	1126.25
1052.33	1113.25
1051.76	1138.75
1051.2	1130.5
1050.63	1122.75
1050.06	1119
1049.5	1124.25
1048.93	1098.5
1048.37	1157.75
1047.8	1123.25
1047.24	1159
1046.67	1194
1046.1	1173.25
1045.54	1171
1044.97	1158
1044.4	1171
1043.84	1208
1043.27	1194.75
1042.7	1205.75
1042.14	1188
1041.57	1151
1041.01	1181.75
1040.44	1142.25
1039.87	1151.25
1039.3	1150
1038.74	1122.5
1038.17	1113.25
1037.6	1137
1037.04	1133.25
1036.47	1145.75
1035.9	1095.25
1035.34	1134.5
1034.77	1112.5
1034.2	1170
1033.63	1122.5
1033.07	1129.25
1032.5	1131
1031.93	1088.75
1031.36	1105.25
1030.8	1091
1030.23	1099
1029.66	1094.75
1029.09	1138.25
1028.52	1135
1027.96	1053
1027.39	1090.75
1026.82	1129
1026.25	1093.5
1025.68	1139.75
1025.12	1113.75
1024.55	1083.5
1023.98	1138.5
1023.41	1130.5
1022.84	1112.5
1022.28	1096.75
1021.71	1116
1021.14	1114.75
1020.57	1132.5
1020	1138.75
1019.43	1130.5
1018.86	1092.5
1018.3	1115.5
1017.73	1092.75
1017.16	1126
1016.59	1102.5
1016.3	1108.75