File: Testing/Hickernall_HORIBA/g36-mi1_05.txt
#Acq. time (s)=	75
#Accumulations=	5
#Range=	Off
#Autofocus=	Off
#Macrospot=	Off
#AutoExposure=	Off
#Spike filter=	Multiple accum.
#Delay time (s)=	0
#Binning=	1
#Readout mode=	Signal
#DeNoise=	Off
#ICS correction=	Off
#Dark correction=	Off
#Inst. Process=	Off
#Instrument=	LabRAM HR Evol
#Detector=	Andor CCD
#Objective=	x100 LWD
#Grating=	1800 gr/mm
#ND Filter=	100%
#Laser (nm)=	532
#Spectro (cm-¹)=	1240.02
#Hole=	49.98
#Range=	Visible
#AFM=	Off
#StageXY=	Marzhauser
#StageZ=	Marzhauser
#X (µm)=	-15776.2
#Y (µm)=	-1015.1
#Z (µm)=	-314.4
#Project=
#Sample=
#Site=
#Title=	g36-mi1
#Remark=
#Date=	06.05.2022 09:24
#Acquired=	06.05.2022 09:24:53
1454.81	818.75
1454.28	813.75
1453.75	813.75
1453.22	803.75
1452.69	792.25
1452.16	804
1451.64	819
1451.11	824.75
1450.58	778.5
1450.05	836
1449.52	799.75
1448.99	831.75
1448.46	843.25
1447.93	816.25
1447.4	800
1446.88	813.25
1446.35	810.75
1445.82	800
1445.29	804.5
1444.76	815
1444.23	798.75
1443.7	822.25
1443.17	833.75
1442.64	783.5
1442.11	821
1441.58	815.5
1441.05	795.5
1440.52	785.75
1439.99	814
1439.46	807
1438.93	828
1438.4	781.25
1437.87	805.75
1437.34	784
1436.81	812.75
1436.28	784.25
1435.75	790
1435.22	774.25
1434.69	755
1434.16	795.75
1433.63	785.25
1433.1	790.5
1432.57	804.25
1432.04	774
1431.51	786.5
1430.98	779.75
1430.45	777.5
1429.92	799.25
1429.39	776.5
1428.86	772.25
1428.33	778
1427.8	788
1427.26	778.75
1426.73	760
1426.2	789
1425.67	750.25
1425.14	773
1424.61	794.75
1424.08	797.5
1423.55	794.25
1423.02	763.25
1422.49	788
1421.95	735
1421.42	781.5
1420.89	760
1420.36	792.5
1419.83	763.75
1419.3	798.5
1418.76	763.5
1418.23	767
1417.7	781.25
1417.17	750.75
1416.64	763.75
1416.1	724.5
1415.57	756.75
1415.04	786.75
1414.51	768.25
1413.98	757.75
1413.44	779.25
1412.91	769.5
1412.38	764.75
1411.85	752
1411.32	795.25
1410.78	780.5
1410.25	756.75
1409.72	776.5
1409.18	781
1408.65	756.75
1408.12	760.5
1407.59	748.75
1407.05	740.5
1406.52	768
1405.99	791.5
1405.46	784.75
1404.92	771.5
1404.39	749.25
1403.86	739.25
1403.32	738
1402.79	754.5
1402.26	745
1401.72	746.75
1401.19	755
1400.66	765.75
1400.12	782.5
1399.59	784.5
1399.06	783.5
1398.52	726.5
1397.99	765.5
1397.46	745.25
1396.92	754.5
1396.39	775.25
1395.85	778
1395.32	732.25
1394.79	728
1394.25	761.25
1393.72	766.75
1393.18	749
1392.65	747.25
1392.12	746.75
1391.58	750.5
1391.05	736
1390.51	732.5
1389.98	752
1389.44	754
1388.91	823.25
1388.38	867.5
1387.84	932
1387.31	887.25
1386.77	794.25
1386.24	757.5
1385.7	800.5
1385.17	784.25
1384.63	767.25
1384.1	767
1383.56	741.25
1383.03	738.25
1382.49	795.5
1381.96	752
1381.42	757
1380.89	771.25
1380.35	769.5
1379.82	792.5
1379.28	767.25
1378.74	770.25
1378.21	769.25
1377.67	808.25
1377.14	782
1376.6	748.25
1376.07	779.5
1375.53	806.5
1374.99	765.75
1374.46	754
1373.92	755.75
1373.39	759.5
1372.85	771.75
1372.32	768
1371.78	754.5
1371.24	765.25
1370.71	758
1370.17	751
1369.63	758
1369.1	765
1368.56	735.25
1368.03	770.75
1367.49	758.25
1366.95	771.5
1366.42	754
1365.88	785.75
1365.34	752.75
1364.81	752.75
1364.27	745
1363.73	766.75
1363.19	746.25
1362.66	755.25
1362.12	743.75
1361.58	716.5
1361.05	770.5
1360.51	744.75
1359.97	779
1359.44	754.75
1358.9	767
1358.36	787
1357.82	718.75
1357.29	763.5
1356.75	761.75
1356.21	731.25
1355.67	739.75
1355.14	758.25
1354.6	723
1354.06	780.5
1353.52	768
1352.99	760
1352.45	746.25
1351.91	737.75
1351.37	730.5
1350.83	748.75
1350.3	760.25
1349.76	734.25
1349.22	766.75
1348.68	779.25
1348.14	758.5
1347.6	754.75
1347.06	752.25
1346.53	756.75
1345.99	760
1345.45	737.5
1344.91	728.25
1344.37	723
1343.83	730.25
1343.3	743
1342.76	768
1342.22	751.75
1341.68	780.5
1341.14	739
1340.6	753.25
1340.06	764.25
1339.52	743.5
1338.98	724.75
1338.45	738.75
1337.91	697.75
1337.37	736.75
1336.83	751.25
1336.29	724.5
1335.75	743.75
1335.21	756.25
1334.67	745.5
1334.13	757
1333.59	736
1333.05	743
1332.51	728.5
1331.97	751.5
1331.43	743
1330.89	720.75
1330.35	734
1329.81	745
1329.27	783
1328.73	748.75
1328.19	743.5
1327.65	709.5
1327.11	771
1326.57	750.75
1326.03	787.5
1325.49	765.75
1324.95	741.25
1324.41	736.5
1323.87	763.25
1323.33	752
1322.79	720.75
1322.25	765.75
1321.71	753.25
1321.16	760.5
1320.62	772.5
1320.08	760.5
1319.54	743
1319	747
1318.46	736.75
1317.92	762
1317.38	759
1316.84	760.75
1316.29	751
1315.75	742
1315.21	755.25
1314.67	744.25
1314.13	748.25
1313.59	742
1313.05	758.25
1312.5	771.5
1311.96	777.25
1311.42	748.5
1310.88	739.5
1310.34	756
1309.8	774
1309.25	761.5
1308.71	772.5
1308.17	747.5
1307.63	769
1307.09	770.5
1306.54	773
1306	769.5
1305.46	771.5
1304.92	751
1304.38	759
1303.83	785
1303.29	780.75
1302.75	782
1302.21	743
1301.66	771.5
1301.12	746
1300.58	785.75
1300.04	774
1299.49	758
1298.95	744.5
1298.41	795
1297.86	766
1297.32	810
1296.78	757.75
1296.23	799
1295.69	765
1295.15	755.25
1294.6	764.25
1294.06	799.25
1293.52	804
1292.97	793
1292.43	796.75
1291.89	755
1291.34	756.25
1290.8	768
1290.26	751
1289.71	764.5
1289.17	768.75
1288.63	769.25
1288.08	781
1287.54	778
1286.99	789
1286.45	765.5
1285.9	825.5
1285.36	904.25
1284.82	902.75
1284.27	810
1283.73	770.25
1283.19	783.25
1282.64	803.5
1282.1	770.5
1281.55	774.75
1281.01	782.25
1280.46	769
1279.92	756
1279.37	778.25
1278.83	765
1278.28	764
1277.74	737.25
1277.19	758.75
1276.65	758.75
1276.1	791
1275.56	782.25
1275.01	768.75
1274.47	769
1273.92	780.5
1273.38	792.75
1272.83	799
1272.29	763.5
1271.74	778
1271.2	761.75
1270.65	771.25
1270.11	790.75
1269.56	785.25
1269.01	795.75
1268.47	749
1267.92	779.25
1267.38	796.5
1266.83	786.25
1266.29	796.5
1265.74	784.25
1265.19	805
1264.65	789
1264.1	755.5
1263.55	802.25
1263.01	821.75
1262.46	786.75
1261.92	761
1261.37	803.25
1260.82	798
1260.28	814.25
1259.73	798.5
1259.18	815
1258.64	801.5
1258.09	794.5
1257.55	802
1257	795.75
1256.45	815.5
1255.9	799
1255.36	789
1254.81	823.75
1254.26	855
1253.72	818.5
1253.17	836
1252.62	833
1252.07	848.75
1251.53	845.25
1250.98	837.75
1250.43	840.25
1249.89	839
1249.34	838
1248.79	838
1248.24	846
1247.7	834
1247.15	822
1246.6	842.25
1246.05	854.25
1245.5	864.75
1244.96	831.5
1244.41	870
1243.86	822.5
1243.31	881
1242.77	883.75
1242.22	860.75
1241.67	877.75
1241.12	866.25
1240.57	890.25
1240.02	907.5
1239.48	891
1238.93	936
1238.38	896.5
1237.83	942
1237.28	911.25
1236.73	920.25
1236.18	951.75
1235.64	944.5
1235.09	977.75
1234.54	987.5
1233.99	992.75
1233.44	1012.5
1232.89	1010.5
1232.34	1000.5
1231.79	1015.5
1231.24	1032
1230.69	1062.25
1230.15	1047
1229.6	1043.75
1229.05	1034.5
1228.5	1066.5
1227.95	1084.75
1227.4	1037.25
1226.85	1020.5
1226.3	1001
1225.75	1011.5
1225.2	975.75
1224.65	1003
1224.1	994
1223.55	977.25
1223	945.5
1222.45	962
1221.9	954.25
1221.35	962.25
1220.8	950
1220.25	921
1219.7	932.5
1219.15	918.75
1218.6	915.75
1218.05	932.5
1217.5	917.25
1216.95	906.25
1216.4	894.5
1215.85	910.5
1215.3	931
1214.75	892
1214.2	900
1213.65	867.25
1213.09	900.25
1212.54	882
1211.99	891.25
1211.44	855
1210.89	888.25
1210.34	917
1209.79	879.5
1209.24	864
1208.69	888
1208.14	883.5
1207.58	904.25
1207.03	897.5
1206.48	890
1205.93	891.75
1205.38	893.5
1204.83	904.5
1204.27	859.5
1203.72	901
1203.17	858
1202.62	892.5
1202.07	906
1201.52	888
1200.96	914.25
1200.41	878
1199.86	891.75
1199.31	918
1198.76	879.25
1198.2	897.75
1197.65	892.5
1197.1	887.5
1196.55	891.25
1196	870.5
1195.44	914
1194.89	919.75
1194.34	908.75
1193.78	919.75
1193.23	946
1192.68	901
1192.13	930.5
1191.57	933
1191.02	950
1190.47	997
1189.91	930.5
1189.36	968.75
1188.81	989
1188.26	948
1187.7	956
1187.15	1000.75
1186.6	982
1186.04	997.25
1185.49	988.75
1184.94	1004.5
1184.38	964.25
1183.83	1001.75
1183.28	1012
1182.72	981.5
1182.17	999.75
1181.61	977
1181.06	973.75
1180.51	993.25
1179.95	1027.5
1179.4	1002
1178.85	984
1178.29	974
1177.74	998.5
1177.18	1001.75
1176.63	972.5
1176.07	1010.75
1175.52	961.5
1174.97	996.25
1174.41	1010.5
1173.86	972.5
1173.3	1046
1172.75	983
1172.19	992.25
1171.64	989.5
1171.09	1007.25
1170.53	1011.5
1169.97	1035.5
1169.42	1039.75
1168.86	1010
1168.31	1039.25
1167.76	1052.5
1167.2	1054.25
1166.65	1067.5
1166.09	1066.25
1165.53	1094.5
1164.98	1141.25
1164.42	1141.75
1163.87	1116.25
1163.31	1163.5
1162.76	1203.25
1162.2	1248.25
1161.65	1253
1161.09	1251.5
1160.54	1296
1159.98	1358
1159.42	1329.5
1158.87	1373.5
1158.31	1404.5
1157.76	1402.75
1157.2	1345.5
1156.65	1330.5
1156.09	1296
1155.53	1321.25
1154.98	1231
1154.42	1264
1153.86	1228.5
1153.31	1180
1152.75	1176.75
1152.19	1185.5
1151.64	1133.25
1151.08	1142.5
1150.52	1076.75
1149.97	1140.5
1149.41	1101
1148.86	1117
1148.3	1107
1147.74	1090.75
1147.18	1104.25
1146.63	1093.25
1146.07	1116.25
1145.51	1079.75
1144.96	1101
1144.4	1087.5
1143.84	1085.5
1143.28	1088.75
1142.73	1085.75
1142.17	1093.25
1141.61	1079.25
1141.06	1059
1140.5	1081.25
1139.94	1116
1139.38	1086
1138.83	1088.75
1138.27	1127.5
1137.71	1067.5
1137.15	1059.75
1136.59	1080
1136.04	1078.75
1135.48	1093.25
1134.92	1095.25
1134.36	1087.5
1133.8	1092.5
1133.25	1112.5
1132.69	1087.75
1132.13	1113
1131.57	1093.25
1131.01	1086.5
1130.45	1075.5
1129.9	1083
1129.34	1102.75
1128.78	1106
1128.22	1149
1127.66	1100.5
1127.1	1126.25
1126.54	1109
1125.98	1105.5
1125.43	1143.25
1124.87	1135
1124.31	1122.25
1123.75	1075.25
1123.19	1093.25
1122.63	1163.75
1122.07	1103
1121.51	1123
1120.95	1164.5
1120.39	1119.25
1119.83	1118
1119.27	1138.5
1118.72	1106.75
1118.15	1155.5
1117.6	1114.75
1117.04	1119.75
1116.48	1162.5
1115.92	1151
1115.36	1141.5
1114.8	1196.25
1114.24	1194.25
1113.68	1190.5
1113.12	1197.5
1112.56	1185.75
1112	1187.75
1111.44	1206
1110.88	1170
1110.32	1189.5
1109.76	1197.75
1109.19	1163.75
1108.64	1117
1108.07	1164.5
1107.51	1159.25
1106.95	1127.75
1106.39	1138.25
1105.83	1115
1105.27	1153
1104.71	1143.25
1104.15	1095.75
1103.59	1152.25
1103.03	1124.5
1102.47	1114.75
1101.91	1101.25
1101.34	1122
1100.78	1118.75
1100.22	1101
1099.66	1077
1099.1	1130.5
1098.54	1100
1097.98	1119
1097.41	1047.25
1096.85	1101.5
1096.29	1152
1095.73	1127.75
1095.17	1099
1094.61	1107
1094.04	1134.5
1093.48	1110.75
1092.92	1103
1092.36	1119.25
1091.8	1118.25
1091.23	1113.75
1090.67	1130.5
1090.11	1164.5
1089.55	1187.25
1088.99	1169
1088.42	1150.75
1087.86	1146.5
1087.3	1202.75
1086.74	1204.75
1086.17	1264.25
1085.61	1248
1085.05	1345.75
1084.49	1354.25
1083.92	1468
1083.36	1499.25
1082.8	1606.25
1082.23	1674
1081.67	1702.75
1081.11	1778.25
1080.55	1700.25
1079.98	1683.25
1079.42	1634.25
1078.86	1528.5
1078.29	1442.75
1077.73	1428.5
1077.17	1315.25
1076.6	1288.5
1076.04	1257.75
1075.48	1213
1074.91	1235.25
1074.35	1227.75
1073.79	1194.5
1073.22	1175
1072.66	1172.25
1072.09	1161.5
1071.53	1167.5
1070.97	1140.25
1070.4	1134
1069.84	1128
1069.27	1125.75
1068.71	1126.5
1068.15	1124
1067.58	1106.5
1067.02	1146
1066.45	1135.75
1065.89	1142
1065.32	1121
1064.76	1142.25
1064.19	1125.5
1063.63	1146.25
1063.07	1144.75
1062.5	1125.75
1061.94	1090.25
1061.37	1143.75
1060.81	1090.75
1060.24	1102
1059.68	1125.5
1059.11	1115
1058.55	1094.5
1057.98	1075.25
1057.42	1069.75
1056.85	1073
1056.29	1054.25
1055.72	1078.5
1055.16	1088.25
1054.59	1093.75
1054.03	1108.25
1053.46	1079
1052.89	1102
1052.33	1069
1051.76	1109.75
1051.2	1106
1050.63	1141.75
1050.06	1098.5
1049.5	1130
1048.93	1120.5
1048.37	1113.5
1047.8	1136.5
1047.24	1108.25
1046.67	1153.25
1046.1	1166.75
1045.54	1136
1044.97	1167.75
1044.4	1148.25
1043.84	1188.5
1043.27	1184
1042.7	1172.75
1042.14	1191.25
1041.57	1150.75
1041.01	1130
1040.44	1136.75
1039.87	1128
1039.3	1118.5
1038.74	1118
1038.17	1141
1037.6	1087
1037.04	1112.75
1036.47	1082.5
1035.9	1117.25
1035.34	1114.25
1034.77	1119.5
1034.2	1093.5
1033.63	1083.25
1033.07	1070.5
1032.5	1058.75
1031.93	1053.25
1031.36	1077.75
1030.8	1048
1030.23	1086
1029.66	1051.5
1029.09	1099
1028.52	1095
1027.96	1079.25
1027.39	1077
1026.82	1057.75
1026.25	1081.75
1025.68	1074.75
1025.12	1091.5
1024.55	1096.5
1023.98	1086.25
1023.41	1053
1022.84	1097
1022.28	1087.75
1021.71	1069.5
1021.14	1066.75
1020.57	1068.25
1020	1071.5
1019.43	1039.5
1018.86	1057.25
1018.3	1048
1017.73	1115.25
1017.16	1133.5
1016.59	1104
1016.3	1091