File: Testing/Hickernall_HORIBA/g45-mi1bub1_01.txt
#Acq. time (s)=	75
#Accumulations=	5
#Range=	Off
#Autofocus=	Off
#Macrospot=	Off
#AutoExposure=	Off
#Spike filter=	Multiple accum.
#Delay time (s)=	0
#Binning=	1
#Readout mode=	Signal
#DeNoise=	Off
#ICS correction=	Off
#Dark correction=	Off
#Inst. Process=	Off
#Instrument=	LabRAM HR Evol
#Detector=	Andor CCD
#Objective=	x100 LWD
#Grating=	1800 gr/mm
#ND Filter=	100%
#Laser (nm)=	532
#Spectro (cm-¹)=	1240.02
#Hole=	49.98
#Range=	Visible
#AFM=	Off
#StageXY=	Marzhauser
#StageZ=	Marzhauser
#X (µm)=	-15857.1
#Y (µm)=	-1056.9
#Z (µm)=	-343.6
#Project=
#Sample=
#Site=
#Title=	g45-mi1bub1
#Remark=
#Date=	06.05.2022 09:45
#Acquired=	06.05.2022 09:45:01
1454.81	2018
1454.28	2102
1453.75	2019
1453.22	2100.75
1452.69	2067.25
1452.16	2102.5
1451.64	2017
1451.11	2087.25
1450.58	2080.25
1450.05	2073
1449.52	1992.25
1448.99	2115.25
1448.46	2063.5
1447.93	2023.5
1447.4	2035
1446.88	2100
1446.35	2100.25
1445.82	2050.25
1445.29	2061
1444.76	2082.5
1444.23	2106.5
1443.7	2023
1443.17	1996
1442.64	2081
1442.11	2084.5
1441.58	2069.5
1441.05	2068.5
1440.52	1992
1439.99	2026.75
1439.46	2105.25
1438.93	2047
1438.4	2082.5
1437.87	2061
1437.34	2040.5
1436.81	2014
1436.28	2046.5
1435.75	2051
1435.22	1990
1434.69	2100.75
1434.16	2025.5
1433.63	1942.5
1433.1	1975.25
1432.57	2032.75
1432.04	1973
1431.51	2002.25
1430.98	1967.75
1430.45	2048.75
1429.92	2016
1429.39	1932
1428.86	1990.5
1428.33	2031.75
1427.8	1949.5
1427.26	1974.75
1426.73	2080
1426.2	1995
1425.67	2002.5
1425.14	1975
1424.61	1979.75
1424.08	2004.5
1423.55	1997
1423.02	2008
1422.49	1987.75
1421.95	2001.25
1421.42	2010
1420.89	2009.25
1420.36	1956
1419.83	1966
1419.3	1994.25
1418.76	1927.5
1418.23	2029
1417.7	1978.5
1417.17	2013.5
1416.64	1940.25
1416.1	2013.75
1415.57	1974.5
1415.04	1972
1414.51	1980.75
1413.98	1926.5
1413.44	1959
1412.91	1952
1412.38	1997.5
1411.85	1943.25
1411.32	2005.5
1410.78	1925
1410.25	1936.5
1409.72	2048.25
1409.18	2049.5
1408.65	2033.5
1408.12	1991.75
1407.59	1952.5
1407.05	1971.25
1406.52	1968
1405.99	1949.25
1405.46	1976.5
1404.92	1978.5
1404.39	1939.75
1403.86	1936.25
1403.32	2025.5
1402.79	1914.75
1402.26	1959.75
1401.72	1984
1401.19	1942.5
1400.66	1912.5
1400.12	1979.25
1399.59	1914.75
1399.06	1946.5
1398.52	1953.5
1397.99	1954.25
1397.46	1965.75
1396.92	1971
1396.39	1967.25
1395.85	1948.5
1395.32	1946.75
1394.79	1973.25
1394.25	1941.75
1393.72	1988.5
1393.18	1941.5
1392.65	1954
1392.12	1971.75
1391.58	1952.5
1391.05	1940.5
1390.51	1988
1389.98	2024.5
1389.44	2089
1388.91	2212
1388.38	2576.5
1387.84	2930.5
1387.31	2572.5
1386.77	2060.5
1386.24	1993
1385.7	2020.5
1385.17	2002.25
1384.63	2019
1384.1	1904.5
1383.56	1900.5
1383.03	1976.5
1382.49	1995.25
1381.96	1908
1381.42	1947
1380.89	1898
1380.35	1977.25
1379.82	1988.75
1379.28	1996.5
1378.74	1990.25
1378.21	2001.75
1377.67	1979
1377.14	1922.5
1376.6	1955.5
1376.07	1962.5
1375.53	1977.75
1374.99	1917
1374.46	1933.25
1373.92	1941.75
1373.39	1940.5
1372.85	1947
1372.32	1980.5
1371.78	1943.5
1371.24	1892.5
1370.71	1984.25
1370.17	1931
1369.63	1974.25
1369.1	2017.75
1368.56	1953
1368.03	1900
1367.49	1929.5
1366.95	1916.25
1366.42	1962.75
1365.88	1949
1365.34	1926.5
1364.81	1966.5
1364.27	1940.5
1363.73	1918.5
1363.19	1934.25
1362.66	1932
1362.12	1949.75
1361.58	1926.25
1361.05	1931.25
1360.51	1968.25
1359.97	1916
1359.44	1940.75
1358.9	1894.25
1358.36	1963.25
1357.82	1942.5
1357.29	1950.75
1356.75	1873.5
1356.21	1964
1355.67	1958.5
1355.14	1903
1354.6	1932.5
1354.06	1936.5
1353.52	1938.75
1352.99	1921.5
1352.45	1919
1351.91	1957
1351.37	1883
1350.83	1917
1350.3	1903.75
1349.76	1914.25
1349.22	1977.75
1348.68	1938.5
1348.14	1883
1347.6	1894.25
1347.06	1906.25
1346.53	1879.5
1345.99	1950.25
1345.45	1919.25
1344.91	2012.75
1344.37	1932.5
1343.83	1892.5
1343.3	1931.25
1342.76	1945.25
1342.22	1961
1341.68	1862
1341.14	1884.5
1340.6	1939.25
1340.06	1971
1339.52	1899.25
1338.98	1942.5
1338.45	1967.25
1337.91	1923.5
1337.37	1993.5
1336.83	1938
1336.29	1900.5
1335.75	1923
1335.21	1858
1334.67	1897.25
1334.13	1942.5
1333.59	1960.5
1333.05	1878.5
1332.51	1931.25
1331.97	1906.5
1331.43	1914.25
1330.89	1919
1330.35	1822
1329.81	1908
1329.27	1931.25
1328.73	1909.25
1328.19	1917
1327.65	1914.5
1327.11	1916
1326.57	1917.5
1326.03	1947.75
1325.49	1960
1324.95	1915.75
1324.41	1941
1323.87	1908.75
1323.33	1941.5
1322.79	1879.25
1322.25	1940.25
1321.71	1855
1321.16	1912
1320.62	1873.25
1320.08	1905
1319.54	1889
1319	1938.75
1318.46	1965
1317.92	1921
1317.38	1896.25
1316.84	1907.75
1316.29	1950.5
1315.75	1953.5
1315.21	1915.5
1314.67	1949
1314.13	1976
1313.59	1936.5
1313.05	1938
1312.5	1869.5
1311.96	1948
1311.42	1956.5
1310.88	1967
1310.34	1914.5
1309.8	2038.5
1309.25	1979.5
1308.71	1926.5
1308.17	1912.5
1307.63	1986.5
1307.09	1982.5
1306.54	1959
1306	1920.5
1305.46	1958.5
1304.92	1958.5
1304.38	1987
1303.83	2010
1303.29	2000.5
1302.75	1959
1302.21	1965.5
1301.66	1941.75
1301.12	1982.25
1300.58	1997.25
1300.04	2046.75
1299.49	1991
1298.95	1948
1298.41	1999
1297.86	2020
1297.32	2019.5
1296.78	2046.25
1296.23	2043
1295.69	1963
1295.15	1996
1294.6	2011
1294.06	2018.75
1293.52	1979.5
1292.97	1947
1292.43	2022.5
1291.89	1967.5
1291.34	1983.5
1290.8	1970.75
1290.26	1957
1289.71	1961.75
1289.17	1988
1288.63	1986.75
1288.08	1989.5
1287.54	1961.5
1286.99	1970
1286.45	2074.5
1285.9	2162
1285.36	2512
1284.82	2645.75
1284.27	2140
1283.73	1998
1283.19	1966.25
1282.64	1926.5
1282.1	1938
1281.55	1996
1281.01	1949.5
1280.46	1934.75
1279.92	1935
1279.37	1969
1278.83	1934.5
1278.28	1930
1277.74	1874
1277.19	1955.25
1276.65	1923
1276.1	1962.5
1275.56	1949
1275.01	1952
1274.47	1981
1273.92	1937
1273.38	1968
1272.83	1962.5
1272.29	1982
1271.74	1988
1271.2	1951.25
1270.65	1975
1270.11	1958.75
1269.56	1910.5
1269.01	1909
1268.47	1926.5
1267.92	1987.75
1267.38	2022
1266.83	1994.5
1266.29	1989
1265.74	1981.5
1265.19	2014.5
1264.65	2038.5
1264.1	2037
1263.55	1992.5
1263.01	1935.5
1262.46	1985.5
1261.92	2000
1261.37	2036.5
1260.82	2011
1260.28	2045.5
1259.73	2006.5
1259.18	2094.75
1258.64	2063.25
1258.09	2017.5
1257.55	2103
1257	2060
1256.45	2052.75
1255.9	2073
1255.36	1993
1254.81	2090
1254.26	2094.5
1253.72	2076
1253.17	2063
1252.62	2047
1252.07	2069
1251.53	2068.5
1250.98	2147.5
1250.43	2067.75
1249.89	2077.5
1249.34	2069
1248.79	2098
1248.24	2140.75
1247.7	2091.5
1247.15	2156.25
1246.6	2127.5
1246.05	2134.5
1245.5	2173.75
1244.96	2166.25
1244.41	2142
1243.86	2160.5
1243.31	2109.5
1242.77	2123.5
1242.22	2108
1241.67	2177.25
1241.12	2145
1240.57	2146.5
1240.02	2283.25
1239.48	2179.5
1238.93	2244
1238.38	2249
1237.83	2261.75
1237.28	2248.75
1236.73	2369.75
1236.18	2341.5
1235.64	2381.5
1235.09	2412.5
1234.54	2412
1233.99	2418.5
1233.44	2529.5
1232.89	2523
1232.34	2527
1231.79	2581
1231.24	2592.5
1230.69	2665
1230.15	2696
1229.6	2674.5
1229.05	2679.5
1228.5	2670.25
1227.95	2665
1227.4	2602
1226.85	2569.5
1226.3	2634.25
1225.75	2575
1225.2	2478
1224.65	2380
1224.1	2437.5
1223.55	2403
1223	2356.5
1222.45	2302.5
1221.9	2341.75
1221.35	2319
1220.8	2302.5
1220.25	2264.5
1219.7	2219.25
1219.15	2181.75
1218.6	2199.5
1218.05	2118.5
1217.5	2217.5
1216.95	2162
1216.4	2106.75
1215.85	2106
1215.3	2147.75
1214.75	2104.75
1214.2	2048.5
1213.65	2061
1213.09	2113
1212.54	2055.25
1211.99	1994
1211.44	2058.25
1210.89	2020.5
1210.34	2010
1209.79	1994.5
1209.24	2029
1208.69	2003.25
1208.14	2037.75
1207.58	1941.5
1207.03	1966
1206.48	1979.5
1205.93	1974.5
1205.38	1957.5
1204.83	1937.25
1204.27	1981.75
1203.72	1998.5
1203.17	1982.5
1202.62	1929.5
1202.07	1916.5
1201.52	1920.5
1200.96	1941.75
1200.41	1924.5
1199.86	1916
1199.31	1924
1198.76	1944
1198.2	1971.5
1197.65	1989.75
1197.1	1915
1196.55	1934
1196	1892
1195.44	1912
1194.89	2066.5
1194.34	1887
1193.78	1914
1193.23	2003.25
1192.68	1991
1192.13	1965.75
1191.57	2047.5
1191.02	2079
1190.47	2064.5
1189.91	2071
1189.36	2039.5
1188.81	2133
1188.26	2097
1187.7	2131
1187.15	2063.5
1186.6	2155.5
1186.04	2110.5
1185.49	2114.5
1184.94	2171
1184.38	2147
1183.83	2130
1183.28	2088.5
1182.72	2119
1182.17	2155
1181.61	2031.5
1181.06	2111.5
1180.51	2072
1179.95	2097.75
1179.4	2057.5
1178.85	2083.25
1178.29	2092.5
1177.74	2071
1177.18	2077.5
1176.63	2022.25
1176.07	2009
1175.52	1954.5
1174.97	1966.5
1174.41	2003.25
1173.86	2021.75
1173.3	2002
1172.75	2014
1172.19	2036
1171.64	1976
1171.09	2072
1170.53	2077.75
1169.97	2095
1169.42	2048.5
1168.86	2079.5
1168.31	2113.5
1167.76	2146.75
1167.2	2162.5
1166.65	2271.5
1166.09	2244
1165.53	2215.5
1164.98	2295
1164.42	2423.5
1163.87	2505.25
1163.31	2592.75
1162.76	2730.5
1162.2	2789.5
1161.65	2949.5
1161.09	3039.25
1160.54	3160
1159.98	3280
1159.42	3422.25
1158.87	3485.25
1158.31	3497.5
1157.76	3546.75
1157.2	3472.5
1156.65	3350
1156.09	3210
1155.53	3189.75
1154.98	3029
1154.42	2853.75
1153.86	2730.25
1153.31	2681
1152.75	2538
1152.19	2452.5
1151.64	2522.75
1151.08	2347.5
1150.52	2324
1149.97	2271
1149.41	2270.25
1148.86	2149.5
1148.3	2180.5
1147.74	2133.5
1147.18	2077
1146.63	2133.5
1146.07	2142
1145.51	2076.5
1144.96	2069.5
1144.4	2082.75
1143.84	2026.5
1143.28	2016.5
1142.73	1985.5
1142.17	1961
1141.61	1998
1141.06	2002.5
1140.5	1982
1139.94	1985.25
1139.38	2032
1138.83	1955.5
1138.27	2036
1137.71	2013.75
1137.15	2016.5
1136.59	1934.5
1136.04	1937.5
1135.48	1906
1134.92	1986.5
1134.36	1939.75
1133.8	1954.5
1133.25	1926
1132.69	1934
1132.13	1944.5
1131.57	1953
1131.01	1906.5
1130.45	1885
1129.9	1909.5
1129.34	1948
1128.78	1883
1128.22	1974.5
1127.66	1893
1127.1	1943.5
1126.54	1918.5
1125.98	1918.5
1125.43	1898
1124.87	1909.5
1124.31	1975
1123.75	1913
1123.19	1915
1122.63	1944
1122.07	1902.5
1121.51	1949.5
1120.95	1945.5
1120.39	1923.5
1119.83	1990.5
1119.27	2003.5
1118.72	2001
1118.15	2004
1117.6	2014
1117.04	2049.75
1116.48	2082
1115.92	2087
1115.36	2117.5
1114.8	2092.25
1114.24	2159.5
1113.68	2112.5
1113.12	2189
1112.56	2183.5
1112	2130
1111.44	2238.25
1110.88	2127
1110.32	2174.5
1109.76	2176.5
1109.19	2110
1108.64	2084.5
1108.07	2094.5
1107.51	2037.5
1106.95	2039
1106.39	2101
1105.83	2021
1105.27	2045.5
1104.71	1961
1104.15	1937.75
1103.59	1937
1103.03	1965.5
1102.47	1940.25
1101.91	1925
1101.34	1908.5
1100.78	1951.5
1100.22	1879.5
1099.66	1894.5
1099.1	1849.5
1098.54	1939.5
1097.98	1955.5
1097.41	1890.5
1096.85	1925
1096.29	1866.5
1095.73	1900.5
1095.17	1899.75
1094.61	1894
1094.04	1882.5
1093.48	1871.5
1092.92	1888.25
1092.36	1863.5
1091.8	1880.5
1091.23	1841.5
1090.67	1917.5
1090.11	1947.75
1089.55	1931
1088.99	1922.5
1088.42	1879.25
1087.86	1930.5
1087.3	1978.75
1086.74	1905.5
1086.17	1950.5
1085.61	1977
1085.05	1977
1084.49	1983
1083.92	1952.5
1083.36	2029
1082.8	2121.5
1082.23	2095.75
1081.67	2197.5
1081.11	2147
1080.55	2200
1079.98	2119
1079.42	2163.75
1078.86	2097
1078.29	2047.25
1077.73	1987
1077.17	2011.75
1076.6	1958
1076.04	1922.5
1075.48	1894.5
1074.91	1938
1074.35	1944
1073.79	1895.5
1073.22	1870.5
1072.66	1915.75
1072.09	1871
1071.53	1897
1070.97	1871.5
1070.4	1878.75
1069.84	1879.5
1069.27	1897.5
1068.71	1863.5
1068.15	1899.75
1067.58	1912
1067.02	1876.5
1066.45	1857.5
1065.89	1902.75
1065.32	1899.5
1064.76	1856.5
1064.19	1946
1063.63	1882
1063.07	1892.5
1062.5	1839.5
1061.94	1915
1061.37	1836.5
1060.81	1820
1060.24	1799
1059.68	1839.5
1059.11	1863.5
1058.55	1859
1057.98	1827.5
1057.42	1804
1056.85	1855.5
1056.29	1827
1055.72	1829
1055.16	1820.25
1054.59	1808.5
1054.03	1764
1053.46	1802.5
1052.89	1829
1052.33	1841
1051.76	1804.5
1051.2	1858.5
1050.63	1870.75
1050.06	1834.25
1049.5	1801.75
1048.93	1813
1048.37	1788
1047.8	1764.25
1047.24	1866
1046.67	1821
1046.1	1778
1045.54	1783.75
1044.97	1825
1044.4	1837.75
1043.84	1835.5
1043.27	1826
1042.7	1891.5
1042.14	1841.5
1041.57	1779.5
1041.01	1802.5
1040.44	1761.5
1039.87	1839.25
1039.3	1754
1038.74	1805
1038.17	1803.5
1037.6	1741
1037.04	1782
1036.47	1763
1035.9	1848.25
1035.34	1820.5
1034.77	1734
1034.2	1747.25
1033.63	1795.75
1033.07	1763
1032.5	1806
1031.93	1776.5
1031.36	1778.5
1030.8	1762.5
1030.23	1751.5
1029.66	1737.5
1029.09	1722
1028.52	1756
1027.96	1738
1027.39	1760.5
1026.82	1752
1026.25	1738.5
1025.68	1697
1025.12	1720.25
1024.55	1714
1023.98	1759
1023.41	1732
1022.84	1763
1022.28	1754.5
1021.71	1758.75
1021.14	1704
1020.57	1732
1020	1723
1019.43	1734.5
1018.86	1724.5
1018.3	1755
1017.73	1730
1017.16	1768
1016.59	1732.5
1016.3	1809.5