File: Testing/Hickernall_HORIBA/g45-mi2_03.txt
#Acq. time (s)=	75
#Accumulations=	5
#Range=	Off
#Autofocus=	Off
#Macrospot=	Off
#AutoExposure=	Off
#Spike filter=	Multiple accum.
#Delay time (s)=	0
#Binning=	1
#Readout mode=	Signal
#DeNoise=	Off
#ICS correction=	Off
#Dark correction=	Off
#Inst. Process=	Off
#Instrument=	LabRAM HR Evol
#Detector=	Andor CCD
#Objective=	x100 LWD
#Grating=	1800 gr/mm
#ND Filter=	100%
#Laser (nm)=	532
#Spectro (cm-¹)=	1240.02
#Hole=	49.98
#Range=	Visible
#AFM=	Off
#StageXY=	Marzhauser
#StageZ=	Marzhauser
#X (µm)=	-16206.7
#Y (µm)=	-738.5
#Z (µm)=	-344.9
#Project=
#Sample=
#Site=
#Title=	g45-mi2
#Remark=
#Date=	06.05.2022 11:16
#Acquired=	06.05.2022 11:16:39
1454.81	1379.5
1454.28	1274.75
1453.75	1302.75
1453.22	1340
1452.69	1339.5
1452.16	1319
1451.64	1357.25
1451.11	1332
1450.58	1318
1450.05	1334
1449.52	1272.5
1448.99	1321
1448.46	1318.5
1447.93	1317.5
1447.4	1272.75
1446.88	1306.75
1446.35	1312.75
1445.82	1317.25
1445.29	1315.75
1444.76	1292.25
1444.23	1312
1443.7	1319
1443.17	1297
1442.64	1274.5
1442.11	1318.25
1441.58	1287
1441.05	1299.75
1440.52	1294
1439.99	1342.25
1439.46	1281.5
1438.93	1291
1438.4	1293.75
1437.87	1254.5
1437.34	1279.5
1436.81	1289.25
1436.28	1264.75
1435.75	1303.75
1435.22	1238.5
1434.69	1262
1434.16	1273
1433.63	1277.75
1433.1	1228
1432.57	1282.5
1432.04	1231
1431.51	1266.75
1430.98	1305.25
1430.45	1203
1429.92	1227.5
1429.39	1210.5
1428.86	1268
1428.33	1262
1427.8	1265
1427.26	1234.5
1426.73	1215
1426.2	1233
1425.67	1237.5
1425.14	1248.75
1424.61	1218.5
1424.08	1235
1423.55	1174.75
1423.02	1218.5
1422.49	1216.25
1421.95	1218.5
1421.42	1249.75
1420.89	1249.25
1420.36	1210.75
1419.83	1249
1419.3	1219.75
1418.76	1253.25
1418.23	1225.5
1417.7	1224.5
1417.17	1261
1416.64	1182
1416.1	1202
1415.57	1196.5
1415.04	1208.25
1414.51	1233.5
1413.98	1201.75
1413.44	1184.25
1412.91	1231.75
1412.38	1224.5
1411.85	1232.25
1411.32	1187.75
1410.78	1221
1410.25	1202.75
1409.72	1181.5
1409.18	1193.5
1408.65	1219
1408.12	1187.5
1407.59	1243.75
1407.05	1241.5
1406.52	1190.25
1405.99	1221.75
1405.46	1231.5
1404.92	1196.25
1404.39	1214
1403.86	1210.75
1403.32	1154.75
1402.79	1182.5
1402.26	1162.25
1401.72	1197
1401.19	1158
1400.66	1190
1400.12	1189.25
1399.59	1146.75
1399.06	1168
1398.52	1202
1397.99	1202
1397.46	1219
1396.92	1202.5
1396.39	1192.25
1395.85	1223
1395.32	1186.5
1394.79	1185.75
1394.25	1163
1393.72	1224.75
1393.18	1186.5
1392.65	1186
1392.12	1181
1391.58	1194
1391.05	1171
1390.51	1167.5
1389.98	1256.5
1389.44	1404.75
1388.91	1475
1388.38	1562.75
1387.84	1557.5
1387.31	1430.5
1386.77	1235.75
1386.24	1193.5
1385.7	1167.25
1385.17	1173.25
1384.63	1180.5
1384.1	1186.75
1383.56	1174.25
1383.03	1192
1382.49	1188.75
1381.96	1188.75
1381.42	1167
1380.89	1161
1380.35	1216
1379.82	1187.5
1379.28	1155.5
1378.74	1192
1378.21	1185
1377.67	1178.5
1377.14	1143.25
1376.6	1137.5
1376.07	1185.25
1375.53	1173
1374.99	1192.25
1374.46	1164.5
1373.92	1209.5
1373.39	1218.75
1372.85	1178
1372.32	1146.5
1371.78	1150.25
1371.24	1185.5
1370.71	1167.25
1370.17	1147.5
1369.63	1186.75
1369.1	1204.25
1368.56	1151
1368.03	1137
1367.49	1123.75
1366.95	1157.5
1366.42	1160
1365.88	1241.5
1365.34	1140.5
1364.81	1182
1364.27	1168.5
1363.73	1171.75
1363.19	1153.5
1362.66	1151.75
1362.12	1150.5
1361.58	1160.25
1361.05	1181
1360.51	1150.75
1359.97	1157.25
1359.44	1146.75
1358.9	1130
1358.36	1165
1357.82	1198.75
1357.29	1167.5
1356.75	1140.75
1356.21	1169
1355.67	1140.75
1355.14	1147.25
1354.6	1133.25
1354.06	1144.5
1353.52	1146.25
1352.99	1150.5
1352.45	1151.75
1351.91	1087.5
1351.37	1123
1350.83	1143.5
1350.3	1158.25
1349.76	1166.5
1349.22	1151.5
1348.68	1172.5
1348.14	1126
1347.6	1138
1347.06	1124.25
1346.53	1170.5
1345.99	1138.75
1345.45	1158
1344.91	1132.5
1344.37	1149.25
1343.83	1134
1343.3	1146.75
1342.76	1165.5
1342.22	1178.5
1341.68	1089
1341.14	1142.75
1340.6	1162.75
1340.06	1135.5
1339.52	1154.75
1338.98	1107.25
1338.45	1140
1337.91	1144.75
1337.37	1107
1336.83	1137
1336.29	1150
1335.75	1149.25
1335.21	1121
1334.67	1140.75
1334.13	1160.5
1333.59	1128
1333.05	1089.25
1332.51	1144
1331.97	1111
1331.43	1121.5
1330.89	1174
1330.35	1155.5
1329.81	1173.75
1329.27	1091
1328.73	1125.5
1328.19	1127.75
1327.65	1148
1327.11	1137.75
1326.57	1153.5
1326.03	1160
1325.49	1149.5
1324.95	1142.25
1324.41	1132
1323.87	1141
1323.33	1124.5
1322.79	1127.5
1322.25	1127.5
1321.71	1139.25
1321.16	1118.25
1320.62	1180
1320.08	1136.75
1319.54	1127.5
1319	1153.25
1318.46	1150.25
1317.92	1126.5
1317.38	1198
1316.84	1135.25
1316.29	1155.25
1315.75	1165.25
1315.21	1142.75
1314.67	1193.5
1314.13	1145
1313.59	1179.75
1313.05	1163.5
1312.5	1171.5
1311.96	1162
1311.42	1193.5
1310.88	1170.5
1310.34	1159
1309.8	1199.75
1309.25	1192.5
1308.71	1194.5
1308.17	1156.75
1307.63	1215.25
1307.09	1160.75
1306.54	1201
1306	1172.5
1305.46	1219
1304.92	1163
1304.38	1199.25
1303.83	1162.75
1303.29	1242
1302.75	1187
1302.21	1203.5
1301.66	1190
1301.12	1205.25
1300.58	1227.25
1300.04	1248.5
1299.49	1192
1298.95	1215.25
1298.41	1180.75
1297.86	1200.75
1297.32	1217.5
1296.78	1264.75
1296.23	1211.5
1295.69	1184.5
1295.15	1210.25
1294.6	1233.5
1294.06	1210
1293.52	1246.5
1292.97	1214.25
1292.43	1190.75
1291.89	1214.5
1291.34	1163
1290.8	1209.5
1290.26	1182.25
1289.71	1187.25
1289.17	1184
1288.63	1186.25
1288.08	1197.5
1287.54	1211
1286.99	1252.25
1286.45	1372.75
1285.9	1335.5
1285.36	1458
1284.82	1422.25
1284.27	1288
1283.73	1179.25
1283.19	1169
1282.64	1154.25
1282.1	1207.25
1281.55	1222
1281.01	1158.5
1280.46	1206
1279.92	1155.5
1279.37	1159.75
1278.83	1188
1278.28	1175
1277.74	1135
1277.19	1160.5
1276.65	1179.25
1276.1	1166.75
1275.56	1177.5
1275.01	1164
1274.47	1171.5
1273.92	1152.5
1273.38	1155
1272.83	1168.75
1272.29	1185
1271.74	1190
1271.2	1179.25
1270.65	1161.75
1270.11	1182.25
1269.56	1174
1269.01	1158.75
1268.47	1196
1267.92	1193.25
1267.38	1200.5
1266.83	1191
1266.29	1191.5
1265.74	1234.5
1265.19	1179.25
1264.65	1176
1264.1	1240
1263.55	1203
1263.01	1220.75
1262.46	1208
1261.92	1246.25
1261.37	1209.5
1260.82	1222.25
1260.28	1256
1259.73	1221.5
1259.18	1243.5
1258.64	1269
1258.09	1248.5
1257.55	1261.5
1257	1226.75
1256.45	1231.25
1255.9	1249.75
1255.36	1254
1254.81	1233.5
1254.26	1271.5
1253.72	1286.25
1253.17	1280.5
1252.62	1327.25
1252.07	1327
1251.53	1315
1250.98	1273
1250.43	1312.25
1249.89	1307
1249.34	1315.25
1248.79	1306.25
1248.24	1339.25
1247.7	1344.25
1247.15	1342.5
1246.6	1352.25
1246.05	1374.5
1245.5	1358.25
1244.96	1378.5
1244.41	1400.25
1243.86	1362.5
1243.31	1393
1242.77	1370.75
1242.22	1414.5
1241.67	1367.25
1241.12	1435
1240.57	1445.5
1240.02	1467.25
1239.48	1463.5
1238.93	1480.75
1238.38	1517.75
1237.83	1521.5
1237.28	1567.25
1236.73	1611
1236.18	1585.25
1235.64	1620.5
1235.09	1713.25
1234.54	1729.5
1233.99	1733.75
1233.44	1837.5
1232.89	1786.5
1232.34	1878
1231.79	1813.5
1231.24	1874.5
1230.69	1877
1230.15	1877.5
1229.6	1936.25
1229.05	1935.5
1228.5	1949.25
1227.95	1919.5
1227.4	1900
1226.85	1829.5
1226.3	1814.5
1225.75	1794.5
1225.2	1708
1224.65	1673.5
1224.1	1660
1223.55	1624.5
1223	1653
1222.45	1575.25
1221.9	1527
1221.35	1512
1220.8	1489
1220.25	1477
1219.7	1469.5
1219.15	1427.75
1218.6	1413.5
1218.05	1421.25
1217.5	1395.75
1216.95	1375.25
1216.4	1327.75
1215.85	1347.75
1215.3	1371.75
1214.75	1317.75
1214.2	1287.5
1213.65	1302
1213.09	1290.5
1212.54	1252.25
1211.99	1252
1211.44	1238.75
1210.89	1293.5
1210.34	1241.5
1209.79	1235.5
1209.24	1207
1208.69	1228.25
1208.14	1243.25
1207.58	1207.75
1207.03	1209.75
1206.48	1210.5
1205.93	1194.5
1205.38	1227.75
1204.83	1151
1204.27	1188.5
1203.72	1200
1203.17	1154.25
1202.62	1224.25
1202.07	1187.5
1201.52	1168.25
1200.96	1161.75
1200.41	1177.75
1199.86	1156.25
1199.31	1191.5
1198.76	1186.5
1198.2	1147
1197.65	1134.5
1197.1	1173.75
1196.55	1187
1196	1173.75
1195.44	1163.75
1194.89	1179
1194.34	1208.25
1193.78	1187
1193.23	1165.75
1192.68	1243.25
1192.13	1213
1191.57	1214
1191.02	1221.75
1190.47	1269.5
1189.91	1246
1189.36	1299
1188.81	1291.5
1188.26	1331.5
1187.7	1271.75
1187.15	1326.25
1186.6	1302.25
1186.04	1348
1185.49	1325.25
1184.94	1301
1184.38	1282
1183.83	1321
1183.28	1319.5
1182.72	1278.5
1182.17	1275.5
1181.61	1281.5
1181.06	1263
1180.51	1304.5
1179.95	1289.25
1179.4	1272.25
1178.85	1227
1178.29	1217.25
1177.74	1250.5
1177.18	1229.5
1176.63	1216.5
1176.07	1223.25
1175.52	1238.25
1174.97	1212.5
1174.41	1247.25
1173.86	1195.25
1173.3	1221
1172.75	1227.75
1172.19	1228.75
1171.64	1226.75
1171.09	1240.5
1170.53	1214.75
1169.97	1265
1169.42	1276.25
1168.86	1296
1168.31	1351.25
1167.76	1333
1167.2	1338.75
1166.65	1395.75
1166.09	1443
1165.53	1480.75
1164.98	1541.5
1164.42	1648.75
1163.87	1653.25
1163.31	1691
1162.76	1849
1162.2	1939
1161.65	2024.25
1161.09	2143.75
1160.54	2192.25
1159.98	2366
1159.42	2377.5
1158.87	2405.75
1158.31	2449.75
1157.76	2440.75
1157.2	2332.75
1156.65	2261
1156.09	2220
1155.53	2071.5
1154.98	1899.25
1154.42	1879.5
1153.86	1781.25
1153.31	1696.5
1152.75	1578
1152.19	1553
1151.64	1567.25
1151.08	1505
1150.52	1403
1149.97	1373
1149.41	1376.5
1148.86	1352.5
1148.3	1403.25
1147.74	1340.75
1147.18	1282
1146.63	1288.25
1146.07	1267.5
1145.51	1264
1144.96	1284
1144.4	1226.5
1143.84	1216.25
1143.28	1206.5
1142.73	1235.75
1142.17	1227.75
1141.61	1190
1141.06	1205.5
1140.5	1217
1139.94	1200.25
1139.38	1174
1138.83	1196.25
1138.27	1169.75
1137.71	1161.5
1137.15	1199.5
1136.59	1155.5
1136.04	1207.25
1135.48	1150.75
1134.92	1173
1134.36	1151.5
1133.8	1150
1133.25	1163.75
1132.69	1176
1132.13	1148.25
1131.57	1116
1131.01	1125.25
1130.45	1142.25
1129.9	1160.25
1129.34	1164.75
1128.78	1147.75
1128.22	1181
1127.66	1141.5
1127.1	1142.75
1126.54	1193.75
1125.98	1098.75
1125.43	1154.25
1124.87	1159.75
1124.31	1145
1123.75	1158.5
1123.19	1143.25
1122.63	1150.75
1122.07	1181.5
1121.51	1218
1120.95	1176
1120.39	1189
1119.83	1224.25
1119.27	1222
1118.72	1233.5
1118.15	1226
1117.6	1248.25
1117.04	1284.75
1116.48	1312.25
1115.92	1318
1115.36	1340.25
1114.8	1380
1114.24	1361.75
1113.68	1387
1113.12	1364.5
1112.56	1375
1112	1402
1111.44	1415
1110.88	1401.5
1110.32	1344
1109.76	1327.5
1109.19	1326.25
1108.64	1300
1108.07	1277.75
1107.51	1260
1106.95	1298.5
1106.39	1207.5
1105.83	1204
1105.27	1223
1104.71	1225.75
1104.15	1187.5
1103.59	1188.25
1103.03	1154
1102.47	1151.75
1101.91	1159.5
1101.34	1147
1100.78	1170
1100.22	1113.75
1099.66	1113.5
1099.1	1141.5
1098.54	1153.5
1097.98	1085.25
1097.41	1110.5
1096.85	1108.75
1096.29	1118
1095.73	1137.5
1095.17	1133.25
1094.61	1117
1094.04	1148
1093.48	1137
1092.92	1113.5
1092.36	1159
1091.8	1117.75
1091.23	1157.5
1090.67	1124.5
1090.11	1135.75
1089.55	1153.75
1088.99	1145
1088.42	1147
1087.86	1175.25
1087.3	1205.25
1086.74	1189
1086.17	1199.25
1085.61	1199
1085.05	1252.5
1084.49	1266.75
1083.92	1308
1083.36	1319.75
1082.8	1352.5
1082.23	1343
1081.67	1367.75
1081.11	1391.5
1080.55	1365.5
1079.98	1345.25
1079.42	1308.5
1078.86	1257.5
1078.29	1276.5
1077.73	1186.25
1077.17	1230
1076.6	1173.25
1076.04	1154
1075.48	1168.75
1074.91	1129.25
1074.35	1133.5
1073.79	1180.75
1073.22	1190
1072.66	1165
1072.09	1166
1071.53	1146.25
1070.97	1203.5
1070.4	1142
1069.84	1184.5
1069.27	1171.5
1068.71	1147.75
1068.15	1106
1067.58	1104
1067.02	1126.25
1066.45	1159
1065.89	1141
1065.32	1165
1064.76	1089
1064.19	1153.75
1063.63	1156.25
1063.07	1124.25
1062.5	1098
1061.94	1140
1061.37	1154.25
1060.81	1101.5
1060.24	1092.75
1059.68	1103.5
1059.11	1109
1058.55	1117.5
1057.98	1104.5
1057.42	1109
1056.85	1045.25
1056.29	1090.75
1055.72	1070.5
1055.16	1067
1054.59	1059.25
1054.03	1098
1053.46	1061.5
1052.89	1102
1052.33	1111.75
1051.76	1086
1051.2	1057
1050.63	1109
1050.06	1088.25
1049.5	1055.25
1048.93	1084.25
1048.37	1066
1047.8	1119
1047.24	1104
1046.67	1096
1046.1	1086.75
1045.54	1091
1044.97	1076
1044.4	1102
1043.84	1122.5
1043.27	1105.25
1042.7	1111.25
1042.14	1089.25
1041.57	1090.75
1041.01	1094.25
1040.44	1066.25
1039.87	1067
1039.3	1073.5
1038.74	1075
1038.17	1059.75
1037.6	1079.75
1037.04	1059.25
1036.47	1073.25
1035.9	1066.75
1035.34	1080.5
1034.77	1046
1034.2	1035.5
1033.63	1045.25
1033.07	1035
1032.5	1010.5
1031.93	1063.75
1031.36	1058.5
1030.8	1024.75
1030.23	1040
1029.66	1024.75
1029.09	1037
1028.52	1043
1027.96	1036.25
1027.39	1001
1026.82	1050.75
1026.25	1017.75
1025.68	1028.5
1025.12	1041.75
1024.55	1026.75
1023.98	1012.25
1023.41	1005.5
1022.84	1025.5
1022.28	1035
1021.71	997.75
1021.14	1021.5
1020.57	1010
1020	982
1019.43	1035.5
1018.86	1004.75
1018.3	1050.5
1017.73	1025.75
1017.16	1021
1016.59	996.75
1016.3	1028.75