File: Testing/Hickernall_HORIBA/g45-mi1bub2_03.txt
#Acq. time (s)=	75
#Accumulations=	5
#Range=	Off
#Autofocus=	Off
#Macrospot=	Off
#AutoExposure=	Off
#Spike filter=	Multiple accum.
#Delay time (s)=	0
#Binning=	1
#Readout mode=	Signal
#DeNoise=	Off
#ICS correction=	Off
#Dark correction=	Off
#Inst. Process=	Off
#Instrument=	LabRAM HR Evol
#Detector=	Andor CCD
#Objective=	x100 LWD
#Grating=	1800 gr/mm
#ND Filter=	100%
#Laser (nm)=	532
#Spectro (cm-¹)=	1240.02
#Hole=	49.98
#Range=	Visible
#AFM=	Off
#StageXY=	Marzhauser
#StageZ=	Marzhauser
#X (µm)=	-15953.4
#Y (µm)=	-816.2
#Z (µm)=	-348.6
#Project=
#Sample=
#Site=
#Title=	g45-mi1bub2
#Remark=
#Date=	06.05.2022 10:37
#Acquired=	06.05.2022 10:37:32
1454.81	2101.75
1454.28	2115.5
1453.75	2134
1453.22	2075.5
1452.69	2130.5
1452.16	2113.75
1451.64	2133.75
1451.11	2149.25
1450.58	2138.5
1450.05	2117.75
1449.52	2143.5
1448.99	2142
1448.46	2084
1447.93	2063.5
1447.4	2117.75
1446.88	2108.25
1446.35	2129
1445.82	2093.25
1445.29	2053.5
1444.76	2121.5
1444.23	2156
1443.7	2121
1443.17	2089.25
1442.64	2068.75
1442.11	2059
1441.58	2101.5
1441.05	2110.75
1440.52	2094
1439.99	2084.75
1439.46	2070.5
1438.93	2084.5
1438.4	2029.75
1437.87	2101.75
1437.34	2103.5
1436.81	2098.75
1436.28	2111.5
1435.75	2112
1435.22	2123
1434.69	2047
1434.16	1979
1433.63	2100
1433.1	2045
1432.57	2048.25
1432.04	2005
1431.51	2074.75
1430.98	2080.75
1430.45	2018.5
1429.92	2061.75
1429.39	2020.5
1428.86	2083
1428.33	2067
1427.8	2073.5
1427.26	2029
1426.73	2082
1426.2	2080.5
1425.67	1989.75
1425.14	2052.75
1424.61	2070.5
1424.08	2062.25
1423.55	2089
1423.02	2043
1422.49	2009.5
1421.95	2037.75
1421.42	2003.5
1420.89	2036.75
1420.36	2033.25
1419.83	2051.25
1419.3	1984.25
1418.76	2018.5
1418.23	2028.5
1417.7	2032.5
1417.17	1983.25
1416.64	2002.5
1416.1	2029.25
1415.57	2048.75
1415.04	2038.25
1414.51	2018
1413.98	2056.25
1413.44	2002
1412.91	2008
1412.38	1977
1411.85	1991.25
1411.32	2047.5
1410.78	2021.5
1410.25	2067
1409.72	2044.25
1409.18	2081
1408.65	2102.25
1408.12	2074.5
1407.59	1965.25
1407.05	2030.5
1406.52	1997.75
1405.99	2031.25
1405.46	2019.5
1404.92	2002
1404.39	2049.5
1403.86	2014.5
1403.32	2018.25
1402.79	1975
1402.26	1976
1401.72	2030
1401.19	1968
1400.66	1995.75
1400.12	1977
1399.59	1960.75
1399.06	1986.5
1398.52	1981.25
1397.99	1987.5
1397.46	2027.75
1396.92	1967.5
1396.39	1972.75
1395.85	2008
1395.32	1990.25
1394.79	2013
1394.25	1952.75
1393.72	2004.75
1393.18	1984.5
1392.65	1982.5
1392.12	1952.75
1391.58	2004.25
1391.05	1985.5
1390.51	2037.75
1389.98	2128.5
1389.44	2203.75
1388.91	2332.75
1388.38	2532.25
1387.84	2617
1387.31	2380.5
1386.77	2039
1386.24	1957.75
1385.7	2024
1385.17	1977.25
1384.63	1976
1384.1	1996.5
1383.56	1941.25
1383.03	1987.25
1382.49	2000.5
1381.96	1979.5
1381.42	1968.25
1380.89	1981.75
1380.35	1988.5
1379.82	2037.25
1379.28	1984.5
1378.74	1998.25
1378.21	1958.25
1377.67	1959.5
1377.14	1973.5
1376.6	1988.25
1376.07	2010.25
1375.53	1958.75
1374.99	1983.5
1374.46	1972
1373.92	1964.25
1373.39	2010
1372.85	1992.5
1372.32	1938.5
1371.78	1979
1371.24	1993.5
1370.71	1929
1370.17	1942.5
1369.63	2003.5
1369.1	1986.5
1368.56	1949.75
1368.03	1951.75
1367.49	1895
1366.95	1981
1366.42	1960.5
1365.88	1959.25
1365.34	1948.75
1364.81	1979.25
1364.27	1961.5
1363.73	1897.5
1363.19	1944.75
1362.66	1956.25
1362.12	1970.75
1361.58	1943.5
1361.05	1889
1360.51	1956.25
1359.97	1950.25
1359.44	1937.25
1358.9	1953.25
1358.36	1969.75
1357.82	1986.75
1357.29	1970.5
1356.75	1947.5
1356.21	1990
1355.67	1915.75
1355.14	1969.75
1354.6	1952.75
1354.06	1978.5
1353.52	1938.5
1352.99	1962
1352.45	1889.5
1351.91	1903
1351.37	1919.25
1350.83	1926
1350.3	1929.75
1349.76	1968
1349.22	1992.75
1348.68	1949.75
1348.14	1926.5
1347.6	1949
1347.06	1933.75
1346.53	1933.25
1345.99	1914.5
1345.45	1937.75
1344.91	1938.25
1344.37	1948
1343.83	1953.25
1343.3	1956.25
1342.76	1961.75
1342.22	1930
1341.68	1926
1341.14	1955.25
1340.6	1877
1340.06	1868
1339.52	1934.5
1338.98	1949.75
1338.45	1921.5
1337.91	1957.75
1337.37	1923.5
1336.83	1912.5
1336.29	1937.75
1335.75	1899.25
1335.21	1909.75
1334.67	1881.5
1334.13	1892.75
1333.59	1854.75
1333.05	1867.75
1332.51	1926.5
1331.97	1879.5
1331.43	1922.25
1330.89	1882.5
1330.35	1910.5
1329.81	1920
1329.27	1878
1328.73	1902
1328.19	1884.5
1327.65	1877.5
1327.11	1892.5
1326.57	1884
1326.03	1912.5
1325.49	1880
1324.95	1943.75
1324.41	1813.25
1323.87	1870.5
1323.33	1871.75
1322.79	1909
1322.25	1875
1321.71	1862.75
1321.16	1922
1320.62	1890
1320.08	1911.25
1319.54	1895.25
1319	1912.5
1318.46	1858.5
1317.92	1934.5
1317.38	1913
1316.84	1878
1316.29	1874.5
1315.75	1882.75
1315.21	1864.75
1314.67	1932.5
1314.13	1907
1313.59	1914.5
1313.05	1901.25
1312.5	1947.25
1311.96	1944.5
1311.42	1913.75
1310.88	1882.25
1310.34	1904.5
1309.8	1976.5
1309.25	1889
1308.71	1887.75
1308.17	1925.5
1307.63	1940.75
1307.09	1875.25
1306.54	1894.5
1306	1906.75
1305.46	1944
1304.92	1866.25
1304.38	1912.25
1303.83	1909.75
1303.29	1967.5
1302.75	1964
1302.21	1935.75
1301.66	1910
1301.12	1920.25
1300.58	1924.25
1300.04	1920
1299.49	1992.25
1298.95	2014.25
1298.41	1986.25
1297.86	1901
1297.32	1899.75
1296.78	1967.25
1296.23	1935.25
1295.69	1950
1295.15	1938
1294.6	1943
1294.06	1975.75
1293.52	1922.25
1292.97	1879.5
1292.43	1905.5
1291.89	1936.75
1291.34	1927.25
1290.8	1922.25
1290.26	1876
1289.71	1962.25
1289.17	1931.75
1288.63	1866
1288.08	1934.75
1287.54	1965.5
1286.99	2022.5
1286.45	2075.25
1285.9	2129.75
1285.36	2293.25
1284.82	2235.5
1284.27	1993.75
1283.73	1922
1283.19	1944.75
1282.64	1891.5
1282.1	1867
1281.55	1950.75
1281.01	1954.5
1280.46	1893
1279.92	1902.25
1279.37	1945.5
1278.83	1918.5
1278.28	1887.25
1277.74	1873.75
1277.19	1876.75
1276.65	1890
1276.1	1860.5
1275.56	1838.25
1275.01	1910.75
1274.47	1908.75
1273.92	1946
1273.38	1895
1272.83	1916.5
1272.29	1900.5
1271.74	1863.5
1271.2	1920
1270.65	1930
1270.11	1930
1269.56	1865
1269.01	1897.25
1268.47	1868.75
1267.92	1918.25
1267.38	1939.25
1266.83	1899.75
1266.29	1922
1265.74	1979.5
1265.19	1966.75
1264.65	1964
1264.1	1974
1263.55	1949.75
1263.01	1918.5
1262.46	1872.5
1261.92	1926.5
1261.37	1962.25
1260.82	1929.5
1260.28	1939.5
1259.73	1955.25
1259.18	1967
1258.64	1948
1258.09	1933.5
1257.55	1950.25
1257	2030.75
1256.45	1954.5
1255.9	1903.5
1255.36	1987.75
1254.81	1955.25
1254.26	2020
1253.72	1951.75
1253.17	1984.5
1252.62	1953
1252.07	1994.5
1251.53	2029
1250.98	2051.75
1250.43	2008
1249.89	2064.25
1249.34	2015
1248.79	2053.75
1248.24	2062.5
1247.7	2022.5
1247.15	2078.5
1246.6	2025.5
1246.05	2006.25
1245.5	2019.25
1244.96	2033.5
1244.41	2054
1243.86	2035.25
1243.31	2113
1242.77	2007.25
1242.22	2120.75
1241.67	2114.25
1241.12	2102.25
1240.57	2101.5
1240.02	2141.75
1239.48	2137.25
1238.93	2096.5
1238.38	2137.75
1237.83	2179
1237.28	2200.75
1236.73	2201.5
1236.18	2199
1235.64	2225.25
1235.09	2252.25
1234.54	2327
1233.99	2297.25
1233.44	2323
1232.89	2331.5
1232.34	2358
1231.79	2325
1231.24	2433.75
1230.69	2427.5
1230.15	2373.75
1229.6	2443
1229.05	2387.75
1228.5	2439.75
1227.95	2458
1227.4	2388.25
1226.85	2360.5
1226.3	2378
1225.75	2371.5
1225.2	2316
1224.65	2311.25
1224.1	2315.5
1223.55	2213.25
1223	2205
1222.45	2232
1221.9	2195
1221.35	2204.75
1220.8	2112.25
1220.25	2111
1219.7	2170.25
1219.15	2107.75
1218.6	2051.5
1218.05	2140
1217.5	2050.25
1216.95	2111.75
1216.4	2060.25
1215.85	2039.5
1215.3	2126.5
1214.75	2049.25
1214.2	2051
1213.65	2035.5
1213.09	2054
1212.54	2031
1211.99	2017
1211.44	2021.75
1210.89	2049.25
1210.34	2014
1209.79	1998.25
1209.24	1986
1208.69	1975.5
1208.14	1981.75
1207.58	1968.25
1207.03	2045.75
1206.48	1957.25
1205.93	1985.5
1205.38	1937.5
1204.83	1943.75
1204.27	1979.5
1203.72	2022
1203.17	1941.25
1202.62	1961.75
1202.07	1980.75
1201.52	1899
1200.96	1935.5
1200.41	1937
1199.86	1923.25
1199.31	1983.25
1198.76	1959.25
1198.2	1970
1197.65	1979.75
1197.1	1987.5
1196.55	1940.5
1196	1951.5
1195.44	1963
1194.89	1970.75
1194.34	1972
1193.78	2001.5
1193.23	1994.75
1192.68	1969.75
1192.13	1979.25
1191.57	1983
1191.02	2064.5
1190.47	2071.75
1189.91	2018.25
1189.36	2047.5
1188.81	2089.75
1188.26	2082.75
1187.7	2090.75
1187.15	2109.75
1186.6	2141.25
1186.04	2111.25
1185.49	2087.75
1184.94	2062
1184.38	2083
1183.83	2091
1183.28	2112.75
1182.72	2055
1182.17	2108.75
1181.61	2118.25
1181.06	2028.75
1180.51	2011
1179.95	2044.5
1179.4	2051.5
1178.85	2002.25
1178.29	2039
1177.74	2011.75
1177.18	1998.25
1176.63	1988.5
1176.07	2042.5
1175.52	2047.5
1174.97	1999.75
1174.41	2017
1173.86	1979.25
1173.3	2042.5
1172.75	2073
1172.19	2004.75
1171.64	2001.75
1171.09	2073
1170.53	2030.75
1169.97	2058
1169.42	2095.5
1168.86	2119
1168.31	2130.5
1167.76	2158.75
1167.2	2145
1166.65	2170.5
1166.09	2282.5
1165.53	2258.75
1164.98	2348.25
1164.42	2356.5
1163.87	2398.25
1163.31	2518.5
1162.76	2595
1162.2	2689.75
1161.65	2779.75
1161.09	2778.75
1160.54	2858.75
1159.98	3006.25
1159.42	3045.5
1158.87	2958
1158.31	3065.5
1157.76	3036
1157.2	2965.75
1156.65	2921.75
1156.09	2822.25
1155.53	2759.75
1154.98	2645
1154.42	2499.5
1153.86	2527.5
1153.31	2478
1152.75	2383.5
1152.19	2266
1151.64	2273.75
1151.08	2290
1150.52	2232
1149.97	2168.5
1149.41	2197.75
1148.86	2158
1148.3	2138.5
1147.74	2107.75
1147.18	2065.5
1146.63	2034.25
1146.07	2058
1145.51	2038
1144.96	2115.5
1144.4	2051.75
1143.84	2042
1143.28	2007.25
1142.73	2030.5
1142.17	2043
1141.61	1988
1141.06	1995.75
1140.5	2029
1139.94	2045.5
1139.38	2029
1138.83	1974
1138.27	1978.75
1137.71	2041
1137.15	1967.5
1136.59	1922
1136.04	1984.5
1135.48	1997.5
1134.92	1972.5
1134.36	1953.25
1133.8	1961.5
1133.25	1969.5
1132.69	1942.5
1132.13	1922
1131.57	1994
1131.01	1985
1130.45	1971.25
1129.9	1954.25
1129.34	1956.75
1128.78	1925.75
1128.22	1953.75
1127.66	1992.75
1127.1	1986.5
1126.54	1946.25
1125.98	1984.5
1125.43	1933
1124.87	2004.25
1124.31	1951
1123.75	1961.75
1123.19	2006.5
1122.63	1983
1122.07	1970
1121.51	1975
1120.95	1931.5
1120.39	1960.25
1119.83	1970
1119.27	1971.25
1118.72	1974
1118.15	2029
1117.6	2034.5
1117.04	2025.5
1116.48	2044.5
1115.92	2077
1115.36	2063
1114.8	2090.25
1114.24	2134
1113.68	2097.75
1113.12	2088.5
1112.56	2094.75
1112	2137.5
1111.44	2179
1110.88	2099.75
1110.32	2136
1109.76	2083.75
1109.19	2047.75
1108.64	2017.75
1108.07	1998.25
1107.51	1969
1106.95	2029.25
1106.39	1989
1105.83	1985.25
1105.27	2023.25
1104.71	1938.75
1104.15	1955.5
1103.59	1952
1103.03	1940.5
1102.47	1873.5
1101.91	1831
1101.34	1916.25
1100.78	1933.25
1100.22	1887.25
1099.66	1870
1099.1	1903.5
1098.54	1939.75
1097.98	1911.5
1097.41	1876.75
1096.85	1890
1096.29	1963.25
1095.73	1864.75
1095.17	1865.5
1094.61	1917.75
1094.04	1873.75
1093.48	1863
1092.92	1841
1092.36	1876
1091.8	1871.5
1091.23	1873.75
1090.67	1841.25
1090.11	1880.5
1089.55	1887.25
1088.99	1930.25
1088.42	1890
1087.86	1938.75
1087.3	1929.25
1086.74	1911.25
1086.17	1923
1085.61	1963.75
1085.05	1969.75
1084.49	1984
1083.92	2042.75
1083.36	2002.25
1082.8	2015.25
1082.23	2073.75
1081.67	2089
1081.11	2102.5
1080.55	2055
1079.98	2038.5
1079.42	2032
1078.86	2050
1078.29	1976.75
1077.73	1979.25
1077.17	1933
1076.6	1938.75
1076.04	1926.25
1075.48	1928.75
1074.91	1957.5
1074.35	1952
1073.79	1871.25
1073.22	1886.5
1072.66	1887
1072.09	1920.75
1071.53	1890
1070.97	1903.75
1070.4	1912.5
1069.84	1863.75
1069.27	1874
1068.71	1839
1068.15	1885
1067.58	1923.25
1067.02	1868
1066.45	1887.75
1065.89	1890.25
1065.32	1870
1064.76	1841
1064.19	1925
1063.63	1909.75
1063.07	1872
1062.5	1896
1061.94	1882.75
1061.37	1877.5
1060.81	1889
1060.24	1860
1059.68	1881.25
1059.11	1828.5
1058.55	1830.5
1057.98	1861.25
1057.42	1853
1056.85	1860.5
1056.29	1887.75
1055.72	1777
1055.16	1849
1054.59	1848
1054.03	1852
1053.46	1840
1052.89	1797
1052.33	1805.5
1051.76	1850.75
1051.2	1752
1050.63	1838.75
1050.06	1832.5
1049.5	1791.5
1048.93	1874.75
1048.37	1894.25
1047.8	1871.75
1047.24	1781
1046.67	1834.5
1046.1	1815.25
1045.54	1820.75
1044.97	1842.75
1044.4	1862
1043.84	1843.25
1043.27	1866.25
1042.7	1798
1042.14	1834.75
1041.57	1840.5
1041.01	1828
1040.44	1817
1039.87	1844
1039.3	1814.25
1038.74	1837.25
1038.17	1806
1037.6	1832.25
1037.04	1840.25
1036.47	1786
1035.9	1809.25
1035.34	1835.5
1034.77	1806
1034.2	1822.25
1033.63	1792.5
1033.07	1791.75
1032.5	1772.5
1031.93	1750
1031.36	1799.25
1030.8	1774.75
1030.23	1777
1029.66	1785.75
1029.09	1837
1028.52	1782.75
1027.96	1797.75
1027.39	1758.25
1026.82	1766.5
1026.25	1763
1025.68	1732.75
1025.12	1742
1024.55	1798.75
1023.98	1785
1023.41	1752
1022.84	1775.5
1022.28	1725.25
1021.71	1768.5
1021.14	1720.5
1020.57	1723.75
1020	1746.5
1019.43	1791
1018.86	1766.5
1018.3	1749.25
1017.73	1817.75
1017.16	1755
1016.59	1781.25
1016.3	1708