File: Testing/Hickernall_HORIBA/g45-mi1bub1_02.txt
#Acq. time (s)=	75
#Accumulations=	5
#Range=	Off
#Autofocus=	Off
#Macrospot=	Off
#AutoExposure=	Off
#Spike filter=	Multiple accum.
#Delay time (s)=	0
#Binning=	1
#Readout mode=	Signal
#DeNoise=	Off
#ICS correction=	Off
#Dark correction=	Off
#Inst. Process=	Off
#Instrument=	LabRAM HR Evol
#Detector=	Andor CCD
#Objective=	x100 LWD
#Grating=	1800 gr/mm
#ND Filter=	100%
#Laser (nm)=	532
#Spectro (cm-¹)=	1240.02
#Hole=	49.98
#Range=	Visible
#AFM=	Off
#StageXY=	Marzhauser
#StageZ=	Marzhauser
#X (µm)=	-15857
#Y (µm)=	-1055.5
#Z (µm)=	-344.6
#Project=
#Sample=
#Site=
#Title=	g45-mi1bub1
#Remark=
#Date=	06.05.2022 09:51
#Acquired=	06.05.2022 09:51:50
1454.81	2458.75
1454.28	2450.5
1453.75	2424
1453.22	2421.25
1452.69	2418.75
1452.16	2463.25
1451.64	2419
1451.11	2402
1450.58	2485.25
1450.05	2380.75
1449.52	2353.25
1448.99	2450.25
1448.46	2440
1447.93	2406.5
1447.4	2431
1446.88	2447.75
1446.35	2468.25
1445.82	2403.5
1445.29	2386.25
1444.76	2417.75
1444.23	2415.5
1443.7	2404.5
1443.17	2407.25
1442.64	2379.25
1442.11	2390.25
1441.58	2421.5
1441.05	2383.25
1440.52	2391
1439.99	2438.75
1439.46	2462.75
1438.93	2482.75
1438.4	2348
1437.87	2339.25
1437.34	2371
1436.81	2355.25
1436.28	2388
1435.75	2338.75
1435.22	2422.75
1434.69	2424.5
1434.16	2410.75
1433.63	2334.5
1433.1	2355.75
1432.57	2426.5
1432.04	2407.75
1431.51	2343.5
1430.98	2320.25
1430.45	2425.5
1429.92	2327.5
1429.39	2395.75
1428.86	2329.5
1428.33	2334
1427.8	2351.25
1427.26	2286.75
1426.73	2308.5
1426.2	2385.5
1425.67	2338.25
1425.14	2287.75
1424.61	2350.5
1424.08	2360.25
1423.55	2356.75
1423.02	2326.75
1422.49	2289.25
1421.95	2356.5
1421.42	2352.5
1420.89	2288.5
1420.36	2268.75
1419.83	2320.25
1419.3	2341.5
1418.76	2291.25
1418.23	2324
1417.7	2292.5
1417.17	2379.25
1416.64	2251.25
1416.1	2302.75
1415.57	2355.75
1415.04	2274
1414.51	2353.5
1413.98	2299.75
1413.44	2293
1412.91	2360
1412.38	2365
1411.85	2322
1411.32	2295
1410.78	2360
1410.25	2410.25
1409.72	2298
1409.18	2382.5
1408.65	2390
1408.12	2335.5
1407.59	2244
1407.05	2299
1406.52	2342
1405.99	2292.75
1405.46	2297.25
1404.92	2309.5
1404.39	2320.75
1403.86	2307.5
1403.32	2312
1402.79	2274
1402.26	2334.75
1401.72	2292.75
1401.19	2326
1400.66	2257.25
1400.12	2315.5
1399.59	2284.25
1399.06	2326
1398.52	2370
1397.99	2323.25
1397.46	2263.25
1396.92	2314.75
1396.39	2349.25
1395.85	2290
1395.32	2316
1394.79	2301
1394.25	2282.25
1393.72	2231.25
1393.18	2292.75
1392.65	2277
1392.12	2299.75
1391.58	2253.5
1391.05	2378.75
1390.51	2316.75
1389.98	2339.75
1389.44	2470.75
1388.91	2603.75
1388.38	2871
1387.84	3069
1387.31	2853.25
1386.77	2380
1386.24	2362
1385.7	2360.25
1385.17	2276
1384.63	2367.25
1384.1	2300.75
1383.56	2281.75
1383.03	2290.5
1382.49	2416
1381.96	2347.5
1381.42	2335.5
1380.89	2372.5
1380.35	2352.25
1379.82	2391.5
1379.28	2278.25
1378.74	2303.75
1378.21	2312.75
1377.67	2357.25
1377.14	2352
1376.6	2263.25
1376.07	2316
1375.53	2294
1374.99	2327
1374.46	2331.5
1373.92	2371.75
1373.39	2304
1372.85	2296.25
1372.32	2289
1371.78	2241.5
1371.24	2299.25
1370.71	2340.75
1370.17	2256
1369.63	2303.25
1369.1	2302
1368.56	2305.75
1368.03	2337.25
1367.49	2315.5
1366.95	2303.25
1366.42	2298.5
1365.88	2333.5
1365.34	2262.75
1364.81	2232
1364.27	2323.5
1363.73	2285.75
1363.19	2287.5
1362.66	2342.75
1362.12	2314.75
1361.58	2281.5
1361.05	2278
1360.51	2352
1359.97	2337.75
1359.44	2249.25
1358.9	2305.5
1358.36	2366.75
1357.82	2292.75
1357.29	2302
1356.75	2277.25
1356.21	2310.75
1355.67	2312.5
1355.14	2269
1354.6	2254.5
1354.06	2327
1353.52	2354.25
1352.99	2250.25
1352.45	2308
1351.91	2316.5
1351.37	2278.25
1350.83	2301
1350.3	2320.25
1349.76	2295.75
1349.22	2297.5
1348.68	2272.75
1348.14	2315.75
1347.6	2331
1347.06	2318
1346.53	2267
1345.99	2288.25
1345.45	2295.25
1344.91	2311.75
1344.37	2322.25
1343.83	2257.75
1343.3	2315.75
1342.76	2285.75
1342.22	2326.25
1341.68	2238.5
1341.14	2356.5
1340.6	2262.5
1340.06	2338.25
1339.52	2296
1338.98	2248.25
1338.45	2337
1337.91	2294.25
1337.37	2268.75
1336.83	2246.5
1336.29	2347.75
1335.75	2306.5
1335.21	2278
1334.67	2239
1334.13	2259.25
1333.59	2287.75
1333.05	2243
1332.51	2225
1331.97	2309.5
1331.43	2325.25
1330.89	2279.75
1330.35	2245.25
1329.81	2308.5
1329.27	2275.5
1328.73	2272
1328.19	2201.25
1327.65	2283
1327.11	2320.75
1326.57	2254.5
1326.03	2274
1325.49	2292.75
1324.95	2323.25
1324.41	2283.75
1323.87	2263.25
1323.33	2263.5
1322.79	2294.25
1322.25	2297.25
1321.71	2301.75
1321.16	2246.25
1320.62	2280.5
1320.08	2236.25
1319.54	2266.75
1319	2356.25
1318.46	2273
1317.92	2231.5
1317.38	2306.75
1316.84	2287.75
1316.29	2285.5
1315.75	2264.5
1315.21	2314.75
1314.67	2313.5
1314.13	2313.25
1313.59	2314.75
1313.05	2290.75
1312.5	2333.5
1311.96	2354.75
1311.42	2357.5
1310.88	2301
1310.34	2339
1309.8	2332
1309.25	2249.5
1308.71	2368.5
1308.17	2293.25
1307.63	2314
1307.09	2329.5
1306.54	2312.75
1306	2302.5
1305.46	2328.5
1304.92	2372.75
1304.38	2329.25
1303.83	2324.5
1303.29	2311.75
1302.75	2355.5
1302.21	2357
1301.66	2333.5
1301.12	2343.75
1300.58	2356.25
1300.04	2370
1299.49	2321.25
1298.95	2368
1298.41	2389.75
1297.86	2415.75
1297.32	2384
1296.78	2381.5
1296.23	2422
1295.69	2374.5
1295.15	2316
1294.6	2312
1294.06	2417.25
1293.52	2350.25
1292.97	2416
1292.43	2359
1291.89	2339.5
1291.34	2327.5
1290.8	2356.75
1290.26	2391.25
1289.71	2290
1289.17	2365.25
1288.63	2279.5
1288.08	2328.25
1287.54	2364
1286.99	2382.75
1286.45	2460.5
1285.9	2551
1285.36	2825
1284.82	2815.5
1284.27	2474.75
1283.73	2424.5
1283.19	2341.5
1282.64	2319.25
1282.1	2263.5
1281.55	2301.5
1281.01	2334.25
1280.46	2295.25
1279.92	2310.5
1279.37	2248.75
1278.83	2345
1278.28	2303.75
1277.74	2322.25
1277.19	2339.25
1276.65	2330.25
1276.1	2330.75
1275.56	2293.75
1275.01	2292
1274.47	2316.5
1273.92	2337
1273.38	2309.75
1272.83	2313.25
1272.29	2376.5
1271.74	2344
1271.2	2272.75
1270.65	2285.75
1270.11	2349.25
1269.56	2344.25
1269.01	2308.75
1268.47	2304.5
1267.92	2311.75
1267.38	2307.5
1266.83	2334
1266.29	2339
1265.74	2409.75
1265.19	2329
1264.65	2352.25
1264.1	2375.75
1263.55	2340.5
1263.01	2352.25
1262.46	2353.5
1261.92	2404.75
1261.37	2380
1260.82	2383.25
1260.28	2369.5
1259.73	2400.5
1259.18	2376.5
1258.64	2370.5
1258.09	2329.5
1257.55	2323
1257	2402.5
1256.45	2402.25
1255.9	2432.5
1255.36	2440.5
1254.81	2482.75
1254.26	2467.25
1253.72	2398
1253.17	2435.5
1252.62	2462.5
1252.07	2499.5
1251.53	2384
1250.98	2470.75
1250.43	2456.75
1249.89	2469.75
1249.34	2427.75
1248.79	2530.75
1248.24	2443.75
1247.7	2488.25
1247.15	2458.5
1246.6	2463.5
1246.05	2461.5
1245.5	2437.5
1244.96	2459.75
1244.41	2462.5
1243.86	2525.75
1243.31	2493.25
1242.77	2543.75
1242.22	2489.5
1241.67	2546.75
1241.12	2529.5
1240.57	2488.25
1240.02	2583.5
1239.48	2609.5
1238.93	2645
1238.38	2565.75
1237.83	2591.75
1237.28	2657.25
1236.73	2670.25
1236.18	2710.5
1235.64	2666.75
1235.09	2724.25
1234.54	2766.75
1233.99	2758.5
1233.44	2802.5
1232.89	2830.5
1232.34	2841.75
1231.79	2715.25
1231.24	2907
1230.69	2885.25
1230.15	2921.5
1229.6	2906.5
1229.05	2933
1228.5	2904.25
1227.95	2895.25
1227.4	2851
1226.85	2816
1226.3	2865.5
1225.75	2816.25
1225.2	2759.25
1224.65	2761.25
1224.1	2761.5
1223.55	2714.25
1223	2688.25
1222.45	2564.5
1221.9	2637.25
1221.35	2663.25
1220.8	2568
1220.25	2594.25
1219.7	2559.25
1219.15	2529.5
1218.6	2490
1218.05	2497.75
1217.5	2546.5
1216.95	2541.5
1216.4	2450.75
1215.85	2525.5
1215.3	2467
1214.75	2478.25
1214.2	2390
1213.65	2391.5
1213.09	2379.25
1212.54	2372
1211.99	2390.75
1211.44	2398.25
1210.89	2392.5
1210.34	2455.25
1209.79	2393.25
1209.24	2373
1208.69	2365.75
1208.14	2386.25
1207.58	2319.5
1207.03	2336
1206.48	2331.5
1205.93	2460
1205.38	2334.75
1204.83	2253.25
1204.27	2346
1203.72	2375.75
1203.17	2315.75
1202.62	2349.25
1202.07	2296
1201.52	2345.5
1200.96	2277
1200.41	2334.25
1199.86	2395.75
1199.31	2519.75
1198.76	2334.25
1198.2	2282.25
1197.65	2336.5
1197.1	2330
1196.55	2345.5
1196	2317.75
1195.44	2289
1194.89	2339.5
1194.34	2369.5
1193.78	2347.25
1193.23	2386.5
1192.68	2366.25
1192.13	2337
1191.57	2359.75
1191.02	2400.25
1190.47	2416.25
1189.91	2442
1189.36	2400.5
1188.81	2487
1188.26	2479.75
1187.7	2508.75
1187.15	2493.5
1186.6	2507.5
1186.04	2509.5
1185.49	2561.5
1184.94	2475
1184.38	2503.75
1183.83	2501
1183.28	2495.5
1182.72	2435.75
1182.17	2507.5
1181.61	2475
1181.06	2457
1180.51	2470.75
1179.95	2449.25
1179.4	2383
1178.85	2329.25
1178.29	2435.25
1177.74	2383.25
1177.18	2418.5
1176.63	2339.5
1176.07	2362.5
1175.52	2382.75
1174.97	2401
1174.41	2359.75
1173.86	2396.5
1173.3	2356.75
1172.75	2388.5
1172.19	2375.25
1171.64	2449.75
1171.09	2437.25
1170.53	2361.75
1169.97	2420.75
1169.42	2448
1168.86	2434.75
1168.31	2489.75
1167.76	2499.75
1167.2	2477.75
1166.65	2536.75
1166.09	2636.25
1165.53	2584.25
1164.98	2674
1164.42	2712
1163.87	2781.25
1163.31	2845.75
1162.76	2963
1162.2	3074.5
1161.65	3044.75
1161.09	3261.75
1160.54	3379.5
1159.98	3462.25
1159.42	3429.5
1158.87	3586.25
1158.31	3640.5
1157.76	3561
1157.2	3480
1156.65	3492.75
1156.09	3275
1155.53	3221
1154.98	3196.5
1154.42	3043.25
1153.86	2936
1153.31	2912
1152.75	2916.5
1152.19	2746.25
1151.64	2718.5
1151.08	2616.5
1150.52	2571
1149.97	2552.75
1149.41	2593.25
1148.86	2575.5
1148.3	2598.5
1147.74	2492.75
1147.18	2571
1146.63	2482.5
1146.07	2544.5
1145.51	2430
1144.96	2428.25
1144.4	2406.25
1143.84	2416.75
1143.28	2379.25
1142.73	2438.75
1142.17	2369.75
1141.61	2372.25
1141.06	2417
1140.5	2324.75
1139.94	2382.25
1139.38	2366.75
1138.83	2350.5
1138.27	2327.75
1137.71	2358
1137.15	2325
1136.59	2324.25
1136.04	2341.25
1135.48	2314.5
1134.92	2349
1134.36	2296.75
1133.8	2311.25
1133.25	2345.75
1132.69	2329.25
1132.13	2244.5
1131.57	2323.25
1131.01	2302.75
1130.45	2285
1129.9	2271.5
1129.34	2299.25
1128.78	2319
1128.22	2272
1127.66	2345.5
1127.1	2301.25
1126.54	2290
1125.98	2318.25
1125.43	2335
1124.87	2323.5
1124.31	2351.5
1123.75	2407.5
1123.19	2312.75
1122.63	2349.75
1122.07	2346.25
1121.51	2318.5
1120.95	2355.5
1120.39	2409.25
1119.83	2379
1119.27	2390.5
1118.72	2379
1118.15	2415
1117.6	2449.5
1117.04	2454
1116.48	2429.75
1115.92	2453.75
1115.36	2488.75
1114.8	2517
1114.24	2588
1113.68	2646.5
1113.12	2515.25
1112.56	2592.25
1112	2597.75
1111.44	2570
1110.88	2550.25
1110.32	2474.75
1109.76	2564.75
1109.19	2490.75
1108.64	2496.25
1108.07	2426.75
1107.51	2461.25
1106.95	2463.5
1106.39	2387
1105.83	2370
1105.27	2421.75
1104.71	2305.25
1104.15	2319.25
1103.59	2319.25
1103.03	2321
1102.47	2323.5
1101.91	2366
1101.34	2358.25
1100.78	2339
1100.22	2348.25
1099.66	2352.5
1099.1	2299.5
1098.54	2332.75
1097.98	2280.5
1097.41	2286.5
1096.85	2268.5
1096.29	2310.5
1095.73	2270
1095.17	2296.75
1094.61	2254.75
1094.04	2287.25
1093.48	2294.5
1092.92	2333.25
1092.36	2318.25
1091.8	2338.75
1091.23	2304.25
1090.67	2333.75
1090.11	2271
1089.55	2322.25
1088.99	2324.5
1088.42	2282
1087.86	2329.25
1087.3	2345
1086.74	2298.75
1086.17	2316.75
1085.61	2325.5
1085.05	2408.5
1084.49	2375.5
1083.92	2385.5
1083.36	2453
1082.8	2486.5
1082.23	2456.5
1081.67	2501.5
1081.11	2503.75
1080.55	2566.5
1079.98	2476.25
1079.42	2468.5
1078.86	2468
1078.29	2351.25
1077.73	2306.75
1077.17	2370.25
1076.6	2334.25
1076.04	2344.5
1075.48	2328.5
1074.91	2323.75
1074.35	2289
1073.79	2292.5
1073.22	2256.25
1072.66	2278.75
1072.09	2271.75
1071.53	2305.5
1070.97	2312.25
1070.4	2260
1069.84	2286.25
1069.27	2283.75
1068.71	2254.75
1068.15	2262.5
1067.58	2251
1067.02	2248.25
1066.45	2201
1065.89	2333
1065.32	2262
1064.76	2336
1064.19	2284.75
1063.63	2267.75
1063.07	2238
1062.5	2291
1061.94	2221
1061.37	2261.25
1060.81	2253.5
1060.24	2231.25
1059.68	2260
1059.11	2263
1058.55	2263.5
1057.98	2219.75
1057.42	2199.5
1056.85	2249.5
1056.29	2276
1055.72	2215.5
1055.16	2220.75
1054.59	2266.25
1054.03	2214
1053.46	2265
1052.89	2254.25
1052.33	2229.75
1051.76	2258.75
1051.2	2298.25
1050.63	2209
1050.06	2250.75
1049.5	2288.25
1048.93	2225.75
1048.37	2231.5
1047.8	2258.25
1047.24	2234.5
1046.67	2289.75
1046.1	2257.75
1045.54	2268.25
1044.97	2180
1044.4	2260
1043.84	2271.75
1043.27	2273.75
1042.7	2191.75
1042.14	2227.75
1041.57	2191.75
1041.01	2246
1040.44	2268
1039.87	2209.25
1039.3	2209
1038.74	2175.75
1038.17	2241.75
1037.6	2217.5
1037.04	2287
1036.47	2240
1035.9	2196.25
1035.34	2237
1034.77	2230.5
1034.2	2148.75
1033.63	2214
1033.07	2213.75
1032.5	2262.5
1031.93	2210.25
1031.36	2206.25
1030.8	2233.75
1030.23	2183.25
1029.66	2180.75
1029.09	2211.25
1028.52	2210.25
1027.96	2196.25
1027.39	2210.5
1026.82	2163
1026.25	2177.25
1025.68	2104.25
1025.12	2156.25
1024.55	2145.75
1023.98	2165.75
1023.41	2167.25
1022.84	2171.75
1022.28	2193.75
1021.71	2179.5
1021.14	2160.5
1020.57	2149.5
1020	2182
1019.43	2161
1018.86	2126
1018.3	2163.25
1017.73	2207.75
1017.16	2162.75
1016.59	2223
1016.3	2167.5