File: Testing/Hickernall_HORIBA/g45-mi1bub2_02.txt
#Acq. time (s)=	75
#Accumulations=	5
#Range=	Off
#Autofocus=	Off
#Macrospot=	Off
#AutoExposure=	Off
#Spike filter=	Multiple accum.
#Delay time (s)=	0
#Binning=	1
#Readout mode=	Signal
#DeNoise=	Off
#ICS correction=	Off
#Dark correction=	Off
#Inst. Process=	Off
#Instrument=	LabRAM HR Evol
#Detector=	Andor CCD
#Objective=	x100 LWD
#Grating=	1800 gr/mm
#ND Filter=	100%
#Laser (nm)=	532
#Spectro (cm-¹)=	1240.02
#Hole=	49.98
#Range=	Visible
#AFM=	Off
#StageXY=	Marzhauser
#StageZ=	Marzhauser
#X (µm)=	-15953.4
#Y (µm)=	-816.5
#Z (µm)=	-348.9
#Project=
#Sample=
#Site=
#Title=	g45-mi1bub2
#Remark=
#Date=	06.05.2022 10:30
#Acquired=	06.05.2022 10:30:46
1454.81	2625.5
1454.28	2612.5
1453.75	2612.75
1453.22	2748
1452.69	2636.75
1452.16	2664.5
1451.64	2624
1451.11	2622.5
1450.58	2681.75
1450.05	2701
1449.52	2650.5
1448.99	2640.5
1448.46	2657.75
1447.93	2692.5
1447.4	2610
1446.88	2656.5
1446.35	2588.5
1445.82	2608.5
1445.29	2631.5
1444.76	2575.5
1444.23	2672.5
1443.7	2636.5
1443.17	2613.75
1442.64	2604
1442.11	2638.25
1441.58	2677
1441.05	2642.5
1440.52	2577.75
1439.99	2607.5
1439.46	2618.5
1438.93	2596.25
1438.4	2666.5
1437.87	2607
1437.34	2641.75
1436.81	2561.5
1436.28	2570
1435.75	2575
1435.22	2583.5
1434.69	2607
1434.16	2630
1433.63	2502.75
1433.1	2620.5
1432.57	2601
1432.04	2546
1431.51	2659.75
1430.98	2594
1430.45	2555.5
1429.92	2565
1429.39	2544.5
1428.86	2554.25
1428.33	2564.5
1427.8	2586.75
1427.26	2638.5
1426.73	2566.75
1426.2	2606.25
1425.67	2599.25
1425.14	2631.75
1424.61	2532.75
1424.08	2622.75
1423.55	2529.5
1423.02	2603.25
1422.49	2513
1421.95	2527.5
1421.42	2527.75
1420.89	2544
1420.36	2559.75
1419.83	2540
1419.3	2553.25
1418.76	2586
1418.23	2532.25
1417.7	2549.25
1417.17	2613.75
1416.64	2506
1416.1	2521.75
1415.57	2537.75
1415.04	2507.5
1414.51	2507.75
1413.98	2574.5
1413.44	2496
1412.91	2542.75
1412.38	2506.25
1411.85	2523.5
1411.32	2589.75
1410.78	2564.5
1410.25	2576
1409.72	2555.5
1409.18	2573.5
1408.65	2596.5
1408.12	2554.75
1407.59	2501
1407.05	2519
1406.52	2536.25
1405.99	2527
1405.46	2512
1404.92	2506.5
1404.39	2457.5
1403.86	2621
1403.32	2503.25
1402.79	2527.75
1402.26	2479
1401.72	2479
1401.19	2521
1400.66	2524.5
1400.12	2507.5
1399.59	2472
1399.06	2514
1398.52	2511.5
1397.99	2462.75
1397.46	2489.25
1396.92	2472.25
1396.39	2560.75
1395.85	2537.5
1395.32	2521
1394.79	2517.5
1394.25	2435.75
1393.72	2496
1393.18	2465.25
1392.65	2491.5
1392.12	2432.5
1391.58	2576.75
1391.05	2590.25
1390.51	2513.75
1389.98	2599.5
1389.44	2666
1388.91	2759
1388.38	2885
1387.84	3040.5
1387.31	2892.75
1386.77	2723
1386.24	2520.5
1385.7	2454.25
1385.17	2468.25
1384.63	2533
1384.1	2548
1383.56	2528
1383.03	2467.75
1382.49	2448
1381.96	2533.5
1381.42	2525
1380.89	2533
1380.35	2513.5
1379.82	2515.25
1379.28	2520.5
1378.74	2522
1378.21	2484
1377.67	2501.5
1377.14	2439
1376.6	2507.5
1376.07	2467.5
1375.53	2528
1374.99	2461.5
1374.46	2495
1373.92	2498.5
1373.39	2532.75
1372.85	2463.75
1372.32	2464
1371.78	2484.25
1371.24	2561.5
1370.71	2495.5
1370.17	2463.75
1369.63	2475.25
1369.1	2515
1368.56	2528.5
1368.03	2480
1367.49	2527.25
1366.95	2482.25
1366.42	2517
1365.88	2508.75
1365.34	2512.5
1364.81	2488
1364.27	2550.75
1363.73	2449.75
1363.19	2462
1362.66	2484.75
1362.12	2492
1361.58	2444.75
1361.05	2489.5
1360.51	2500.25
1359.97	2444
1359.44	2451
1358.9	2464
1358.36	2484.5
1357.82	2506.5
1357.29	2483
1356.75	2462.5
1356.21	2529
1355.67	2485.25
1355.14	2527
1354.6	2462.5
1354.06	2536.25
1353.52	2420.5
1352.99	2428.25
1352.45	2446.5
1351.91	2486
1351.37	2497
1350.83	2486.75
1350.3	2423.75
1349.76	2526.25
1349.22	2469.25
1348.68	2476.75
1348.14	2472.75
1347.6	2499.5
1347.06	2471.5
1346.53	2429
1345.99	2487.75
1345.45	2474
1344.91	2521.5
1344.37	2483
1343.83	2374.25
1343.3	2505.5
1342.76	2479.25
1342.22	2401.5
1341.68	2423
1341.14	2478
1340.6	2423.5
1340.06	2452
1339.52	2411.25
1338.98	2419.25
1338.45	2487.5
1337.91	2434.25
1337.37	2491.25
1336.83	2419
1336.29	2424.25
1335.75	2492.25
1335.21	2461.5
1334.67	2421.25
1334.13	2453
1333.59	2429.5
1333.05	2418.75
1332.51	2424
1331.97	2447
1331.43	2448.5
1330.89	2415.25
1330.35	2446.25
1329.81	2426.75
1329.27	2426
1328.73	2410.25
1328.19	2400.25
1327.65	2474.25
1327.11	2450.5
1326.57	2423.5
1326.03	2415.75
1325.49	2438.25
1324.95	2440.75
1324.41	2428.25
1323.87	2426.25
1323.33	2451.5
1322.79	2400
1322.25	2420.5
1321.71	2394
1321.16	2424.25
1320.62	2429
1320.08	2395
1319.54	2367
1319	2391.5
1318.46	2464.25
1317.92	2408.5
1317.38	2390.25
1316.84	2486.75
1316.29	2453.5
1315.75	2388.75
1315.21	2376.25
1314.67	2451
1314.13	2419.25
1313.59	2473.5
1313.05	2458
1312.5	2457.25
1311.96	2437.75
1311.42	2453
1310.88	2451.5
1310.34	2439.25
1309.8	2511.75
1309.25	2426.5
1308.71	2513
1308.17	2385.75
1307.63	2479.75
1307.09	2468.25
1306.54	2443.25
1306	2481.75
1305.46	2447.75
1304.92	2405.5
1304.38	2527
1303.83	2420.75
1303.29	2516.25
1302.75	2375.75
1302.21	2449.75
1301.66	2439.75
1301.12	2540
1300.58	2495.75
1300.04	2514
1299.49	2403.75
1298.95	2490.75
1298.41	2472.5
1297.86	2460.75
1297.32	2483
1296.78	2510.75
1296.23	2557.5
1295.69	2462.75
1295.15	2507
1294.6	2464
1294.06	2490
1293.52	2531
1292.97	2524
1292.43	2442.25
1291.89	2466.25
1291.34	2427.75
1290.8	2474.5
1290.26	2432.25
1289.71	2523.75
1289.17	2444.75
1288.63	2469.5
1288.08	2533
1287.54	2499.75
1286.99	2510
1286.45	2603.5
1285.9	2678.75
1285.36	2826.5
1284.82	2759.25
1284.27	2608
1283.73	2465.25
1283.19	2421.5
1282.64	2508.5
1282.1	2458
1281.55	2478.75
1281.01	2431.5
1280.46	2455
1279.92	2347
1279.37	2389.5
1278.83	2454.25
1278.28	2471
1277.74	2389
1277.19	2446.5
1276.65	2382.75
1276.1	2443.75
1275.56	2402.5
1275.01	2455.25
1274.47	2400.25
1273.92	2433.5
1273.38	2374.25
1272.83	2487.75
1272.29	2429.75
1271.74	2438
1271.2	2410.25
1270.65	2513.25
1270.11	2439
1269.56	2449
1269.01	2422.25
1268.47	2406.5
1267.92	2444
1267.38	2466.5
1266.83	2489.75
1266.29	2452.5
1265.74	2473
1265.19	2489.5
1264.65	2514.75
1264.1	2424.75
1263.55	2488.5
1263.01	2467.5
1262.46	2482
1261.92	2465.75
1261.37	2533
1260.82	2495.75
1260.28	2454
1259.73	2483
1259.18	2508.25
1258.64	2500.5
1258.09	2455
1257.55	2516.75
1257	2591
1256.45	2528.25
1255.9	2526.5
1255.36	2613
1254.81	2592.25
1254.26	2568.75
1253.72	2593.75
1253.17	2577.75
1252.62	2542.5
1252.07	2555.5
1251.53	2552.5
1250.98	2543
1250.43	2605.25
1249.89	2592.5
1249.34	2610.75
1248.79	2599
1248.24	2629.5
1247.7	2628
1247.15	2594.25
1246.6	2624.75
1246.05	2573.5
1245.5	2639
1244.96	2613.75
1244.41	2682.5
1243.86	2681.5
1243.31	2719.5
1242.77	2698.5
1242.22	2700.25
1241.67	2684.75
1241.12	2687
1240.57	2726.25
1240.02	2743.75
1239.48	2736
1238.93	2775
1238.38	2730.5
1237.83	2792
1237.28	2797.5
1236.73	2776.75
1236.18	2914.25
1235.64	2923
1235.09	2912.75
1234.54	2938.25
1233.99	2954.75
1233.44	3019.75
1232.89	3059.75
1232.34	3084
1231.79	3062.75
1231.24	3084.75
1230.69	3092.5
1230.15	3114.5
1229.6	3061.5
1229.05	3164
1228.5	3095.25
1227.95	3072.25
1227.4	3139.5
1226.85	3030.5
1226.3	3043.5
1225.75	3066.25
1225.2	3026
1224.65	2969.75
1224.1	2862.5
1223.55	2869.5
1223	2761
1222.45	2783.5
1221.9	2796.5
1221.35	2801.75
1220.8	2814.25
1220.25	2729.5
1219.7	2808
1219.15	2680.75
1218.6	2770.25
1218.05	2661
1217.5	2692.25
1216.95	2689.5
1216.4	2673
1215.85	2633
1215.3	2641.5
1214.75	2632.75
1214.2	2580.25
1213.65	2577.75
1213.09	2581.75
1212.54	2567.5
1211.99	2589.75
1211.44	2550.75
1210.89	2651.5
1210.34	2570.25
1209.79	2590
1209.24	2547.75
1208.69	2570
1208.14	2561.75
1207.58	2552.25
1207.03	2594
1206.48	2583.5
1205.93	2511.25
1205.38	2580
1204.83	2528
1204.27	2490.25
1203.72	2551.75
1203.17	2536
1202.62	2525
1202.07	2548
1201.52	2532
1200.96	2546.5
1200.41	2559.5
1199.86	2496.75
1199.31	2561
1198.76	2507.25
1198.2	2513.75
1197.65	2526.75
1197.1	2560
1196.55	2550.25
1196	2613
1195.44	2534.25
1194.89	2571.25
1194.34	2538
1193.78	2564.5
1193.23	2558
1192.68	2575.5
1192.13	2603
1191.57	2574.75
1191.02	2659.5
1190.47	2606.25
1189.91	2567.75
1189.36	2637.25
1188.81	2623.75
1188.26	2655.25
1187.7	2653
1187.15	2613
1186.6	2755.75
1186.04	2684.25
1185.49	2708.25
1184.94	2660.5
1184.38	2720.5
1183.83	2643
1183.28	2649.5
1182.72	2657
1182.17	2609.75
1181.61	2650.25
1181.06	2634.5
1180.51	2629.25
1179.95	2635
1179.4	2619
1178.85	2579.25
1178.29	2564.75
1177.74	2609.25
1177.18	2616
1176.63	2584.5
1176.07	2571
1175.52	2621
1174.97	2591.5
1174.41	2586.5
1173.86	2587.75
1173.3	2663.75
1172.75	2591.25
1172.19	2624.25
1171.64	2609.25
1171.09	2637
1170.53	2677
1169.97	2700.25
1169.42	2669.25
1168.86	2732.25
1168.31	2764
1167.76	2751.75
1167.2	2804.5
1166.65	2918.75
1166.09	2913.5
1165.53	2965.5
1164.98	3004
1164.42	3207
1163.87	3157
1163.31	3376.25
1162.76	3421.25
1162.2	3536.5
1161.65	3673.25
1161.09	3788
1160.54	3881.25
1159.98	4071
1159.42	4077.75
1158.87	4038.75
1158.31	4080.25
1157.76	4105.5
1157.2	3995.75
1156.65	3916
1156.09	3770.25
1155.53	3650
1154.98	3519.5
1154.42	3473.25
1153.86	3427
1153.31	3223.5
1152.75	3176.75
1152.19	3007.75
1151.64	3030.25
1151.08	2964
1150.52	2887.75
1149.97	2837.25
1149.41	2841.25
1148.86	2764
1148.3	2726
1147.74	2756.5
1147.18	2742.75
1146.63	2712
1146.07	2700.25
1145.51	2652.25
1144.96	2675.75
1144.4	2608.25
1143.84	2614.75
1143.28	2621.25
1142.73	2684.75
1142.17	2608.25
1141.61	2600.5
1141.06	2606
1140.5	2616
1139.94	2644
1139.38	2618
1138.83	2571.75
1138.27	2642
1137.71	2592
1137.15	2589.25
1136.59	2605
1136.04	2582.25
1135.48	2516.25
1134.92	2610
1134.36	2538
1133.8	2548.75
1133.25	2554.5
1132.69	2522.75
1132.13	2510
1131.57	2504.25
1131.01	2490.75
1130.45	2560.5
1129.9	2533.5
1129.34	2541
1128.78	2542.25
1128.22	2524.5
1127.66	2579.5
1127.1	2536.25
1126.54	2461.5
1125.98	2559.5
1125.43	2507.25
1124.87	2581.75
1124.31	2466
1123.75	2587.75
1123.19	2518.25
1122.63	2559
1122.07	2529
1121.51	2547.75
1120.95	2525.5
1120.39	2590.75
1119.83	2502.75
1119.27	2585.75
1118.72	2526.75
1118.15	2540.5
1117.6	2588.5
1117.04	2617.75
1116.48	2606.5
1115.92	2673.5
1115.36	2667.5
1114.8	2660.5
1114.24	2681.75
1113.68	2730.75
1113.12	2685.5
1112.56	2672
1112	2685.5
1111.44	2672
1110.88	2709.25
1110.32	2637.25
1109.76	2703.5
1109.19	2619.5
1108.64	2560.25
1108.07	2542
1107.51	2571.25
1106.95	2549.5
1106.39	2524
1105.83	2583.25
1105.27	2484.25
1104.71	2553
1104.15	2494.5
1103.59	2524.75
1103.03	2529.25
1102.47	2509.25
1101.91	2474.75
1101.34	2465.25
1100.78	2448
1100.22	2450.25
1099.66	2439.5
1099.1	2393.75
1098.54	2484.5
1097.98	2424.75
1097.41	2416.25
1096.85	2438.5
1096.29	2564
1095.73	2459.25
1095.17	2446.5
1094.61	2475.75
1094.04	2403
1093.48	2411.5
1092.92	2435.75
1092.36	2450.25
1091.8	2490
1091.23	2390.25
1090.67	2473.5
1090.11	2501.5
1089.55	2478.5
1088.99	2403.25
1088.42	2481.75
1087.86	2498
1087.3	2468.75
1086.74	2527.5
1086.17	2538.75
1085.61	2507.75
1085.05	2581.5
1084.49	2619
1083.92	2660.75
1083.36	2723.75
1082.8	2688.25
1082.23	2753.25
1081.67	2791.25
1081.11	2779.75
1080.55	2760
1079.98	2704.75
1079.42	2731.5
1078.86	2623.75
1078.29	2699.25
1077.73	2563.75
1077.17	2576.75
1076.6	2518.75
1076.04	2510.75
1075.48	2523.25
1074.91	2514
1074.35	2441.75
1073.79	2509
1073.22	2472.5
1072.66	2478.25
1072.09	2481.5
1071.53	2474.5
1070.97	2444
1070.4	2435.5
1069.84	2450
1069.27	2497.25
1068.71	2435.5
1068.15	2449
1067.58	2454.75
1067.02	2463
1066.45	2510.5
1065.89	2478.75
1065.32	2469.25
1064.76	2480.25
1064.19	2539
1063.63	2478.5
1063.07	2530.25
1062.5	2431
1061.94	2474.25
1061.37	2450
1060.81	2464.5
1060.24	2492
1059.68	2417.5
1059.11	2431.75
1058.55	2390.75
1057.98	2380
1057.42	2480.5
1056.85	2408.5
1056.29	2349
1055.72	2416.5
1055.16	2406.5
1054.59	2441.25
1054.03	2396.75
1053.46	2380.25
1052.89	2428.5
1052.33	2441
1051.76	2351.5
1051.2	2387.25
1050.63	2441.25
1050.06	2391.75
1049.5	2399.5
1048.93	2365.5
1048.37	2413.5
1047.8	2366.25
1047.24	2402
1046.67	2491
1046.1	2475
1045.54	2406
1044.97	2384.5
1044.4	2336.5
1043.84	2431.25
1043.27	2405.25
1042.7	2337
1042.14	2401.75
1041.57	2383.5
1041.01	2372
1040.44	2395
1039.87	2365.5
1039.3	2364
1038.74	2356
1038.17	2364.75
1037.6	2367.5
1037.04	2341.25
1036.47	2437.25
1035.9	2403.75
1035.34	2365
1034.77	2367.5
1034.2	2372.5
1033.63	2304.5
1033.07	2394.75
1032.5	2364
1031.93	2350.25
1031.36	2314.75
1030.8	2390
1030.23	2253.25
1029.66	2338.75
1029.09	2323
1028.52	2354.5
1027.96	2335.5
1027.39	2324.25
1026.82	2313.5
1026.25	2293.5
1025.68	2380.25
1025.12	2308.25
1024.55	2381.25
1023.98	2345.25
1023.41	2354
1022.84	2348.75
1022.28	2324
1021.71	2321.25
1021.14	2355.75
1020.57	2228.75
1020	2336.5
1019.43	2285.75
1018.86	2302.5
1018.3	2300
1017.73	2342.75
1017.16	2322.25
1016.59	2333.25
1016.3	2306