File: Testing/Hickernall_HORIBA/g45-mi1bub1_04.txt
#Acq. time (s)=	75
#Accumulations=	5
#Range=	Off
#Autofocus=	Off
#Macrospot=	Off
#AutoExposure=	Off
#Spike filter=	Multiple accum.
#Delay time (s)=	0
#Binning=	1
#Readout mode=	Signal
#DeNoise=	Off
#ICS correction=	Off
#Dark correction=	Off
#Inst. Process=	Off
#Instrument=	LabRAM HR Evol
#Detector=	Andor CCD
#Objective=	x100 LWD
#Grating=	1800 gr/mm
#ND Filter=	100%
#Laser (nm)=	532
#Spectro (cm-¹)=	1240.02
#Hole=	49.98
#Range=	Visible
#AFM=	Off
#StageXY=	Marzhauser
#StageZ=	Marzhauser
#X (µm)=	-15856.6
#Y (µm)=	-1055.5
#Z (µm)=	-344.6
#Project=
#Sample=
#Site=
#Title=	g45-mi1bub1
#Remark=
#Date=	06.05.2022 10:05
#Acquired=	06.05.2022 10:05:13
1454.81	1484.5
1454.28	1446
1453.75	1444
1453.22	1488.25
1452.69	1517
1452.16	1484
1451.64	1438.5
1451.11	1471
1450.58	1455.75
1450.05	1497.5
1449.52	1447
1448.99	1438.5
1448.46	1450.5
1447.93	1458.5
1447.4	1408
1446.88	1432
1446.35	1471.5
1445.82	1507.25
1445.29	1478.5
1444.76	1432.25
1444.23	1485
1443.7	1456
1443.17	1427
1442.64	1415.5
1442.11	1458.5
1441.58	1414.5
1441.05	1491
1440.52	1438
1439.99	1486
1439.46	1416.5
1438.93	1415
1438.4	1427
1437.87	1441.5
1437.34	1448
1436.81	1391
1436.28	1397
1435.75	1428
1435.22	1400.5
1434.69	1404.5
1434.16	1376.5
1433.63	1392
1433.1	1427.5
1432.57	1365.5
1432.04	1362
1431.51	1377
1430.98	1357
1430.45	1371.5
1429.92	1325.5
1429.39	1367.5
1428.86	1360.5
1428.33	1410.5
1427.8	1427.5
1427.26	1405
1426.73	1428
1426.2	1363
1425.67	1417.25
1425.14	1407.5
1424.61	1365.5
1424.08	1376
1423.55	1377
1423.02	1380.5
1422.49	1404.5
1421.95	1389.25
1421.42	1446
1420.89	1373.5
1420.36	1354.25
1419.83	1343
1419.3	1363.5
1418.76	1359
1418.23	1393
1417.7	1319.5
1417.17	1393.75
1416.64	1372.5
1416.1	1360.5
1415.57	1311
1415.04	1400
1414.51	1387
1413.98	1439.5
1413.44	1338
1412.91	1415
1412.38	1319
1411.85	1331
1411.32	1387.75
1410.78	1377.5
1410.25	1395.25
1409.72	1395
1409.18	1395.5
1408.65	1451.5
1408.12	1384.75
1407.59	1311
1407.05	1333
1406.52	1406.5
1405.99	1349.75
1405.46	1317
1404.92	1350
1404.39	1370
1403.86	1301.5
1403.32	1316.5
1402.79	1368
1402.26	1317
1401.72	1368
1401.19	1337.5
1400.66	1329.5
1400.12	1341.5
1399.59	1281.5
1399.06	1356.75
1398.52	1330.75
1397.99	1365.75
1397.46	1318
1396.92	1359.5
1396.39	1339.5
1395.85	1344.5
1395.32	1338.5
1394.79	1322.25
1394.25	1334
1393.72	1355
1393.18	1333
1392.65	1320
1392.12	1324.75
1391.58	1342.5
1391.05	1376
1390.51	1388
1389.98	1450.5
1389.44	1496
1388.91	1645
1388.38	1826.5
1387.84	1996.5
1387.31	1785
1386.77	1464.5
1386.24	1300
1385.7	1350.5
1385.17	1339
1384.63	1390.25
1384.1	1320.5
1383.56	1334
1383.03	1311
1382.49	1350.75
1381.96	1347
1381.42	1288
1380.89	1348.5
1380.35	1313
1379.82	1322
1379.28	1315
1378.74	1350.5
1378.21	1350
1377.67	1321.5
1377.14	1375.25
1376.6	1315.75
1376.07	1322.5
1375.53	1363.5
1374.99	1314
1374.46	1353
1373.92	1389.75
1373.39	1366.75
1372.85	1336.75
1372.32	1313.5
1371.78	1259.5
1371.24	1362.75
1370.71	1307.5
1370.17	1300
1369.63	1345.25
1369.1	1337.5
1368.56	1341.5
1368.03	1302
1367.49	1302
1366.95	1358.5
1366.42	1316.25
1365.88	1359
1365.34	1352.5
1364.81	1341.5
1364.27	1351.5
1363.73	1283.5
1363.19	1378.5
1362.66	1342.5
1362.12	1323
1361.58	1346
1361.05	1361
1360.51	1311.5
1359.97	1316.5
1359.44	1337
1358.9	1321
1358.36	1348.75
1357.82	1331
1357.29	1292.75
1356.75	1313.75
1356.21	1354.75
1355.67	1255.5
1355.14	1343.25
1354.6	1306.5
1354.06	1312
1353.52	1278.5
1352.99	1319.5
1352.45	1313
1351.91	1332.5
1351.37	1308
1350.83	1375
1350.3	1283
1349.76	1315.5
1349.22	1303
1348.68	1299.75
1348.14	1271
1347.6	1267
1347.06	1281.25
1346.53	1329
1345.99	1338
1345.45	1253
1344.91	1341.75
1344.37	1319
1343.83	1282.5
1343.3	1299
1342.76	1307
1342.22	1323
1341.68	1320.5
1341.14	1353.5
1340.6	1350.75
1340.06	1338
1339.52	1291
1338.98	1309
1338.45	1365.25
1337.91	1248
1337.37	1269
1336.83	1326
1336.29	1310.5
1335.75	1289.5
1335.21	1292.75
1334.67	1280.5
1334.13	1337
1333.59	1331
1333.05	1291.5
1332.51	1287
1331.97	1294.5
1331.43	1271.75
1330.89	1261
1330.35	1328.75
1329.81	1305.5
1329.27	1353.25
1328.73	1326
1328.19	1263
1327.65	1279.75
1327.11	1281
1326.57	1298.75
1326.03	1313
1325.49	1334
1324.95	1293
1324.41	1305.5
1323.87	1335.5
1323.33	1314
1322.79	1313.5
1322.25	1303.5
1321.71	1276
1321.16	1306
1320.62	1309.5
1320.08	1313.5
1319.54	1293.5
1319	1314
1318.46	1300
1317.92	1301.5
1317.38	1323
1316.84	1342.25
1316.29	1304.5
1315.75	1272.5
1315.21	1349
1314.67	1331
1314.13	1274.5
1313.59	1276
1313.05	1350.5
1312.5	1345
1311.96	1364
1311.42	1316.5
1310.88	1369.25
1310.34	1374
1309.8	1307.5
1309.25	1330
1308.71	1320
1308.17	1332.75
1307.63	1350.25
1307.09	1337.5
1306.54	1346
1306	1341.5
1305.46	1393.5
1304.92	1341
1304.38	1381
1303.83	1366.5
1303.29	1361
1302.75	1427
1302.21	1429.5
1301.66	1360
1301.12	1373.25
1300.58	1438.5
1300.04	1403.75
1299.49	1394.25
1298.95	1409
1298.41	1456
1297.86	1422.5
1297.32	1354.5
1296.78	1367
1296.23	1391
1295.69	1420
1295.15	1378
1294.6	1376.5
1294.06	1375.5
1293.52	1384.75
1292.97	1395.75
1292.43	1356.5
1291.89	1394.5
1291.34	1389.5
1290.8	1414.25
1290.26	1316.5
1289.71	1380
1289.17	1344.5
1288.63	1367.5
1288.08	1378
1287.54	1388.5
1286.99	1396.5
1286.45	1484.5
1285.9	1561.5
1285.36	1756
1284.82	1696.75
1284.27	1488.5
1283.73	1367
1283.19	1362
1282.64	1331.75
1282.1	1291.5
1281.55	1369
1281.01	1325
1280.46	1338.75
1279.92	1309.75
1279.37	1315.5
1278.83	1338
1278.28	1325
1277.74	1304.5
1277.19	1281.5
1276.65	1320.5
1276.1	1330
1275.56	1327
1275.01	1343
1274.47	1372
1273.92	1348
1273.38	1310.5
1272.83	1366.5
1272.29	1317.5
1271.74	1334
1271.2	1326
1270.65	1312
1270.11	1350
1269.56	1363
1269.01	1335.5
1268.47	1311.25
1267.92	1352.5
1267.38	1344
1266.83	1418.5
1266.29	1365.5
1265.74	1371
1265.19	1394.5
1264.65	1361.5
1264.1	1360
1263.55	1404.75
1263.01	1426.5
1262.46	1412.75
1261.92	1395.5
1261.37	1389.75
1260.82	1365
1260.28	1353.5
1259.73	1378.5
1259.18	1404
1258.64	1371.5
1258.09	1387.75
1257.55	1413
1257	1430
1256.45	1465.5
1255.9	1449.5
1255.36	1384.5
1254.81	1407.5
1254.26	1464.5
1253.72	1418.75
1253.17	1491
1252.62	1467.5
1252.07	1489
1251.53	1453
1250.98	1425.75
1250.43	1439.5
1249.89	1534.5
1249.34	1490.5
1248.79	1442
1248.24	1421
1247.7	1484.5
1247.15	1460.5
1246.6	1508
1246.05	1473
1245.5	1448
1244.96	1445.5
1244.41	1506
1243.86	1505.25
1243.31	1536
1242.77	1491
1242.22	1497.5
1241.67	1520.5
1241.12	1539
1240.57	1508
1240.02	1532
1239.48	1581
1238.93	1593
1238.38	1576.5
1237.83	1611
1237.28	1607
1236.73	1641.5
1236.18	1712.5
1235.64	1647.25
1235.09	1699.5
1234.54	1737.5
1233.99	1697.5
1233.44	1800.5
1232.89	1772.5
1232.34	1810
1231.79	1819
1231.24	1823
1230.69	1832
1230.15	1859
1229.6	1842
1229.05	1875
1228.5	1869.5
1227.95	1832
1227.4	1829.5
1226.85	1805
1226.3	1867.5
1225.75	1783
1225.2	1789.75
1224.65	1712.5
1224.1	1754.5
1223.55	1696.75
1223	1610.5
1222.45	1595.25
1221.9	1626.75
1221.35	1587.5
1220.8	1523.5
1220.25	1623
1219.7	1593
1219.15	1562.5
1218.6	1494
1218.05	1523.5
1217.5	1484
1216.95	1523.5
1216.4	1466.5
1215.85	1480.25
1215.3	1464.25
1214.75	1440.5
1214.2	1418.5
1213.65	1435
1213.09	1466.5
1212.54	1481.5
1211.99	1419
1211.44	1419
1210.89	1405.5
1210.34	1353
1209.79	1342.5
1209.24	1343
1208.69	1368.5
1208.14	1291.5
1207.58	1386.5
1207.03	1322.5
1206.48	1370.5
1205.93	1411.5
1205.38	1355
1204.83	1378.75
1204.27	1418
1203.72	1336
1203.17	1313.25
1202.62	1342.5
1202.07	1287
1201.52	1385.5
1200.96	1355.5
1200.41	1359
1199.86	1335.5
1199.31	1313
1198.76	1310.5
1198.2	1325.5
1197.65	1352
1197.1	1403.75
1196.55	1311
1196	1374
1195.44	1335
1194.89	1376
1194.34	1320.5
1193.78	1371
1193.23	1349.25
1192.68	1386.5
1192.13	1429.75
1191.57	1413
1191.02	1444.25
1190.47	1492.5
1189.91	1414
1189.36	1424
1188.81	1456.5
1188.26	1448
1187.7	1447
1187.15	1465.25
1186.6	1482
1186.04	1553.25
1185.49	1503
1184.94	1496.5
1184.38	1524.25
1183.83	1502.5
1183.28	1498.75
1182.72	1480.5
1182.17	1470.75
1181.61	1515
1181.06	1474.75
1180.51	1441.5
1179.95	1442
1179.4	1375
1178.85	1419.75
1178.29	1351.5
1177.74	1426.5
1177.18	1435
1176.63	1420
1176.07	1374.5
1175.52	1370
1174.97	1374.5
1174.41	1356.5
1173.86	1371
1173.3	1384.5
1172.75	1360
1172.19	1386
1171.64	1381
1171.09	1387
1170.53	1428.75
1169.97	1435.5
1169.42	1439
1168.86	1474
1168.31	1492
1167.76	1507.5
1167.2	1546.5
1166.65	1546
1166.09	1569.25
1165.53	1665.75
1164.98	1651.5
1164.42	1676.5
1163.87	1746.5
1163.31	1925.5
1162.76	1927
1162.2	2086.5
1161.65	2089
1161.09	2199
1160.54	2316
1159.98	2414.25
1159.42	2453.5
1158.87	2467.5
1158.31	2511.5
1157.76	2514.75
1157.2	2470.5
1156.65	2382.5
1156.09	2235
1155.53	2229.25
1154.98	2089
1154.42	2011
1153.86	1958
1153.31	1890.5
1152.75	1822.5
1152.19	1743
1151.64	1687.5
1151.08	1657.5
1150.52	1596
1149.97	1557.5
1149.41	1563.5
1148.86	1586.5
1148.3	1521.25
1147.74	1447
1147.18	1491.75
1146.63	1492.5
1146.07	1477.5
1145.51	1463.5
1144.96	1466.5
1144.4	1432
1143.84	1404.5
1143.28	1409
1142.73	1401.5
1142.17	1441.5
1141.61	1359.25
1141.06	1389
1140.5	1400.25
1139.94	1417
1139.38	1358.5
1138.83	1388
1138.27	1386
1137.71	1334
1137.15	1331
1136.59	1353.5
1136.04	1333
1135.48	1333
1134.92	1376
1134.36	1316.5
1133.8	1360.5
1133.25	1328
1132.69	1311
1132.13	1354.5
1131.57	1364
1131.01	1338.5
1130.45	1326.5
1129.9	1352.25
1129.34	1376
1128.78	1326.5
1128.22	1323.5
1127.66	1427.5
1127.1	1355.25
1126.54	1350.5
1125.98	1416.5
1125.43	1325.5
1124.87	1368
1124.31	1385.5
1123.75	1347
1123.19	1364.75
1122.63	1393
1122.07	1341
1121.51	1369
1120.95	1340.5
1120.39	1383
1119.83	1404.5
1119.27	1401
1118.72	1412
1118.15	1459
1117.6	1476.75
1117.04	1456.5
1116.48	1504
1115.92	1550.5
1115.36	1518
1114.8	1557.25
1114.24	1552.5
1113.68	1582.5
1113.12	1548
1112.56	1633
1112	1602.5
1111.44	1652.5
1110.88	1519
1110.32	1541.5
1109.76	1570
1109.19	1544.5
1108.64	1520.5
1108.07	1447
1107.51	1493.5
1106.95	1429
1106.39	1365.25
1105.83	1436.5
1105.27	1410
1104.71	1367
1104.15	1372
1103.59	1364
1103.03	1349.25
1102.47	1329.5
1101.91	1296
1101.34	1378
1100.78	1339.5
1100.22	1352
1099.66	1325
1099.1	1341
1098.54	1309.25
1097.98	1292
1097.41	1311
1096.85	1320
1096.29	1325.75
1095.73	1322
1095.17	1303.5
1094.61	1373
1094.04	1334
1093.48	1322.5
1092.92	1328
1092.36	1315
1091.8	1320.25
1091.23	1325
1090.67	1276.75
1090.11	1264
1089.55	1305
1088.99	1349.75
1088.42	1355
1087.86	1350.5
1087.3	1326.5
1086.74	1334.5
1086.17	1392
1085.61	1353.5
1085.05	1367
1084.49	1450.5
1083.92	1415
1083.36	1478
1082.8	1439
1082.23	1517.5
1081.67	1490
1081.11	1441
1080.55	1553.5
1079.98	1400
1079.42	1505.5
1078.86	1464.5
1078.29	1389.5
1077.73	1365
1077.17	1325.5
1076.6	1341.5
1076.04	1345.25
1075.48	1330.75
1074.91	1330.25
1074.35	1308.5
1073.79	1321.5
1073.22	1301
1072.66	1337.5
1072.09	1322
1071.53	1307.5
1070.97	1306.25
1070.4	1339.5
1069.84	1343
1069.27	1316
1068.71	1295
1068.15	1294.25
1067.58	1346.5
1067.02	1309.5
1066.45	1303
1065.89	1286.5
1065.32	1320.5
1064.76	1346
1064.19	1306.5
1063.63	1304
1063.07	1273.75
1062.5	1282.5
1061.94	1314.5
1061.37	1268.5
1060.81	1274
1060.24	1282
1059.68	1336.25
1059.11	1305
1058.55	1267
1057.98	1287.5
1057.42	1259
1056.85	1282.5
1056.29	1274
1055.72	1248.5
1055.16	1272.5
1054.59	1286.5
1054.03	1305.25
1053.46	1284
1052.89	1242.5
1052.33	1305
1051.76	1287.5
1051.2	1318.75
1050.63	1236.5
1050.06	1245.5
1049.5	1259.5
1048.93	1297
1048.37	1283
1047.8	1328
1047.24	1261.5
1046.67	1291.5
1046.1	1228.5
1045.54	1232.5
1044.97	1231.5
1044.4	1279.5
1043.84	1255
1043.27	1316.25
1042.7	1259.5
1042.14	1267.5
1041.57	1239
1041.01	1278.5
1040.44	1267
1039.87	1273.5
1039.3	1275.5
1038.74	1281.75
1038.17	1247.5
1037.6	1246.5
1037.04	1254.25
1036.47	1266
1035.9	1227.25
1035.34	1283.25
1034.77	1237
1034.2	1224.5
1033.63	1199
1033.07	1290
1032.5	1247.5
1031.93	1227.75
1031.36	1219
1030.8	1206.5
1030.23	1259.75
1029.66	1268
1029.09	1221.75
1028.52	1234.75
1027.96	1250
1027.39	1191
1026.82	1232.25
1026.25	1272.75
1025.68	1194
1025.12	1175.5
1024.55	1243
1023.98	1196.5
1023.41	1229.5
1022.84	1178.5
1022.28	1232
1021.71	1221.25
1021.14	1170.5
1020.57	1198
1020	1132.5
1019.43	1217.5
1018.86	1172
1018.3	1212
1017.73	1217
1017.16	1171.5
1016.59	1203.5
1016.3	1189