File: Testing/Hickernall_HORIBA/g45-mi2_05.txt
#Acq. time (s)=	75
#Accumulations=	5
#Range=	Off
#Autofocus=	Off
#Macrospot=	Off
#AutoExposure=	Off
#Spike filter=	Multiple accum.
#Delay time (s)=	0
#Binning=	1
#Readout mode=	Signal
#DeNoise=	Off
#ICS correction=	Off
#Dark correction=	Off
#Inst. Process=	Off
#Instrument=	LabRAM HR Evol
#Detector=	Andor CCD
#Objective=	x100 LWD
#Grating=	1800 gr/mm
#ND Filter=	100%
#Laser (nm)=	532
#Spectro (cm-¹)=	1240.02
#Hole=	49.98
#Range=	Visible
#AFM=	Off
#StageXY=	Marzhauser
#StageZ=	Marzhauser
#X (µm)=	-16206.4
#Y (µm)=	-737.9
#Z (µm)=	-344.3
#Project=
#Sample=
#Site=
#Title=	g45-mi2
#Remark=
#Date=	06.05.2022 11:30
#Acquired=	06.05.2022 11:30:08
1454.81	1098
1454.28	1086.5
1453.75	1121.75
1453.22	1072.5
1452.69	1080.75
1452.16	1083.75
1451.64	1070.25
1451.11	1099.5
1450.58	1084.75
1450.05	1097.5
1449.52	1043.75
1448.99	1084
1448.46	1067.5
1447.93	1095.75
1447.4	1067.25
1446.88	1084.5
1446.35	1072.25
1445.82	1068
1445.29	1089
1444.76	1029.25
1444.23	1093.25
1443.7	1059.75
1443.17	1112.25
1442.64	1084.25
1442.11	1054
1441.58	1084.75
1441.05	1069.75
1440.52	1038.25
1439.99	1034.75
1439.46	1033
1438.93	1038.5
1438.4	1057.25
1437.87	1008.25
1437.34	1057
1436.81	1041
1436.28	1033
1435.75	1011.25
1435.22	1041.25
1434.69	962.25
1434.16	1026.25
1433.63	1042
1433.1	989.25
1432.57	1016.75
1432.04	1017
1431.51	1015.75
1430.98	1031.25
1430.45	1034.5
1429.92	1006
1429.39	992.25
1428.86	1016.25
1428.33	988
1427.8	994
1427.26	984.75
1426.73	997
1426.2	989.75
1425.67	976.5
1425.14	971.75
1424.61	977.5
1424.08	987.5
1423.55	985
1423.02	995.25
1422.49	967.75
1421.95	965.5
1421.42	985.5
1420.89	973.75
1420.36	999
1419.83	977
1419.3	988
1418.76	985.25
1418.23	995.5
1417.7	981
1417.17	980
1416.64	940.75
1416.1	989.5
1415.57	984.25
1415.04	975.5
1414.51	968.5
1413.98	987.75
1413.44	992.5
1412.91	995.5
1412.38	998.75
1411.85	946.25
1411.32	959
1410.78	1016
1410.25	973.5
1409.72	967.25
1409.18	1022.25
1408.65	1007.25
1408.12	984.75
1407.59	982
1407.05	978
1406.52	948.5
1405.99	948.25
1405.46	939.5
1404.92	985
1404.39	982.25
1403.86	982
1403.32	958.75
1402.79	951.25
1402.26	958.5
1401.72	946.5
1401.19	938
1400.66	951.5
1400.12	947
1399.59	962.5
1399.06	947.25
1398.52	953.25
1397.99	941.25
1397.46	1014.75
1396.92	919.5
1396.39	941
1395.85	954.5
1395.32	945.5
1394.79	918.75
1394.25	933.25
1393.72	959
1393.18	961.75
1392.65	966
1392.12	933.75
1391.58	934
1391.05	949.75
1390.51	958
1389.98	995.75
1389.44	1144
1388.91	1290.75
1388.38	1299
1387.84	1335.25
1387.31	1229
1386.77	1041
1386.24	982.25
1385.7	949.25
1385.17	947.75
1384.63	989.75
1384.1	917
1383.56	976.75
1383.03	932.5
1382.49	964.75
1381.96	959.5
1381.42	955
1380.89	964.75
1380.35	966
1379.82	922.5
1379.28	904
1378.74	929.75
1378.21	909.75
1377.67	970
1377.14	938
1376.6	951.5
1376.07	934
1375.53	966.75
1374.99	920.5
1374.46	949
1373.92	961.75
1373.39	993.25
1372.85	926
1372.32	912.25
1371.78	938
1371.24	895
1370.71	928.5
1370.17	916
1369.63	941.75
1369.1	926.25
1368.56	923
1368.03	939.75
1367.49	928.25
1366.95	931
1366.42	952.5
1365.88	951.5
1365.34	941.5
1364.81	929
1364.27	930
1363.73	970.5
1363.19	948.75
1362.66	929
1362.12	943.75
1361.58	951.5
1361.05	944.75
1360.51	944.75
1359.97	952.25
1359.44	929.5
1358.9	917.5
1358.36	927.25
1357.82	947.25
1357.29	927.5
1356.75	926.75
1356.21	920.5
1355.67	944
1355.14	901
1354.6	940
1354.06	922.75
1353.52	943
1352.99	915.5
1352.45	905.25
1351.91	952.5
1351.37	926.75
1350.83	926.75
1350.3	886.75
1349.76	907.25
1349.22	921
1348.68	934.25
1348.14	916.5
1347.6	936
1347.06	900.5
1346.53	947.75
1345.99	930.75
1345.45	935.5
1344.91	925.5
1344.37	933.25
1343.83	917.25
1343.3	906.5
1342.76	917.75
1342.22	935.5
1341.68	929.25
1341.14	925.25
1340.6	926.25
1340.06	907
1339.52	926.5
1338.98	904.5
1338.45	890
1337.91	911.5
1337.37	890.5
1336.83	930
1336.29	899
1335.75	920.75
1335.21	899
1334.67	896.5
1334.13	914.5
1333.59	889.75
1333.05	893.5
1332.51	920.5
1331.97	881.5
1331.43	923.75
1330.89	917
1330.35	904.75
1329.81	909.5
1329.27	915.5
1328.73	937.75
1328.19	937.75
1327.65	919
1327.11	952.5
1326.57	900.75
1326.03	928.25
1325.49	909
1324.95	905
1324.41	887.5
1323.87	906.75
1323.33	926
1322.79	902
1322.25	913.25
1321.71	901.25
1321.16	910
1320.62	938
1320.08	909.75
1319.54	921.25
1319	892.5
1318.46	923.5
1317.92	910
1317.38	935.25
1316.84	883.25
1316.29	912.5
1315.75	909.25
1315.21	960.5
1314.67	929
1314.13	943.25
1313.59	957.5
1313.05	975.75
1312.5	947
1311.96	960.75
1311.42	964.75
1310.88	939.25
1310.34	982.75
1309.8	939.75
1309.25	984
1308.71	962.75
1308.17	955.75
1307.63	994.25
1307.09	957
1306.54	997
1306	947.25
1305.46	965
1304.92	955.5
1304.38	993.5
1303.83	979.5
1303.29	974.75
1302.75	1007.75
1302.21	1032.25
1301.66	980
1301.12	1009.75
1300.58	979.75
1300.04	991.5
1299.49	1006.25
1298.95	1038.5
1298.41	1007
1297.86	1035
1297.32	992.5
1296.78	1012.25
1296.23	1006.25
1295.69	1020.5
1295.15	996.5
1294.6	1026.75
1294.06	997.75
1293.52	1033
1292.97	1003.25
1292.43	993
1291.89	1010
1291.34	984.5
1290.8	985.75
1290.26	1024.75
1289.71	1007.25
1289.17	975.25
1288.63	1004.5
1288.08	957
1287.54	1021.75
1286.99	1053
1286.45	1134
1285.9	1153
1285.36	1253
1284.82	1240.5
1284.27	1085.5
1283.73	990.5
1283.19	977
1282.64	976.5
1282.1	993
1281.55	951
1281.01	969
1280.46	956.5
1279.92	955
1279.37	983.5
1278.83	970
1278.28	977
1277.74	918
1277.19	951.25
1276.65	953
1276.1	964.75
1275.56	941.25
1275.01	968.25
1274.47	981.25
1273.92	980.75
1273.38	973
1272.83	965.25
1272.29	961
1271.74	965.25
1271.2	958.75
1270.65	969.25
1270.11	984.5
1269.56	957
1269.01	946.75
1268.47	974.25
1267.92	975
1267.38	986
1266.83	958.25
1266.29	977.5
1265.74	1000.75
1265.19	1014.5
1264.65	1025.5
1264.1	975.75
1263.55	984.5
1263.01	1024.5
1262.46	1000.75
1261.92	1000.5
1261.37	1001.5
1260.82	1007
1260.28	1038.75
1259.73	1042.5
1259.18	1030.5
1258.64	1022.5
1258.09	1046.25
1257.55	1053
1257	1028
1256.45	1069.75
1255.9	1055
1255.36	1068.5
1254.81	1062
1254.26	1105
1253.72	1087.25
1253.17	1025
1252.62	1095
1252.07	1119.5
1251.53	1078
1250.98	1077.75
1250.43	1144.5
1249.89	1150.75
1249.34	1085
1248.79	1106.25
1248.24	1144.75
1247.7	1129.5
1247.15	1107.75
1246.6	1140.5
1246.05	1148.5
1245.5	1145.25
1244.96	1119.5
1244.41	1149.5
1243.86	1150.25
1243.31	1177.75
1242.77	1193.75
1242.22	1168.25
1241.67	1216
1241.12	1252.75
1240.57	1250.5
1240.02	1252
1239.48	1297.75
1238.93	1261.75
1238.38	1350.75
1237.83	1393.25
1237.28	1387.75
1236.73	1421.75
1236.18	1413.5
1235.64	1495
1235.09	1487.75
1234.54	1539
1233.99	1588
1233.44	1664
1232.89	1644.5
1232.34	1694.5
1231.79	1691.25
1231.24	1730.25
1230.69	1758.25
1230.15	1781.5
1229.6	1775
1229.05	1756.75
1228.5	1803
1227.95	1776
1227.4	1748.75
1226.85	1685.5
1226.3	1684.5
1225.75	1645.25
1225.2	1602.5
1224.65	1521.5
1224.1	1519.75
1223.55	1472.5
1223	1363
1222.45	1393.75
1221.9	1386.25
1221.35	1345.25
1220.8	1319.75
1220.25	1271.75
1219.7	1239.75
1219.15	1212.75
1218.6	1249
1218.05	1205.75
1217.5	1194.25
1216.95	1153
1216.4	1172.25
1215.85	1163.25
1215.3	1147.25
1214.75	1106
1214.2	1141.75
1213.65	1087.5
1213.09	1092
1212.54	1064.75
1211.99	1065.5
1211.44	1053
1210.89	1074.25
1210.34	1056
1209.79	1043.25
1209.24	1007.25
1208.69	1012.5
1208.14	1049.5
1207.58	997.5
1207.03	1017
1206.48	1018.25
1205.93	988
1205.38	1001.75
1204.83	994.5
1204.27	962.25
1203.72	987.5
1203.17	948
1202.62	966.75
1202.07	978.25
1201.52	988.75
1200.96	970.75
1200.41	1014.75
1199.86	980.75
1199.31	1000
1198.76	939
1198.2	936.25
1197.65	972.5
1197.1	996.75
1196.55	960
1196	951.5
1195.44	979.75
1194.89	964.25
1194.34	960
1193.78	1020
1193.23	962.75
1192.68	1021.25
1192.13	1028.75
1191.57	1054.25
1191.02	1023.25
1190.47	1015.75
1189.91	1073.25
1189.36	1051.25
1188.81	1094.75
1188.26	1104.5
1187.7	1061.5
1187.15	1108
1186.6	1118.25
1186.04	1136.75
1185.49	1124.25
1184.94	1099.75
1184.38	1119
1183.83	1116.25
1183.28	1067.25
1182.72	1091.5
1182.17	1118.75
1181.61	1098.5
1181.06	1087.75
1180.51	1086.25
1179.95	1074.25
1179.4	1043.25
1178.85	1052
1178.29	1037.5
1177.74	1038.5
1177.18	1027.75
1176.63	1013.5
1176.07	1000.75
1175.52	1016.75
1174.97	1014
1174.41	1011
1173.86	1009.5
1173.3	1052.25
1172.75	1037.75
1172.19	1049
1171.64	1023.5
1171.09	1052
1170.53	1095
1169.97	1093
1169.42	1099.75
1168.86	1062.5
1168.31	1100.5
1167.76	1143.5
1167.2	1189.25
1166.65	1245.25
1166.09	1263
1165.53	1303.5
1164.98	1381.75
1164.42	1462.25
1163.87	1510.25
1163.31	1615.75
1162.76	1750.25
1162.2	1811.75
1161.65	1898.5
1161.09	2004.75
1160.54	2134
1159.98	2245
1159.42	2300.5
1158.87	2276.25
1158.31	2318.75
1157.76	2288.25
1157.2	2213.75
1156.65	2142.5
1156.09	2071
1155.53	1972
1154.98	1835.25
1154.42	1659.75
1153.86	1618.75
1153.31	1514.25
1152.75	1434.25
1152.19	1436
1151.64	1375.5
1151.08	1319.75
1150.52	1272
1149.97	1182.5
1149.41	1173.25
1148.86	1161
1148.3	1150.75
1147.74	1082.75
1147.18	1140.75
1146.63	1082.5
1146.07	1079
1145.51	1070.5
1144.96	1058
1144.4	1031
1143.84	1053.25
1143.28	1043
1142.73	1006
1142.17	999.75
1141.61	1016
1141.06	1002.75
1140.5	997
1139.94	970.75
1139.38	966
1138.83	965.5
1138.27	968.75
1137.71	958.5
1137.15	968.25
1136.59	952.25
1136.04	983.75
1135.48	1004.75
1134.92	956.25
1134.36	933.25
1133.8	931
1133.25	934
1132.69	947.5
1132.13	910.5
1131.57	945.75
1131.01	929
1130.45	925.25
1129.9	939.75
1129.34	961.5
1128.78	945.75
1128.22	964.75
1127.66	966.5
1127.1	969
1126.54	957.5
1125.98	959.25
1125.43	965.25
1124.87	985.75
1124.31	949.25
1123.75	927.5
1123.19	969
1122.63	965.5
1122.07	960.25
1121.51	977.5
1120.95	1014
1120.39	987.75
1119.83	1005.25
1119.27	1007.75
1118.72	1065.75
1118.15	1065.25
1117.6	1069.5
1117.04	1089.25
1116.48	1090.5
1115.92	1096.75
1115.36	1165.75
1114.8	1145.5
1114.24	1179.25
1113.68	1188.75
1113.12	1224
1112.56	1191.25
1112	1211.5
1111.44	1188
1110.88	1175.25
1110.32	1179.25
1109.76	1138.25
1109.19	1145
1108.64	1138.25
1108.07	1117.25
1107.51	1046.75
1106.95	1038.25
1106.39	1060.25
1105.83	1010.5
1105.27	1035.5
1104.71	1018.75
1104.15	998.5
1103.59	1025.5
1103.03	990.75
1102.47	939
1101.91	947.75
1101.34	965.5
1100.78	982.75
1100.22	954
1099.66	980.5
1099.1	963.75
1098.54	943
1097.98	948.25
1097.41	922.25
1096.85	957.5
1096.29	947.5
1095.73	936.75
1095.17	946.5
1094.61	944
1094.04	936.5
1093.48	927
1092.92	943
1092.36	906.75
1091.8	959.5
1091.23	976.5
1090.67	940
1090.11	955.5
1089.55	971
1088.99	971.5
1088.42	958.25
1087.86	970
1087.3	991.25
1086.74	1016
1086.17	1023.25
1085.61	1043.5
1085.05	1073.25
1084.49	1091
1083.92	1079.5
1083.36	1100.25
1082.8	1164.5
1082.23	1165.25
1081.67	1151.75
1081.11	1194.5
1080.55	1191.75
1079.98	1143
1079.42	1103
1078.86	1070
1078.29	1074.5
1077.73	1065.5
1077.17	1022.75
1076.6	1061
1076.04	986.25
1075.48	980.25
1074.91	1004.75
1074.35	991.5
1073.79	970.75
1073.22	980.75
1072.66	981
1072.09	997
1071.53	987.25
1070.97	981.5
1070.4	962.25
1069.84	968.75
1069.27	955.5
1068.71	948.5
1068.15	946.75
1067.58	945.75
1067.02	941.5
1066.45	942.5
1065.89	945.75
1065.32	965.5
1064.76	975.5
1064.19	950
1063.63	940
1063.07	944.75
1062.5	937.75
1061.94	939.5
1061.37	957
1060.81	932.25
1060.24	900.25
1059.68	937.5
1059.11	922.5
1058.55	886
1057.98	874.5
1057.42	915.75
1056.85	874
1056.29	922.25
1055.72	891.25
1055.16	869
1054.59	910.5
1054.03	901
1053.46	884.25
1052.89	897.75
1052.33	895
1051.76	933
1051.2	917
1050.63	915.25
1050.06	887
1049.5	841.5
1048.93	920.5
1048.37	934
1047.8	842.5
1047.24	923.75
1046.67	897.75
1046.1	886
1045.54	863
1044.97	890
1044.4	909.25
1043.84	887.5
1043.27	919.75
1042.7	896.5
1042.14	896.5
1041.57	902.75
1041.01	873.5
1040.44	912.5
1039.87	888.5
1039.3	896.75
1038.74	903.25
1038.17	858.75
1037.6	867.75
1037.04	862
1036.47	891.5
1035.9	863.5
1035.34	895.75
1034.77	883.75
1034.2	865.75
1033.63	837
1033.07	873.25
1032.5	867
1031.93	843.25
1031.36	851.5
1030.8	837
1030.23	816.5
1029.66	861
1029.09	863
1028.52	855.25
1027.96	874
1027.39	860.5
1026.82	847
1026.25	836.25
1025.68	843.75
1025.12	840.5
1024.55	819.5
1023.98	813.25
1023.41	817
1022.84	854.75
1022.28	819
1021.71	821.5
1021.14	835.75
1020.57	845.5
1020	850.75
1019.43	854.5
1018.86	828.75
1018.3	845
1017.73	828
1017.16	867.5
1016.59	833
1016.3	864