File: Testing/Hickernall_HORIBA/g45-mi2_04.txt
#Acq. time (s)=	75
#Accumulations=	5
#Range=	Off
#Autofocus=	Off
#Macrospot=	Off
#AutoExposure=	Off
#Spike filter=	Multiple accum.
#Delay time (s)=	0
#Binning=	1
#Readout mode=	Signal
#DeNoise=	Off
#ICS correction=	Off
#Dark correction=	Off
#Inst. Process=	Off
#Instrument=	LabRAM HR Evol
#Detector=	Andor CCD
#Objective=	x100 LWD
#Grating=	1800 gr/mm
#ND Filter=	100%
#Laser (nm)=	532
#Spectro (cm-¹)=	1240.02
#Hole=	49.98
#Range=	Visible
#AFM=	Off
#StageXY=	Marzhauser
#StageZ=	Marzhauser
#X (µm)=	-16206.4
#Y (µm)=	-737.9
#Z (µm)=	-344.3
#Project=
#Sample=
#Site=
#Title=	g45-mi2
#Remark=
#Date=	06.05.2022 11:23
#Acquired=	06.05.2022 11:23:44
1454.81	1038
1454.28	1095.75
1453.75	1083.25
1453.22	1078.25
1452.69	1092
1452.16	1084.5
1451.64	1048.5
1451.11	1109
1450.58	1059
1450.05	1024
1449.52	1034
1448.99	1031.25
1448.46	1059.25
1447.93	1059
1447.4	1048.5
1446.88	1062.25
1446.35	1052.5
1445.82	1044.25
1445.29	1059.75
1444.76	1040.5
1444.23	1041.5
1443.7	1076.75
1443.17	1023
1442.64	1030.5
1442.11	1027.75
1441.58	1064
1441.05	1043.75
1440.52	1029.5
1439.99	1053
1439.46	1012.25
1438.93	1039
1438.4	1027.5
1437.87	1023.75
1437.34	1031.5
1436.81	1040.75
1436.28	1054.25
1435.75	1025.75
1435.22	1063
1434.69	1035.25
1434.16	1008.25
1433.63	1011.5
1433.1	962.5
1432.57	1018
1432.04	972.75
1431.51	1030.5
1430.98	991.5
1430.45	964
1429.92	991
1429.39	973.25
1428.86	970.75
1428.33	998.25
1427.8	999.75
1427.26	956.75
1426.73	973.75
1426.2	976.5
1425.67	962
1425.14	973.25
1424.61	993.75
1424.08	956.75
1423.55	980
1423.02	939.5
1422.49	979
1421.95	959
1421.42	960.75
1420.89	958.25
1420.36	979
1419.83	962.5
1419.3	994.5
1418.76	958
1418.23	962.25
1417.7	966
1417.17	947.5
1416.64	958.25
1416.1	970
1415.57	999
1415.04	971
1414.51	957.25
1413.98	966.5
1413.44	960.75
1412.91	1020.5
1412.38	986.25
1411.85	930.5
1411.32	953.5
1410.78	994.5
1410.25	961
1409.72	997.75
1409.18	951
1408.65	972.25
1408.12	957.75
1407.59	954.5
1407.05	931
1406.52	941.5
1405.99	949.5
1405.46	943.75
1404.92	916
1404.39	945.5
1403.86	955.25
1403.32	932
1402.79	948.25
1402.26	936.25
1401.72	928
1401.19	960.75
1400.66	939
1400.12	961.25
1399.59	928.75
1399.06	947.75
1398.52	963.5
1397.99	979
1397.46	906
1396.92	912
1396.39	930.5
1395.85	941.5
1395.32	927
1394.79	963.25
1394.25	918.25
1393.72	922
1393.18	946.75
1392.65	928.25
1392.12	917.25
1391.58	944
1391.05	950.75
1390.51	990.75
1389.98	1021.5
1389.44	1170
1388.91	1236
1388.38	1288.5
1387.84	1368.25
1387.31	1230.25
1386.77	995.25
1386.24	966.5
1385.7	929
1385.17	953.75
1384.63	979.25
1384.1	927.25
1383.56	945.5
1383.03	945.25
1382.49	980.5
1381.96	936.25
1381.42	970.75
1380.89	954
1380.35	970.25
1379.82	974.5
1379.28	918
1378.74	935.5
1378.21	948
1377.67	929
1377.14	928
1376.6	920
1376.07	952.75
1375.53	939
1374.99	925.5
1374.46	897.5
1373.92	902.5
1373.39	950.25
1372.85	919.25
1372.32	892.25
1371.78	943
1371.24	949.75
1370.71	944
1370.17	942.5
1369.63	901.25
1369.1	909
1368.56	897.5
1368.03	920.75
1367.49	908
1366.95	916.25
1366.42	900.75
1365.88	976.25
1365.34	899.75
1364.81	936
1364.27	915
1363.73	940.5
1363.19	937.25
1362.66	925
1362.12	909.5
1361.58	906.25
1361.05	922.5
1360.51	949.75
1359.97	931
1359.44	909
1358.9	954.25
1358.36	949
1357.82	940.25
1357.29	946.5
1356.75	895.25
1356.21	925
1355.67	905
1355.14	875.25
1354.6	887.25
1354.06	918.5
1353.52	893.75
1352.99	909.25
1352.45	906
1351.91	903
1351.37	923.25
1350.83	902.75
1350.3	895.5
1349.76	935.25
1349.22	922
1348.68	918
1348.14	904
1347.6	946
1347.06	908.5
1346.53	869
1345.99	916.25
1345.45	918
1344.91	909.25
1344.37	929
1343.83	901.5
1343.3	887.75
1342.76	932.75
1342.22	893
1341.68	906.25
1341.14	901.5
1340.6	884.5
1340.06	875
1339.52	901.5
1338.98	865.25
1338.45	915
1337.91	907
1337.37	890.75
1336.83	915
1336.29	905.5
1335.75	897.5
1335.21	906.25
1334.67	872
1334.13	924.75
1333.59	908.25
1333.05	850.5
1332.51	920
1331.97	893.25
1331.43	871
1330.89	881.25
1330.35	902.5
1329.81	871.75
1329.27	877.75
1328.73	892.75
1328.19	893.5
1327.65	904.75
1327.11	911.25
1326.57	884
1326.03	915.25
1325.49	902.75
1324.95	931
1324.41	882.25
1323.87	882
1323.33	886.5
1322.79	918.25
1322.25	935.5
1321.71	902.25
1321.16	909.75
1320.62	878.5
1320.08	893
1319.54	919.5
1319	899.5
1318.46	919
1317.92	920
1317.38	922.75
1316.84	925.75
1316.29	867.25
1315.75	897
1315.21	878.5
1314.67	948
1314.13	946.75
1313.59	953.25
1313.05	963
1312.5	957.5
1311.96	950
1311.42	950
1310.88	940.25
1310.34	920.25
1309.8	937
1309.25	964.5
1308.71	980
1308.17	944.5
1307.63	956.5
1307.09	927
1306.54	952
1306	953
1305.46	966.5
1304.92	978.25
1304.38	970.5
1303.83	954.25
1303.29	988.25
1302.75	992.25
1302.21	959
1301.66	970.25
1301.12	1017.75
1300.58	1014
1300.04	1010.5
1299.49	1004.5
1298.95	958.75
1298.41	979.5
1297.86	1001.5
1297.32	986.5
1296.78	1009.75
1296.23	1021.25
1295.69	997
1295.15	999.75
1294.6	1000.25
1294.06	1007
1293.52	977
1292.97	1001.75
1292.43	965.75
1291.89	962.75
1291.34	972
1290.8	970
1290.26	970
1289.71	1013
1289.17	983.5
1288.63	957.25
1288.08	970.5
1287.54	1028.5
1286.99	1041.75
1286.45	1136
1285.9	1193.75
1285.36	1272.75
1284.82	1213.75
1284.27	1074.5
1283.73	1008.5
1283.19	966.5
1282.64	951.75
1282.1	961.5
1281.55	942.75
1281.01	961.5
1280.46	970
1279.92	915.25
1279.37	939
1278.83	924.25
1278.28	955.25
1277.74	928.75
1277.19	942.25
1276.65	971.75
1276.1	921.5
1275.56	910.5
1275.01	961.5
1274.47	951
1273.92	951.75
1273.38	913.5
1272.83	992.75
1272.29	977.5
1271.74	993.5
1271.2	975
1270.65	945.25
1270.11	950.25
1269.56	983
1269.01	977
1268.47	986.25
1267.92	986
1267.38	978.75
1266.83	980.25
1266.29	961.5
1265.74	1004.5
1265.19	987.25
1264.65	1010
1264.1	1031.5
1263.55	970
1263.01	995
1262.46	997.25
1261.92	969
1261.37	1008.5
1260.82	997
1260.28	1045.25
1259.73	1012.25
1259.18	1056.5
1258.64	1028
1258.09	1002.25
1257.55	1037.75
1257	1066.25
1256.45	1073.75
1255.9	1026
1255.36	1061.75
1254.81	1054.5
1254.26	1056.5
1253.72	1028.75
1253.17	1065.75
1252.62	1105.25
1252.07	1097.5
1251.53	1083.75
1250.98	1096
1250.43	1126.25
1249.89	1096.25
1249.34	1064.75
1248.79	1116
1248.24	1126.5
1247.7	1134.75
1247.15	1115
1246.6	1099.25
1246.05	1123.5
1245.5	1156
1244.96	1144.5
1244.41	1129.75
1243.86	1193
1243.31	1182.25
1242.77	1177.25
1242.22	1228.5
1241.67	1214
1241.12	1223.75
1240.57	1265.25
1240.02	1311.75
1239.48	1284.25
1238.93	1343.5
1238.38	1315.25
1237.83	1336.25
1237.28	1347.5
1236.73	1431.25
1236.18	1428.75
1235.64	1500.25
1235.09	1461.5
1234.54	1546.25
1233.99	1585.5
1233.44	1677.5
1232.89	1666
1232.34	1692.75
1231.79	1697.5
1231.24	1736.5
1230.69	1775
1230.15	1796.5
1229.6	1791.75
1229.05	1806.5
1228.5	1780.25
1227.95	1800.5
1227.4	1693
1226.85	1692.5
1226.3	1639.25
1225.75	1635.75
1225.2	1536.5
1224.65	1519.5
1224.1	1491.5
1223.55	1480.5
1223	1408.75
1222.45	1375
1221.9	1338
1221.35	1306.5
1220.8	1302.25
1220.25	1312
1219.7	1256.25
1219.15	1225
1218.6	1161.75
1218.05	1213.75
1217.5	1182.5
1216.95	1154.75
1216.4	1134.25
1215.85	1132.25
1215.3	1107
1214.75	1109.25
1214.2	1091
1213.65	1059
1213.09	1091.25
1212.54	1087.75
1211.99	1056.5
1211.44	1010.25
1210.89	997
1210.34	1013.75
1209.79	1000.25
1209.24	992.75
1208.69	1034
1208.14	1015
1207.58	964.75
1207.03	1001
1206.48	1006.25
1205.93	1004.25
1205.38	970
1204.83	975
1204.27	957
1203.72	989.5
1203.17	984.5
1202.62	994.5
1202.07	989
1201.52	951.25
1200.96	956.25
1200.41	936.25
1199.86	959.5
1199.31	992.25
1198.76	968.25
1198.2	958.75
1197.65	980.5
1197.1	913.5
1196.55	934.5
1196	938.75
1195.44	976.5
1194.89	974.75
1194.34	964
1193.78	1001
1193.23	990.75
1192.68	1015
1192.13	971.5
1191.57	1060
1191.02	1045.5
1190.47	1072
1189.91	1049.75
1189.36	1051
1188.81	1046.5
1188.26	1087.25
1187.7	1070.75
1187.15	1104
1186.6	1123
1186.04	1118.5
1185.49	1110
1184.94	1103.5
1184.38	1132.25
1183.83	1115.25
1183.28	1091
1182.72	1095.75
1182.17	1082.25
1181.61	1088.5
1181.06	1018.75
1180.51	1077.25
1179.95	1089.5
1179.4	1041.75
1178.85	1029.25
1178.29	989.5
1177.74	1041.5
1177.18	1039
1176.63	997
1176.07	995.5
1175.52	1024.75
1174.97	1007.75
1174.41	1032
1173.86	1016.5
1173.3	1010.25
1172.75	1005.75
1172.19	994.5
1171.64	1010.25
1171.09	1051.25
1170.53	1072
1169.97	1068.75
1169.42	1093
1168.86	1073.75
1168.31	1125.25
1167.76	1188
1167.2	1182.25
1166.65	1258.75
1166.09	1273.75
1165.53	1334.75
1164.98	1377.5
1164.42	1432.5
1163.87	1549
1163.31	1581.5
1162.76	1736.75
1162.2	1843.75
1161.65	1950.5
1161.09	2061.25
1160.54	2142.75
1159.98	2293.5
1159.42	2291
1158.87	2345.5
1158.31	2332.5
1157.76	2295
1157.2	2252.5
1156.65	2160.25
1156.09	2033
1155.53	1967.25
1154.98	1875.5
1154.42	1671
1153.86	1650.25
1153.31	1527
1152.75	1503.75
1152.19	1412
1151.64	1327
1151.08	1315.5
1150.52	1244.25
1149.97	1254.25
1149.41	1165
1148.86	1170.5
1148.3	1144.75
1147.74	1133.5
1147.18	1122
1146.63	1106
1146.07	1059.5
1145.51	1059
1144.96	1047
1144.4	1057.5
1143.84	1045.5
1143.28	982
1142.73	999.75
1142.17	1023.75
1141.61	1013.75
1141.06	1030
1140.5	970.75
1139.94	1004.25
1139.38	959.5
1138.83	956.5
1138.27	971
1137.71	1002.25
1137.15	967
1136.59	949.5
1136.04	942
1135.48	964.75
1134.92	954.5
1134.36	941.75
1133.8	947.25
1133.25	932.25
1132.69	947
1132.13	925.5
1131.57	943
1131.01	922.25
1130.45	922
1129.9	925.5
1129.34	931.5
1128.78	920
1128.22	941
1127.66	947
1127.1	969.5
1126.54	955.25
1125.98	932.5
1125.43	973.75
1124.87	957.5
1124.31	965
1123.75	955.75
1123.19	953.5
1122.63	963
1122.07	988.5
1121.51	949
1120.95	962
1120.39	1005
1119.83	982.5
1119.27	1000.25
1118.72	1041.75
1118.15	1054.25
1117.6	1072.25
1117.04	1054.25
1116.48	1074
1115.92	1148.5
1115.36	1148.5
1114.8	1141.5
1114.24	1157.25
1113.68	1174.25
1113.12	1210.5
1112.56	1174.5
1112	1216.25
1111.44	1182
1110.88	1143.5
1110.32	1144
1109.76	1140.25
1109.19	1123.25
1108.64	1108.5
1108.07	1095.75
1107.51	1069.25
1106.95	1071
1106.39	1016.5
1105.83	1036
1105.27	995.5
1104.71	996.75
1104.15	990
1103.59	976.5
1103.03	971
1102.47	923
1101.91	967.5
1101.34	976.75
1100.78	978.5
1100.22	942
1099.66	947.75
1099.1	937.25
1098.54	953.5
1097.98	940.5
1097.41	945.5
1096.85	926.75
1096.29	917
1095.73	936.25
1095.17	929.25
1094.61	921
1094.04	919.5
1093.48	945.75
1092.92	917
1092.36	961
1091.8	955.5
1091.23	929.5
1090.67	944.25
1090.11	915.5
1089.55	967.25
1088.99	960.25
1088.42	942
1087.86	979.25
1087.3	1023.5
1086.74	995.75
1086.17	987.75
1085.61	1030
1085.05	1034
1084.49	1060.25
1083.92	1126
1083.36	1119
1082.8	1166
1082.23	1194.75
1081.67	1176
1081.11	1212.5
1080.55	1171.75
1079.98	1159
1079.42	1133.25
1078.86	1087.5
1078.29	1074.25
1077.73	1030
1077.17	1034.75
1076.6	1027.25
1076.04	1009
1075.48	982.25
1074.91	986
1074.35	982.75
1073.79	948
1073.22	974.25
1072.66	954.25
1072.09	986
1071.53	960
1070.97	978
1070.4	965.75
1069.84	943.25
1069.27	940.5
1068.71	943
1068.15	969.5
1067.58	936
1067.02	957.75
1066.45	963
1065.89	954.5
1065.32	934
1064.76	940.75
1064.19	942
1063.63	935.75
1063.07	915
1062.5	930
1061.94	905.75
1061.37	939.5
1060.81	914
1060.24	896.75
1059.68	937.25
1059.11	905.5
1058.55	890.75
1057.98	904.5
1057.42	875.5
1056.85	919.25
1056.29	882.5
1055.72	861.5
1055.16	921.25
1054.59	905
1054.03	904.75
1053.46	883.75
1052.89	898.75
1052.33	943.75
1051.76	896.5
1051.2	886
1050.63	891.5
1050.06	927.25
1049.5	885.25
1048.93	876.25
1048.37	916.25
1047.8	882.5
1047.24	881.5
1046.67	879.5
1046.1	903
1045.54	862.5
1044.97	913
1044.4	895.75
1043.84	905.75
1043.27	885.75
1042.7	885
1042.14	886
1041.57	882.75
1041.01	898.25
1040.44	870.5
1039.87	900
1039.3	874.25
1038.74	882
1038.17	858.5
1037.6	885.5
1037.04	864
1036.47	877
1035.9	871
1035.34	854.5
1034.77	835.5
1034.2	845.75
1033.63	851
1033.07	876.25
1032.5	883.5
1031.93	857.75
1031.36	810.75
1030.8	856
1030.23	834.25
1029.66	826
1029.09	841.5
1028.52	819.75
1027.96	825.25
1027.39	841
1026.82	861
1026.25	858.5
1025.68	833.75
1025.12	853.25
1024.55	839
1023.98	805.25
1023.41	834.5
1022.84	825
1022.28	855.5
1021.71	806
1021.14	821.25
1020.57	851.75
1020	822
1019.43	809.5
1018.86	829
1018.3	821
1017.73	858.25
1017.16	843
1016.59	857
1016.3	811.25