File: Testing/Hickernall_HORIBA/g45-mi2_02.txt
#Acq. time (s)=	75
#Accumulations=	5
#Range=	Off
#Autofocus=	Off
#Macrospot=	Off
#AutoExposure=	Off
#Spike filter=	Multiple accum.
#Delay time (s)=	0
#Binning=	1
#Readout mode=	Signal
#DeNoise=	Off
#ICS correction=	Off
#Dark correction=	Off
#Inst. Process=	Off
#Instrument=	LabRAM HR Evol
#Detector=	Andor CCD
#Objective=	x100 LWD
#Grating=	1800 gr/mm
#ND Filter=	100%
#Laser (nm)=	532
#Spectro (cm-¹)=	1240.02
#Hole=	49.98
#Range=	Visible
#AFM=	Off
#StageXY=	Marzhauser
#StageZ=	Marzhauser
#X (µm)=	-16206.7
#Y (µm)=	-738.5
#Z (µm)=	-344.9
#Project=
#Sample=
#Site=
#Title=	g45-mi2
#Remark=
#Date=	06.05.2022 11:10
#Acquired=	06.05.2022 11:10:19
1454.81	1238
1454.28	1245.75
1453.75	1187
1453.22	1264.5
1452.69	1272.25
1452.16	1259
1451.64	1279
1451.11	1258.5
1450.58	1217.5
1450.05	1247.25
1449.52	1247.75
1448.99	1268.75
1448.46	1209.25
1447.93	1264
1447.4	1240.5
1446.88	1246.75
1446.35	1258.25
1445.82	1234
1445.29	1256.5
1444.76	1216.75
1444.23	1251.5
1443.7	1246.25
1443.17	1228.5
1442.64	1239.75
1442.11	1226.75
1441.58	1233
1441.05	1248.25
1440.52	1252.75
1439.99	1217
1439.46	1197
1438.93	1252
1438.4	1231.25
1437.87	1208
1437.34	1184.25
1436.81	1222.25
1436.28	1230.25
1435.75	1224.75
1435.22	1230.5
1434.69	1235
1434.16	1204.5
1433.63	1215
1433.1	1164.5
1432.57	1200.25
1432.04	1132
1431.51	1166
1430.98	1185.5
1430.45	1184.25
1429.92	1201.75
1429.39	1172.75
1428.86	1217
1428.33	1209.75
1427.8	1185.25
1427.26	1153.5
1426.73	1217.75
1426.2	1137
1425.67	1150.25
1425.14	1166
1424.61	1139
1424.08	1181.75
1423.55	1162.5
1423.02	1182.5
1422.49	1184
1421.95	1158.5
1421.42	1171
1420.89	1182.25
1420.36	1150.25
1419.83	1171
1419.3	1160.75
1418.76	1165.25
1418.23	1159
1417.7	1157.25
1417.17	1160
1416.64	1140
1416.1	1177
1415.57	1142.5
1415.04	1175.25
1414.51	1123
1413.98	1163.5
1413.44	1137.5
1412.91	1144.25
1412.38	1148.25
1411.85	1156.25
1411.32	1100
1410.78	1156
1410.25	1159.75
1409.72	1165.5
1409.18	1169.5
1408.65	1164.5
1408.12	1123.5
1407.59	1106.25
1407.05	1128
1406.52	1148
1405.99	1191
1405.46	1140.25
1404.92	1098.5
1404.39	1175
1403.86	1141
1403.32	1128.5
1402.79	1094.75
1402.26	1120.5
1401.72	1131.75
1401.19	1130.5
1400.66	1093.5
1400.12	1134.5
1399.59	1099.75
1399.06	1125.25
1398.52	1141
1397.99	1154.75
1397.46	1149.5
1396.92	1133.5
1396.39	1127.75
1395.85	1143.25
1395.32	1070
1394.79	1114.5
1394.25	1124.5
1393.72	1123
1393.18	1150.5
1392.65	1139.5
1392.12	1116.75
1391.58	1114
1391.05	1127.75
1390.51	1155.5
1389.98	1177
1389.44	1322.75
1388.91	1383.25
1388.38	1483
1387.84	1524.5
1387.31	1375.75
1386.77	1205.5
1386.24	1124.5
1385.7	1122.75
1385.17	1138.25
1384.63	1151.5
1384.1	1126
1383.56	1154.5
1383.03	1134.75
1382.49	1101
1381.96	1142.5
1381.42	1116.25
1380.89	1108
1380.35	1130.75
1379.82	1121.5
1379.28	1112.25
1378.74	1138
1378.21	1104.5
1377.67	1182.5
1377.14	1099.5
1376.6	1109.25
1376.07	1160.5
1375.53	1128.75
1374.99	1097
1374.46	1113.5
1373.92	1110.25
1373.39	1103
1372.85	1100
1372.32	1106.5
1371.78	1136.75
1371.24	1105.25
1370.71	1112.25
1370.17	1126.25
1369.63	1104
1369.1	1136
1368.56	1081.25
1368.03	1131.75
1367.49	1114.5
1366.95	1084.75
1366.42	1130.5
1365.88	1088.5
1365.34	1117.5
1364.81	1133
1364.27	1109.75
1363.73	1069
1363.19	1106.5
1362.66	1099
1362.12	1081
1361.58	1122.5
1361.05	1116.5
1360.51	1098.5
1359.97	1090
1359.44	1089.5
1358.9	1120.75
1358.36	1084.5
1357.82	1102.75
1357.29	1104
1356.75	1080.75
1356.21	1082.25
1355.67	1070.75
1355.14	1087.5
1354.6	1103.5
1354.06	1088.5
1353.52	1103
1352.99	1085
1352.45	1093.25
1351.91	1117.25
1351.37	1115
1350.83	1074
1350.3	1093
1349.76	1100.5
1349.22	1105.75
1348.68	1118
1348.14	1081.5
1347.6	1113.75
1347.06	1093
1346.53	1084
1345.99	1086.25
1345.45	1121.25
1344.91	1093.5
1344.37	1086.5
1343.83	1086.75
1343.3	1066
1342.76	1055.5
1342.22	1093.25
1341.68	1101.5
1341.14	1059.25
1340.6	1063.25
1340.06	1130
1339.52	1115.75
1338.98	1076.25
1338.45	1077.75
1337.91	1089
1337.37	1070.5
1336.83	1085
1336.29	1092.75
1335.75	1082.75
1335.21	1090.5
1334.67	1048
1334.13	1107
1333.59	1077
1333.05	1102.25
1332.51	1102
1331.97	1072.5
1331.43	1097.5
1330.89	1062.75
1330.35	1060.5
1329.81	1017
1329.27	1077.5
1328.73	1074
1328.19	1089.75
1327.65	1124.75
1327.11	1064.5
1326.57	1067.5
1326.03	1096.5
1325.49	1060.25
1324.95	1104.5
1324.41	1092
1323.87	1066
1323.33	1051.75
1322.79	1083.25
1322.25	1063.25
1321.71	1116.75
1321.16	1081
1320.62	1100.75
1320.08	1071.5
1319.54	1050
1319	1105.75
1318.46	1109.75
1317.92	1116.5
1317.38	1105.25
1316.84	1093.5
1316.29	1131.25
1315.75	1053.5
1315.21	1118.25
1314.67	1098
1314.13	1091.75
1313.59	1135
1313.05	1116
1312.5	1118.75
1311.96	1082.5
1311.42	1116.5
1310.88	1113.5
1310.34	1119.25
1309.8	1110
1309.25	1117.25
1308.71	1118
1308.17	1118
1307.63	1142.5
1307.09	1146
1306.54	1137
1306	1121.25
1305.46	1117.75
1304.92	1152.5
1304.38	1176
1303.83	1162.5
1303.29	1131.75
1302.75	1145.5
1302.21	1191.5
1301.66	1188.5
1301.12	1153.75
1300.58	1160.5
1300.04	1190.25
1299.49	1194.75
1298.95	1144.75
1298.41	1158
1297.86	1180.25
1297.32	1156
1296.78	1164
1296.23	1185
1295.69	1153
1295.15	1168.25
1294.6	1175.5
1294.06	1181
1293.52	1157
1292.97	1148.5
1292.43	1159.5
1291.89	1173
1291.34	1151.5
1290.8	1173
1290.26	1151.5
1289.71	1185
1289.17	1157.25
1288.63	1151
1288.08	1160
1287.54	1184.25
1286.99	1211.75
1286.45	1271.5
1285.9	1304
1285.36	1404.5
1284.82	1368.5
1284.27	1251.5
1283.73	1165.75
1283.19	1130.75
1282.64	1148.75
1282.1	1115.5
1281.55	1118.25
1281.01	1160.25
1280.46	1116.75
1279.92	1080.75
1279.37	1125.25
1278.83	1106
1278.28	1105
1277.74	1142
1277.19	1112.5
1276.65	1096.25
1276.1	1108.75
1275.56	1125.25
1275.01	1149.5
1274.47	1140.75
1273.92	1106.75
1273.38	1104.5
1272.83	1144.25
1272.29	1099
1271.74	1130.75
1271.2	1129
1270.65	1144.5
1270.11	1133.5
1269.56	1121
1269.01	1122.5
1268.47	1173.25
1267.92	1132
1267.38	1147
1266.83	1132.75
1266.29	1181
1265.74	1154.75
1265.19	1143.5
1264.65	1178.25
1264.1	1173.75
1263.55	1189
1263.01	1150.75
1262.46	1163
1261.92	1185.5
1261.37	1209.75
1260.82	1205.5
1260.28	1184.5
1259.73	1203.5
1259.18	1206.5
1258.64	1201.75
1258.09	1201.5
1257.55	1224.5
1257	1228
1256.45	1231.5
1255.9	1213.5
1255.36	1249.5
1254.81	1236.5
1254.26	1202
1253.72	1233.5
1253.17	1260.5
1252.62	1234.5
1252.07	1270.75
1251.53	1221
1250.98	1263
1250.43	1243.75
1249.89	1232.5
1249.34	1305
1248.79	1257.5
1248.24	1282.75
1247.7	1316
1247.15	1285.5
1246.6	1271
1246.05	1278
1245.5	1304.5
1244.96	1282.75
1244.41	1279
1243.86	1325.5
1243.31	1337
1242.77	1327
1242.22	1376.25
1241.67	1395.75
1241.12	1395.5
1240.57	1413
1240.02	1352
1239.48	1444
1238.93	1462
1238.38	1472.25
1237.83	1496
1237.28	1511.5
1236.73	1522.5
1236.18	1545
1235.64	1602.25
1235.09	1675
1234.54	1740
1233.99	1738.25
1233.44	1799.75
1232.89	1737
1232.34	1765
1231.79	1798.25
1231.24	1907.75
1230.69	1855.25
1230.15	1914.25
1229.6	1879.25
1229.05	1914.75
1228.5	1871
1227.95	1895
1227.4	1817.5
1226.85	1821.25
1226.3	1761.5
1225.75	1755.25
1225.2	1693
1224.65	1677
1224.1	1659.5
1223.55	1590.5
1223	1583.75
1222.45	1566.25
1221.9	1494.75
1221.35	1472
1220.8	1484.25
1220.25	1366.75
1219.7	1406.75
1219.15	1359.75
1218.6	1362.25
1218.05	1327.75
1217.5	1319.25
1216.95	1313.5
1216.4	1326.25
1215.85	1292.75
1215.3	1311
1214.75	1306
1214.2	1257.5
1213.65	1248.5
1213.09	1221
1212.54	1206.25
1211.99	1243
1211.44	1268.5
1210.89	1251
1210.34	1186.5
1209.79	1207.75
1209.24	1184.5
1208.69	1198
1208.14	1192.75
1207.58	1181
1207.03	1157
1206.48	1174.5
1205.93	1163.75
1205.38	1156
1204.83	1113.5
1204.27	1143.25
1203.72	1120.5
1203.17	1139.75
1202.62	1095.75
1202.07	1131.75
1201.52	1150.75
1200.96	1145.5
1200.41	1116
1199.86	1135.75
1199.31	1132
1198.76	1094.25
1198.2	1147.5
1197.65	1108.25
1197.1	1138
1196.55	1138.25
1196	1136.75
1195.44	1125
1194.89	1160.5
1194.34	1150.25
1193.78	1157.25
1193.23	1141.5
1192.68	1165.5
1192.13	1168.5
1191.57	1213
1191.02	1129.75
1190.47	1224.25
1189.91	1218.75
1189.36	1245.25
1188.81	1252
1188.26	1267.5
1187.7	1266.5
1187.15	1266.75
1186.6	1300.25
1186.04	1277.25
1185.49	1293.25
1184.94	1278.5
1184.38	1254.5
1183.83	1248.25
1183.28	1283.5
1182.72	1269.5
1182.17	1244.5
1181.61	1287
1181.06	1246.5
1180.51	1215.5
1179.95	1211.75
1179.4	1209.25
1178.85	1145.5
1178.29	1180.5
1177.74	1169.5
1177.18	1177
1176.63	1176.25
1176.07	1145.5
1175.52	1157.5
1174.97	1186.75
1174.41	1193.25
1173.86	1165.25
1173.3	1161
1172.75	1199.5
1172.19	1206.25
1171.64	1191.5
1171.09	1224.75
1170.53	1209.5
1169.97	1217.75
1169.42	1221.25
1168.86	1192
1168.31	1275.75
1167.76	1272.25
1167.2	1305.75
1166.65	1391
1166.09	1414
1165.53	1410.25
1164.98	1523.5
1164.42	1582.25
1163.87	1706.75
1163.31	1731.25
1162.76	1794.5
1162.2	1981
1161.65	1996.5
1161.09	2111.25
1160.54	2234.5
1159.98	2292.5
1159.42	2347.5
1158.87	2343.25
1158.31	2407.25
1157.76	2406
1157.2	2270
1156.65	2266.75
1156.09	2126.75
1155.53	2080
1154.98	1948
1154.42	1878.5
1153.86	1734.25
1153.31	1672
1152.75	1589
1152.19	1557.5
1151.64	1507.25
1151.08	1407
1150.52	1397.5
1149.97	1361.25
1149.41	1312.25
1148.86	1319
1148.3	1311.25
1147.74	1281.75
1147.18	1282
1146.63	1239.75
1146.07	1234.25
1145.51	1214
1144.96	1219
1144.4	1227
1143.84	1208.75
1143.28	1145.5
1142.73	1208
1142.17	1166.5
1141.61	1172
1141.06	1161
1140.5	1138.5
1139.94	1170.5
1139.38	1139
1138.83	1125.5
1138.27	1068.5
1137.71	1132
1137.15	1123.25
1136.59	1096
1136.04	1063.75
1135.48	1107.25
1134.92	1097.75
1134.36	1082.5
1133.8	1109.75
1133.25	1120
1132.69	1105.25
1132.13	1118.5
1131.57	1121.25
1131.01	1097
1130.45	1105.5
1129.9	1080
1129.34	1094
1128.78	1089.25
1128.22	1101.5
1127.66	1101.5
1127.1	1119
1126.54	1107.75
1125.98	1119.5
1125.43	1102.5
1124.87	1107
1124.31	1138.75
1123.75	1170
1123.19	1124.5
1122.63	1126.75
1122.07	1102.75
1121.51	1144.5
1120.95	1135
1120.39	1185
1119.83	1159.5
1119.27	1171.75
1118.72	1182.75
1118.15	1213
1117.6	1215
1117.04	1253
1116.48	1286.75
1115.92	1276.5
1115.36	1270
1114.8	1300.75
1114.24	1329
1113.68	1377.75
1113.12	1325
1112.56	1328.5
1112	1329
1111.44	1356.5
1110.88	1377
1110.32	1338.5
1109.76	1302
1109.19	1301.25
1108.64	1240.25
1108.07	1233.25
1107.51	1219.5
1106.95	1196.25
1106.39	1173.75
1105.83	1196.5
1105.27	1167
1104.71	1183.75
1104.15	1125
1103.59	1162.5
1103.03	1146.25
1102.47	1106
1101.91	1120.5
1101.34	1099.75
1100.78	1137
1100.22	1114
1099.66	1130.5
1099.1	1096
1098.54	1097
1097.98	1116.75
1097.41	1076.5
1096.85	1069.75
1096.29	1088.75
1095.73	1071.5
1095.17	1067
1094.61	1067.5
1094.04	1125.75
1093.48	1067
1092.92	1089.25
1092.36	1072.25
1091.8	1066.25
1091.23	1081.5
1090.67	1133.75
1090.11	1120
1089.55	1108.5
1088.99	1100
1088.42	1114.5
1087.86	1115
1087.3	1093.5
1086.74	1147
1086.17	1174.75
1085.61	1176.5
1085.05	1164
1084.49	1209.5
1083.92	1232.5
1083.36	1294
1082.8	1286.25
1082.23	1284.5
1081.67	1303.5
1081.11	1321.25
1080.55	1339.5
1079.98	1303.5
1079.42	1287.75
1078.86	1241
1078.29	1214
1077.73	1215.75
1077.17	1186
1076.6	1199.75
1076.04	1153
1075.48	1146
1074.91	1125.5
1074.35	1102
1073.79	1099.75
1073.22	1144.5
1072.66	1100
1072.09	1110
1071.53	1115.5
1070.97	1158
1070.4	1147.75
1069.84	1098.25
1069.27	1078.75
1068.71	1098.75
1068.15	1106.5
1067.58	1094.75
1067.02	1104.5
1066.45	1072
1065.89	1114.25
1065.32	1100.25
1064.76	1050
1064.19	1078.75
1063.63	1098.5
1063.07	1088.75
1062.5	1096
1061.94	1039.5
1061.37	1086
1060.81	1064
1060.24	1075
1059.68	1077.75
1059.11	1051.25
1058.55	1056
1057.98	1021.5
1057.42	1047.5
1056.85	1064.75
1056.29	1041.25
1055.72	1059.75
1055.16	1008
1054.59	1066.75
1054.03	1075.5
1053.46	1050.5
1052.89	1098
1052.33	1047
1051.76	1029
1051.2	1053.75
1050.63	1038.25
1050.06	1081
1049.5	1016.75
1048.93	1032.75
1048.37	1043.5
1047.8	1052.75
1047.24	1015.5
1046.67	1058.25
1046.1	1061.25
1045.54	1038
1044.97	1053.75
1044.4	1088
1043.84	1021.5
1043.27	1108.25
1042.7	1015.25
1042.14	1010.5
1041.57	1044.25
1041.01	1037.5
1040.44	1027.25
1039.87	1007.25
1039.3	1029.5
1038.74	1070
1038.17	1042.25
1037.6	1026.75
1037.04	1006.5
1036.47	1037
1035.9	1012
1035.34	1013
1034.77	1033.25
1034.2	983.5
1033.63	1041
1033.07	1004
1032.5	1019
1031.93	1025
1031.36	1017
1030.8	1015.5
1030.23	967
1029.66	1002
1029.09	1019.5
1028.52	1007.25
1027.96	994.75
1027.39	1016.5
1026.82	1022.75
1026.25	974.75
1025.68	1013.25
1025.12	973.5
1024.55	1006
1023.98	991.5
1023.41	963.25
1022.84	993.75
1022.28	1030
1021.71	1030.25
1021.14	978.5
1020.57	998.75
1020	998.5
1019.43	982.5
1018.86	980.5
1018.3	971.25
1017.73	985.25
1017.16	957
1016.59	945.75
1016.3	968.75