File: Testing/Hickernall_HORIBA/g45-mi2_01.txt
#Acq. time (s)=	75
#Accumulations=	5
#Range=	Off
#Autofocus=	Off
#Macrospot=	Off
#AutoExposure=	Off
#Spike filter=	Multiple accum.
#Delay time (s)=	0
#Binning=	1
#Readout mode=	Signal
#DeNoise=	Off
#ICS correction=	Off
#Dark correction=	Off
#Inst. Process=	Off
#Instrument=	LabRAM HR Evol
#Detector=	Andor CCD
#Objective=	x100 LWD
#Grating=	1800 gr/mm
#ND Filter=	100%
#Laser (nm)=	532
#Spectro (cm-¹)=	1240.02
#Hole=	49.98
#Range=	Visible
#AFM=	Off
#StageXY=	Marzhauser
#StageZ=	Marzhauser
#X (µm)=	-16206.8
#Y (µm)=	-738.5
#Z (µm)=	-343.8
#Project=
#Sample=
#Site=
#Title=	g45-mi2
#Remark=
#Date=	06.05.2022 11:03
#Acquired=	06.05.2022 11:03:26
1454.81	1230.25
1454.28	1209.75
1453.75	1196.5
1453.22	1222.25
1452.69	1191.5
1452.16	1196.5
1451.64	1212.75
1451.11	1190.5
1450.58	1195
1450.05	1199.75
1449.52	1197.25
1448.99	1212.5
1448.46	1201.5
1447.93	1217.5
1447.4	1196.5
1446.88	1212.75
1446.35	1209.5
1445.82	1194.25
1445.29	1152.25
1444.76	1192.5
1444.23	1203.25
1443.7	1218.5
1443.17	1165.25
1442.64	1157
1442.11	1152.75
1441.58	1197.25
1441.05	1193.25
1440.52	1142.5
1439.99	1165.25
1439.46	1169
1438.93	1203
1438.4	1169.5
1437.87	1142.75
1437.34	1184
1436.81	1143.5
1436.28	1186.5
1435.75	1125.5
1435.22	1196.5
1434.69	1185.25
1434.16	1163.5
1433.63	1122
1433.1	1118.25
1432.57	1133.25
1432.04	1166.75
1431.51	1146
1430.98	1133
1430.45	1147.5
1429.92	1142.25
1429.39	1073.75
1428.86	1090.5
1428.33	1100.25
1427.8	1097.5
1427.26	1112.75
1426.73	1137.5
1426.2	1151.75
1425.67	1102
1425.14	1082.5
1424.61	1079.5
1424.08	1103.75
1423.55	1077.75
1423.02	1149.5
1422.49	1138.75
1421.95	1133.25
1421.42	1126.5
1420.89	1109.5
1420.36	1109
1419.83	1111.25
1419.3	1124.5
1418.76	1074.5
1418.23	1126
1417.7	1080
1417.17	1065
1416.64	1103.5
1416.1	1074.5
1415.57	1075.75
1415.04	1098
1414.51	1098
1413.98	1107.25
1413.44	1082.5
1412.91	1124.25
1412.38	1068
1411.85	1103
1411.32	1079.25
1410.78	1134.25
1410.25	1094.75
1409.72	1131.75
1409.18	1121.25
1408.65	1144.75
1408.12	1084.5
1407.59	1104.75
1407.05	1089.5
1406.52	1067
1405.99	1075.5
1405.46	1076.25
1404.92	1095.75
1404.39	1096
1403.86	1096.5
1403.32	1062
1402.79	1087.5
1402.26	1063
1401.72	1057.25
1401.19	1115.5
1400.66	1053
1400.12	1058
1399.59	1065.75
1399.06	1082.75
1398.52	1052.75
1397.99	1097.25
1397.46	1096.5
1396.92	1069.5
1396.39	1076.75
1395.85	1066.75
1395.32	1067
1394.79	1070.25
1394.25	1073.25
1393.72	1072.75
1393.18	1078.25
1392.65	1070.25
1392.12	1069
1391.58	1071.75
1391.05	1077
1390.51	1114.75
1389.98	1126
1389.44	1266.75
1388.91	1382
1388.38	1481.75
1387.84	1502.75
1387.31	1422.25
1386.77	1160.25
1386.24	1116.25
1385.7	1076.25
1385.17	1080.75
1384.63	1081
1384.1	1088.25
1383.56	1050.5
1383.03	1050.25
1382.49	1081
1381.96	1046.75
1381.42	1041.25
1380.89	1081.5
1380.35	1087.25
1379.82	1070.75
1379.28	1048.75
1378.74	1050
1378.21	1068.5
1377.67	1074.75
1377.14	1095
1376.6	1100.75
1376.07	1058.25
1375.53	1100.5
1374.99	1003.5
1374.46	1057.25
1373.92	1062.25
1373.39	1036.5
1372.85	1060
1372.32	1065.5
1371.78	1055.75
1371.24	1070.5
1370.71	1072.25
1370.17	1101.25
1369.63	1016.5
1369.1	1077
1368.56	1081.25
1368.03	1029.75
1367.49	1048.5
1366.95	1050
1366.42	1039
1365.88	1072.5
1365.34	1042.5
1364.81	1084.25
1364.27	1082
1363.73	1026
1363.19	1075.5
1362.66	1069.75
1362.12	1024.25
1361.58	1064.5
1361.05	1030.5
1360.51	1035
1359.97	1072
1359.44	1065.5
1358.9	1040.25
1358.36	1057.25
1357.82	1058.5
1357.29	1039
1356.75	1029.5
1356.21	1036.25
1355.67	1066
1355.14	1067
1354.6	1045.5
1354.06	1038.25
1353.52	1069.5
1352.99	1060.5
1352.45	1058.75
1351.91	1026.25
1351.37	1067.25
1350.83	1000.5
1350.3	1011.5
1349.76	1028
1349.22	1044.25
1348.68	1053
1348.14	1009.5
1347.6	1065.5
1347.06	1062.75
1346.53	1071.25
1345.99	1056.75
1345.45	1015
1344.91	1076.25
1344.37	1020.25
1343.83	1056.5
1343.3	1048.5
1342.76	1065.5
1342.22	1045.25
1341.68	1049.5
1341.14	1060.5
1340.6	1033.5
1340.06	1023
1339.52	1035.25
1338.98	1045
1338.45	1057.5
1337.91	1087.25
1337.37	1013
1336.83	1018.25
1336.29	1049
1335.75	1060.25
1335.21	1055.5
1334.67	1011.25
1334.13	1031.5
1333.59	1034
1333.05	1012.25
1332.51	1026.5
1331.97	1057.5
1331.43	1050.5
1330.89	1021.25
1330.35	1035.25
1329.81	1024.75
1329.27	1060
1328.73	1029.75
1328.19	1004.5
1327.65	1016.25
1327.11	1056.75
1326.57	1011.25
1326.03	1043.75
1325.49	1054
1324.95	1070.75
1324.41	1040.25
1323.87	1021.25
1323.33	1051.5
1322.79	1046.5
1322.25	1017.5
1321.71	1033
1321.16	1042
1320.62	1058
1320.08	1001.75
1319.54	1019.75
1319	1048.75
1318.46	1069.5
1317.92	1047.5
1317.38	1048.5
1316.84	1078.5
1316.29	1054.5
1315.75	1043.5
1315.21	1019.25
1314.67	1091.75
1314.13	1069.5
1313.59	1087.25
1313.05	1071.5
1312.5	1075.5
1311.96	1093.25
1311.42	1118.5
1310.88	1074
1310.34	1088.25
1309.8	1066
1309.25	1100.75
1308.71	1091
1308.17	1068.25
1307.63	1114.5
1307.09	1089
1306.54	1103.75
1306	1110.5
1305.46	1121.25
1304.92	1097.5
1304.38	1098.5
1303.83	1078.25
1303.29	1138
1302.75	1092.75
1302.21	1112.5
1301.66	1125
1301.12	1093.25
1300.58	1110.5
1300.04	1133.75
1299.49	1074
1298.95	1133.75
1298.41	1158.5
1297.86	1146
1297.32	1121.5
1296.78	1114
1296.23	1138
1295.69	1138.5
1295.15	1098.75
1294.6	1157.75
1294.06	1130.5
1293.52	1100
1292.97	1137.75
1292.43	1111.25
1291.89	1117.25
1291.34	1121.75
1290.8	1091
1290.26	1104
1289.71	1154.25
1289.17	1139
1288.63	1098.5
1288.08	1095
1287.54	1142
1286.99	1177
1286.45	1277.25
1285.9	1326
1285.36	1404.25
1284.82	1384.75
1284.27	1179.75
1283.73	1110.25
1283.19	1121.25
1282.64	1109.75
1282.1	1062.5
1281.55	1119.75
1281.01	1107.5
1280.46	1120.75
1279.92	1063
1279.37	1096.25
1278.83	1085.75
1278.28	1116.75
1277.74	1114.5
1277.19	1123.25
1276.65	1094.5
1276.1	1063
1275.56	1102.5
1275.01	1089.75
1274.47	1093.25
1273.92	1113.25
1273.38	1078
1272.83	1095.5
1272.29	1108.5
1271.74	1083.25
1271.2	1103
1270.65	1067.5
1270.11	1089.25
1269.56	1094
1269.01	1121.5
1268.47	1091
1267.92	1102.25
1267.38	1119
1266.83	1104
1266.29	1121.75
1265.74	1158.25
1265.19	1114
1264.65	1168.25
1264.1	1105.75
1263.55	1099.5
1263.01	1144.25
1262.46	1139.75
1261.92	1151.75
1261.37	1161
1260.82	1134.75
1260.28	1156
1259.73	1154.75
1259.18	1183.25
1258.64	1197.25
1258.09	1214.25
1257.55	1195.5
1257	1202
1256.45	1190
1255.9	1197.75
1255.36	1163.5
1254.81	1235
1254.26	1204.5
1253.72	1194.25
1253.17	1230.5
1252.62	1250.25
1252.07	1233.25
1251.53	1241.5
1250.98	1216.25
1250.43	1191.5
1249.89	1229.25
1249.34	1210.25
1248.79	1240.25
1248.24	1297.75
1247.7	1279.25
1247.15	1239
1246.6	1239
1246.05	1252
1245.5	1327.5
1244.96	1268
1244.41	1294
1243.86	1295
1243.31	1338.25
1242.77	1294
1242.22	1348.75
1241.67	1367.25
1241.12	1376.75
1240.57	1383.25
1240.02	1398
1239.48	1388.25
1238.93	1462.5
1238.38	1479.25
1237.83	1501
1237.28	1513.75
1236.73	1585.75
1236.18	1572
1235.64	1582
1235.09	1611.75
1234.54	1693
1233.99	1709.75
1233.44	1783.75
1232.89	1791.5
1232.34	1847.75
1231.79	1853
1231.24	1868.5
1230.69	1910
1230.15	1933
1229.6	1908.25
1229.05	1889.5
1228.5	1981
1227.95	1936.75
1227.4	1833.75
1226.85	1865.75
1226.3	1819.75
1225.75	1755.5
1225.2	1714.75
1224.65	1691
1224.1	1647.5
1223.55	1623.75
1223	1569
1222.45	1484.25
1221.9	1481.5
1221.35	1482.75
1220.8	1476.75
1220.25	1418
1219.7	1410.75
1219.15	1400.5
1218.6	1406.75
1218.05	1349.75
1217.5	1287.75
1216.95	1302
1216.4	1308.5
1215.85	1255.25
1215.3	1278.75
1214.75	1253.75
1214.2	1219.25
1213.65	1211.75
1213.09	1236.5
1212.54	1193.75
1211.99	1156.25
1211.44	1201.25
1210.89	1179
1210.34	1183.25
1209.79	1178.25
1209.24	1175.75
1208.69	1138.75
1208.14	1130
1207.58	1143.25
1207.03	1111
1206.48	1129.5
1205.93	1122.5
1205.38	1102
1204.83	1125.25
1204.27	1109.5
1203.72	1108.25
1203.17	1132
1202.62	1116.5
1202.07	1096.5
1201.52	1116
1200.96	1081.75
1200.41	1133.5
1199.86	1102.5
1199.31	1131.25
1198.76	1077.5
1198.2	1112.25
1197.65	1151.75
1197.1	1120.25
1196.55	1075.5
1196	1112
1195.44	1109.75
1194.89	1083
1194.34	1117.5
1193.78	1125.5
1193.23	1148.75
1192.68	1162
1192.13	1157.75
1191.57	1151.75
1191.02	1154.5
1190.47	1203.75
1189.91	1133.5
1189.36	1180.25
1188.81	1238
1188.26	1259.5
1187.7	1203.25
1187.15	1235
1186.6	1224
1186.04	1289
1185.49	1221.25
1184.94	1288.75
1184.38	1272.5
1183.83	1307.75
1183.28	1203.75
1182.72	1242.25
1182.17	1272.25
1181.61	1230.25
1181.06	1217
1180.51	1204.5
1179.95	1171
1179.4	1164.5
1178.85	1165.25
1178.29	1136.75
1177.74	1157.75
1177.18	1157.75
1176.63	1170.5
1176.07	1170
1175.52	1119.25
1174.97	1167.5
1174.41	1169
1173.86	1151
1173.3	1143.5
1172.75	1137.75
1172.19	1114.75
1171.64	1185
1171.09	1157.75
1170.53	1162.75
1169.97	1203.25
1169.42	1209.5
1168.86	1258.25
1168.31	1259.5
1167.76	1297
1167.2	1301
1166.65	1361
1166.09	1393.75
1165.53	1424
1164.98	1499.5
1164.42	1573.5
1163.87	1674.5
1163.31	1730.75
1162.76	1870.25
1162.2	1946
1161.65	2022.5
1161.09	2227.75
1160.54	2190
1159.98	2425
1159.42	2441.5
1158.87	2462.75
1158.31	2450
1157.76	2451
1157.2	2409.25
1156.65	2278.5
1156.09	2205
1155.53	2049.75
1154.98	1980.25
1154.42	1825.25
1153.86	1790
1153.31	1683.5
1152.75	1637.5
1152.19	1497.75
1151.64	1506.75
1151.08	1480.25
1150.52	1404
1149.97	1341.75
1149.41	1319
1148.86	1297
1148.3	1283.75
1147.74	1293
1147.18	1249
1146.63	1234.25
1146.07	1216.75
1145.51	1216.75
1144.96	1204.25
1144.4	1162.5
1143.84	1142
1143.28	1169.25
1142.73	1147.25
1142.17	1127
1141.61	1149.75
1141.06	1135.5
1140.5	1150.75
1139.94	1151.75
1139.38	1138.25
1138.83	1078.75
1138.27	1101.75
1137.71	1125.25
1137.15	1115.5
1136.59	1088
1136.04	1095.5
1135.48	1077.5
1134.92	1109.5
1134.36	1126.5
1133.8	1082.25
1133.25	1079.25
1132.69	1040
1132.13	1056.5
1131.57	1024.75
1131.01	1072
1130.45	1097.75
1129.9	1056.5
1129.34	1054.25
1128.78	1087.75
1128.22	1087.25
1127.66	1055.75
1127.1	1088.5
1126.54	1064.5
1125.98	1059.5
1125.43	1068
1124.87	1037.75
1124.31	1072.5
1123.75	1077.25
1123.19	1097.75
1122.63	1119.75
1122.07	1078.5
1121.51	1090
1120.95	1135.75
1120.39	1132.5
1119.83	1133
1119.27	1167.25
1118.72	1116.75
1118.15	1182
1117.6	1203.5
1117.04	1188.25
1116.48	1265.5
1115.92	1266.5
1115.36	1240.25
1114.8	1292.25
1114.24	1335.25
1113.68	1334
1113.12	1353.75
1112.56	1301.75
1112	1377.5
1111.44	1315.25
1110.88	1306.5
1110.32	1320.25
1109.76	1259
1109.19	1260.25
1108.64	1254
1108.07	1236.5
1107.51	1202.25
1106.95	1181.5
1106.39	1187.25
1105.83	1173
1105.27	1173
1104.71	1178
1104.15	1100.75
1103.59	1147.25
1103.03	1108.5
1102.47	1087.75
1101.91	1086.5
1101.34	1088.25
1100.78	1111.25
1100.22	1046
1099.66	1071.25
1099.1	1056
1098.54	1064.5
1097.98	1058.5
1097.41	1081.5
1096.85	1050.25
1096.29	1067.75
1095.73	1080.25
1095.17	1045.25
1094.61	1071.5
1094.04	1085
1093.48	1061.5
1092.92	1059.5
1092.36	1035
1091.8	1055.75
1091.23	1058.25
1090.67	1057.75
1090.11	1070.25
1089.55	1093.5
1088.99	1088.25
1088.42	1109.75
1087.86	1102.75
1087.3	1103.75
1086.74	1143.5
1086.17	1150.25
1085.61	1187
1085.05	1174.5
1084.49	1195
1083.92	1217.5
1083.36	1293
1082.8	1308.75
1082.23	1316
1081.67	1364.75
1081.11	1310.75
1080.55	1299
1079.98	1250.25
1079.42	1261.5
1078.86	1211.5
1078.29	1207
1077.73	1176
1077.17	1190.75
1076.6	1153.75
1076.04	1098
1075.48	1118.5
1074.91	1155.5
1074.35	1100.25
1073.79	1092
1073.22	1104.5
1072.66	1122.5
1072.09	1107.5
1071.53	1127.5
1070.97	1087.5
1070.4	1068.25
1069.84	1085.25
1069.27	1042.5
1068.71	1079.75
1068.15	1100.25
1067.58	1086.5
1067.02	1061.5
1066.45	1085
1065.89	1110.25
1065.32	1123
1064.76	1084.5
1064.19	1088.5
1063.63	1056.5
1063.07	1063
1062.5	1053
1061.94	1050.25
1061.37	1044.25
1060.81	1067.25
1060.24	1027.25
1059.68	1043.25
1059.11	1054.5
1058.55	1032
1057.98	1024.5
1057.42	1035.5
1056.85	1015.25
1056.29	985.75
1055.72	1043.25
1055.16	1041
1054.59	1028.75
1054.03	1028.75
1053.46	1054
1052.89	1020.5
1052.33	1014.5
1051.76	1030.5
1051.2	1026.75
1050.63	995.75
1050.06	1029.25
1049.5	1010.5
1048.93	1009.5
1048.37	1043.5
1047.8	1008
1047.24	1028.5
1046.67	1038.5
1046.1	1008
1045.54	1037.5
1044.97	1031
1044.4	1002
1043.84	1016.25
1043.27	1041.5
1042.7	1021.5
1042.14	1014
1041.57	1041.25
1041.01	1015.5
1040.44	987.25
1039.87	1033
1039.3	1013.5
1038.74	1039
1038.17	977.5
1037.6	982.75
1037.04	992
1036.47	1029.5
1035.9	1005.75
1035.34	955.5
1034.77	979.25
1034.2	980
1033.63	945.5
1033.07	967
1032.5	977.25
1031.93	1000.25
1031.36	1005
1030.8	969
1030.23	978.75
1029.66	983
1029.09	995.25
1028.52	974.75
1027.96	1005.75
1027.39	942.25
1026.82	992.5
1026.25	975.25
1025.68	966.25
1025.12	963.25
1024.55	985.75
1023.98	1005.5
1023.41	955.5
1022.84	947.5
1022.28	952.25
1021.71	944.5
1021.14	944
1020.57	938.5
1020	945.25
1019.43	943
1018.86	929.5
1018.3	972.75
1017.73	957.75
1017.16	968
1016.59	934.5
1016.3	959.5