File: Testing/Hickernall_HORIBA/g47-mi1-bub2_01.txt
#Acq. time (s)=	75
#Accumulations=	5
#Range=	Off
#Autofocus=	Off
#Macrospot=	Off
#AutoExposure=	Off
#Spike filter=	Multiple accum.
#Delay time (s)=	0
#Binning=	1
#Readout mode=	Signal
#DeNoise=	Off
#ICS correction=	Off
#Dark correction=	Off
#Inst. Process=	Off
#Instrument=	LabRAM HR Evol
#Detector=	Andor CCD
#Objective=	x100 LWD
#Grating=	1800 gr/mm
#ND Filter=	100%
#Laser (nm)=	532
#Spectro (cm-¹)=	1240.02
#Hole=	49.98
#Range=	Visible
#AFM=	Off
#StageXY=	Marzhauser
#StageZ=	Marzhauser
#X (µm)=	-16433.5
#Y (µm)=	-893.5
#Z (µm)=	-370.8
#Project=
#Sample=
#Site=
#Title=	g47-mi1-bub2
#Remark=
#Date=	06.05.2022 12:18
#Acquired=	06.05.2022 12:18:36
1454.81	7871.75
1454.28	7795.75
1453.75	7865.25
1453.22	7835
1452.69	7761.75
1452.16	7891
1451.64	7848.5
1451.11	7867.25
1450.58	7675.75
1450.05	7784.75
1449.52	7639.5
1448.99	7847.5
1448.46	7738.25
1447.93	7786.75
1447.4	7738.75
1446.88	7847.25
1446.35	7869.5
1445.82	7622.5
1445.29	7754
1444.76	7719.5
1444.23	7704.5
1443.7	7780.75
1443.17	7777
1442.64	7686.5
1442.11	7840.75
1441.58	7751.5
1441.05	7767.75
1440.52	7696
1439.99	7779.25
1439.46	7709.5
1438.93	7756
1438.4	7634.25
1437.87	7657
1437.34	7751.75
1436.81	7646
1436.28	7717.75
1435.75	7655
1435.22	7662
1434.69	7673
1434.16	7652
1433.63	7534.75
1433.1	7649
1432.57	7510.75
1432.04	7639.25
1431.51	7566.25
1430.98	7545
1430.45	7522
1429.92	7470
1429.39	7491.5
1428.86	7529.25
1428.33	7623.75
1427.8	7524.5
1427.26	7604.5
1426.73	7496
1426.2	7582.25
1425.67	7455.75
1425.14	7444.25
1424.61	7487.5
1424.08	7519.75
1423.55	7499
1423.02	7550.75
1422.49	7412.75
1421.95	7539
1421.42	7474.5
1420.89	7553.75
1420.36	7428.25
1419.83	7387
1419.3	7523.75
1418.76	7354
1418.23	7483.25
1417.7	7422.75
1417.17	7463.25
1416.64	7356.25
1416.1	7472.5
1415.57	7399.25
1415.04	7520.5
1414.51	7365.75
1413.98	7450.5
1413.44	7400.25
1412.91	7442.25
1412.38	7431
1411.85	7457
1411.32	7457.5
1410.78	7376.5
1410.25	7366.25
1409.72	7325
1409.18	7416.25
1408.65	7471.5
1408.12	7403.5
1407.59	7342.25
1407.05	7395
1406.52	7400.5
1405.99	7394.5
1405.46	7303.5
1404.92	7517.5
1404.39	7404.25
1403.86	7445.75
1403.32	7472.75
1402.79	7377
1402.26	7336.25
1401.72	7345.75
1401.19	7434.5
1400.66	7360.75
1400.12	7471
1399.59	7271.75
1399.06	7331
1398.52	7335.5
1397.99	7490
1397.46	7386.25
1396.92	7356
1396.39	7261.25
1395.85	7272.5
1395.32	7250.75
1394.79	7303
1394.25	7207
1393.72	7269
1393.18	7338
1392.65	7214.5
1392.12	7240.75
1391.58	7295.25
1391.05	7372
1390.51	7306.75
1389.98	7341.5
1389.44	7350.5
1388.91	7397
1388.38	7311.75
1387.84	7376.75
1387.31	7408
1386.77	7290
1386.24	7290.75
1385.7	7201
1385.17	7210.25
1384.63	7358
1384.1	7277.25
1383.56	7278
1383.03	7341.5
1382.49	7416.75
1381.96	7334.5
1381.42	7247.25
1380.89	7328
1380.35	7309.5
1379.82	7211.75
1379.28	7239.75
1378.74	7332.25
1378.21	7290.75
1377.67	7254.25
1377.14	7232.25
1376.6	7247
1376.07	7250
1375.53	7295.5
1374.99	7221.25
1374.46	7248
1373.92	7308.25
1373.39	7300.5
1372.85	7203.75
1372.32	7255.25
1371.78	7201.75
1371.24	7276.75
1370.71	7174.5
1370.17	7215
1369.63	7130.75
1369.1	7166.75
1368.56	7174
1368.03	7108.25
1367.49	7252
1366.95	7278.75
1366.42	7236.25
1365.88	7148.75
1365.34	7278.25
1364.81	7056
1364.27	7177.5
1363.73	7148
1363.19	7098.5
1362.66	7092.5
1362.12	7271.75
1361.58	7157.25
1361.05	7177.25
1360.51	7248
1359.97	7247.25
1359.44	7210.5
1358.9	7180
1358.36	7190.75
1357.82	7157.25
1357.29	7125.25
1356.75	7054
1356.21	7228.75
1355.67	7158
1355.14	7064.25
1354.6	7037.75
1354.06	7268
1353.52	7062
1352.99	7084.75
1352.45	7070.25
1351.91	7103.5
1351.37	7113
1350.83	7162.5
1350.3	7164.75
1349.76	7178.25
1349.22	7098.25
1348.68	7750
1348.14	7125.5
1347.6	7036
1347.06	7087
1346.53	7068.75
1345.99	7036.25
1345.45	7000.5
1344.91	7149.25
1344.37	7075.5
1343.83	7006.25
1343.3	7006
1342.76	7109.5
1342.22	7102
1341.68	7049
1341.14	6923.5
1340.6	7091
1340.06	7047.5
1339.52	6997.5
1338.98	6943.25
1338.45	7057.75
1337.91	7050
1337.37	6963.25
1336.83	6895.75
1336.29	7083.25
1335.75	6981.25
1335.21	7055.5
1334.67	6858
1334.13	6993.25
1333.59	7006.5
1333.05	6995.25
1332.51	7060.5
1331.97	7007.25
1331.43	7088.25
1330.89	6831.5
1330.35	6994
1329.81	6953.25
1329.27	6981.25
1328.73	6819
1328.19	6989.75
1327.65	6924.5
1327.11	6888.75
1326.57	6847
1326.03	6974.75
1325.49	6937
1324.95	6957.75
1324.41	6929.75
1323.87	6942.25
1323.33	6849.5
1322.79	6882.75
1322.25	6896.75
1321.71	6813.75
1321.16	6931
1320.62	6886.75
1320.08	6911.5
1319.54	6937.5
1319	6869.75
1318.46	6840.25
1317.92	6934.5
1317.38	6948
1316.84	7020.5
1316.29	6911
1315.75	7010.25
1315.21	6982
1314.67	7054.75
1314.13	6924.75
1313.59	7028.75
1313.05	6993.5
1312.5	6998.5
1311.96	7010.25
1311.42	7039
1310.88	6923.75
1310.34	7019.75
1309.8	7044.5
1309.25	6916.5
1308.71	6999.25
1308.17	6903.75
1307.63	7047.25
1307.09	6949.25
1306.54	6986
1306	7044.25
1305.46	7054.5
1304.92	7018
1304.38	7100
1303.83	7023.75
1303.29	7113.75
1302.75	7003.5
1302.21	7143.5
1301.66	6855.75
1301.12	7028
1300.58	7024.5
1300.04	7090.5
1299.49	6963.5
1298.95	6974.25
1298.41	7045
1297.86	7096.25
1297.32	7003
1296.78	7027.75
1296.23	7016.25
1295.69	7090.75
1295.15	7050.5
1294.6	7019
1294.06	7065
1293.52	6967
1292.97	7010.75
1292.43	6890.25
1291.89	7050
1291.34	6823.25
1290.8	7043.75
1290.26	6858.75
1289.71	7018.25
1289.17	6881
1288.63	6943.75
1288.08	6934
1287.54	7010.75
1286.99	6864.25
1286.45	6952.5
1285.9	6857.25
1285.36	6924
1284.82	6877.5
1284.27	6907.75
1283.73	6960.5
1283.19	6825
1282.64	6858.5
1282.1	6840.75
1281.55	6889.75
1281.01	6829.5
1280.46	6924.75
1279.92	6840.75
1279.37	6815.25
1278.83	6848
1278.28	6912.25
1277.74	6767.75
1277.19	6869.25
1276.65	6812.75
1276.1	6801
1275.56	6760.5
1275.01	6827.5
1274.47	6776
1273.92	6931.75
1273.38	6757
1272.83	6790.75
1272.29	6815.5
1271.74	6906.5
1271.2	6743
1270.65	6814.5
1270.11	6843
1269.56	6793.25
1269.01	6824.25
1268.47	6757.25
1267.92	6849.25
1267.38	6855.5
1266.83	6836
1266.29	6812.5
1265.74	6890.75
1265.19	6857
1264.65	6820.25
1264.1	6743
1263.55	6856
1263.01	6887.75
1262.46	6896
1261.92	6910.25
1261.37	6952.75
1260.82	6882.5
1260.28	6857.5
1259.73	6861
1259.18	6982.25
1258.64	6873
1258.09	6961.5
1257.55	6934.75
1257	6870.5
1256.45	6953.25
1255.9	6863.5
1255.36	6911
1254.81	7019.5
1254.26	6992.75
1253.72	6994.75
1253.17	7039.5
1252.62	7093.5
1252.07	7000.5
1251.53	6970.5
1250.98	7074
1250.43	7001
1249.89	7098
1249.34	6953.75
1248.79	7051.75
1248.24	7090.75
1247.7	7006
1247.15	6903.75
1246.6	7044.5
1246.05	6902
1245.5	7031
1244.96	6964.25
1244.41	7014
1243.86	6957
1243.31	6972.25
1242.77	7009.25
1242.22	7067.75
1241.67	7064
1241.12	7073.25
1240.57	6982.5
1240.02	7105.5
1239.48	7040.75
1238.93	7090
1238.38	7010.5
1237.83	7195.25
1237.28	7176.75
1236.73	7168
1236.18	7264.5
1235.64	7179
1235.09	7173.25
1234.54	7282
1233.99	7129.5
1233.44	7258.5
1232.89	7323.5
1232.34	7254.25
1231.79	7239.75
1231.24	7280.25
1230.69	7359.75
1230.15	7291
1229.6	7234
1229.05	7126.75
1228.5	7222.25
1227.95	7235.75
1227.4	7203.75
1226.85	7267.5
1226.3	7180.25
1225.75	7117.75
1225.2	7086.5
1224.65	7190.25
1224.1	7247
1223.55	6991.5
1223	7124.5
1222.45	7019.25
1221.9	7091.75
1221.35	6970.5
1220.8	7101
1220.25	7067
1219.7	7117
1219.15	6958.25
1218.6	6906
1218.05	6950.5
1217.5	6898.5
1216.95	6851.5
1216.4	7041.5
1215.85	6875
1215.3	6964.5
1214.75	6888.75
1214.2	6846.25
1213.65	6895.25
1213.09	6850.75
1212.54	6828
1211.99	6737.5
1211.44	6838.75
1210.89	6818.75
1210.34	6727.25
1209.79	6787.25
1209.24	6725.75
1208.69	6705
1208.14	6688.25
1207.58	6707.25
1207.03	6631.75
1206.48	6776.5
1205.93	6749
1205.38	6658.25
1204.83	6765.75
1204.27	6634.75
1203.72	6600.75
1203.17	6585.5
1202.62	6702.75
1202.07	6625
1201.52	6651.5
1200.96	6629
1200.41	6606
1199.86	6649.5
1199.31	6775.75
1198.76	6592.75
1198.2	6606
1197.65	6617.5
1197.1	6568
1196.55	6607
1196	6631.75
1195.44	6630.5
1194.89	6664.25
1194.34	6580
1193.78	6657
1193.23	6683.75
1192.68	6834.75
1192.13	6713.75
1191.57	6751.25
1191.02	6802
1190.47	6836.25
1189.91	6768.75
1189.36	6918.5
1188.81	6929
1188.26	6941.25
1187.7	7001
1187.15	7025
1186.6	6907
1186.04	7061
1185.49	6994.75
1184.94	7036.25
1184.38	7058.25
1183.83	7058.25
1183.28	6884
1182.72	7011.5
1182.17	6907
1181.61	6898
1181.06	6826.5
1180.51	6840
1179.95	6835.75
1179.4	6847
1178.85	6796.75
1178.29	6695.5
1177.74	6828.25
1177.18	6755
1176.63	6650
1176.07	6625.75
1175.52	6727.25
1174.97	6686.75
1174.41	6714.25
1173.86	6638.75
1173.3	6807.75
1172.75	6598.75
1172.19	6756.5
1171.64	6694
1171.09	6825.75
1170.53	6837.75
1169.97	6796.5
1169.42	6820.5
1168.86	6913.5
1168.31	6896.25
1167.76	6918
1167.2	6950.25
1166.65	7161.75
1166.09	7167.25
1165.53	7251.5
1164.98	7308
1164.42	7626.75
1163.87	7653.75
1163.31	7924.5
1162.76	8114.5
1162.2	8381.75
1161.65	8471.25
1161.09	8572
1160.54	8820.5
1159.98	8752.25
1159.42	8601.25
1158.87	8403
1158.31	8421.5
1157.76	8281.75
1157.2	8021.75
1156.65	7855
1156.09	7740.25
1155.53	7600.25
1154.98	7430
1154.42	7313
1153.86	7172.5
1153.31	7137.75
1152.75	7079
1152.19	6893
1151.64	7009.25
1151.08	6978.5
1150.52	6842
1149.97	6771
1149.41	6837.75
1148.86	6736.5
1148.3	6702
1147.74	6677.75
1147.18	6657.75
1146.63	6561.25
1146.07	6667.75
1145.51	6614.75
1144.96	6673.75
1144.4	6715.25
1143.84	6543.25
1143.28	6442.5
1142.73	6627.75
1142.17	6423.25
1141.61	6479.75
1141.06	6502.25
1140.5	6562
1139.94	6527
1139.38	6416.5
1138.83	6447.25
1138.27	6562
1137.71	6464.25
1137.15	6515.25
1136.59	6346.5
1136.04	6499.25
1135.48	6460
1134.92	6456.5
1134.36	6450.25
1133.8	6411.5
1133.25	6438.5
1132.69	6372.5
1132.13	6426.5
1131.57	6518.5
1131.01	6439
1130.45	6415.5
1129.9	6395
1129.34	6487.75
1128.78	6330
1128.22	6371
1127.66	6476.5
1127.1	6406.25
1126.54	6436.5
1125.98	6424.25
1125.43	6474
1124.87	6522
1124.31	6393
1123.75	6453.5
1123.19	6421.75
1122.63	6604.75
1122.07	6441.25
1121.51	6488.5
1120.95	6414.5
1120.39	6528.25
1119.83	6471.25
1119.27	6508
1118.72	6624
1118.15	6658.75
1117.6	6633.25
1117.04	6788.5
1116.48	6711
1115.92	6817.5
1115.36	6758.5
1114.8	6880.25
1114.24	6836
1113.68	6895
1113.12	6899
1112.56	6917.25
1112	6958.5
1111.44	6900
1110.88	6913
1110.32	6864.25
1109.76	6777.5
1109.19	6790.75
1108.64	6638.5
1108.07	6637
1107.51	6592
1106.95	6637.25
1106.39	6441.25
1105.83	6475.25
1105.27	6382.25
1104.71	6396.25
1104.15	6373.5
1103.59	6420.75
1103.03	6430.75
1102.47	6401.75
1101.91	6262.5
1101.34	6211.75
1100.78	6189.75
1100.22	6174.25
1099.66	6218.5
1099.1	6189
1098.54	6209.5
1097.98	6166.75
1097.41	6136.25
1096.85	6200.75
1096.29	6230.5
1095.73	6194.75
1095.17	6165.25
1094.61	6198.75
1094.04	6287
1093.48	6211.75
1092.92	6162
1092.36	6131
1091.8	6149.75
1091.23	6097
1090.67	6185.25
1090.11	6165
1089.55	6184.5
1088.99	6204.25
1088.42	6209.5
1087.86	6239
1087.3	6263
1086.74	6123.25
1086.17	6236.5
1085.61	6262
1085.05	6264.25
1084.49	6308.75
1083.92	6267.25
1083.36	6304.75
1082.8	6331.25
1082.23	6392.25
1081.67	6456.25
1081.11	6341.5
1080.55	6326.75
1079.98	6227.25
1079.42	6361.75
1078.86	6261.5
1078.29	6198.25
1077.73	6050.75
1077.17	6252.25
1076.6	6192.75
1076.04	6257
1075.48	6116.5
1074.91	6240.75
1074.35	6178.75
1073.79	6178.5
1073.22	6125.5
1072.66	6185.25
1072.09	6170
1071.53	6223.5
1070.97	6265.25
1070.4	6340
1069.84	6221.5
1069.27	6277.25
1068.71	6234
1068.15	6377.75
1067.58	6333.5
1067.02	6315
1066.45	6418.5
1065.89	6598.5
1065.32	6397.75
1064.76	6351
1064.19	6346.25
1063.63	6339.75
1063.07	6304.25
1062.5	6325.25
1061.94	6265.5
1061.37	6320
1060.81	6212.75
1060.24	6097.5
1059.68	6022.75
1059.11	6159.75
1058.55	6060.75
1057.98	6107.5
1057.42	6027.5
1056.85	6023
1056.29	5963.5
1055.72	5957.25
1055.16	5956
1054.59	5986.25
1054.03	5934
1053.46	6026.5
1052.89	5991.5
1052.33	6001.25
1051.76	5949
1051.2	6002.25
1050.63	5911.75
1050.06	5947.75
1049.5	5942
1048.93	6004.75
1048.37	6037
1047.8	5992.25
1047.24	5985.75
1046.67	5935.75
1046.1	6012.75
1045.54	5921.5
1044.97	5942.25
1044.4	5957.75
1043.84	5845.5
1043.27	5968.25
1042.7	5812
1042.14	6010.5
1041.57	5972.5
1041.01	5941.5
1040.44	5977.5
1039.87	5868.75
1039.3	5873.5
1038.74	5899
1038.17	5809.5
1037.6	5823.5
1037.04	5804.75
1036.47	5923.25
1035.9	5851.25
1035.34	5876.75
1034.77	5838.75
1034.2	5769.25
1033.63	5892
1033.07	5849.25
1032.5	5730.75
1031.93	5783.25
1031.36	5863
1030.8	5824.25
1030.23	5754
1029.66	5750.25
1029.09	5827.25
1028.52	5739.75
1027.96	5765.5
1027.39	5812.25
1026.82	5864.5
1026.25	5779
1025.68	5725.25
1025.12	5781.75
1024.55	5806
1023.98	5726.25
1023.41	5781
1022.84	5753.75
1022.28	5743.75
1021.71	5712.5
1021.14	5704.5
1020.57	5746
1020	5752
1019.43	5673.5
1018.86	5763.25
1018.3	5728.5
1017.73	5681
1017.16	5786.75
1016.59	5679.25
1016.3	5727.75