File: Testing/Hickernall_HORIBA/g47-mi1-bub1_01.txt
#Acq. time (s)=	75
#Accumulations=	5
#Range=	Off
#Autofocus=	Off
#Macrospot=	Off
#AutoExposure=	Off
#Spike filter=	Multiple accum.
#Delay time (s)=	0
#Binning=	1
#Readout mode=	Signal
#DeNoise=	Off
#ICS correction=	Off
#Dark correction=	Off
#Inst. Process=	Off
#Instrument=	LabRAM HR Evol
#Detector=	Andor CCD
#Objective=	x100 LWD
#Grating=	1800 gr/mm
#ND Filter=	100%
#Laser (nm)=	532
#Spectro (cm-¹)=	1240.02
#Hole=	49.98
#Range=	Visible
#AFM=	Off
#StageXY=	Marzhauser
#StageZ=	Marzhauser
#X (µm)=	-16419.1
#Y (µm)=	-903.6
#Z (µm)=	-369.3
#Project=
#Sample=
#Site=
#Title=	g47-mi1-bub1
#Remark=
#Date=	06.05.2022 11:44
#Acquired=	06.05.2022 11:44:05
1454.81	1820
1454.28	1787.5
1453.75	1790.75
1453.22	1866.5
1452.69	1772
1452.16	1785.5
1451.64	1817
1451.11	1841.25
1450.58	1798.75
1450.05	1801.75
1449.52	1811.75
1448.99	1783
1448.46	1784
1447.93	1738.25
1447.4	1786.5
1446.88	1782.25
1446.35	1807.25
1445.82	1770.75
1445.29	1799.25
1444.76	1766.5
1444.23	1764.25
1443.7	1733
1443.17	1792.25
1442.64	1755
1442.11	1765.25
1441.58	1770.5
1441.05	1801
1440.52	1747.25
1439.99	1774.25
1439.46	1763
1438.93	1750.5
1438.4	1749.5
1437.87	1722.25
1437.34	1742
1436.81	1761.5
1436.28	1720.5
1435.75	1743
1435.22	1751.25
1434.69	1699
1434.16	1736
1433.63	1663
1433.1	1725.5
1432.57	1728.5
1432.04	1681
1431.51	1696
1430.98	1723
1430.45	1736.75
1429.92	1685.25
1429.39	1667
1428.86	1688.5
1428.33	1704.5
1427.8	1663.75
1427.26	1691.75
1426.73	1711.75
1426.2	1717.5
1425.67	1677
1425.14	1641.75
1424.61	1700.5
1424.08	1703
1423.55	1707.5
1423.02	1647.25
1422.49	1657.25
1421.95	1664.75
1421.42	1717
1420.89	1669
1420.36	1688
1419.83	1677.5
1419.3	1653.75
1418.76	1646.75
1418.23	1683.75
1417.7	1673.25
1417.17	1688
1416.64	1623
1416.1	1649.75
1415.57	1634
1415.04	1641.25
1414.51	1674
1413.98	1683
1413.44	1656
1412.91	1679.25
1412.38	1630.75
1411.85	1657.75
1411.32	1682.75
1410.78	1756.5
1410.25	1734
1409.72	1746.5
1409.18	1783.75
1408.65	1755.25
1408.12	1684
1407.59	1640.25
1407.05	1664.75
1406.52	1638.5
1405.99	1650
1405.46	1573.25
1404.92	1644.75
1404.39	1658
1403.86	1680.5
1403.32	1705.75
1402.79	1685.5
1402.26	1628
1401.72	1685.75
1401.19	1613.25
1400.66	1632.75
1400.12	1666
1399.59	1649
1399.06	1607.75
1398.52	1622.25
1397.99	1616.5
1397.46	1619.75
1396.92	1659.25
1396.39	1626.5
1395.85	1655.75
1395.32	1672
1394.79	1616.75
1394.25	1664.5
1393.72	1655.75
1393.18	1654
1392.65	1641
1392.12	1623
1391.58	1654.75
1391.05	1633.75
1390.51	1737.25
1389.98	1903
1389.44	2213
1388.91	2533
1388.38	2927
1387.84	3115
1387.31	2651
1386.77	1973.25
1386.24	1718.75
1385.7	1709
1385.17	1664.75
1384.63	1643.5
1384.1	1620
1383.56	1632.75
1383.03	1623.25
1382.49	1711.75
1381.96	1666
1381.42	1672
1380.89	1665.75
1380.35	1643.25
1379.82	1654.5
1379.28	1643.25
1378.74	1640
1378.21	1629.5
1377.67	1707.25
1377.14	1638.5
1376.6	1649
1376.07	1618.25
1375.53	1651.5
1374.99	1612.5
1374.46	1626.5
1373.92	1664
1373.39	1650.5
1372.85	1724.25
1372.32	1646
1371.78	1648.5
1371.24	1615
1370.71	1658.75
1370.17	1653.5
1369.63	1607.75
1369.1	1658.25
1368.56	1666.5
1368.03	1581.75
1367.49	1666
1366.95	1655
1366.42	1623.5
1365.88	1637.5
1365.34	1623.5
1364.81	1609.75
1364.27	1622.75
1363.73	1639.5
1363.19	1628.5
1362.66	1669.75
1362.12	1666.25
1361.58	1609.5
1361.05	1653.5
1360.51	1625
1359.97	1628.5
1359.44	1636.5
1358.9	1614.75
1358.36	1633.75
1357.82	1607
1357.29	1574.75
1356.75	1593.25
1356.21	1576.75
1355.67	1631
1355.14	1583.75
1354.6	1565.5
1354.06	1607
1353.52	1645.75
1352.99	1637.5
1352.45	1597.5
1351.91	1630.5
1351.37	1591
1350.83	1617.25
1350.3	1546
1349.76	1604.25
1349.22	1624.5
1348.68	1602
1348.14	1610.25
1347.6	1586.5
1347.06	1609.25
1346.53	1607
1345.99	1619.75
1345.45	1564
1344.91	1612.5
1344.37	1622
1343.83	1634.75
1343.3	1589.5
1342.76	1656.5
1342.22	1590.5
1341.68	1589
1341.14	1551
1340.6	1600.25
1340.06	1611.5
1339.52	1584.25
1338.98	1586.5
1338.45	1618.5
1337.91	1590.5
1337.37	1589.25
1336.83	1608.75
1336.29	1575.25
1335.75	1599.5
1335.21	1579
1334.67	1600.5
1334.13	1636.5
1333.59	1587.75
1333.05	1545.5
1332.51	1607.75
1331.97	1611
1331.43	1617.75
1330.89	1582.25
1330.35	1583
1329.81	1616.75
1329.27	1587.5
1328.73	1600
1328.19	1579.25
1327.65	1542.5
1327.11	1579.25
1326.57	1546.25
1326.03	1597.25
1325.49	1614.25
1324.95	1582.75
1324.41	1580
1323.87	1592.75
1323.33	1548.5
1322.79	1621
1322.25	1603.25
1321.71	1644
1321.16	1577.5
1320.62	1600.75
1320.08	1603.75
1319.54	1589.5
1319	1592.5
1318.46	1682.75
1317.92	1618.5
1317.38	1584.75
1316.84	1644.75
1316.29	1643.25
1315.75	1668
1315.21	1586.25
1314.67	1639
1314.13	1646.5
1313.59	1659
1313.05	1653.25
1312.5	1659.5
1311.96	1648.5
1311.42	1655.25
1310.88	1647.5
1310.34	1640
1309.8	1674.75
1309.25	1704.5
1308.71	1641.75
1308.17	1664.5
1307.63	1679.25
1307.09	1651.75
1306.54	1685.5
1306	1683.75
1305.46	1715.25
1304.92	1667.5
1304.38	1715.5
1303.83	1654.75
1303.29	1691.25
1302.75	1680.5
1302.21	1677
1301.66	1684.5
1301.12	1725.25
1300.58	1696
1300.04	1710.75
1299.49	1647.25
1298.95	1756.75
1298.41	1707
1297.86	1708.75
1297.32	1671.25
1296.78	1673.5
1296.23	1714.5
1295.69	1703.75
1295.15	1706
1294.6	1748
1294.06	1670.75
1293.52	1716
1292.97	1692
1292.43	1707.25
1291.89	1671
1291.34	1674.5
1290.8	1684
1290.26	1686.5
1289.71	1692
1289.17	1681.5
1288.63	1664.75
1288.08	1692.5
1287.54	1793.75
1286.99	1963.75
1286.45	2184.5
1285.9	2304.75
1285.36	2612.75
1284.82	2553.5
1284.27	2074.75
1283.73	1759
1283.19	1674.5
1282.64	1663
1282.1	1652
1281.55	1663.25
1281.01	1646.5
1280.46	1626
1279.92	1653.75
1279.37	1672
1278.83	1602.25
1278.28	1666.75
1277.74	1606.75
1277.19	1633
1276.65	1609.25
1276.1	1608.75
1275.56	1617.75
1275.01	1659.25
1274.47	1628.5
1273.92	1602.25
1273.38	1633
1272.83	1658.25
1272.29	1644.5
1271.74	1649.75
1271.2	1618.75
1270.65	1624.75
1270.11	1667
1269.56	1637.25
1269.01	1668.5
1268.47	1646.25
1267.92	1616.75
1267.38	1692.25
1266.83	1713.25
1266.29	1722.5
1265.74	1729.5
1265.19	1719.25
1264.65	1748.75
1264.1	1707.75
1263.55	1693.25
1263.01	1700.5
1262.46	1703.25
1261.92	1689.25
1261.37	1663.75
1260.82	1682.75
1260.28	1682.75
1259.73	1710.5
1259.18	1720.5
1258.64	1725
1258.09	1738.25
1257.55	1772.5
1257	1725.25
1256.45	1688.75
1255.9	1722.75
1255.36	1737.25
1254.81	1773.25
1254.26	1744.75
1253.72	1749.25
1253.17	1753
1252.62	1765
1252.07	1734.75
1251.53	1761.75
1250.98	1779.5
1250.43	1784.75
1249.89	1745
1249.34	1781
1248.79	1796.5
1248.24	1806
1247.7	1759.25
1247.15	1756.25
1246.6	1765.25
1246.05	1790.5
1245.5	1763.25
1244.96	1769.25
1244.41	1791.25
1243.86	1803
1243.31	1764
1242.77	1775
1242.22	1776.5
1241.67	1800
1241.12	1813.75
1240.57	1776
1240.02	1855
1239.48	1849.25
1238.93	1966
1238.38	1841.5
1237.83	1867
1237.28	1893.25
1236.73	1871.25
1236.18	1864.5
1235.64	1878.5
1235.09	1916
1234.54	1947.25
1233.99	1932
1233.44	1977.25
1232.89	1921
1232.34	1963
1231.79	1950.75
1231.24	1955
1230.69	1919.25
1230.15	1950.75
1229.6	1901.25
1229.05	1990
1228.5	1932.25
1227.95	1940.5
1227.4	1895.25
1226.85	1884.25
1226.3	1886
1225.75	1873.5
1225.2	1871
1224.65	1864.75
1224.1	1876.75
1223.55	1848.75
1223	1839.75
1222.45	1819.25
1221.9	1814.75
1221.35	1808.25
1220.8	1795.25
1220.25	1766.25
1219.7	1784.75
1219.15	1783.75
1218.6	1776.25
1218.05	1793.5
1217.5	1747
1216.95	1752.5
1216.4	1782.75
1215.85	1699.25
1215.3	1748.5
1214.75	1709.25
1214.2	1698.5
1213.65	1731.75
1213.09	1718.75
1212.54	1718.25
1211.99	1673
1211.44	1709
1210.89	1689.5
1210.34	1679.5
1209.79	1693.75
1209.24	1658
1208.69	1648
1208.14	1731.75
1207.58	1710.25
1207.03	1709.25
1206.48	1695
1205.93	1672.5
1205.38	1658
1204.83	1641.75
1204.27	1659.5
1203.72	1670.25
1203.17	1632.5
1202.62	1643.75
1202.07	1645.25
1201.52	1682.5
1200.96	1642.5
1200.41	1669
1199.86	1670.25
1199.31	1666
1198.76	1652.25
1198.2	1651.75
1197.65	1687.5
1197.1	1667.75
1196.55	1682
1196	1673
1195.44	1712.25
1194.89	1668.25
1194.34	1722.75
1193.78	1725.5
1193.23	1715.5
1192.68	1705.75
1192.13	1733.75
1191.57	1734
1191.02	1743
1190.47	1793
1189.91	1785.75
1189.36	1810
1188.81	1846.5
1188.26	1874.25
1187.7	1814.5
1187.15	1844.25
1186.6	1931.25
1186.04	1894.5
1185.49	1901.25
1184.94	1923
1184.38	1924.75
1183.83	1888.5
1183.28	1826.5
1182.72	1873
1182.17	1827
1181.61	1879.75
1181.06	1822
1180.51	1828.5
1179.95	1799
1179.4	1832.25
1178.85	1751.75
1178.29	1834.25
1177.74	1818.75
1177.18	1758.25
1176.63	1777.75
1176.07	1745.25
1175.52	1783.5
1174.97	1789.5
1174.41	1744.75
1173.86	1807.25
1173.3	1768.25
1172.75	1804.75
1172.19	1833.75
1171.64	1802.5
1171.09	1887.25
1170.53	1864.5
1169.97	1877.75
1169.42	1930.75
1168.86	1967.25
1168.31	1986
1167.76	2071.75
1167.2	2117.75
1166.65	2252
1166.09	2293
1165.53	2432
1164.98	2535.75
1164.42	2661
1163.87	2807.75
1163.31	2982
1162.76	3073.5
1162.2	3321.5
1161.65	3418.25
1161.09	3575.5
1160.54	3612.25
1159.98	3598.25
1159.42	3579
1158.87	3453.75
1158.31	3360.5
1157.76	3198
1157.2	2971.75
1156.65	2785.25
1156.09	2727.75
1155.53	2619.5
1154.98	2460
1154.42	2365.75
1153.86	2306
1153.31	2221.5
1152.75	2127.25
1152.19	2082.25
1151.64	2067.25
1151.08	2066.25
1150.52	1962.25
1149.97	1889.75
1149.41	1959.75
1148.86	1911.75
1148.3	1884
1147.74	1846.25
1147.18	1835.5
1146.63	1873.5
1146.07	1833.5
1145.51	1806.25
1144.96	1841.25
1144.4	1796.25
1143.84	1781.25
1143.28	1776.25
1142.73	1781.25
1142.17	1758.25
1141.61	1718.75
1141.06	1746.25
1140.5	1806.75
1139.94	1783.75
1139.38	1730
1138.83	1687.5
1138.27	1759.25
1137.71	1729.5
1137.15	1722.25
1136.59	1707.25
1136.04	1726.25
1135.48	1728.5
1134.92	1728.75
1134.36	1742
1133.8	1721
1133.25	1708.25
1132.69	1686.25
1132.13	1681
1131.57	1701.25
1131.01	1705
1130.45	1691.25
1129.9	1695.25
1129.34	1703.25
1128.78	1676
1128.22	1711.75
1127.66	1691.75
1127.1	1728.75
1126.54	1666.5
1125.98	1709.25
1125.43	1670
1124.87	1688
1124.31	1713.75
1123.75	1731.25
1123.19	1734.5
1122.63	1766.5
1122.07	1720.25
1121.51	1723.75
1120.95	1728.75
1120.39	1809
1119.83	1763.75
1119.27	1761
1118.72	1773.5
1118.15	1866.25
1117.6	1840
1117.04	1824.75
1116.48	1914
1115.92	1865.5
1115.36	1990.25
1114.8	1900.5
1114.24	1959
1113.68	2010.25
1113.12	1973.75
1112.56	1943
1112	1971
1111.44	1972.75
1110.88	1982.25
1110.32	1973.25
1109.76	1951.75
1109.19	1893.5
1108.64	1863
1108.07	1801.5
1107.51	1840.5
1106.95	1811.25
1106.39	1743.25
1105.83	1783
1105.27	1744
1104.71	1761.75
1104.15	1716.5
1103.59	1702.5
1103.03	1738.25
1102.47	1722
1101.91	1689.25
1101.34	1663
1100.78	1712.5
1100.22	1665
1099.66	1659.25
1099.1	1663.25
1098.54	1701.25
1097.98	1642
1097.41	1652.75
1096.85	1704
1096.29	1656.5
1095.73	1692
1095.17	1637.75
1094.61	1680.5
1094.04	1640.75
1093.48	1640.25
1092.92	1612.5
1092.36	1664.75
1091.8	1665.25
1091.23	1667.75
1090.67	1686.75
1090.11	1646.25
1089.55	1682.25
1088.99	1675.75
1088.42	1649.5
1087.86	1699.25
1087.3	1711.75
1086.74	1741.5
1086.17	1683
1085.61	1759.5
1085.05	1727.75
1084.49	1773.25
1083.92	1774
1083.36	1832.25
1082.8	1780.5
1082.23	1784.75
1081.67	1871.25
1081.11	1850
1080.55	1820.75
1079.98	1814.5
1079.42	1836
1078.86	1790
1078.29	1771
1077.73	1782.5
1077.17	1724.25
1076.6	1729.25
1076.04	1757.5
1075.48	1711.5
1074.91	1791
1074.35	1764.25
1073.79	1758.5
1073.22	1730.75
1072.66	1736.5
1072.09	1796
1071.53	1779
1070.97	1811.75
1070.4	1851
1069.84	1861.25
1069.27	1893.25
1068.71	1907.5
1068.15	1963
1067.58	1931.75
1067.02	1991.75
1066.45	1991.25
1065.89	2027.5
1065.32	1948.75
1064.76	2041
1064.19	1994.5
1063.63	1961.5
1063.07	1928.75
1062.5	1859.75
1061.94	1875
1061.37	1830
1060.81	1815.5
1060.24	1726.5
1059.68	1780
1059.11	1694.5
1058.55	1718
1057.98	1693.5
1057.42	1736
1056.85	1670.75
1056.29	1630.5
1055.72	1646.5
1055.16	1682.25
1054.59	1617.75
1054.03	1675.25
1053.46	1635.75
1052.89	1666
1052.33	1628.75
1051.76	1627.75
1051.2	1599.25
1050.63	1687
1050.06	1656
1049.5	1661
1048.93	1623.75
1048.37	1621
1047.8	1666
1047.24	1632.5
1046.67	1629.25
1046.1	1643.75
1045.54	1631
1044.97	1639.75
1044.4	1647.25
1043.84	1678.5
1043.27	1671.25
1042.7	1611.75
1042.14	1639.5
1041.57	1662.25
1041.01	1598.75
1040.44	1625.25
1039.87	1662.5
1039.3	1656.75
1038.74	1574.5
1038.17	1609.5
1037.6	1639
1037.04	1596.25
1036.47	1589
1035.9	1602.25
1035.34	1564.75
1034.77	1613.25
1034.2	1553.5
1033.63	1551
1033.07	1600.5
1032.5	1587
1031.93	1557.5
1031.36	1617.75
1030.8	1561.75
1030.23	1617.25
1029.66	1558.75
1029.09	1574.25
1028.52	1609.5
1027.96	1593
1027.39	1609.75
1026.82	1614.5
1026.25	1611.25
1025.68	1493
1025.12	1572
1024.55	1575.75
1023.98	1557.75
1023.41	1543.25
1022.84	1578.75
1022.28	1545
1021.71	1570.5
1021.14	1559.25
1020.57	1558.75
1020	1585.25
1019.43	1593.75
1018.86	1568.75
1018.3	1587
1017.73	1584.25
1017.16	1571.5
1016.59	1547.5
1016.3	1564.75