File: Testing/Hickernall_HORIBA/g47-mi1-bub1_03.txt
#Acq. time (s)=	75
#Accumulations=	5
#Range=	Off
#Autofocus=	Off
#Macrospot=	Off
#AutoExposure=	Off
#Spike filter=	Multiple accum.
#Delay time (s)=	0
#Binning=	1
#Readout mode=	Signal
#DeNoise=	Off
#ICS correction=	Off
#Dark correction=	Off
#Inst. Process=	Off
#Instrument=	LabRAM HR Evol
#Detector=	Andor CCD
#Objective=	x100 LWD
#Grating=	1800 gr/mm
#ND Filter=	100%
#Laser (nm)=	532
#Spectro (cm-¹)=	1240.02
#Hole=	49.98
#Range=	Visible
#AFM=	Off
#StageXY=	Marzhauser
#StageZ=	Marzhauser
#X (µm)=	-16420.2
#Y (µm)=	-903.6
#Z (µm)=	-367.2
#Project=
#Sample=
#Site=
#Title=	g47-mi1-bub1
#Remark=
#Date=	06.05.2022 11:57
#Acquired=	06.05.2022 11:57:49
1454.81	13053
1454.28	12989.3
1453.75	12810.8
1453.22	12993.5
1452.69	12929
1452.16	13061.3
1451.64	12898.8
1451.11	13014.8
1450.58	12695.5
1450.05	12997.8
1449.52	12740.3
1448.99	12944.3
1448.46	12817
1447.93	12966
1447.4	12783.5
1446.88	12884.3
1446.35	12850.3
1445.82	12906
1445.29	12838
1444.76	12742
1444.23	12809
1443.7	12796.8
1443.17	12839.3
1442.64	12704.8
1442.11	12838
1441.58	12826.3
1441.05	12937
1440.52	12693
1439.99	12884.8
1439.46	12844.3
1438.93	12740.8
1438.4	12791
1437.87	12785.3
1437.34	12888.5
1436.81	12713
1436.28	12706.8
1435.75	12640.3
1435.22	12839.3
1434.69	12630.8
1434.16	12755.8
1433.63	12421
1433.1	12907.8
1432.57	12657.3
1432.04	12679
1431.51	12493.3
1430.98	12750
1430.45	12670.5
1429.92	12601.5
1429.39	12642
1428.86	12629.5
1428.33	12599.5
1427.8	12571.5
1427.26	12628.8
1426.73	12561.3
1426.2	12704.8
1425.67	12472
1425.14	12732
1424.61	12480
1424.08	12770
1423.55	12356
1423.02	12592.8
1422.49	12394.8
1421.95	12599.8
1421.42	12532.5
1420.89	12599
1420.36	12393
1419.83	12721.5
1419.3	12750
1418.76	12595.5
1418.23	12508.8
1417.7	12378.5
1417.17	12519
1416.64	12554.3
1416.1	12509.3
1415.57	12432.8
1415.04	12578.5
1414.51	12515.3
1413.98	12550.3
1413.44	12413
1412.91	12632.8
1412.38	12490.3
1411.85	12398
1411.32	12430.3
1410.78	12619
1410.25	12514.8
1409.72	12495
1409.18	12602.3
1408.65	12511
1408.12	12564
1407.59	12289.3
1407.05	12648.5
1406.52	12290.5
1405.99	12512.5
1405.46	12303.3
1404.92	12450.5
1404.39	12504.5
1403.86	12549
1403.32	12151
1402.79	12291
1402.26	12307.5
1401.72	12280.3
1401.19	12316.5
1400.66	12411.3
1400.12	12338.8
1399.59	12245
1399.06	12459.3
1398.52	12337.8
1397.99	12295.5
1397.46	12271.3
1396.92	12277
1396.39	12059.8
1395.85	12399
1395.32	12131.8
1394.79	12219
1394.25	12147.8
1393.72	12327.8
1393.18	12188.8
1392.65	12162.3
1392.12	12153.8
1391.58	12237.5
1391.05	12303
1390.51	12369.8
1389.98	12575.5
1389.44	12861.3
1388.91	13324.8
1388.38	13377
1387.84	13690.8
1387.31	13224.5
1386.77	12755.8
1386.24	12147.5
1385.7	12201
1385.17	12270
1384.63	12435
1384.1	12177.3
1383.56	12126
1383.03	12117.3
1382.49	12207.3
1381.96	12157.8
1381.42	12093.5
1380.89	12203
1380.35	12043
1379.82	12282.3
1379.28	12094.3
1378.74	12194.5
1378.21	12157.3
1377.67	12266.3
1377.14	12023
1376.6	12090.8
1376.07	12057
1375.53	12266.8
1374.99	12127.3
1374.46	12160.3
1373.92	12107.3
1373.39	12292.3
1372.85	12043.3
1372.32	12113.3
1371.78	12066.8
1371.24	12126.8
1370.71	12097
1370.17	12042
1369.63	12030.3
1369.1	12011.3
1368.56	11952
1368.03	11929.3
1367.49	12013.5
1366.95	11930
1366.42	12293.5
1365.88	11977.3
1365.34	12057
1364.81	12019.3
1364.27	11981
1363.73	11871.3
1363.19	12105.5
1362.66	12037
1362.12	11989.3
1361.58	11993.3
1361.05	11947
1360.51	11929.5
1359.97	12133
1359.44	11911.8
1358.9	12093
1358.36	11944.5
1357.82	11896
1357.29	11897.8
1356.75	11875
1356.21	12016.3
1355.67	11889.3
1355.14	11991
1354.6	11768.5
1354.06	11990.5
1353.52	11899.8
1352.99	11878.5
1352.45	11765.5
1351.91	11814.5
1351.37	11806.5
1350.83	11843.3
1350.3	11940.3
1349.76	11997.5
1349.22	11876.5
1348.68	11751
1348.14	11755.8
1347.6	11842.8
1347.06	11805.8
1346.53	11755
1345.99	11720.3
1345.45	11715
1344.91	11901.3
1344.37	11679.5
1343.83	11719
1343.3	11702.8
1342.76	11815.8
1342.22	11777.3
1341.68	11775
1341.14	11705.5
1340.6	11776.8
1340.06	11673.5
1339.52	11682
1338.98	11555.5
1338.45	11725
1337.91	11571
1337.37	11727.5
1336.83	11583
1336.29	11856
1335.75	11612.5
1335.21	11514
1334.67	11659.3
1334.13	11549.8
1333.59	11587.5
1333.05	11410
1332.51	11572.5
1331.97	11536.5
1331.43	11671.3
1330.89	11431.3
1330.35	11578.3
1329.81	11510.5
1329.27	11648.3
1328.73	11437
1328.19	11548.3
1327.65	11456.8
1327.11	11636
1326.57	11347
1326.03	11586.5
1325.49	11442.3
1324.95	11611
1324.41	11380.8
1323.87	11470.3
1323.33	11357.8
1322.79	11483.3
1322.25	11490.8
1321.71	11395.3
1321.16	11445.5
1320.62	11442.5
1320.08	11467.5
1319.54	11374.3
1319	11631.5
1318.46	11291.5
1317.92	11517
1317.38	11250.3
1316.84	11564.3
1316.29	11443.3
1315.75	11580.3
1315.21	11381
1314.67	11488.8
1314.13	11297.8
1313.59	11461.3
1313.05	11324.5
1312.5	11391.3
1311.96	11297.5
1311.42	11549.3
1310.88	11299
1310.34	11369.5
1309.8	11330.3
1309.25	11336.8
1308.71	11352.5
1308.17	11297.8
1307.63	11492
1307.09	11303.5
1306.54	11367
1306	11345.8
1305.46	11454.5
1304.92	11294.8
1304.38	11402.3
1303.83	11176.8
1303.29	11336.5
1302.75	11282.3
1302.21	11348.8
1301.66	11047.5
1301.12	11439
1300.58	11295.8
1300.04	11440.5
1299.49	11156.8
1298.95	11212.5
1298.41	11172.5
1297.86	11197
1297.32	11349.8
1296.78	11281.3
1296.23	11415
1295.69	11338.8
1295.15	11216.5
1294.6	11193.5
1294.06	11309.5
1293.52	11135.5
1292.97	11269.8
1292.43	11111.5
1291.89	11318
1291.34	11050.3
1290.8	11235.5
1290.26	11140
1289.71	11326.8
1289.17	11095.8
1288.63	11368.5
1288.08	10968.5
1287.54	11430
1286.99	11454.3
1286.45	11719
1285.9	11733.5
1285.36	12152.8
1284.82	12067
1284.27	11620.5
1283.73	11105
1283.19	10989.3
1282.64	11204.3
1282.1	11212.5
1281.55	11191.8
1281.01	11006.3
1280.46	11144
1279.92	11060
1279.37	11228.8
1278.83	11030
1278.28	11245.5
1277.74	11026.8
1277.19	11229
1276.65	10994.8
1276.1	11182.8
1275.56	11002.5
1275.01	11143.5
1274.47	11120.8
1273.92	11221.8
1273.38	10992
1272.83	11229.8
1272.29	11055
1271.74	11097.5
1271.2	10958.5
1270.65	11135.8
1270.11	11071.5
1269.56	11121.8
1269.01	10953
1268.47	11048.5
1267.92	11155.3
1267.38	11165.5
1266.83	11222.5
1266.29	11151.5
1265.74	11101.8
1265.19	11148.3
1264.65	11191
1264.1	10980.8
1263.55	11085
1263.01	11056.8
1262.46	11142.5
1261.92	11129
1261.37	11211.5
1260.82	11060.3
1260.28	11177.8
1259.73	11089.8
1259.18	11238.5
1258.64	10933
1258.09	11242.5
1257.55	11104
1257	11219
1256.45	11136
1255.9	11122.5
1255.36	11078.5
1254.81	11229.3
1254.26	11115.5
1253.72	11130.5
1253.17	11070.5
1252.62	11172
1252.07	11033.5
1251.53	11101.5
1250.98	11130.3
1250.43	11057.8
1249.89	11162
1249.34	11073.8
1248.79	11277.5
1248.24	11181.5
1247.7	11095.3
1247.15	11043.3
1246.6	11159.5
1246.05	11180.8
1245.5	11264
1244.96	11110.8
1244.41	11232
1243.86	11146
1243.31	11211.8
1242.77	11165.8
1242.22	11202.5
1241.67	11190.3
1241.12	11324.3
1240.57	11234
1240.02	11279
1239.48	11289.3
1238.93	11224.3
1238.38	11167.3
1237.83	11331.3
1237.28	11163.8
1236.73	11218
1236.18	11108.5
1235.64	11265.8
1235.09	11246.3
1234.54	11270
1233.99	11216.3
1233.44	11397
1232.89	11182
1232.34	11271
1231.79	11212.8
1231.24	11129.8
1230.69	11293.8
1230.15	11232.5
1229.6	11215
1229.05	11075.3
1228.5	11165.8
1227.95	11253.5
1227.4	11174.8
1226.85	11197
1226.3	11142
1225.75	11185.3
1225.2	11028
1224.65	11158.5
1224.1	11092.8
1223.55	11050.3
1223	11061.3
1222.45	10959.5
1221.9	11037.3
1221.35	10960.5
1220.8	11017.5
1220.25	11060.8
1219.7	11111
1219.15	10925.3
1218.6	11022.5
1218.05	11030.8
1217.5	10922.3
1216.95	10993
1216.4	10941.3
1215.85	10799.5
1215.3	10996
1214.75	10763.3
1214.2	10888.8
1213.65	10717.8
1213.09	10840.8
1212.54	10786.5
1211.99	10807.8
1211.44	10657
1210.89	10838.8
1210.34	10731
1209.79	10692
1209.24	10766
1208.69	10732
1208.14	10826.5
1207.58	10780
1207.03	10663.3
1206.48	10705.8
1205.93	10805.3
1205.38	10730
1204.83	10656.8
1204.27	10681.8
1203.72	10641.3
1203.17	10639.3
1202.62	10681
1202.07	10663.3
1201.52	10770.5
1200.96	10626.3
1200.41	10684.5
1199.86	10577.5
1199.31	10640.8
1198.76	10519.8
1198.2	10634
1197.65	10596.8
1197.1	10673.8
1196.55	10597.5
1196	10682
1195.44	10560
1194.89	10719.3
1194.34	10487.8
1193.78	10694.5
1193.23	10597.3
1192.68	10758.5
1192.13	10573.5
1191.57	10585.5
1191.02	10591
1190.47	10768.8
1189.91	10487
1189.36	10744
1188.81	10736.3
1188.26	10797.8
1187.7	10504.8
1187.15	10701.3
1186.6	10648
1186.04	10767
1185.49	10598.3
1184.94	10668.3
1184.38	10607
1183.83	10772.8
1183.28	10553.3
1182.72	10592.8
1182.17	10562
1181.61	10600.3
1181.06	10454.3
1180.51	10612.5
1179.95	10689.3
1179.4	10597
1178.85	10658.8
1178.29	10509.5
1177.74	10575
1177.18	10516
1176.63	10561.8
1176.07	10461.8
1175.52	10614.5
1174.97	10385
1174.41	10477.3
1173.86	10428.5
1173.3	10555
1172.75	10530.8
1172.19	10612.5
1171.64	10554.8
1171.09	10722.5
1170.53	10498.5
1169.97	10800.3
1169.42	10666.3
1168.86	10797.8
1168.31	10643.3
1167.76	10782.8
1167.2	10853.3
1166.65	11011.8
1166.09	10972.8
1165.53	11253.3
1164.98	11291.5
1164.42	11615.3
1163.87	11609.3
1163.31	11867
1162.76	11853
1162.2	12394
1161.65	12332.3
1161.09	12552.5
1160.54	12497.5
1159.98	12650.8
1159.42	12206.8
1158.87	12351.3
1158.31	12194
1157.76	12047.3
1157.2	11876.5
1156.65	11690.5
1156.09	11497.3
1155.53	11433.3
1154.98	11085.5
1154.42	11116.5
1153.86	11043.3
1153.31	10927.8
1152.75	10690.8
1152.19	10753
1151.64	10642.5
1151.08	10733
1150.52	10487
1149.97	10439.3
1149.41	10479.8
1148.86	10591.5
1148.3	10493.5
1147.74	10432
1147.18	10446
1146.63	10507.8
1146.07	10366.5
1145.51	10415.8
1144.96	10294
1144.4	10292
1143.84	10402.5
1143.28	10326.8
1142.73	10245.5
1142.17	10241
1141.61	10203.3
1141.06	10247.3
1140.5	10234.5
1139.94	10219.3
1139.38	10267.3
1138.83	10065.5
1138.27	10319.3
1137.71	10162.5
1137.15	10286.3
1136.59	10086
1136.04	10252
1135.48	10048
1134.92	10199
1134.36	10046.5
1133.8	10236.3
1133.25	9950
1132.69	10125.5
1132.13	10081.8
1131.57	10112.3
1131.01	10023
1130.45	9962
1129.9	9976.75
1129.34	10089.3
1128.78	9968.5
1128.22	10157.8
1127.66	10153
1127.1	10168.3
1126.54	10097.3
1125.98	10121
1125.43	9967.25
1124.87	10177
1124.31	10016.8
1123.75	10169.3
1123.19	9988.75
1122.63	10116.8
1122.07	9930
1121.51	10080.5
1120.95	10059.3
1120.39	10039
1119.83	10026.3
1119.27	10138
1118.72	10010
1118.15	10137.3
1117.6	9878.25
1117.04	10127.8
1116.48	10008.8
1115.92	10096
1115.36	10072.5
1114.8	10078.8
1114.24	10066.5
1113.68	10093.3
1113.12	10105.8
1112.56	10098.5
1112	10056
1111.44	10070.8
1110.88	10075.3
1110.32	10126.5
1109.76	9975.75
1109.19	10098.5
1108.64	9911.75
1108.07	9997.5
1107.51	10007.8
1106.95	10027.5
1106.39	9840.75
1105.83	9950.25
1105.27	9914.75
1104.71	9942.25
1104.15	9749.5
1103.59	9876.25
1103.03	9922
1102.47	9820.5
1101.91	9686.5
1101.34	9819
1100.78	9790.75
1100.22	9820
1099.66	9691.75
1099.1	9823.75
1098.54	9650.5
1097.98	9800
1097.41	9789
1096.85	9774.25
1096.29	9761.75
1095.73	9769
1095.17	9704.25
1094.61	9814.5
1094.04	9732.25
1093.48	9700.5
1092.92	9772.25
1092.36	9779.5
1091.8	9752.75
1091.23	9635.75
1090.67	9816.5
1090.11	9740.25
1089.55	9613.75
1088.99	9703.75
1088.42	9790.75
1087.86	9685.75
1087.3	9656
1086.74	9598.75
1086.17	9800.25
1085.61	9640.25
1085.05	9714.5
1084.49	9713.5
1083.92	9867.75
1083.36	9815
1082.8	9767.5
1082.23	9902.5
1081.67	9761.25
1081.11	9951.5
1080.55	9781.25
1079.98	9748.75
1079.42	9807.75
1078.86	9743.75
1078.29	9779.75
1077.73	9781
1077.17	9804
1076.6	9723.75
1076.04	9762.5
1075.48	9572
1074.91	9848.5
1074.35	9728.5
1073.79	9811.25
1073.22	9575.5
1072.66	9826
1072.09	9794
1071.53	9772
1070.97	9807
1070.4	9933.75
1069.84	9805
1069.27	9965.5
1068.71	9979.25
1068.15	10060
1067.58	9921.75
1067.02	9934
1066.45	9966.75
1065.89	9961
1065.32	9990.25
1064.76	9876.5
1064.19	9957.25
1063.63	9936.25
1063.07	9736.25
1062.5	9977
1061.94	9872
1061.37	9828.75
1060.81	9737
1060.24	9728.75
1059.68	9666.75
1059.11	9590.25
1058.55	9589
1057.98	9466.5
1057.42	9626.5
1056.85	9609.75
1056.29	9474
1055.72	9463.25
1055.16	9550.25
1054.59	9432.5
1054.03	9456.75
1053.46	9460
1052.89	9457.5
1052.33	9552.75
1051.76	9412.25
1051.2	9460.25
1050.63	9574
1050.06	9554.25
1049.5	9380.75
1048.93	9465.5
1048.37	9472
1047.8	9504.25
1047.24	9434.25
1046.67	9427
1046.1	9313.5
1045.54	9375
1044.97	9293.5
1044.4	9401.75
1043.84	9418.25
1043.27	9428.25
1042.7	9353.5
1042.14	9456.75
1041.57	9400.5
1041.01	9314
1040.44	9334.5
1039.87	9383.25
1039.3	9314.75
1038.74	9212
1038.17	9254.25
1037.6	9325.75
1037.04	9265
1036.47	9256.5
1035.9	9345.75
1035.34	9227.75
1034.77	9318.5
1034.2	9194.25
1033.63	9224.25
1033.07	9274.75
1032.5	9270.5
1031.93	9224.5
1031.36	9237.75
1030.8	9177.5
1030.23	9141.5
1029.66	9210
1029.09	9225
1028.52	9113.75
1027.96	9225
1027.39	9082.5
1026.82	9251.5
1026.25	9154
1025.68	9227.25
1025.12	9094
1024.55	9240.5
1023.98	9124.25
1023.41	9130
1022.84	9062.75
1022.28	9119.25
1021.71	9094.75
1021.14	9135
1020.57	9083
1020	9168.25
1019.43	9071.75
1018.86	9010
1018.3	9111.5
1017.73	9109
1017.16	9086.5
1016.59	9085.25
1016.3	9105