File: Testing/Hickernall_HORIBA/g47-mi1-bub2_03.txt
#Acq. time (s)=	75
#Accumulations=	5
#Range=	Off
#Autofocus=	Off
#Macrospot=	Off
#AutoExposure=	Off
#Spike filter=	Multiple accum.
#Delay time (s)=	0
#Binning=	1
#Readout mode=	Signal
#DeNoise=	Off
#ICS correction=	Off
#Dark correction=	Off
#Inst. Process=	Off
#Instrument=	LabRAM HR Evol
#Detector=	Andor CCD
#Objective=	x100 LWD
#Grating=	1800 gr/mm
#ND Filter=	100%
#Laser (nm)=	532
#Spectro (cm-¹)=	1240.02
#Hole=	49.98
#Range=	Visible
#AFM=	Off
#StageXY=	Marzhauser
#StageZ=	Marzhauser
#X (µm)=	-16434
#Y (µm)=	-893.6
#Z (µm)=	-371.3
#Project=
#Sample=
#Site=
#Title=	g47-mi1-bub2
#Remark=
#Date=	06.05.2022 12:32
#Acquired=	06.05.2022 12:32:15
1454.81	5224
1454.28	5084.75
1453.75	5188
1453.22	5171
1452.69	5165
1452.16	5161
1451.64	5089.5
1451.11	5245.25
1450.58	5118.25
1450.05	5134
1449.52	5061
1448.99	5128
1448.46	5051.5
1447.93	5110.75
1447.4	5137
1446.88	5134.5
1446.35	5123
1445.82	5112.5
1445.29	5111.75
1444.76	5085.5
1444.23	5005
1443.7	5126
1443.17	5184.25
1442.64	5061.75
1442.11	5051.25
1441.58	5118.75
1441.05	5081.5
1440.52	5021.25
1439.99	5127
1439.46	5041
1438.93	5100.5
1438.4	5069.25
1437.87	5079.75
1437.34	5081.25
1436.81	5077.25
1436.28	5144.5
1435.75	4997.75
1435.22	5059.75
1434.69	5014.5
1434.16	5073.5
1433.63	5010.25
1433.1	5003
1432.57	4881.75
1432.04	4999.25
1431.51	5004.5
1430.98	5067.25
1430.45	4918.5
1429.92	5002.25
1429.39	4879.25
1428.86	4945.5
1428.33	4917.75
1427.8	4920
1427.26	4952.75
1426.73	4906.5
1426.2	4915.25
1425.67	4929
1425.14	4936.25
1424.61	4907.25
1424.08	4960.75
1423.55	4909.5
1423.02	4939.25
1422.49	4902.5
1421.95	4977.5
1421.42	4942.25
1420.89	4841
1420.36	4989.5
1419.83	4963
1419.3	4901
1418.76	4880.5
1418.23	4916.5
1417.7	4920.75
1417.17	4923.5
1416.64	4857.25
1416.1	4877.25
1415.57	4820.5
1415.04	4860.75
1414.51	4812.5
1413.98	4919.25
1413.44	4850
1412.91	4928.25
1412.38	4843.5
1411.85	4900.5
1411.32	4897.75
1410.78	4904
1410.25	4863
1409.72	4909.5
1409.18	4888
1408.65	4962.5
1408.12	4886.5
1407.59	4865
1407.05	4841.5
1406.52	4893
1405.99	4874.75
1405.46	4864.75
1404.92	4894
1404.39	4789
1403.86	4852.75
1403.32	4831.75
1402.79	4805.75
1402.26	4808.75
1401.72	4812.75
1401.19	4782.5
1400.66	4777.25
1400.12	4783.75
1399.59	4804.75
1399.06	4935
1398.52	4790.5
1397.99	4859.75
1397.46	4859
1396.92	4884
1396.39	4751
1395.85	4883.75
1395.32	4779.75
1394.79	4807.5
1394.25	4780.25
1393.72	4819.25
1393.18	4772.25
1392.65	4797
1392.12	4784.25
1391.58	4764.5
1391.05	4799
1390.51	4850.5
1389.98	4812
1389.44	4881.75
1388.91	5000.25
1388.38	4997.5
1387.84	4986.25
1387.31	4898.5
1386.77	4876.25
1386.24	4819
1385.7	4787
1385.17	4734
1384.63	4812
1384.1	4763.5
1383.56	4769
1383.03	4701.75
1382.49	4815.25
1381.96	4877
1381.42	4794.25
1380.89	4852.75
1380.35	4884
1379.82	4815.75
1379.28	4796
1378.74	4830.25
1378.21	4710
1377.67	4894.75
1377.14	4690
1376.6	4786
1376.07	4787
1375.53	4859.5
1374.99	4832
1374.46	4797
1373.92	4780.5
1373.39	4748.75
1372.85	4855.25
1372.32	4728
1371.78	4743.75
1371.24	4841
1370.71	4761
1370.17	4671
1369.63	4780
1369.1	4802.5
1368.56	4786.25
1368.03	4683.25
1367.49	4736.75
1366.95	4781.75
1366.42	4741.75
1365.88	4764.25
1365.34	4716.5
1364.81	4725.75
1364.27	4769.75
1363.73	4733.5
1363.19	4722.5
1362.66	4806.25
1362.12	4751.5
1361.58	4784
1361.05	4743
1360.51	4759
1359.97	4707
1359.44	4713.75
1358.9	4653.25
1358.36	4741
1357.82	4777.75
1357.29	4645.25
1356.75	4732
1356.21	4756
1355.67	4658.25
1355.14	4748
1354.6	4655.25
1354.06	4641.5
1353.52	4693.75
1352.99	4653.5
1352.45	4655.25
1351.91	4735.5
1351.37	4619.5
1350.83	4693.5
1350.3	4686
1349.76	4703.75
1349.22	4694.25
1348.68	4727
1348.14	4606.75
1347.6	4639
1347.06	4688.75
1346.53	4642.75
1345.99	4629.75
1345.45	4621.5
1344.91	4754.75
1344.37	4678
1343.83	4636
1343.3	4664.75
1342.76	4639.25
1342.22	4615
1341.68	4669
1341.14	4632.25
1340.6	4646.25
1340.06	4597
1339.52	4593.25
1338.98	4552.25
1338.45	4681.75
1337.91	4661.75
1337.37	4591
1336.83	4538.75
1336.29	4653.5
1335.75	4571.25
1335.21	4602.5
1334.67	4571
1334.13	4647
1333.59	4651
1333.05	4610
1332.51	4646.5
1331.97	4568.5
1331.43	4698.25
1330.89	4547
1330.35	4626.75
1329.81	4538.75
1329.27	4600
1328.73	4559.25
1328.19	4567.25
1327.65	4571.5
1327.11	4539.75
1326.57	4547
1326.03	4571.25
1325.49	4555.25
1324.95	4589
1324.41	4549
1323.87	4505.25
1323.33	4529
1322.79	4524.75
1322.25	4597
1321.71	4547.25
1321.16	4519
1320.62	4597
1320.08	4593.25
1319.54	4585.75
1319	4581.5
1318.46	4535.5
1317.92	4652.25
1317.38	4523.25
1316.84	4606.5
1316.29	4626.5
1315.75	4655.25
1315.21	4581.75
1314.67	4579.25
1314.13	4576.25
1313.59	4623.5
1313.05	4629.25
1312.5	4670.5
1311.96	4635.25
1311.42	4631.25
1310.88	4636
1310.34	4618.25
1309.8	4634.25
1309.25	4638.75
1308.71	4661
1308.17	4599.5
1307.63	4640.5
1307.09	4645.75
1306.54	4629.75
1306	4557
1305.46	4663.75
1304.92	4620.75
1304.38	4687.5
1303.83	4628.25
1303.29	4657.25
1302.75	4583.5
1302.21	4629.5
1301.66	4581
1301.12	4710.5
1300.58	4581.5
1300.04	4738.75
1299.49	4653.25
1298.95	4668.5
1298.41	4630.75
1297.86	4608.5
1297.32	4586
1296.78	4624
1296.23	4562.5
1295.69	4700.75
1295.15	4562.5
1294.6	4531
1294.06	4689.5
1293.52	4659.25
1292.97	4618.5
1292.43	4573.75
1291.89	4676.75
1291.34	4587
1290.8	4622.5
1290.26	4552.75
1289.71	4629
1289.17	4588.75
1288.63	4591
1288.08	4592
1287.54	4613
1286.99	4550
1286.45	4672
1285.9	4690.75
1285.36	4780.25
1284.82	4756
1284.27	4639.5
1283.73	4598
1283.19	4517
1282.64	4652.25
1282.1	4497.75
1281.55	4510.75
1281.01	4525.75
1280.46	4623.25
1279.92	4580
1279.37	4584.25
1278.83	4511
1278.28	4500.25
1277.74	4501.5
1277.19	4552.5
1276.65	4487
1276.1	4516.25
1275.56	4443.25
1275.01	4538.5
1274.47	4521.75
1273.92	4536.25
1273.38	4535.75
1272.83	4521.5
1272.29	4482.75
1271.74	4566.75
1271.2	4462.5
1270.65	4619.5
1270.11	4573.25
1269.56	4582.5
1269.01	4534.5
1268.47	4541.75
1267.92	4545.25
1267.38	4533
1266.83	4624.5
1266.29	4548.75
1265.74	4497.75
1265.19	4481.5
1264.65	4559
1264.1	4569.25
1263.55	4574.5
1263.01	4566.5
1262.46	4556.5
1261.92	4574.25
1261.37	4573.75
1260.82	4578
1260.28	4668.75
1259.73	4588.5
1259.18	4691.5
1258.64	4618.5
1258.09	4603.5
1257.55	4620.5
1257	4658.5
1256.45	4680.75
1255.9	4689.5
1255.36	4672.25
1254.81	4722
1254.26	4640.5
1253.72	4618
1253.17	4587.5
1252.62	4681.75
1252.07	4727.25
1251.53	4590.75
1250.98	4681.5
1250.43	4669.5
1249.89	4771.75
1249.34	4693
1248.79	4683
1248.24	4662.5
1247.7	4703.25
1247.15	4687.5
1246.6	4689.5
1246.05	4749.5
1245.5	4701.25
1244.96	4648.25
1244.41	4697.5
1243.86	4764.25
1243.31	4685.25
1242.77	4701
1242.22	4719.5
1241.67	4679.25
1241.12	4725.75
1240.57	4727.5
1240.02	4756.75
1239.48	4720.5
1238.93	4802.75
1238.38	4779.5
1237.83	4755
1237.28	4751.5
1236.73	4771
1236.18	4802.75
1235.64	4814.5
1235.09	4829
1234.54	4928.75
1233.99	4813
1233.44	4869.25
1232.89	4939.25
1232.34	4859
1231.79	4847.5
1231.24	4866.25
1230.69	4890
1230.15	4885
1229.6	4917
1229.05	4845
1228.5	4901
1227.95	4973
1227.4	4887
1226.85	4911.5
1226.3	4879.5
1225.75	4837.25
1225.2	4774.5
1224.65	4808.25
1224.1	4794.75
1223.55	4853.75
1223	4814
1222.45	4807.25
1221.9	4790.5
1221.35	4790.75
1220.8	4819
1220.25	4637
1219.7	4720.25
1219.15	4727.75
1218.6	4700.5
1218.05	4683.5
1217.5	4764.5
1216.95	4713.25
1216.4	4655.75
1215.85	4579.25
1215.3	4644.25
1214.75	4624
1214.2	4667.75
1213.65	4643.25
1213.09	4729.75
1212.54	4696.5
1211.99	4590.5
1211.44	4586.25
1210.89	4625.5
1210.34	4609.5
1209.79	4566.25
1209.24	4519
1208.69	4563
1208.14	4532.25
1207.58	4524
1207.03	4513
1206.48	4580.5
1205.93	4517
1205.38	4563.25
1204.83	4496.75
1204.27	4529.5
1203.72	4516.75
1203.17	4565.25
1202.62	4519
1202.07	4531.75
1201.52	4551
1200.96	4499
1200.41	4477.25
1199.86	4517.25
1199.31	4551.5
1198.76	4513.25
1198.2	4575.75
1197.65	4532
1197.1	4633
1196.55	4464.75
1196	4529.5
1195.44	4535
1194.89	4586.5
1194.34	4475.25
1193.78	4683
1193.23	4542
1192.68	4586.75
1192.13	4599
1191.57	4570.5
1191.02	4700
1190.47	4774.25
1189.91	4649
1189.36	4772
1188.81	4797
1188.26	4780.5
1187.7	4803.25
1187.15	4809.5
1186.6	4836.75
1186.04	4877.25
1185.49	4881.25
1184.94	4820
1184.38	4836.25
1183.83	4766.25
1183.28	4756
1182.72	4811
1182.17	4867.75
1181.61	4740.5
1181.06	4679
1180.51	4720.25
1179.95	4706
1179.4	4767
1178.85	4725
1178.29	4649.25
1177.74	4696.25
1177.18	4688.75
1176.63	4598.25
1176.07	4640.75
1175.52	4592.75
1174.97	4653.25
1174.41	4611.5
1173.86	4643
1173.3	4682.75
1172.75	4636.25
1172.19	4631.75
1171.64	4637
1171.09	4697.25
1170.53	4660
1169.97	4732.5
1169.42	4723.75
1168.86	4679.75
1168.31	4818.75
1167.76	4882.5
1167.2	4873.5
1166.65	4972.5
1166.09	5109
1165.53	5107.75
1164.98	5176.75
1164.42	5378.75
1163.87	5555.25
1163.31	5619.5
1162.76	5713.5
1162.2	6018.75
1161.65	6150.5
1161.09	6259.75
1160.54	6226
1159.98	6410.5
1159.42	6249.75
1158.87	6157.25
1158.31	6005.25
1157.76	5999.75
1157.2	5753.25
1156.65	5665
1156.09	5549
1155.53	5459.75
1154.98	5275.5
1154.42	5230
1153.86	5061
1153.31	5022.5
1152.75	4967.25
1152.19	4991
1151.64	4919.5
1151.08	4855.75
1150.52	4836.25
1149.97	4782.25
1149.41	4758.5
1148.86	4776
1148.3	4752.75
1147.74	4641.75
1147.18	4716.75
1146.63	4688.75
1146.07	4629.5
1145.51	4547.75
1144.96	4657.5
1144.4	4722
1143.84	4639.25
1143.28	4578.75
1142.73	4630
1142.17	4528.25
1141.61	4558
1141.06	4473.75
1140.5	4589.5
1139.94	4589.5
1139.38	4582.25
1138.83	4482.25
1138.27	4533.5
1137.71	4543
1137.15	4487.75
1136.59	4478.75
1136.04	4539.25
1135.48	4470
1134.92	4480.75
1134.36	4481.25
1133.8	4479.75
1133.25	4444.5
1132.69	4510
1132.13	4462.25
1131.57	4488.75
1131.01	4417
1130.45	4446
1129.9	4422.75
1129.34	4487
1128.78	4481
1128.22	4526
1127.66	4445.75
1127.1	4535.25
1126.54	4466.75
1125.98	4499.75
1125.43	4434.25
1124.87	4512
1124.31	4483
1123.75	4485
1123.19	4516.5
1122.63	4526.5
1122.07	4492
1121.51	4562.5
1120.95	4486.5
1120.39	4656.75
1119.83	4574
1119.27	4627
1118.72	4588.25
1118.15	4627.75
1117.6	4625.25
1117.04	4582.75
1116.48	4685
1115.92	4758.75
1115.36	4675.75
1114.8	4723
1114.24	4839
1113.68	4899.5
1113.12	4844.5
1112.56	4870.5
1112	4877.5
1111.44	4800.25
1110.88	4771
1110.32	4689
1109.76	4782.5
1109.19	4742.25
1108.64	4645.5
1108.07	4616.25
1107.51	4631.5
1106.95	4604.75
1106.39	4467.25
1105.83	4471
1105.27	4552.25
1104.71	4485
1104.15	4476.75
1103.59	4411
1103.03	4420.75
1102.47	4375.75
1101.91	4371
1101.34	4401.25
1100.78	4315.5
1100.22	4308.75
1099.66	4360.25
1099.1	4371.75
1098.54	4358.25
1097.98	4378.5
1097.41	4344.25
1096.85	4351.5
1096.29	4373.25
1095.73	4358.75
1095.17	4294
1094.61	4293
1094.04	4271.5
1093.48	4284.75
1092.92	4356.75
1092.36	4329.25
1091.8	4282.5
1091.23	4332.5
1090.67	4299
1090.11	4320.75
1089.55	4348.25
1088.99	4321.5
1088.42	4275.5
1087.86	4310.25
1087.3	4298
1086.74	4284
1086.17	4284.25
1085.61	4407
1085.05	4336.25
1084.49	4334.5
1083.92	4397.5
1083.36	4461.25
1082.8	4463
1082.23	4407.75
1081.67	4514.5
1081.11	4466.5
1080.55	4467.75
1079.98	4457.75
1079.42	4469
1078.86	4487
1078.29	4374.5
1077.73	4321.5
1077.17	4384
1076.6	4405.75
1076.04	4336.25
1075.48	4312.5
1074.91	4296.5
1074.35	4311.75
1073.79	4315
1073.22	4299.25
1072.66	4412.25
1072.09	4413.75
1071.53	4367
1070.97	4379.25
1070.4	4354
1069.84	4307.75
1069.27	4388
1068.71	4397.75
1068.15	4429
1067.58	4492.75
1067.02	4461.5
1066.45	4487
1065.89	4546.5
1065.32	4538.75
1064.76	4574.5
1064.19	4547
1063.63	4522
1063.07	4476.75
1062.5	4485
1061.94	4413.75
1061.37	4419.5
1060.81	4404
1060.24	4323.25
1059.68	4322.75
1059.11	4271.25
1058.55	4254.75
1057.98	4286.25
1057.42	4317.75
1056.85	4326.5
1056.29	4178.25
1055.72	4262.75
1055.16	4202.5
1054.59	4245.25
1054.03	4229.5
1053.46	4222
1052.89	4194.5
1052.33	4291.5
1051.76	4195
1051.2	4164.75
1050.63	4270.75
1050.06	4212.5
1049.5	4193.75
1048.93	4193
1048.37	4241.25
1047.8	4199.75
1047.24	4154
1046.67	4197.25
1046.1	4252.5
1045.54	4164.75
1044.97	4200.25
1044.4	4187.25
1043.84	4190.25
1043.27	4251.75
1042.7	4178.25
1042.14	4217.75
1041.57	4237
1041.01	4164.25
1040.44	4119.25
1039.87	4221.25
1039.3	4154.5
1038.74	4137.25
1038.17	4116.25
1037.6	4140.5
1037.04	4223
1036.47	4142.75
1035.9	4112.5
1035.34	4246.5
1034.77	4133
1034.2	4093
1033.63	4080.5
1033.07	4151
1032.5	4063.75
1031.93	4117
1031.36	4075.25
1030.8	4159.25
1030.23	4048.25
1029.66	4106.5
1029.09	4035
1028.52	4114
1027.96	4068
1027.39	3982
1026.82	4162.5
1026.25	4110.25
1025.68	4138
1025.12	4001.5
1024.55	4136.5
1023.98	4100.75
1023.41	4019.25
1022.84	4014.75
1022.28	4039.5
1021.71	4040
1021.14	3982.25
1020.57	4083.25
1020	4094.75
1019.43	4053.75
1018.86	4050.5
1018.3	4018
1017.73	4028.75
1017.16	4070
1016.59	4075.75
1016.3	4032.5