File: Testing/Hickernall_HORIBA/g47-mi1-bub1_02.txt
#Acq. time (s)=	75
#Accumulations=	5
#Range=	Off
#Autofocus=	Off
#Macrospot=	Off
#AutoExposure=	Off
#Spike filter=	Multiple accum.
#Delay time (s)=	0
#Binning=	1
#Readout mode=	Signal
#DeNoise=	Off
#ICS correction=	Off
#Dark correction=	Off
#Inst. Process=	Off
#Instrument=	LabRAM HR Evol
#Detector=	Andor CCD
#Objective=	x100 LWD
#Grating=	1800 gr/mm
#ND Filter=	100%
#Laser (nm)=	532
#Spectro (cm-¹)=	1240.02
#Hole=	49.98
#Range=	Visible
#AFM=	Off
#StageXY=	Marzhauser
#StageZ=	Marzhauser
#X (µm)=	-16419.4
#Y (µm)=	-903.3
#Z (µm)=	-369.6
#Project=
#Sample=
#Site=
#Title=	g47-mi1-bub1
#Remark=
#Date=	06.05.2022 11:50
#Acquired=	06.05.2022 11:50:49
1454.81	12776
1454.28	12699.3
1453.75	12702.8
1453.22	12939.3
1452.69	12771
1452.16	12691.3
1451.64	12631.8
1451.11	12685.3
1450.58	12680.8
1450.05	12692
1449.52	12532.8
1448.99	12828.3
1448.46	12716.3
1447.93	12702.5
1447.4	12577.5
1446.88	12770
1446.35	12786.8
1445.82	12677.3
1445.29	12641
1444.76	12556.3
1444.23	12695
1443.7	12767.8
1443.17	12642.5
1442.64	12591.8
1442.11	12797
1441.58	12592.3
1441.05	12670
1440.52	12475.5
1439.99	12768
1439.46	12666.3
1438.93	12713.3
1438.4	12531.5
1437.87	12602.8
1437.34	12648
1436.81	12643.5
1436.28	12570
1435.75	12528.5
1435.22	12695
1434.69	12628.3
1434.16	12504.8
1433.63	12367.8
1433.1	12568.3
1432.57	12491.5
1432.04	12505.8
1431.51	12270
1430.98	12678.8
1430.45	12514.3
1429.92	12486.5
1429.39	12307
1428.86	12539.5
1428.33	12624.8
1427.8	12275.5
1427.26	12312
1426.73	12420.5
1426.2	12628.3
1425.67	12361.8
1425.14	12374.3
1424.61	12235
1424.08	12538.5
1423.55	12252
1423.02	12413
1422.49	12232.3
1421.95	12594.3
1421.42	12394.3
1420.89	12381.5
1420.36	12240
1419.83	12516.3
1419.3	12486.5
1418.76	12227.8
1418.23	12295.8
1417.7	12288.5
1417.17	12410.5
1416.64	12241
1416.1	12430.5
1415.57	12283.8
1415.04	12371
1414.51	12047.5
1413.98	12267
1413.44	12291.3
1412.91	12583.3
1412.38	12195.5
1411.85	12214.8
1411.32	12191.8
1410.78	12381
1410.25	12329.8
1409.72	12190.3
1409.18	12374.8
1408.65	12316.8
1408.12	12249
1407.59	12028.3
1407.05	12238.5
1406.52	12248.8
1405.99	12267.3
1405.46	12055.8
1404.92	12116.8
1404.39	12193
1403.86	12289
1403.32	12148
1402.79	12124.3
1402.26	12252
1401.72	12205.3
1401.19	12187.8
1400.66	12021.5
1400.12	12229.3
1399.59	12058.3
1399.06	12104.3
1398.52	11962.3
1397.99	12234.5
1397.46	12100.3
1396.92	12090.5
1396.39	11939
1395.85	12068.3
1395.32	12016.5
1394.79	12093.5
1394.25	11825.8
1393.72	12028.5
1393.18	12113.3
1392.65	11911.3
1392.12	11937.8
1391.58	12101.5
1391.05	12155.3
1390.51	12099.5
1389.98	12372.3
1389.44	12552
1388.91	13040
1388.38	13078
1387.84	13153.8
1387.31	12828.5
1386.77	12426
1386.24	11921
1385.7	11977.8
1385.17	11968.5
1384.63	12227.8
1384.1	11977.8
1383.56	11975
1383.03	11954.5
1382.49	12046.5
1381.96	11965
1381.42	11948.3
1380.89	11814.3
1380.35	12034.3
1379.82	11993.8
1379.28	11810.5
1378.74	11832.5
1378.21	11940
1377.67	12112.5
1377.14	11890.8
1376.6	11890.5
1376.07	11840.5
1375.53	11995.3
1374.99	11812.8
1374.46	11840.8
1373.92	11945.3
1373.39	11979.5
1372.85	11766.8
1372.32	11791
1371.78	11803
1371.24	11893.8
1370.71	11783
1370.17	11719
1369.63	11817.3
1369.1	11930.5
1368.56	11813
1368.03	11739.3
1367.49	11769
1366.95	11738.5
1366.42	11905.8
1365.88	11647.8
1365.34	11818
1364.81	11814.5
1364.27	11880.8
1363.73	11610.8
1363.19	11809.8
1362.66	11684.8
1362.12	11827.8
1361.58	11712
1361.05	11674.3
1360.51	11859.8
1359.97	11831
1359.44	11603
1358.9	11585.8
1358.36	11757.8
1357.82	11793.5
1357.29	11720
1356.75	11613.5
1356.21	11739.3
1355.67	11689.3
1355.14	11587.8
1354.6	11562.8
1354.06	11869
1353.52	11597.8
1352.99	11662.5
1352.45	11569.3
1351.91	11867.5
1351.37	11582.8
1350.83	11568.5
1350.3	11543.5
1349.76	11787
1349.22	11503
1348.68	11534.8
1348.14	11362.5
1347.6	11693.8
1347.06	11675.3
1346.53	11562.5
1345.99	11489.8
1345.45	11498
1344.91	11752.8
1344.37	11508.5
1343.83	11423.3
1343.3	11612.5
1342.76	11537
1342.22	11510.5
1341.68	11433.5
1341.14	11371
1340.6	11574
1340.06	11421.5
1339.52	11568.5
1338.98	11368.5
1338.45	11649.5
1337.91	11374.8
1337.37	11307.8
1336.83	11341.8
1336.29	11547.3
1335.75	11397
1335.21	11312.3
1334.67	11335.3
1334.13	11465.3
1333.59	11486
1333.05	11329
1332.51	11302.3
1331.97	11407.5
1331.43	11428.3
1330.89	11234.8
1330.35	11318
1329.81	11245.3
1329.27	11391.3
1328.73	11059.3
1328.19	11388.8
1327.65	11312.3
1327.11	11444
1326.57	11267.8
1326.03	11308.8
1325.49	11304.5
1324.95	11546.3
1324.41	11165.8
1323.87	11184.3
1323.33	11248
1322.79	11295
1322.25	11202
1321.71	11150.5
1321.16	11305.5
1320.62	11280.5
1320.08	11224.5
1319.54	11052.5
1319	11203.3
1318.46	11199.5
1317.92	11262.8
1317.38	11057.8
1316.84	11226.8
1316.29	11255.8
1315.75	11176.3
1315.21	10925.8
1314.67	11353.5
1314.13	11228
1313.59	11208
1313.05	11058.5
1312.5	11239.3
1311.96	11092.8
1311.42	11248.3
1310.88	11010
1310.34	11052.3
1309.8	11210.3
1309.25	11106.5
1308.71	11062.3
1308.17	11107.5
1307.63	11134.5
1307.09	11059
1306.54	11072.8
1306	11009.5
1305.46	11126.5
1304.92	11072
1304.38	11101.3
1303.83	11045.8
1303.29	11326
1302.75	11109.3
1302.21	11173.5
1301.66	10907.8
1301.12	11149.5
1300.58	11062
1300.04	11187.3
1299.49	10996.8
1298.95	11124.8
1298.41	11189
1297.86	11167.8
1297.32	10927
1296.78	11004
1296.23	11123.3
1295.69	11016.3
1295.15	11049
1294.6	10994
1294.06	11175.5
1293.52	11099.3
1292.97	10959.3
1292.43	10909.3
1291.89	11135
1291.34	10895.3
1290.8	10938.8
1290.26	10866.5
1289.71	11120.3
1289.17	10825.5
1288.63	10952.5
1288.08	11036
1287.54	11185.5
1286.99	10999.5
1286.45	11479.8
1285.9	11488
1285.36	11924
1284.82	11673.5
1284.27	11261.8
1283.73	11037.8
1283.19	10911.5
1282.64	10836.3
1282.1	10922.8
1281.55	10829.8
1281.01	10957.5
1280.46	10909
1279.92	10820
1279.37	10966.3
1278.83	10961
1278.28	10935
1277.74	10738
1277.19	10935.5
1276.65	10801.3
1276.1	10806
1275.56	10660.5
1275.01	10926.8
1274.47	10823.3
1273.92	10884
1273.38	10644
1272.83	10847.5
1272.29	10918.5
1271.74	10961.3
1271.2	10774.3
1270.65	10902.5
1270.11	10828.5
1269.56	10992.8
1269.01	10682.8
1268.47	10869.3
1267.92	10877.5
1267.38	10943.8
1266.83	10912
1266.29	10825.5
1265.74	10893.5
1265.19	10864
1264.65	10906.3
1264.1	10841.8
1263.55	10978
1263.01	10825.3
1262.46	10806.3
1261.92	10761.3
1261.37	10968.8
1260.82	10802.3
1260.28	10826
1259.73	10760
1259.18	11023.8
1258.64	10799.3
1258.09	10805.3
1257.55	10861.5
1257	10985
1256.45	10802.3
1255.9	10818.8
1255.36	10839.8
1254.81	10893
1254.26	10911.3
1253.72	10841.8
1253.17	10862.8
1252.62	10886.3
1252.07	10962.5
1251.53	10785.3
1250.98	10882.8
1250.43	10990
1249.89	10976.8
1249.34	10871.5
1248.79	10893.8
1248.24	10965
1247.7	10933.5
1247.15	10846.5
1246.6	10849.3
1246.05	10921
1245.5	10971.5
1244.96	10693
1244.41	10850.8
1243.86	10957
1243.31	10874.8
1242.77	10733
1242.22	10895.8
1241.67	10933.5
1241.12	11055
1240.57	10799.5
1240.02	10943.8
1239.48	10985.3
1238.93	10987.5
1238.38	10802.5
1237.83	10795.5
1237.28	10887.3
1236.73	11066.5
1236.18	10830
1235.64	10931.5
1235.09	11044.5
1234.54	11009.3
1233.99	10940.5
1233.44	10963.3
1232.89	10956.8
1232.34	10930.5
1231.79	10828.5
1231.24	10883.5
1230.69	11068.8
1230.15	10947.5
1229.6	10857
1229.05	10807
1228.5	10983
1227.95	10917.8
1227.4	10842
1226.85	10791.3
1226.3	10902.3
1225.75	10849.5
1225.2	10780
1224.65	10788.5
1224.1	10855.5
1223.55	10848.5
1223	10741.5
1222.45	10674.8
1221.9	10817.5
1221.35	10644
1220.8	10626.8
1220.25	10619
1219.7	10769.5
1219.15	10636.3
1218.6	10677.3
1218.05	10631.3
1217.5	10786.8
1216.95	10689.5
1216.4	10475.3
1215.85	10563.8
1215.3	10719
1214.75	10510
1214.2	10430.8
1213.65	10512.8
1213.09	10633.8
1212.54	10422.8
1211.99	10478.5
1211.44	10369.5
1210.89	10429.8
1210.34	10404.5
1209.79	10398.5
1209.24	10420.8
1208.69	10492.5
1208.14	10389.8
1207.58	10356.5
1207.03	10321.8
1206.48	10383.5
1205.93	10411.3
1205.38	10336.8
1204.83	10397
1204.27	10464
1203.72	10433
1203.17	10227.8
1202.62	10405
1202.07	10444.8
1201.52	10418.3
1200.96	10306.5
1200.41	10199.5
1199.86	10384.5
1199.31	10402.8
1198.76	10215.8
1198.2	10240.5
1197.65	10267.8
1197.1	10267
1196.55	10089
1196	10294
1195.44	10250
1194.89	10325.5
1194.34	10099.8
1193.78	10273.8
1193.23	10217.5
1192.68	10377.5
1192.13	10018.8
1191.57	10409.8
1191.02	10383.8
1190.47	10405.3
1189.91	10151.5
1189.36	10361.5
1188.81	10420.8
1188.26	10527
1187.7	10200
1187.15	10453.5
1186.6	10458
1186.04	10505.3
1185.49	10443
1184.94	10382.3
1184.38	10340.3
1183.83	10531
1183.28	10270.5
1182.72	10327.8
1182.17	10343.8
1181.61	10304
1181.06	10162
1180.51	10289.5
1179.95	10278
1179.4	10353.8
1178.85	10214.3
1178.29	10131.8
1177.74	10241
1177.18	10157.5
1176.63	10186.5
1176.07	10112.8
1175.52	10338
1174.97	10125
1174.41	10165.5
1173.86	10062
1173.3	10185.5
1172.75	10091.8
1172.19	10196.8
1171.64	10051.5
1171.09	10373.5
1170.53	10099.5
1169.97	10215
1169.42	10165.5
1168.86	10278.8
1168.31	10295.8
1167.76	10346.5
1167.2	10386
1166.65	10431.5
1166.09	10495.8
1165.53	10618.5
1164.98	10588.8
1164.42	10989
1163.87	10980.3
1163.31	11190.8
1162.76	11310
1162.2	11628.3
1161.65	11490.5
1161.09	11570.3
1160.54	11840.5
1159.98	11810.3
1159.42	11583.8
1158.87	11592.3
1158.31	11414
1157.76	11481.5
1157.2	11057.3
1156.65	10975.3
1156.09	10842
1155.53	10848
1154.98	10670.8
1154.42	10464
1153.86	10499
1153.31	10543.8
1152.75	10351.3
1152.19	10217.3
1151.64	10271.8
1151.08	10314
1150.52	9993.25
1149.97	10047.8
1149.41	10108.3
1148.86	10101.3
1148.3	9985.5
1147.74	10046.5
1147.18	10058.5
1146.63	9983.75
1146.07	9936
1145.51	9924.5
1144.96	9939
1144.4	9944.25
1143.84	9938
1143.28	9817.25
1142.73	10012.5
1142.17	9777.5
1141.61	9863.5
1141.06	9738.25
1140.5	9898
1139.94	9884.75
1139.38	9817.75
1138.83	9747.25
1138.27	9852.75
1137.71	9717
1137.15	9834.75
1136.59	9707.75
1136.04	9891.5
1135.48	9760.75
1134.92	9696.75
1134.36	9618.75
1133.8	9828.25
1133.25	9610
1132.69	9595.75
1132.13	9599.75
1131.57	9743
1131.01	9652
1130.45	9731.25
1129.9	9663
1129.34	9796.5
1128.78	9619
1128.22	9700.25
1127.66	9548.75
1127.1	9802.75
1126.54	9773.5
1125.98	9676
1125.43	9647.5
1124.87	9822.25
1124.31	9653.75
1123.75	9661
1123.19	9693.75
1122.63	9843.5
1122.07	9599
1121.51	9749.5
1120.95	9681.5
1120.39	9756.25
1119.83	9657.25
1119.27	9825.5
1118.72	9692
1118.15	9798.75
1117.6	9683.5
1117.04	9782.5
1116.48	9714.5
1115.92	9834.5
1115.36	9795.5
1114.8	9752.75
1114.24	9918
1113.68	9965.25
1113.12	9775.25
1112.56	9823.25
1112	9796.75
1111.44	9796.25
1110.88	9785
1110.32	9750.25
1109.76	9755.25
1109.19	9719.25
1108.64	9638
1108.07	9733.75
1107.51	9688
1106.95	9705.25
1106.39	9521.75
1105.83	9534.75
1105.27	9496.5
1104.71	9490
1104.15	9474
1103.59	9521.5
1103.03	9485.5
1102.47	9571
1101.91	9331.75
1101.34	9427.75
1100.78	9487
1100.22	9437
1099.66	9420.25
1099.1	9257.75
1098.54	9377.25
1097.98	9358
1097.41	9219
1096.85	9382.5
1096.29	9392.5
1095.73	9322.75
1095.17	9403
1094.61	9475.25
1094.04	9334.75
1093.48	9254.25
1092.92	9340
1092.36	9317.5
1091.8	9303.75
1091.23	9255.5
1090.67	9154.5
1090.11	9407.25
1089.55	9334.5
1088.99	9245.5
1088.42	9275
1087.86	9334.5
1087.3	9331.75
1086.74	9213
1086.17	9312.5
1085.61	9364.5
1085.05	9315.5
1084.49	9240.5
1083.92	9288
1083.36	9381.5
1082.8	9380.5
1082.23	9371.25
1081.67	9383.25
1081.11	9495
1080.55	9331.75
1079.98	9387.75
1079.42	9400.75
1078.86	9410.75
1078.29	9313.25
1077.73	9245
1077.17	9247.25
1076.6	9384.25
1076.04	9245.25
1075.48	9202.25
1074.91	9397.5
1074.35	9280.25
1073.79	9283.75
1073.22	9257
1072.66	9292
1072.09	9289.75
1071.53	9156.75
1070.97	9293.25
1070.4	9446.5
1069.84	9368.75
1069.27	9291.25
1068.71	9387
1068.15	9451.25
1067.58	9410
1067.02	9387.25
1066.45	9309.5
1065.89	9515.5
1065.32	9526.5
1064.76	9345.5
1064.19	9349.75
1063.63	9378.5
1063.07	9375.25
1062.5	9332.75
1061.94	9317.75
1061.37	9290
1060.81	9191.75
1060.24	9112.25
1059.68	9232
1059.11	9208.75
1058.55	9042.5
1057.98	9082.75
1057.42	9070.5
1056.85	9036.5
1056.29	8951.5
1055.72	8984.5
1055.16	9108
1054.59	9002.25
1054.03	8952.25
1053.46	8983.5
1052.89	9077.25
1052.33	9026.5
1051.76	8990.75
1051.2	9048.75
1050.63	8976.25
1050.06	9076.25
1049.5	8912
1048.93	9054.75
1048.37	9085.25
1047.8	8997.75
1047.24	8930.25
1046.67	8921.75
1046.1	9068.5
1045.54	8974.25
1044.97	8875.75
1044.4	8994.25
1043.84	9030
1043.27	8928.75
1042.7	8807.5
1042.14	8852.75
1041.57	8965.5
1041.01	8904.75
1040.44	8724.25
1039.87	8843.5
1039.3	8913.25
1038.74	8851.5
1038.17	8752.75
1037.6	8813.5
1037.04	8913.75
1036.47	8813.75
1035.9	8780.75
1035.34	8923.75
1034.77	8848.25
1034.2	8684.25
1033.63	8828.75
1033.07	8821.75
1032.5	8785
1031.93	8728.75
1031.36	8696.75
1030.8	8769
1030.23	8652.75
1029.66	8664.25
1029.09	8698.75
1028.52	8750
1027.96	8824.75
1027.39	8687.75
1026.82	8729.25
1026.25	8662.25
1025.68	8709
1025.12	8689.5
1024.55	8806.25
1023.98	8748.5
1023.41	8558.75
1022.84	8630
1022.28	8834.75
1021.71	8623.25
1021.14	8575.75
1020.57	8639.25
1020	8745.75
1019.43	8687
1018.86	8561.75
1018.3	8610.5
1017.73	8742.5
1017.16	8540.5
1016.59	8643.5
1016.3	8527.25