File: Testing/Hickernall_HORIBA/Ne1_01.txt
#Acq. time (s)=	35
#Accumulations=	2
#Range=	Off
#Autofocus=	Off
#Macrospot=	Off
#AutoExposure=	Off
#Spike filter=	Multiple accum.
#Delay time (s)=	0
#Binning=	1
#Readout mode=	Signal
#DeNoise=	Off
#ICS correction=	Off
#Dark correction=	Off
#Inst. Process=	Off
#Instrument=	LabRAM HR Evol
#Detector=	Andor CCD
#Objective=	x100 LWD
#Grating=	1800 gr/mm
#ND Filter=	0.01%
#Laser (nm)=	532
#Spectro (cm-¹)=	1240.02
#Hole=	49.98
#Range=	Visible
#AFM=	Off
#StageXY=	Marzhauser
#StageZ=	Marzhauser
#X (µm)=	-7094.6
#Y (µm)=	-1434
#Z (µm)=	-275.1
#Project=
#Sample=
#Site=
#Title=	Ne1
#Remark=
#Date=	06.05.2022 08:07
#Acquired=	06.05.2022 08:07:26
1454.81	62
1454.28	45
1453.75	52
1453.22	52
1452.69	58
1452.16	52
1451.64	64
1451.11	57
1450.58	79
1450.05	72
1449.52	112
1448.99	148
1448.46	251
1447.93	479
1447.4	5333
1446.88	39167
1446.35	42820
1445.82	10553
1445.29	2468
1444.76	794
1444.23	240
1443.7	159
1443.17	124
1442.64	120
1442.11	104
1441.58	82
1441.05	78
1440.52	85
1439.99	54
1439.46	60
1438.93	64
1438.4	51
1437.87	61
1437.34	52
1436.81	65
1436.28	68
1435.75	346
1435.22	1279
1434.69	1067
1434.16	202
1433.63	51
1433.1	47
1432.57	38
1432.04	39
1431.51	42
1430.98	39
1430.45	44
1429.92	50
1429.39	36
1428.86	35
1428.33	43
1427.8	40
1427.26	33
1426.73	34
1426.2	43
1425.67	33
1425.14	37
1424.61	34
1424.08	25
1423.55	40
1423.02	36
1422.49	35
1421.95	41
1421.42	35
1420.89	33
1420.36	34
1419.83	35
1419.3	36
1418.76	33
1418.23	36
1417.7	31
1417.17	40
1416.64	29
1416.1	29
1415.57	28
1415.04	29
1414.51	28
1413.98	31
1413.44	31
1412.91	31
1412.38	28
1411.85	33
1411.32	30
1410.78	24
1410.25	35
1409.72	35
1409.18	32
1408.65	33
1408.12	28
1407.59	36
1407.05	38
1406.52	36
1405.99	22
1405.46	36
1404.92	35
1404.39	39
1403.86	29
1403.32	28
1402.79	35
1402.26	40
1401.72	53
1401.19	52
1400.66	64
1400.12	78
1399.59	300
1399.06	831
1398.52	4737
1397.99	10670
1397.46	5288
1396.92	503
1396.39	112
1395.85	57
1395.32	54
1394.79	56
1394.25	50
1393.72	31
1393.18	49
1392.65	39
1392.12	37
1391.58	33
1391.05	34
1390.51	28
1389.98	35
1389.44	35
1388.91	33
1388.38	28
1387.84	29
1387.31	21
1386.77	37
1386.24	39
1385.7	36
1385.17	22
1384.63	27
1384.1	18
1383.56	27
1383.03	31
1382.49	33
1381.96	26
1381.42	26
1380.89	31
1380.35	28
1379.82	34
1379.28	26
1378.74	24
1378.21	31
1377.67	28
1377.14	28
1376.6	28
1376.07	29
1375.53	31
1374.99	29
1374.46	32
1373.92	27
1373.39	29
1372.85	28
1372.32	67
1371.78	652
1371.24	1106
1370.71	426
1370.17	66
1369.63	46
1369.1	34
1368.56	53
1368.03	124
1367.49	101
1366.95	38
1366.42	42
1365.88	48
1365.34	31
1364.81	37
1364.27	27
1363.73	24
1363.19	22
1362.66	26
1362.12	27
1361.58	27
1361.05	22
1360.51	24
1359.97	29
1359.44	31
1358.9	32
1358.36	29
1357.82	31
1357.29	30
1356.75	20
1356.21	23
1355.67	20
1355.14	25
1354.6	29
1354.06	23
1353.52	22
1352.99	27
1352.45	25
1351.91	23
1351.37	24
1350.83	26
1350.3	31
1349.76	25
1349.22	30
1348.68	20
1348.14	26
1347.6	18
1347.06	23
1346.53	22
1345.99	23
1345.45	27
1344.91	28
1344.37	29
1343.83	25
1343.3	18
1342.76	22
1342.22	21
1341.68	25
1341.14	17
1340.6	28
1340.06	25
1339.52	22
1338.98	24
1338.45	20
1337.91	26
1337.37	25
1336.83	22
1336.29	25
1335.75	26
1335.21	21
1334.67	19
1334.13	25
1333.59	23
1333.05	22
1332.51	21
1331.97	16
1331.43	22
1330.89	28
1330.35	17
1329.81	32
1329.27	25
1328.73	17
1328.19	25
1327.65	24
1327.11	25
1326.57	21
1326.03	23
1325.49	24
1324.95	22
1324.41	17
1323.87	23
1323.33	20
1322.79	27
1322.25	17
1321.71	20
1321.16	25
1320.62	25
1320.08	14
1319.54	30
1319	24
1318.46	22
1317.92	29
1317.38	45
1316.84	36
1316.29	24
1315.75	19
1315.21	19
1314.67	35
1314.13	29
1313.59	33
1313.05	32
1312.5	25
1311.96	28
1311.42	46
1310.88	210
1310.34	508
1309.8	1679
1309.25	1609
1308.71	653
1308.17	369
1307.63	89
1307.09	34
1306.54	31
1306	27
1305.46	22
1304.92	33
1304.38	26
1303.83	23
1303.29	30
1302.75	20
1302.21	29
1301.66	28
1301.12	29
1300.58	32
1300.04	21
1299.49	22
1298.95	31
1298.41	34
1297.86	75
1297.32	48
1296.78	38
1296.23	20
1295.69	27
1295.15	25
1294.6	31
1294.06	17
1293.52	25
1292.97	24
1292.43	27
1291.89	24
1291.34	23
1290.8	30
1290.26	20
1289.71	25
1289.17	56
1288.63	37
1288.08	31
1287.54	25
1286.99	29
1286.45	25
1285.9	23
1285.36	26
1284.82	26
1284.27	23
1283.73	28
1283.19	27
1282.64	26
1282.1	28
1281.55	25
1281.01	25
1280.46	27
1279.92	22
1279.37	24
1278.83	14
1278.28	22
1277.74	27
1277.19	27
1276.65	27
1276.1	27
1275.56	23
1275.01	24
1274.47	28
1273.92	22
1273.38	18
1272.83	26
1272.29	25
1271.74	27
1271.2	17
1270.65	16
1270.11	24
1269.56	17
1269.01	20
1268.47	23
1267.92	28
1267.38	16
1266.83	19
1266.29	20
1265.74	32
1265.19	24
1264.65	17
1264.1	25
1263.55	21
1263.01	16
1262.46	25
1261.92	29
1261.37	17
1260.82	27
1260.28	26
1259.73	23
1259.18	22
1258.64	29
1258.09	32
1257.55	17
1257	28
1256.45	18
1255.9	20
1255.36	22
1254.81	25
1254.26	23
1253.72	56
1253.17	135
1252.62	75
1252.07	28
1251.53	25
1250.98	28
1250.43	25
1249.89	26
1249.34	26
1248.79	28
1248.24	18
1247.7	27
1247.15	13
1246.6	15
1246.05	16
1245.5	24
1244.96	21
1244.41	22
1243.86	20
1243.31	29
1242.77	24
1242.22	30
1241.67	27
1241.12	19
1240.57	25
1240.02	27
1239.48	20
1238.93	29
1238.38	24
1237.83	33
1237.28	26
1236.73	30
1236.18	24
1235.64	21
1235.09	21
1234.54	26
1233.99	27
1233.44	42
1232.89	22
1232.34	25
1231.79	25
1231.24	22
1230.69	20
1230.15	22
1229.6	17
1229.05	21
1228.5	20
1227.95	24
1227.4	26
1226.85	26
1226.3	22
1225.75	25
1225.2	34
1224.65	30
1224.1	24
1223.55	24
1223	22
1222.45	25
1221.9	35
1221.35	25
1220.8	44
1220.25	117
1219.7	913
1219.15	2986
1218.6	1756
1218.05	310
1217.5	66
1216.95	44
1216.4	45
1215.85	30
1215.3	30
1214.75	23
1214.2	27
1213.65	27
1213.09	22
1212.54	31
1211.99	37
1211.44	30
1210.89	47
1210.34	22
1209.79	37
1209.24	18
1208.69	25
1208.14	17
1207.58	21
1207.03	21
1206.48	23
1205.93	24
1205.38	23
1204.83	17
1204.27	35
1203.72	31
1203.17	24
1202.62	35
1202.07	23
1201.52	26
1200.96	23
1200.41	81
1199.86	60
1199.31	23
1198.76	26
1198.2	17
1197.65	25
1197.1	26
1196.55	26
1196	32
1195.44	47
1194.89	275
1194.34	400
1193.78	118
1193.23	27
1192.68	24
1192.13	28
1191.57	22
1191.02	25
1190.47	25
1189.91	21
1189.36	26
1188.81	25
1188.26	29
1187.7	20
1187.15	21
1186.6	23
1186.04	18
1185.49	26
1184.94	17
1184.38	27
1183.83	23
1183.28	20
1182.72	26
1182.17	21
1181.61	21
1181.06	25
1180.51	16
1179.95	27
1179.4	21
1178.85	25
1178.29	15
1177.74	21
1177.18	22
1176.63	18
1176.07	17
1175.52	26
1174.97	14
1174.41	18
1173.86	19
1173.3	27
1172.75	19
1172.19	19
1171.64	20
1171.09	25
1170.53	19
1169.97	20
1169.42	29
1168.86	22
1168.31	26
1167.76	23
1167.2	25
1166.65	23
1166.09	24
1165.53	27
1164.98	23
1164.42	13
1163.87	19
1163.31	29
1162.76	17
1162.2	22
1161.65	17
1161.09	19
1160.54	31
1159.98	23
1159.42	24
1158.87	25
1158.31	18
1157.76	21
1157.2	15
1156.65	24
1156.09	15
1155.53	20
1154.98	19
1154.42	23
1153.86	20
1153.31	23
1152.75	22
1152.19	25
1151.64	21
1151.08	24
1150.52	28
1149.97	17
1149.41	14
1148.86	24
1148.3	20
1147.74	18
1147.18	19
1146.63	21
1146.07	21
1145.51	25
1144.96	23
1144.4	25
1143.84	25
1143.28	23
1142.73	25
1142.17	25
1141.61	11
1141.06	18
1140.5	32
1139.94	21
1139.38	22
1138.83	28
1138.27	29
1137.71	20
1137.15	27
1136.59	15
1136.04	27
1135.48	50
1134.92	456
1134.36	1313
1133.8	574
1133.25	76
1132.69	47
1132.13	28
1131.57	22
1131.01	28
1130.45	28
1129.9	22
1129.34	16
1128.78	18
1128.22	25
1127.66	25
1127.1	27
1126.54	22
1125.98	22
1125.43	24
1124.87	15
1124.31	58
1123.75	234
1123.19	147
1122.63	37
1122.07	31
1121.51	27
1120.95	16
1120.39	24
1119.83	25
1119.27	30
1118.72	30
1118.15	38
1117.6	60
1117.04	122
1116.48	2034
1115.92	4702
1115.36	1485
1114.8	163
1114.24	534
1113.68	491
1113.12	96
1112.56	30
1112	32
1111.44	26
1110.88	27
1110.32	24
1109.76	27
1109.19	19
1108.64	28
1108.07	18
1107.51	24
1106.95	19
1106.39	28
1105.83	16
1105.27	27
1104.71	19
1104.15	52
1103.59	384
1103.03	681
1102.47	205
1101.91	30
1101.34	22
1100.78	22
1100.22	22
1099.66	25
1099.1	34
1098.54	28
1097.98	129
1097.41	656
1096.85	516
1096.29	60
1095.73	35
1095.17	20
1094.61	29
1094.04	16
1093.48	24
1092.92	25
1092.36	22
1091.8	36
1091.23	161
1090.67	186
1090.11	51
1089.55	21
1088.99	15
1088.42	23
1087.86	19
1087.3	20
1086.74	22
1086.17	24
1085.61	22
1085.05	19
1084.49	24
1083.92	27
1083.36	19
1082.8	21
1082.23	17
1081.67	10
1081.11	18
1080.55	26
1079.98	20
1079.42	18
1078.86	17
1078.29	28
1077.73	21
1077.17	20
1076.6	18
1076.04	19
1075.48	23
1074.91	23
1074.35	23
1073.79	18
1073.22	27
1072.66	20
1072.09	22
1071.53	17
1070.97	30
1070.4	20
1069.84	20
1069.27	26
1068.71	47
1068.15	129
1067.58	116
1067.02	30
1066.45	18
1065.89	18
1065.32	21
1064.76	20
1064.19	23
1063.63	16
1063.07	19
1062.5	19
1061.94	30
1061.37	53
1060.81	93
1060.24	45
1059.68	24
1059.11	24
1058.55	16
1057.98	18
1057.42	21
1056.85	21
1056.29	18
1055.72	48
1055.16	66
1054.59	34
1054.03	19
1053.46	19
1052.89	28
1052.33	21
1051.76	16
1051.2	22
1050.63	38
1050.06	118
1049.5	144
1048.93	54
1048.37	22
1047.8	24
1047.24	19
1046.67	21
1046.1	26
1045.54	24
1044.97	22
1044.4	18
1043.84	13
1043.27	31
1042.7	17
1042.14	25
1041.57	23
1041.01	15
1040.44	23
1039.87	19
1039.3	18
1038.74	31
1038.17	25
1037.6	21
1037.04	14
1036.47	24
1035.9	18
1035.34	20
1034.77	17
1034.2	19
1033.63	33
1033.07	27
1032.5	22
1031.93	19
1031.36	16
1030.8	19
1030.23	23
1029.66	22
1029.09	25
1028.52	27
1027.96	18
1027.39	29
1026.82	28
1026.25	18
1025.68	22
1025.12	19
1024.55	17
1023.98	22
1023.41	23
1022.84	24
1022.28	31
1021.71	27
1021.14	21
1020.57	22
1020	17
1019.43	20
1018.86	18
1018.3	22
1017.73	26
1017.16	27
1016.59	20
1016.3	20