File: Testing/Hickernall_HORIBA/Ne2_04.txt
#Acq. time (s)=	65
#Accumulations=	1
#Range=	Off
#Autofocus=	Off
#Macrospot=	Off
#AutoExposure=	Off
#Spike filter=	Multiple accum.
#Delay time (s)=	0
#Binning=	1
#Readout mode=	Signal
#DeNoise=	Off
#ICS correction=	Off
#Dark correction=	Off
#Inst. Process=	Off
#Instrument=	LabRAM HR Evol
#Detector=	Andor CCD
#Objective=	x100 LWD
#Grating=	1800 gr/mm
#ND Filter=	100%
#Laser (nm)=	532
#Spectro (cm-¹)=	1240.02
#Hole=	49.98
#Range=	Visible
#AFM=	Off
#StageXY=	Marzhauser
#StageZ=	Marzhauser
#X (µm)=	-5516.7
#Y (µm)=	-1264.3
#Z (µm)=	-324.5
#Project=
#Sample=
#Site=
#Title=	Ne2
#Remark=
#Date=	06.05.2022 08:39
#Acquired=	06.05.2022 08:39:44
1454.81	98
1454.28	118
1453.75	130
1453.22	91
1452.69	98
1452.16	136
1451.64	120
1451.11	119
1450.58	150
1450.05	145
1449.52	157
1448.99	188
1448.46	221
1447.93	336
1447.4	1116
1446.88	20154
1446.35	44742
1445.82	20564
1445.29	3315
1444.76	1206
1444.23	357
1443.7	257
1443.17	205
1442.64	187
1442.11	148
1441.58	132
1441.05	136
1440.52	148
1439.99	110
1439.46	122
1438.93	86
1438.4	96
1437.87	117
1437.34	128
1436.81	103
1436.28	107
1435.75	146
1435.22	859
1434.69	1241
1434.16	448
1433.63	141
1433.1	100
1432.57	98
1432.04	91
1431.51	95
1430.98	80
1430.45	93
1429.92	111
1429.39	104
1428.86	108
1428.33	107
1427.8	120
1427.26	99
1426.73	96
1426.2	119
1425.67	84
1425.14	89
1424.61	101
1424.08	105
1423.55	103
1423.02	82
1422.49	69
1421.95	100
1421.42	86
1420.89	81
1420.36	91
1419.83	84
1419.3	109
1418.76	85
1418.23	92
1417.7	102
1417.17	77
1416.64	86
1416.1	82
1415.57	97
1415.04	72
1414.51	91
1413.98	105
1413.44	100
1412.91	91
1412.38	111
1411.85	88
1411.32	119
1410.78	97
1410.25	81
1409.72	79
1409.18	100
1408.65	84
1408.12	93
1407.59	78
1407.05	80
1406.52	74
1405.99	111
1405.46	97
1404.92	96
1404.39	85
1403.86	103
1403.32	90
1402.79	89
1402.26	88
1401.72	87
1401.19	89
1400.66	94
1400.12	104
1399.59	174
1399.06	595
1398.52	1664
1397.99	8275
1397.46	7815
1396.92	1309
1396.39	222
1395.85	136
1395.32	90
1394.79	107
1394.25	100
1393.72	105
1393.18	115
1392.65	83
1392.12	93
1391.58	80
1391.05	92
1390.51	91
1389.98	71
1389.44	82
1388.91	71
1388.38	86
1387.84	91
1387.31	76
1386.77	81
1386.24	90
1385.7	100
1385.17	80
1384.63	88
1384.1	79
1383.56	80
1383.03	74
1382.49	76
1381.96	84
1381.42	81
1380.89	84
1380.35	83
1379.82	82
1379.28	82
1378.74	79
1378.21	99
1377.67	78
1377.14	99
1376.6	85
1376.07	68
1375.53	91
1374.99	75
1374.46	89
1373.92	95
1373.39	92
1372.85	77
1372.32	90
1371.78	318
1371.24	1090
1370.71	838
1370.17	195
1369.63	95
1369.1	109
1368.56	102
1368.03	161
1367.49	177
1366.95	115
1366.42	111
1365.88	108
1365.34	82
1364.81	88
1364.27	91
1363.73	80
1363.19	73
1362.66	82
1362.12	87
1361.58	75
1361.05	67
1360.51	76
1359.97	109
1359.44	83
1358.9	82
1358.36	87
1357.82	81
1357.29	84
1356.75	86
1356.21	98
1355.67	92
1355.14	65
1354.6	73
1354.06	71
1353.52	98
1352.99	89
1352.45	100
1351.91	93
1351.37	88
1350.83	59
1350.3	83
1349.76	81
1349.22	79
1348.68	84
1348.14	76
1347.6	95
1347.06	86
1346.53	97
1345.99	77
1345.45	79
1344.91	101
1344.37	93
1343.83	100
1343.3	72
1342.76	69
1342.22	86
1341.68	85
1341.14	93
1340.6	69
1340.06	84
1339.52	78
1338.98	85
1338.45	83
1337.91	85
1337.37	71
1336.83	71
1336.29	78
1335.75	100
1335.21	74
1334.67	86
1334.13	81
1333.59	87
1333.05	75
1332.51	83
1331.97	88
1331.43	70
1330.89	83
1330.35	58
1329.81	86
1329.27	94
1328.73	80
1328.19	68
1327.65	77
1327.11	79
1326.57	76
1326.03	89
1325.49	78
1324.95	76
1324.41	80
1323.87	88
1323.33	79
1322.79	72
1322.25	75
1321.71	73
1321.16	91
1320.62	78
1320.08	82
1319.54	79
1319	82
1318.46	83
1317.92	87
1317.38	91
1316.84	74
1316.29	86
1315.75	72
1315.21	84
1314.67	82
1314.13	68
1313.59	88
1313.05	93
1312.5	73
1311.96	96
1311.42	79
1310.88	181
1310.34	431
1309.8	1154
1309.25	1960
1308.71	913
1308.17	504
1307.63	229
1307.09	97
1306.54	78
1306	80
1305.46	89
1304.92	86
1304.38	94
1303.83	69
1303.29	84
1302.75	86
1302.21	81
1301.66	72
1301.12	101
1300.58	68
1300.04	75
1299.49	70
1298.95	72
1298.41	60
1297.86	108
1297.32	111
1296.78	83
1296.23	89
1295.69	88
1295.15	85
1294.6	87
1294.06	77
1293.52	75
1292.97	68
1292.43	71
1291.89	75
1291.34	67
1290.8	70
1290.26	76
1289.71	73
1289.17	109
1288.63	102
1288.08	81
1287.54	68
1286.99	77
1286.45	100
1285.9	86
1285.36	76
1284.82	92
1284.27	86
1283.73	77
1283.19	79
1282.64	93
1282.1	87
1281.55	69
1281.01	75
1280.46	73
1279.92	83
1279.37	73
1278.83	79
1278.28	93
1277.74	79
1277.19	87
1276.65	74
1276.1	81
1275.56	87
1275.01	79
1274.47	74
1273.92	92
1273.38	80
1272.83	97
1272.29	77
1271.74	62
1271.2	68
1270.65	81
1270.11	81
1269.56	80
1269.01	69
1268.47	69
1267.92	77
1267.38	66
1266.83	77
1266.29	72
1265.74	89
1265.19	87
1264.65	96
1264.1	76
1263.55	77
1263.01	80
1262.46	83
1261.92	68
1261.37	72
1260.82	65
1260.28	84
1259.73	68
1259.18	84
1258.64	89
1258.09	74
1257.55	87
1257	76
1256.45	86
1255.9	68
1255.36	79
1254.81	74
1254.26	91
1253.72	93
1253.17	154
1252.62	142
1252.07	97
1251.53	77
1250.98	82
1250.43	76
1249.89	92
1249.34	100
1248.79	76
1248.24	77
1247.7	82
1247.15	74
1246.6	83
1246.05	62
1245.5	71
1244.96	79
1244.41	83
1243.86	65
1243.31	69
1242.77	85
1242.22	87
1241.67	81
1241.12	73
1240.57	97
1240.02	89
1239.48	77
1238.93	73
1238.38	77
1237.83	86
1237.28	79
1236.73	85
1236.18	69
1235.64	65
1235.09	60
1234.54	77
1233.99	86
1233.44	109
1232.89	68
1232.34	70
1231.79	66
1231.24	77
1230.69	65
1230.15	81
1229.6	73
1229.05	85
1228.5	66
1227.95	87
1227.4	74
1226.85	97
1226.3	76
1225.75	81
1225.2	74
1224.65	82
1224.1	83
1223.55	80
1223	79
1222.45	93
1221.9	87
1221.35	72
1220.8	94
1220.25	131
1219.7	381
1219.15	2096
1218.6	2310
1218.05	629
1217.5	158
1216.95	96
1216.4	102
1215.85	86
1215.3	96
1214.75	92
1214.2	93
1213.65	89
1213.09	96
1212.54	97
1211.99	98
1211.44	87
1210.89	99
1210.34	95
1209.79	85
1209.24	79
1208.69	80
1208.14	79
1207.58	72
1207.03	100
1206.48	67
1205.93	66
1205.38	66
1204.83	86
1204.27	103
1203.72	66
1203.17	107
1202.62	87
1202.07	99
1201.52	82
1200.96	75
1200.41	116
1199.86	151
1199.31	96
1198.76	81
1198.2	90
1197.65	90
1197.1	90
1196.55	80
1196	86
1195.44	81
1194.89	193
1194.34	410
1193.78	248
1193.23	97
1192.68	108
1192.13	102
1191.57	83
1191.02	84
1190.47	83
1189.91	76
1189.36	82
1188.81	81
1188.26	82
1187.7	95
1187.15	76
1186.6	60
1186.04	100
1185.49	85
1184.94	75
1184.38	77
1183.83	76
1183.28	77
1182.72	70
1182.17	80
1181.61	94
1181.06	76
1180.51	75
1179.95	72
1179.4	71
1178.85	94
1178.29	92
1177.74	99
1177.18	69
1176.63	79
1176.07	90
1175.52	78
1174.97	73
1174.41	91
1173.86	93
1173.3	83
1172.75	99
1172.19	89
1171.64	86
1171.09	78
1170.53	120
1169.97	98
1169.42	90
1168.86	81
1168.31	88
1167.76	95
1167.2	84
1166.65	105
1166.09	71
1165.53	67
1164.98	83
1164.42	79
1163.87	78
1163.31	86
1162.76	78
1162.2	60
1161.65	76
1161.09	93
1160.54	82
1159.98	98
1159.42	98
1158.87	58
1158.31	81
1157.76	96
1157.2	99
1156.65	71
1156.09	83
1155.53	86
1154.98	76
1154.42	87
1153.86	91
1153.31	82
1152.75	82
1152.19	73
1151.64	83
1151.08	82
1150.52	93
1149.97	90
1149.41	89
1148.86	95
1148.3	96
1147.74	85
1147.18	84
1146.63	107
1146.07	67
1145.51	71
1144.96	95
1144.4	113
1143.84	86
1143.28	92
1142.73	90
1142.17	103
1141.61	89
1141.06	88
1140.5	83
1139.94	96
1139.38	87
1138.83	100
1138.27	97
1137.71	87
1137.15	88
1136.59	91
1136.04	78
1135.48	99
1134.92	191
1134.36	1029
1133.8	940
1133.25	196
1132.69	117
1132.13	98
1131.57	96
1131.01	83
1130.45	80
1129.9	77
1129.34	98
1128.78	85
1128.22	113
1127.66	87
1127.1	104
1126.54	95
1125.98	106
1125.43	90
1124.87	91
1124.31	95
1123.75	220
1123.19	259
1122.63	116
1122.07	104
1121.51	83
1120.95	110
1120.39	107
1119.83	80
1119.27	116
1118.72	71
1118.15	118
1117.6	103
1117.04	121
1116.48	601
1115.92	3842
1115.36	2896
1114.8	356
1114.24	390
1113.68	641
1113.12	254
1112.56	108
1112	96
1111.44	69
1110.88	119
1110.32	85
1109.76	96
1109.19	112
1108.64	114
1108.07	90
1107.51	74
1106.95	107
1106.39	82
1105.83	83
1105.27	85
1104.71	96
1104.15	115
1103.59	243
1103.03	702
1102.47	456
1101.91	121
1101.34	91
1100.78	71
1100.22	95
1099.66	102
1099.1	111
1098.54	99
1097.98	92
1097.41	528
1096.85	746
1096.29	227
1095.73	111
1095.17	94
1094.61	102
1094.04	89
1093.48	81
1092.92	98
1092.36	94
1091.8	106
1091.23	136
1090.67	255
1090.11	140
1089.55	94
1088.99	88
1088.42	91
1087.86	90
1087.3	79
1086.74	73
1086.17	91
1085.61	96
1085.05	78
1084.49	76
1083.92	83
1083.36	121
1082.8	90
1082.23	89
1081.67	93
1081.11	106
1080.55	79
1079.98	91
1079.42	86
1078.86	77
1078.29	73
1077.73	104
1077.17	84
1076.6	81
1076.04	90
1075.48	79
1074.91	100
1074.35	84
1073.79	81
1073.22	90
1072.66	89
1072.09	99
1071.53	101
1070.97	106
1070.4	86
1069.84	99
1069.27	85
1068.71	83
1068.15	167
1067.58	216
1067.02	114
1066.45	92
1065.89	87
1065.32	102
1064.76	94
1064.19	77
1063.63	78
1063.07	103
1062.5	101
1061.94	116
1061.37	113
1060.81	178
1060.24	130
1059.68	72
1059.11	105
1058.55	85
1057.98	99
1057.42	108
1056.85	106
1056.29	93
1055.72	95
1055.16	138
1054.59	130
1054.03	109
1053.46	76
1052.89	97
1052.33	98
1051.76	78
1051.2	112
1050.63	113
1050.06	135
1049.5	240
1048.93	140
1048.37	101
1047.8	91
1047.24	74
1046.67	113
1046.1	102
1045.54	77
1044.97	99
1044.4	95
1043.84	88
1043.27	150
1042.7	101
1042.14	118
1041.57	99
1041.01	99
1040.44	96
1039.87	101
1039.3	92
1038.74	93
1038.17	104
1037.6	102
1037.04	101
1036.47	107
1035.9	87
1035.34	116
1034.77	94
1034.2	114
1033.63	106
1033.07	125
1032.5	106
1031.93	84
1031.36	99
1030.8	91
1030.23	107
1029.66	114
1029.09	110
1028.52	97
1027.96	107
1027.39	118
1026.82	104
1026.25	100
1025.68	92
1025.12	83
1024.55	99
1023.98	104
1023.41	98
1022.84	113
1022.28	118
1021.71	97
1021.14	97
1020.57	89
1020	93
1019.43	89
1018.86	95
1018.3	101
1017.73	115
1017.16	118
1016.59	96
1016.3	98