File: Testing/Hickernall_HORIBA/Ne2_01.txt
#Acq. time (s)=	55
#Accumulations=	2
#Range=	Off
#Autofocus=	Off
#Macrospot=	Off
#AutoExposure=	Off
#Spike filter=	Multiple accum.
#Delay time (s)=	0
#Binning=	1
#Readout mode=	Signal
#DeNoise=	Off
#ICS correction=	Off
#Dark correction=	Off
#Inst. Process=	Off
#Instrument=	LabRAM HR Evol
#Detector=	Andor CCD
#Objective=	x100 LWD
#Grating=	1800 gr/mm
#ND Filter=	100%
#Laser (nm)=	532
#Spectro (cm-¹)=	1240.02
#Hole=	49.98
#Range=	Visible
#AFM=	Off
#StageXY=	Marzhauser
#StageZ=	Marzhauser
#X (µm)=	-5516.7
#Y (µm)=	-1264.3
#Z (µm)=	-324.5
#Project=
#Sample=
#Site=
#Title=	Ne2
#Remark=
#Date=	06.05.2022 08:31
#Acquired=	06.05.2022 08:31:46
1454.81	104
1454.28	95
1453.75	107
1453.22	111
1452.69	123
1452.16	123
1451.64	119
1451.11	121
1450.58	127
1450.05	143
1449.52	142
1448.99	172
1448.46	236
1447.93	329
1447.4	1157
1446.88	19802
1446.35	41927
1445.82	20437
1445.29	3079
1444.76	1306
1444.23	366
1443.7	224
1443.17	167
1442.64	187
1442.11	129
1441.58	141
1441.05	142
1440.52	111
1439.99	120
1439.46	126
1438.93	103
1438.4	105
1437.87	102
1437.34	107
1436.81	106
1436.28	93
1435.75	163
1435.22	823
1434.69	1194
1434.16	438
1433.63	130
1433.1	99
1432.57	97
1432.04	96
1431.51	76
1430.98	87
1430.45	99
1429.92	111
1429.39	109
1428.86	81
1428.33	102
1427.8	98
1427.26	97
1426.73	92
1426.2	86
1425.67	85
1425.14	93
1424.61	86
1424.08	90
1423.55	79
1423.02	86
1422.49	87
1421.95	82
1421.42	100
1420.89	99
1420.36	88
1419.83	85
1419.3	94
1418.76	96
1418.23	89
1417.7	91
1417.17	89
1416.64	98
1416.1	89
1415.57	93
1415.04	81
1414.51	87
1413.98	94
1413.44	85
1412.91	80
1412.38	83
1411.85	90
1411.32	89
1410.78	86
1410.25	80
1409.72	80
1409.18	95
1408.65	102
1408.12	86
1407.59	103
1407.05	91
1406.52	66
1405.99	95
1405.46	79
1404.92	98
1404.39	88
1403.86	97
1403.32	96
1402.79	93
1402.26	94
1401.72	95
1401.19	90
1400.66	101
1400.12	96
1399.59	208
1399.06	579
1398.52	1671
1397.99	7961
1397.46	7497
1396.92	1274
1396.39	206
1395.85	134
1395.32	119
1394.79	123
1394.25	91
1393.72	93
1393.18	97
1392.65	84
1392.12	88
1391.58	87
1391.05	88
1390.51	89
1389.98	87
1389.44	88
1388.91	72
1388.38	77
1387.84	68
1387.31	90
1386.77	95
1386.24	90
1385.7	94
1385.17	101
1384.63	86
1384.1	74
1383.56	73
1383.03	91
1382.49	83
1381.96	83
1381.42	81
1380.89	79
1380.35	93
1379.82	90
1379.28	88
1378.74	92
1378.21	99
1377.67	92
1377.14	88
1376.6	76
1376.07	83
1375.53	78
1374.99	98
1374.46	80
1373.92	82
1373.39	92
1372.85	77
1372.32	97
1371.78	322
1371.24	1055
1370.71	745
1370.17	166
1369.63	91
1369.1	101
1368.56	73
1368.03	156
1367.49	162
1366.95	116
1366.42	99
1365.88	86
1365.34	85
1364.81	73
1364.27	94
1363.73	80
1363.19	74
1362.66	87
1362.12	71
1361.58	78
1361.05	78
1360.51	85
1359.97	85
1359.44	77
1358.9	85
1358.36	66
1357.82	68
1357.29	105
1356.75	78
1356.21	77
1355.67	99
1355.14	73
1354.6	92
1354.06	73
1353.52	85
1352.99	90
1352.45	88
1351.91	96
1351.37	81
1350.83	73
1350.3	75
1349.76	86
1349.22	93
1348.68	74
1348.14	95
1347.6	88
1347.06	82
1346.53	83
1345.99	83
1345.45	79
1344.91	75
1344.37	85
1343.83	84
1343.3	63
1342.76	82
1342.22	71
1341.68	81
1341.14	79
1340.6	79
1340.06	75
1339.52	80
1338.98	66
1338.45	81
1337.91	80
1337.37	73
1336.83	69
1336.29	85
1335.75	79
1335.21	77
1334.67	75
1334.13	71
1333.59	82
1333.05	80
1332.51	79
1331.97	77
1331.43	70
1330.89	64
1330.35	77
1329.81	89
1329.27	75
1328.73	78
1328.19	80
1327.65	94
1327.11	82
1326.57	73
1326.03	86
1325.49	92
1324.95	81
1324.41	75
1323.87	80
1323.33	81
1322.79	83
1322.25	71
1321.71	74
1321.16	89
1320.62	67
1320.08	78
1319.54	80
1319	77
1318.46	96
1317.92	99
1317.38	85
1316.84	79
1316.29	80
1315.75	65
1315.21	79
1314.67	89
1314.13	85
1313.59	92
1313.05	72
1312.5	77
1311.96	81
1311.42	95
1310.88	134
1310.34	364
1309.8	1099
1309.25	1836
1308.71	891
1308.17	462
1307.63	228
1307.09	112
1306.54	88
1306	64
1305.46	75
1304.92	84
1304.38	68
1303.83	65
1303.29	76
1302.75	67
1302.21	80
1301.66	64
1301.12	90
1300.58	91
1300.04	80
1299.49	92
1298.95	67
1298.41	94
1297.86	85
1297.32	118
1296.78	96
1296.23	69
1295.69	70
1295.15	81
1294.6	80
1294.06	75
1293.52	69
1292.97	68
1292.43	76
1291.89	76
1291.34	69
1290.8	73
1290.26	71
1289.71	66
1289.17	65
1288.63	90
1288.08	104
1287.54	67
1286.99	70
1286.45	81
1285.9	73
1285.36	92
1284.82	87
1284.27	91
1283.73	77
1283.19	78
1282.64	85
1282.1	86
1281.55	69
1281.01	68
1280.46	74
1279.92	74
1279.37	77
1278.83	75
1278.28	75
1277.74	88
1277.19	77
1276.65	79
1276.1	76
1275.56	91
1275.01	87
1274.47	78
1273.92	68
1273.38	87
1272.83	95
1272.29	65
1271.74	70
1271.2	88
1270.65	77
1270.11	85
1269.56	64
1269.01	72
1268.47	74
1267.92	86
1267.38	88
1266.83	85
1266.29	79
1265.74	82
1265.19	68
1264.65	64
1264.1	80
1263.55	70
1263.01	90
1262.46	70
1261.92	67
1261.37	67
1260.82	82
1260.28	83
1259.73	71
1259.18	80
1258.64	93
1258.09	75
1257.55	81
1257	80
1256.45	69
1255.9	79
1255.36	71
1254.81	85
1254.26	72
1253.72	85
1253.17	150
1252.62	167
1252.07	85
1251.53	90
1250.98	77
1250.43	73
1249.89	75
1249.34	62
1248.79	72
1248.24	77
1247.7	78
1247.15	82
1246.6	82
1246.05	89
1245.5	69
1244.96	83
1244.41	70
1243.86	72
1243.31	64
1242.77	74
1242.22	79
1241.67	73
1241.12	100
1240.57	83
1240.02	82
1239.48	87
1238.93	88
1238.38	65
1237.83	72
1237.28	75
1236.73	77
1236.18	88
1235.64	72
1235.09	63
1234.54	78
1233.99	83
1233.44	93
1232.89	84
1232.34	70
1231.79	77
1231.24	62
1230.69	76
1230.15	82
1229.6	90
1229.05	81
1228.5	75
1227.95	72
1227.4	62
1226.85	93
1226.3	84
1225.75	75
1225.2	85
1224.65	85
1224.1	96
1223.55	74
1223	74
1222.45	78
1221.9	80
1221.35	88
1220.8	90
1220.25	140
1219.7	400
1219.15	2119
1218.6	2174
1218.05	545
1217.5	148
1216.95	97
1216.4	98
1215.85	82
1215.3	92
1214.75	87
1214.2	84
1213.65	87
1213.09	83
1212.54	77
1211.99	69
1211.44	91
1210.89	73
1210.34	81
1209.79	89
1209.24	75
1208.69	67
1208.14	81
1207.58	81
1207.03	90
1206.48	94
1205.93	71
1205.38	99
1204.83	76
1204.27	88
1203.72	68
1203.17	99
1202.62	103
1202.07	89
1201.52	68
1200.96	86
1200.41	109
1199.86	123
1199.31	86
1198.76	86
1198.2	74
1197.65	84
1197.1	78
1196.55	91
1196	75
1195.44	84
1194.89	210
1194.34	410
1193.78	249
1193.23	98
1192.68	82
1192.13	87
1191.57	83
1191.02	85
1190.47	85
1189.91	86
1189.36	65
1188.81	83
1188.26	81
1187.7	64
1187.15	60
1186.6	80
1186.04	84
1185.49	86
1184.94	80
1184.38	86
1183.83	74
1183.28	81
1182.72	64
1182.17	86
1181.61	66
1181.06	79
1180.51	94
1179.95	63
1179.4	79
1178.85	82
1178.29	81
1177.74	93
1177.18	74
1176.63	89
1176.07	86
1175.52	80
1174.97	97
1174.41	77
1173.86	82
1173.3	90
1172.75	57
1172.19	69
1171.64	77
1171.09	102
1170.53	83
1169.97	83
1169.42	86
1168.86	87
1168.31	68
1167.76	92
1167.2	77
1166.65	88
1166.09	78
1165.53	81
1164.98	77
1164.42	83
1163.87	68
1163.31	72
1162.76	80
1162.2	96
1161.65	80
1161.09	82
1160.54	84
1159.98	77
1159.42	76
1158.87	83
1158.31	70
1157.76	67
1157.2	76
1156.65	83
1156.09	88
1155.53	69
1154.98	81
1154.42	75
1153.86	73
1153.31	84
1152.75	82
1152.19	90
1151.64	77
1151.08	75
1150.52	93
1149.97	95
1149.41	89
1148.86	94
1148.3	90
1147.74	73
1147.18	78
1146.63	76
1146.07	82
1145.51	95
1144.96	93
1144.4	89
1143.84	104
1143.28	89
1142.73	88
1142.17	75
1141.61	82
1141.06	78
1140.5	89
1139.94	88
1139.38	90
1138.83	71
1138.27	79
1137.71	93
1137.15	87
1136.59	78
1136.04	95
1135.48	82
1134.92	204
1134.36	1021
1133.8	903
1133.25	196
1132.69	101
1132.13	92
1131.57	101
1131.01	91
1130.45	96
1129.9	86
1129.34	85
1128.78	74
1128.22	97
1127.66	86
1127.1	88
1126.54	82
1125.98	94
1125.43	90
1124.87	90
1124.31	101
1123.75	191
1123.19	226
1122.63	109
1122.07	81
1121.51	82
1120.95	113
1120.39	91
1119.83	88
1119.27	73
1118.72	91
1118.15	97
1117.6	122
1117.04	129
1116.48	736
1115.92	3838
1115.36	2642
1114.8	313
1114.24	370
1113.68	593
1113.12	223
1112.56	110
1112	80
1111.44	77
1110.88	93
1110.32	96
1109.76	102
1109.19	90
1108.64	92
1108.07	74
1107.51	94
1106.95	85
1106.39	102
1105.83	92
1105.27	91
1104.71	94
1104.15	90
1103.59	215
1103.03	654
1102.47	398
1101.91	114
1101.34	85
1100.78	84
1100.22	80
1099.66	80
1099.1	82
1098.54	92
1097.98	142
1097.41	525
1096.85	640
1096.29	212
1095.73	98
1095.17	89
1094.61	89
1094.04	86
1093.48	74
1092.92	94
1092.36	89
1091.8	70
1091.23	154
1090.67	239
1090.11	146
1089.55	89
1088.99	86
1088.42	98
1087.86	82
1087.3	81
1086.74	98
1086.17	106
1085.61	111
1085.05	88
1084.49	83
1083.92	85
1083.36	84
1082.8	93
1082.23	91
1081.67	87
1081.11	96
1080.55	90
1079.98	89
1079.42	86
1078.86	80
1078.29	101
1077.73	80
1077.17	90
1076.6	89
1076.04	79
1075.48	58
1074.91	79
1074.35	90
1073.79	91
1073.22	85
1072.66	84
1072.09	104
1071.53	97
1070.97	104
1070.4	81
1069.84	92
1069.27	86
1068.71	92
1068.15	154
1067.58	202
1067.02	118
1066.45	89
1065.89	88
1065.32	88
1064.76	104
1064.19	88
1063.63	82
1063.07	75
1062.5	91
1061.94	95
1061.37	103
1060.81	148
1060.24	128
1059.68	99
1059.11	108
1058.55	96
1057.98	88
1057.42	83
1056.85	83
1056.29	86
1055.72	93
1055.16	135
1054.59	125
1054.03	84
1053.46	81
1052.89	95
1052.33	93
1051.76	86
1051.2	95
1050.63	107
1050.06	144
1049.5	210
1048.93	144
1048.37	85
1047.8	106
1047.24	97
1046.67	91
1046.1	78
1045.54	91
1044.97	102
1044.4	84
1043.84	95
1043.27	121
1042.7	88
1042.14	85
1041.57	85
1041.01	88
1040.44	93
1039.87	106
1039.3	97
1038.74	89
1038.17	88
1037.6	97
1037.04	91
1036.47	107
1035.9	87
1035.34	80
1034.77	91
1034.2	78
1033.63	88
1033.07	99
1032.5	87
1031.93	92
1031.36	83
1030.8	76
1030.23	94
1029.66	77
1029.09	96
1028.52	108
1027.96	83
1027.39	84
1026.82	94
1026.25	92
1025.68	97
1025.12	99
1024.55	78
1023.98	90
1023.41	83
1022.84	103
1022.28	97
1021.71	94
1021.14	90
1020.57	98
1020	76
1019.43	90
1018.86	80
1018.3	112
1017.73	87
1017.16	106
1016.59	96
1016.3	108