File: Testing/Hickernall_HORIBA/Ne2_06.txt
#Acq. time (s)=	65
#Accumulations=	1
#Range=	Off
#Autofocus=	Off
#Macrospot=	Off
#AutoExposure=	Off
#Spike filter=	Multiple accum.
#Delay time (s)=	0
#Binning=	1
#Readout mode=	Signal
#DeNoise=	Off
#ICS correction=	Off
#Dark correction=	Off
#Inst. Process=	Off
#Instrument=	LabRAM HR Evol
#Detector=	Andor CCD
#Objective=	x100 LWD
#Grating=	1800 gr/mm
#ND Filter=	100%
#Laser (nm)=	532
#Spectro (cm-¹)=	1240.02
#Hole=	49.98
#Range=	Visible
#AFM=	Off
#StageXY=	Marzhauser
#StageZ=	Marzhauser
#X (µm)=	-5516.7
#Y (µm)=	-1264.3
#Z (µm)=	-324.5
#Project=
#Sample=
#Site=
#Title=	Ne2
#Remark=
#Date=	06.05.2022 08:44
#Acquired=	06.05.2022 08:44:15
1454.81	102
1454.28	98
1453.75	128
1453.22	116
1452.69	113
1452.16	101
1451.64	132
1451.11	109
1450.58	142
1450.05	146
1449.52	160
1448.99	196
1448.46	236
1447.93	344
1447.4	1025
1446.88	18705
1446.35	44638
1445.82	21717
1445.29	3371
1444.76	1367
1444.23	374
1443.7	239
1443.17	166
1442.64	179
1442.11	157
1441.58	138
1441.05	153
1440.52	109
1439.99	125
1439.46	104
1438.93	108
1438.4	118
1437.87	113
1437.34	114
1436.81	101
1436.28	101
1435.75	163
1435.22	780
1434.69	1285
1434.16	486
1433.63	132
1433.1	89
1432.57	118
1432.04	105
1431.51	119
1430.98	91
1430.45	93
1429.92	97
1429.39	106
1428.86	95
1428.33	110
1427.8	83
1427.26	91
1426.73	94
1426.2	89
1425.67	73
1425.14	95
1424.61	88
1424.08	82
1423.55	98
1423.02	112
1422.49	92
1421.95	83
1421.42	92
1420.89	97
1420.36	101
1419.83	76
1419.3	102
1418.76	76
1418.23	91
1417.7	78
1417.17	104
1416.64	83
1416.1	89
1415.57	86
1415.04	78
1414.51	91
1413.98	88
1413.44	101
1412.91	80
1412.38	92
1411.85	91
1411.32	77
1410.78	93
1410.25	99
1409.72	73
1409.18	83
1408.65	95
1408.12	92
1407.59	78
1407.05	86
1406.52	93
1405.99	85
1405.46	69
1404.92	74
1404.39	107
1403.86	103
1403.32	87
1402.79	96
1402.26	94
1401.72	87
1401.19	80
1400.66	100
1400.12	108
1399.59	171
1399.06	552
1398.52	1550
1397.99	8225
1397.46	7879
1396.92	1494
1396.39	209
1395.85	117
1395.32	123
1394.79	111
1394.25	111
1393.72	93
1393.18	118
1392.65	69
1392.12	99
1391.58	98
1391.05	91
1390.51	73
1389.98	82
1389.44	104
1388.91	71
1388.38	95
1387.84	88
1387.31	94
1386.77	94
1386.24	89
1385.7	86
1385.17	94
1384.63	68
1384.1	76
1383.56	65
1383.03	87
1382.49	80
1381.96	86
1381.42	75
1380.89	80
1380.35	83
1379.82	67
1379.28	96
1378.74	75
1378.21	96
1377.67	94
1377.14	89
1376.6	85
1376.07	104
1375.53	84
1374.99	87
1374.46	89
1373.92	66
1373.39	96
1372.85	82
1372.32	98
1371.78	300
1371.24	1062
1370.71	834
1370.17	209
1369.63	107
1369.1	116
1368.56	103
1368.03	162
1367.49	169
1366.95	148
1366.42	87
1365.88	158
1365.34	86
1364.81	65
1364.27	65
1363.73	76
1363.19	91
1362.66	87
1362.12	71
1361.58	73
1361.05	76
1360.51	85
1359.97	80
1359.44	75
1358.9	73
1358.36	75
1357.82	95
1357.29	80
1356.75	63
1356.21	95
1355.67	82
1355.14	81
1354.6	90
1354.06	81
1353.52	90
1352.99	87
1352.45	84
1351.91	91
1351.37	74
1350.83	88
1350.3	95
1349.76	79
1349.22	78
1348.68	78
1348.14	97
1347.6	88
1347.06	75
1346.53	90
1345.99	65
1345.45	74
1344.91	71
1344.37	82
1343.83	115
1343.3	80
1342.76	85
1342.22	89
1341.68	71
1341.14	84
1340.6	80
1340.06	87
1339.52	71
1338.98	79
1338.45	74
1337.91	88
1337.37	79
1336.83	76
1336.29	82
1335.75	67
1335.21	70
1334.67	85
1334.13	100
1333.59	83
1333.05	78
1332.51	82
1331.97	82
1331.43	77
1330.89	94
1330.35	81
1329.81	79
1329.27	77
1328.73	84
1328.19	71
1327.65	76
1327.11	72
1326.57	88
1326.03	85
1325.49	82
1324.95	79
1324.41	69
1323.87	84
1323.33	84
1322.79	75
1322.25	82
1321.71	69
1321.16	89
1320.62	89
1320.08	92
1319.54	100
1319	76
1318.46	102
1317.92	65
1317.38	90
1316.84	85
1316.29	77
1315.75	91
1315.21	77
1314.67	76
1314.13	92
1313.59	81
1313.05	64
1312.5	74
1311.96	88
1311.42	84
1310.88	163
1310.34	362
1309.8	1112
1309.25	1898
1308.71	975
1308.17	493
1307.63	242
1307.09	87
1306.54	80
1306	87
1305.46	76
1304.92	77
1304.38	78
1303.83	73
1303.29	85
1302.75	59
1302.21	91
1301.66	61
1301.12	93
1300.58	80
1300.04	91
1299.49	88
1298.95	92
1298.41	91
1297.86	95
1297.32	108
1296.78	103
1296.23	66
1295.69	78
1295.15	90
1294.6	81
1294.06	88
1293.52	78
1292.97	72
1292.43	71
1291.89	76
1291.34	78
1290.8	70
1290.26	83
1289.71	72
1289.17	92
1288.63	117
1288.08	94
1287.54	82
1286.99	88
1286.45	69
1285.9	70
1285.36	76
1284.82	71
1284.27	71
1283.73	79
1283.19	90
1282.64	90
1282.1	71
1281.55	73
1281.01	90
1280.46	63
1279.92	80
1279.37	77
1278.83	84
1278.28	62
1277.74	69
1277.19	76
1276.65	74
1276.1	75
1275.56	77
1275.01	76
1274.47	70
1273.92	67
1273.38	81
1272.83	71
1272.29	70
1271.74	85
1271.2	81
1270.65	87
1270.11	71
1269.56	79
1269.01	89
1268.47	82
1267.92	75
1267.38	75
1266.83	80
1266.29	82
1265.74	74
1265.19	71
1264.65	69
1264.1	73
1263.55	72
1263.01	76
1262.46	88
1261.92	82
1261.37	70
1260.82	87
1260.28	90
1259.73	78
1259.18	95
1258.64	86
1258.09	76
1257.55	93
1257	82
1256.45	68
1255.9	74
1255.36	84
1254.81	72
1254.26	66
1253.72	73
1253.17	150
1252.62	148
1252.07	85
1251.53	64
1250.98	80
1250.43	90
1249.89	92
1249.34	76
1248.79	85
1248.24	70
1247.7	78
1247.15	86
1246.6	92
1246.05	80
1245.5	56
1244.96	86
1244.41	59
1243.86	98
1243.31	71
1242.77	77
1242.22	67
1241.67	92
1241.12	75
1240.57	81
1240.02	89
1239.48	74
1238.93	71
1238.38	81
1237.83	96
1237.28	77
1236.73	76
1236.18	77
1235.64	82
1235.09	85
1234.54	74
1233.99	87
1233.44	134
1232.89	75
1232.34	85
1231.79	65
1231.24	88
1230.69	73
1230.15	76
1229.6	66
1229.05	78
1228.5	83
1227.95	94
1227.4	72
1226.85	84
1226.3	80
1225.75	94
1225.2	78
1224.65	82
1224.1	92
1223.55	74
1223	85
1222.45	84
1221.9	97
1221.35	109
1220.8	94
1220.25	116
1219.7	383
1219.15	2092
1218.6	2365
1218.05	622
1217.5	159
1216.95	119
1216.4	92
1215.85	91
1215.3	84
1214.75	68
1214.2	80
1213.65	74
1213.09	93
1212.54	102
1211.99	86
1211.44	98
1210.89	99
1210.34	83
1209.79	97
1209.24	77
1208.69	92
1208.14	82
1207.58	68
1207.03	92
1206.48	82
1205.93	85
1205.38	101
1204.83	83
1204.27	79
1203.72	92
1203.17	106
1202.62	90
1202.07	75
1201.52	100
1200.96	69
1200.41	109
1199.86	120
1199.31	94
1198.76	84
1198.2	72
1197.65	91
1197.1	73
1196.55	82
1196	75
1195.44	89
1194.89	187
1194.34	448
1193.78	295
1193.23	99
1192.68	93
1192.13	103
1191.57	75
1191.02	86
1190.47	86
1189.91	77
1189.36	89
1188.81	66
1188.26	84
1187.7	71
1187.15	83
1186.6	87
1186.04	84
1185.49	112
1184.94	92
1184.38	83
1183.83	95
1183.28	106
1182.72	110
1182.17	88
1181.61	86
1181.06	78
1180.51	80
1179.95	87
1179.4	93
1178.85	84
1178.29	72
1177.74	87
1177.18	77
1176.63	100
1176.07	74
1175.52	81
1174.97	79
1174.41	67
1173.86	72
1173.3	90
1172.75	79
1172.19	85
1171.64	98
1171.09	85
1170.53	80
1169.97	80
1169.42	94
1168.86	77
1168.31	84
1167.76	96
1167.2	81
1166.65	92
1166.09	92
1165.53	72
1164.98	78
1164.42	70
1163.87	81
1163.31	74
1162.76	76
1162.2	83
1161.65	83
1161.09	89
1160.54	93
1159.98	92
1159.42	79
1158.87	75
1158.31	82
1157.76	85
1157.2	79
1156.65	79
1156.09	87
1155.53	83
1154.98	68
1154.42	80
1153.86	92
1153.31	92
1152.75	104
1152.19	76
1151.64	91
1151.08	96
1150.52	71
1149.97	82
1149.41	94
1148.86	79
1148.3	90
1147.74	78
1147.18	83
1146.63	91
1146.07	99
1145.51	93
1144.96	93
1144.4	92
1143.84	83
1143.28	98
1142.73	71
1142.17	77
1141.61	85
1141.06	103
1140.5	73
1139.94	106
1139.38	98
1138.83	84
1138.27	89
1137.71	88
1137.15	77
1136.59	89
1136.04	89
1135.48	89
1134.92	195
1134.36	1082
1133.8	1052
1133.25	222
1132.69	103
1132.13	105
1131.57	85
1131.01	77
1130.45	95
1129.9	112
1129.34	92
1128.78	82
1128.22	83
1127.66	74
1127.1	70
1126.54	71
1125.98	87
1125.43	93
1124.87	94
1124.31	102
1123.75	216
1123.19	282
1122.63	131
1122.07	92
1121.51	98
1120.95	76
1120.39	83
1119.83	91
1119.27	72
1118.72	97
1118.15	108
1117.6	91
1117.04	138
1116.48	554
1115.92	3920
1115.36	2887
1114.8	383
1114.24	408
1113.68	644
1113.12	236
1112.56	103
1112	93
1111.44	101
1110.88	101
1110.32	105
1109.76	98
1109.19	90
1108.64	96
1108.07	102
1107.51	88
1106.95	87
1106.39	107
1105.83	86
1105.27	96
1104.71	118
1104.15	116
1103.59	200
1103.03	713
1102.47	502
1101.91	129
1101.34	77
1100.78	87
1100.22	103
1099.66	89
1099.1	119
1098.54	87
1097.98	129
1097.41	466
1096.85	735
1096.29	241
1095.73	109
1095.17	87
1094.61	82
1094.04	79
1093.48	106
1092.92	88
1092.36	81
1091.8	96
1091.23	136
1090.67	241
1090.11	160
1089.55	114
1088.99	85
1088.42	77
1087.86	83
1087.3	87
1086.74	88
1086.17	86
1085.61	79
1085.05	92
1084.49	99
1083.92	78
1083.36	84
1082.8	105
1082.23	87
1081.67	101
1081.11	97
1080.55	99
1079.98	72
1079.42	101
1078.86	93
1078.29	84
1077.73	101
1077.17	115
1076.6	96
1076.04	113
1075.48	82
1074.91	91
1074.35	96
1073.79	85
1073.22	90
1072.66	81
1072.09	88
1071.53	105
1070.97	105
1070.4	100
1069.84	96
1069.27	92
1068.71	94
1068.15	162
1067.58	230
1067.02	114
1066.45	108
1065.89	100
1065.32	100
1064.76	87
1064.19	98
1063.63	98
1063.07	96
1062.5	82
1061.94	92
1061.37	109
1060.81	166
1060.24	131
1059.68	110
1059.11	114
1058.55	84
1057.98	128
1057.42	103
1056.85	77
1056.29	104
1055.72	90
1055.16	121
1054.59	124
1054.03	81
1053.46	93
1052.89	99
1052.33	92
1051.76	114
1051.2	104
1050.63	104
1050.06	125
1049.5	209
1048.93	146
1048.37	100
1047.8	97
1047.24	89
1046.67	98
1046.1	94
1045.54	79
1044.97	98
1044.4	107
1043.84	108
1043.27	137
1042.7	97
1042.14	90
1041.57	108
1041.01	85
1040.44	94
1039.87	99
1039.3	86
1038.74	93
1038.17	96
1037.6	95
1037.04	81
1036.47	103
1035.9	74
1035.34	101
1034.77	114
1034.2	90
1033.63	103
1033.07	96
1032.5	92
1031.93	87
1031.36	98
1030.8	117
1030.23	108
1029.66	97
1029.09	104
1028.52	100
1027.96	107
1027.39	96
1026.82	127
1026.25	106
1025.68	95
1025.12	104
1024.55	105
1023.98	98
1023.41	96
1022.84	111
1022.28	132
1021.71	106
1021.14	97
1020.57	80
1020	109
1019.43	80
1018.86	113
1018.3	109
1017.73	101
1017.16	128
1016.59	96
1016.3	96