File: Testing/Hickernall_HORIBA/Ne2_03.txt
#Acq. time (s)=	65
#Accumulations=	2
#Range=	Off
#Autofocus=	Off
#Macrospot=	Off
#AutoExposure=	Off
#Spike filter=	Multiple accum.
#Delay time (s)=	0
#Binning=	1
#Readout mode=	Signal
#DeNoise=	Off
#ICS correction=	Off
#Dark correction=	Off
#Inst. Process=	Off
#Instrument=	LabRAM HR Evol
#Detector=	Andor CCD
#Objective=	x100 LWD
#Grating=	1800 gr/mm
#ND Filter=	100%
#Laser (nm)=	532
#Spectro (cm-¹)=	1240.02
#Hole=	49.98
#Range=	Visible
#AFM=	Off
#StageXY=	Marzhauser
#StageZ=	Marzhauser
#X (µm)=	-5516.7
#Y (µm)=	-1264.3
#Z (µm)=	-324.5
#Project=
#Sample=
#Site=
#Title=	Ne2
#Remark=
#Date=	06.05.2022 08:37
#Acquired=	06.05.2022 08:37:21
1454.81	112
1454.28	91
1453.75	98
1453.22	102
1452.69	109
1452.16	114
1451.64	142
1451.11	128
1450.58	138
1450.05	133
1449.52	145
1448.99	176
1448.46	215
1447.93	319
1447.4	1146
1446.88	20363
1446.35	44180
1445.82	19780
1445.29	3179
1444.76	1178
1444.23	340
1443.7	191
1443.17	172
1442.64	182
1442.11	152
1441.58	160
1441.05	131
1440.52	126
1439.99	117
1439.46	97
1438.93	123
1438.4	105
1437.87	107
1437.34	123
1436.81	99
1436.28	110
1435.75	154
1435.22	896
1434.69	1207
1434.16	446
1433.63	139
1433.1	83
1432.57	100
1432.04	91
1431.51	96
1430.98	104
1430.45	79
1429.92	102
1429.39	99
1428.86	96
1428.33	100
1427.8	85
1427.26	82
1426.73	82
1426.2	72
1425.67	102
1425.14	97
1424.61	77
1424.08	82
1423.55	84
1423.02	85
1422.49	83
1421.95	83
1421.42	106
1420.89	110
1420.36	92
1419.83	81
1419.3	84
1418.76	77
1418.23	83
1417.7	91
1417.17	89
1416.64	73
1416.1	88
1415.57	75
1415.04	79
1414.51	82
1413.98	85
1413.44	84
1412.91	84
1412.38	76
1411.85	81
1411.32	86
1410.78	87
1410.25	85
1409.72	85
1409.18	87
1408.65	82
1408.12	94
1407.59	113
1407.05	88
1406.52	67
1405.99	94
1405.46	82
1404.92	93
1404.39	80
1403.86	91
1403.32	80
1402.79	93
1402.26	82
1401.72	91
1401.19	86
1400.66	92
1400.12	108
1399.59	196
1399.06	590
1398.52	1726
1397.99	8513
1397.46	7658
1396.92	1203
1396.39	201
1395.85	137
1395.32	109
1394.79	109
1394.25	89
1393.72	93
1393.18	98
1392.65	58
1392.12	72
1391.58	86
1391.05	71
1390.51	92
1389.98	90
1389.44	91
1388.91	89
1388.38	84
1387.84	76
1387.31	88
1386.77	67
1386.24	94
1385.7	94
1385.17	85
1384.63	76
1384.1	69
1383.56	78
1383.03	85
1382.49	73
1381.96	82
1381.42	62
1380.89	78
1380.35	80
1379.82	81
1379.28	85
1378.74	70
1378.21	69
1377.67	83
1377.14	68
1376.6	90
1376.07	72
1375.53	69
1374.99	74
1374.46	80
1373.92	71
1373.39	81
1372.85	89
1372.32	105
1371.78	321
1371.24	1114
1370.71	773
1370.17	176
1369.63	84
1369.1	90
1368.56	90
1368.03	158
1367.49	170
1366.95	127
1366.42	95
1365.88	105
1365.34	71
1364.81	96
1364.27	78
1363.73	86
1363.19	73
1362.66	84
1362.12	83
1361.58	77
1361.05	86
1360.51	92
1359.97	94
1359.44	76
1358.9	75
1358.36	75
1357.82	84
1357.29	71
1356.75	87
1356.21	76
1355.67	87
1355.14	88
1354.6	74
1354.06	63
1353.52	90
1352.99	95
1352.45	61
1351.91	81
1351.37	77
1350.83	73
1350.3	80
1349.76	79
1349.22	74
1348.68	87
1348.14	81
1347.6	86
1347.06	72
1346.53	81
1345.99	75
1345.45	63
1344.91	80
1344.37	73
1343.83	78
1343.3	76
1342.76	74
1342.22	92
1341.68	70
1341.14	78
1340.6	80
1340.06	82
1339.52	85
1338.98	78
1338.45	79
1337.91	87
1337.37	68
1336.83	71
1336.29	85
1335.75	87
1335.21	69
1334.67	88
1334.13	72
1333.59	77
1333.05	81
1332.51	75
1331.97	73
1331.43	88
1330.89	74
1330.35	70
1329.81	75
1329.27	83
1328.73	74
1328.19	69
1327.65	67
1327.11	74
1326.57	73
1326.03	75
1325.49	76
1324.95	87
1324.41	83
1323.87	81
1323.33	79
1322.79	66
1322.25	58
1321.71	69
1321.16	77
1320.62	77
1320.08	70
1319.54	74
1319	68
1318.46	84
1317.92	86
1317.38	84
1316.84	87
1316.29	72
1315.75	72
1315.21	79
1314.67	74
1314.13	74
1313.59	79
1313.05	86
1312.5	70
1311.96	75
1311.42	93
1310.88	166
1310.34	399
1309.8	1141
1309.25	1854
1308.71	888
1308.17	480
1307.63	214
1307.09	88
1306.54	81
1306	94
1305.46	65
1304.92	73
1304.38	75
1303.83	77
1303.29	70
1302.75	87
1302.21	67
1301.66	70
1301.12	71
1300.58	79
1300.04	74
1299.49	78
1298.95	79
1298.41	82
1297.86	94
1297.32	116
1296.78	88
1296.23	86
1295.69	72
1295.15	64
1294.6	82
1294.06	70
1293.52	77
1292.97	72
1292.43	67
1291.89	68
1291.34	74
1290.8	84
1290.26	81
1289.71	79
1289.17	79
1288.63	129
1288.08	87
1287.54	80
1286.99	67
1286.45	64
1285.9	71
1285.36	69
1284.82	71
1284.27	74
1283.73	76
1283.19	79
1282.64	73
1282.1	73
1281.55	73
1281.01	67
1280.46	76
1279.92	71
1279.37	78
1278.83	84
1278.28	69
1277.74	58
1277.19	81
1276.65	69
1276.1	64
1275.56	62
1275.01	70
1274.47	69
1273.92	63
1273.38	57
1272.83	91
1272.29	70
1271.74	87
1271.2	80
1270.65	62
1270.11	84
1269.56	70
1269.01	69
1268.47	74
1267.92	73
1267.38	85
1266.83	82
1266.29	71
1265.74	72
1265.19	82
1264.65	76
1264.1	55
1263.55	75
1263.01	83
1262.46	74
1261.92	77
1261.37	82
1260.82	83
1260.28	78
1259.73	70
1259.18	75
1258.64	72
1258.09	83
1257.55	94
1257	66
1256.45	73
1255.9	91
1255.36	75
1254.81	68
1254.26	82
1253.72	77
1253.17	161
1252.62	136
1252.07	90
1251.53	88
1250.98	84
1250.43	68
1249.89	72
1249.34	68
1248.79	65
1248.24	69
1247.7	68
1247.15	70
1246.6	69
1246.05	79
1245.5	79
1244.96	69
1244.41	69
1243.86	82
1243.31	59
1242.77	76
1242.22	70
1241.67	85
1241.12	62
1240.57	73
1240.02	89
1239.48	64
1238.93	80
1238.38	66
1237.83	68
1237.28	79
1236.73	75
1236.18	72
1235.64	86
1235.09	80
1234.54	69
1233.99	79
1233.44	113
1232.89	86
1232.34	66
1231.79	83
1231.24	77
1230.69	74
1230.15	85
1229.6	81
1229.05	76
1228.5	78
1227.95	96
1227.4	77
1226.85	81
1226.3	72
1225.75	89
1225.2	90
1224.65	76
1224.1	74
1223.55	76
1223	62
1222.45	78
1221.9	72
1221.35	83
1220.8	83
1220.25	115
1219.7	377
1219.15	2195
1218.6	2305
1218.05	544
1217.5	152
1216.95	94
1216.4	86
1215.85	92
1215.3	90
1214.75	99
1214.2	82
1213.65	82
1213.09	88
1212.54	71
1211.99	82
1211.44	107
1210.89	87
1210.34	90
1209.79	85
1209.24	83
1208.69	86
1208.14	75
1207.58	69
1207.03	96
1206.48	69
1205.93	85
1205.38	85
1204.83	71
1204.27	71
1203.72	77
1203.17	109
1202.62	97
1202.07	79
1201.52	65
1200.96	75
1200.41	134
1199.86	150
1199.31	85
1198.76	82
1198.2	89
1197.65	85
1197.1	82
1196.55	82
1196	71
1195.44	88
1194.89	208
1194.34	440
1193.78	265
1193.23	93
1192.68	84
1192.13	86
1191.57	78
1191.02	86
1190.47	89
1189.91	83
1189.36	57
1188.81	79
1188.26	71
1187.7	80
1187.15	97
1186.6	86
1186.04	82
1185.49	78
1184.94	84
1184.38	78
1183.83	82
1183.28	60
1182.72	76
1182.17	76
1181.61	89
1181.06	78
1180.51	78
1179.95	78
1179.4	85
1178.85	68
1178.29	88
1177.74	89
1177.18	73
1176.63	81
1176.07	86
1175.52	80
1174.97	84
1174.41	74
1173.86	75
1173.3	84
1172.75	84
1172.19	92
1171.64	75
1171.09	89
1170.53	78
1169.97	65
1169.42	71
1168.86	90
1168.31	79
1167.76	86
1167.2	90
1166.65	73
1166.09	66
1165.53	81
1164.98	73
1164.42	81
1163.87	82
1163.31	84
1162.76	94
1162.2	72
1161.65	78
1161.09	79
1160.54	83
1159.98	80
1159.42	88
1158.87	81
1158.31	79
1157.76	79
1157.2	93
1156.65	67
1156.09	93
1155.53	69
1154.98	90
1154.42	73
1153.86	85
1153.31	85
1152.75	78
1152.19	93
1151.64	82
1151.08	81
1150.52	88
1149.97	80
1149.41	84
1148.86	75
1148.3	84
1147.74	84
1147.18	76
1146.63	88
1146.07	75
1145.51	83
1144.96	78
1144.4	83
1143.84	92
1143.28	89
1142.73	73
1142.17	80
1141.61	92
1141.06	85
1140.5	92
1139.94	86
1139.38	77
1138.83	87
1138.27	82
1137.71	89
1137.15	66
1136.59	85
1136.04	96
1135.48	101
1134.92	205
1134.36	1037
1133.8	972
1133.25	204
1132.69	87
1132.13	96
1131.57	95
1131.01	81
1130.45	92
1129.9	81
1129.34	77
1128.78	89
1128.22	99
1127.66	97
1127.1	88
1126.54	78
1125.98	68
1125.43	59
1124.87	99
1124.31	79
1123.75	190
1123.19	277
1122.63	121
1122.07	91
1121.51	88
1120.95	96
1120.39	80
1119.83	82
1119.27	87
1118.72	87
1118.15	95
1117.6	106
1117.04	126
1116.48	672
1115.92	3996
1115.36	2677
1114.8	349
1114.24	360
1113.68	602
1113.12	227
1112.56	99
1112	88
1111.44	91
1110.88	91
1110.32	89
1109.76	87
1109.19	78
1108.64	95
1108.07	93
1107.51	80
1106.95	83
1106.39	99
1105.83	86
1105.27	92
1104.71	79
1104.15	102
1103.59	221
1103.03	749
1102.47	432
1101.91	114
1101.34	97
1100.78	98
1100.22	100
1099.66	102
1099.1	80
1098.54	90
1097.98	88
1097.41	477
1096.85	683
1096.29	216
1095.73	88
1095.17	96
1094.61	77
1094.04	83
1093.48	95
1092.92	80
1092.36	84
1091.8	95
1091.23	177
1090.67	252
1090.11	136
1089.55	79
1088.99	85
1088.42	73
1087.86	81
1087.3	83
1086.74	78
1086.17	79
1085.61	87
1085.05	87
1084.49	91
1083.92	71
1083.36	75
1082.8	93
1082.23	79
1081.67	106
1081.11	93
1080.55	86
1079.98	86
1079.42	94
1078.86	82
1078.29	91
1077.73	73
1077.17	83
1076.6	96
1076.04	82
1075.48	104
1074.91	87
1074.35	101
1073.79	83
1073.22	80
1072.66	85
1072.09	82
1071.53	83
1070.97	99
1070.4	105
1069.84	89
1069.27	81
1068.71	98
1068.15	172
1067.58	195
1067.02	130
1066.45	87
1065.89	88
1065.32	90
1064.76	75
1064.19	88
1063.63	97
1063.07	90
1062.5	79
1061.94	97
1061.37	92
1060.81	159
1060.24	109
1059.68	88
1059.11	90
1058.55	82
1057.98	95
1057.42	102
1056.85	101
1056.29	98
1055.72	104
1055.16	136
1054.59	123
1054.03	91
1053.46	84
1052.89	95
1052.33	87
1051.76	85
1051.2	93
1050.63	100
1050.06	157
1049.5	202
1048.93	156
1048.37	99
1047.8	85
1047.24	90
1046.67	96
1046.1	97
1045.54	99
1044.97	100
1044.4	93
1043.84	88
1043.27	123
1042.7	82
1042.14	85
1041.57	90
1041.01	97
1040.44	91
1039.87	86
1039.3	84
1038.74	96
1038.17	68
1037.6	84
1037.04	88
1036.47	106
1035.9	92
1035.34	94
1034.77	92
1034.2	108
1033.63	84
1033.07	79
1032.5	93
1031.93	84
1031.36	103
1030.8	103
1030.23	81
1029.66	81
1029.09	94
1028.52	106
1027.96	96
1027.39	97
1026.82	91
1026.25	96
1025.68	86
1025.12	105
1024.55	88
1023.98	88
1023.41	93
1022.84	110
1022.28	93
1021.71	88
1021.14	85
1020.57	89
1020	103
1019.43	86
1018.86	102
1018.3	92
1017.73	108
1017.16	115
1016.59	100
1016.3	92