File: Testing/Hickernall_HORIBA/Ne3_01.txt
#Acq. time (s)=	55
#Accumulations=	2
#Range=	Off
#Autofocus=	Off
#Macrospot=	Off
#AutoExposure=	Off
#Spike filter=	Multiple accum.
#Delay time (s)=	0
#Binning=	1
#Readout mode=	Signal
#DeNoise=	Off
#ICS correction=	Off
#Dark correction=	Off
#Inst. Process=	Off
#Instrument=	LabRAM HR Evol
#Detector=	Andor CCD
#Objective=	x100 LWD
#Grating=	1800 gr/mm
#ND Filter=	100%
#Laser (nm)=	532
#Spectro (cm-¹)=	1240.02
#Hole=	49.98
#Range=	Visible
#AFM=	Off
#StageXY=	Marzhauser
#StageZ=	Marzhauser
#X (µm)=	-15776.2
#Y (µm)=	-1015.1
#Z (µm)=	-314.4
#Project=
#Sample=
#Site=
#Title=	Ne3
#Remark=
#Date=	06.05.2022 09:38
#Acquired=	06.05.2022 09:38:44
1454.81	133
1454.28	139
1453.75	135
1453.22	126
1452.69	152
1452.16	143
1451.64	154
1451.11	141
1450.58	162
1450.05	176
1449.52	177
1448.99	208
1448.46	244
1447.93	318
1447.4	808
1446.88	13338
1446.35	44831
1445.82	26392
1445.29	3767
1444.76	1524
1444.23	398
1443.7	273
1443.17	221
1442.64	210
1442.11	184
1441.58	185
1441.05	187
1440.52	183
1439.99	163
1439.46	161
1438.93	176
1438.4	148
1437.87	134
1437.34	143
1436.81	132
1436.28	130
1435.75	156
1435.22	703
1434.69	1402
1434.16	549
1433.63	168
1433.1	126
1432.57	131
1432.04	134
1431.51	123
1430.98	126
1430.45	136
1429.92	123
1429.39	109
1428.86	118
1428.33	128
1427.8	128
1427.26	115
1426.73	119
1426.2	123
1425.67	104
1425.14	116
1424.61	116
1424.08	126
1423.55	115
1423.02	121
1422.49	116
1421.95	122
1421.42	153
1420.89	120
1420.36	123
1419.83	125
1419.3	123
1418.76	119
1418.23	115
1417.7	113
1417.17	121
1416.64	116
1416.1	101
1415.57	117
1415.04	135
1414.51	109
1413.98	121
1413.44	121
1412.91	121
1412.38	131
1411.85	128
1411.32	108
1410.78	126
1410.25	122
1409.72	124
1409.18	109
1408.65	125
1408.12	129
1407.59	112
1407.05	131
1406.52	113
1405.99	123
1405.46	100
1404.92	103
1404.39	109
1403.86	116
1403.32	141
1402.79	116
1402.26	127
1401.72	120
1401.19	118
1400.66	126
1400.12	141
1399.59	183
1399.06	563
1398.52	1158
1397.99	7402
1397.46	9455
1396.92	1891
1396.39	246
1395.85	164
1395.32	147
1394.79	135
1394.25	127
1393.72	128
1393.18	143
1392.65	135
1392.12	123
1391.58	106
1391.05	117
1390.51	112
1389.98	120
1389.44	141
1388.91	127
1388.38	116
1387.84	111
1387.31	111
1386.77	101
1386.24	138
1385.7	104
1385.17	112
1384.63	119
1384.1	123
1383.56	120
1383.03	122
1382.49	121
1381.96	121
1381.42	134
1380.89	122
1380.35	105
1379.82	115
1379.28	97
1378.74	131
1378.21	109
1377.67	125
1377.14	131
1376.6	97
1376.07	101
1375.53	127
1374.99	123
1374.46	116
1373.92	105
1373.39	120
1372.85	120
1372.32	127
1371.78	231
1371.24	1019
1370.71	961
1370.17	249
1369.63	121
1369.1	134
1368.56	123
1368.03	163
1367.49	232
1366.95	163
1366.42	125
1365.88	152
1365.34	115
1364.81	124
1364.27	126
1363.73	116
1363.19	117
1362.66	120
1362.12	112
1361.58	109
1361.05	119
1360.51	121
1359.97	117
1359.44	107
1358.9	130
1358.36	121
1357.82	116
1357.29	100
1356.75	128
1356.21	113
1355.67	99
1355.14	113
1354.6	104
1354.06	99
1353.52	119
1352.99	104
1352.45	123
1351.91	127
1351.37	115
1350.83	121
1350.3	107
1349.76	108
1349.22	115
1348.68	116
1348.14	111
1347.6	112
1347.06	111
1346.53	106
1345.99	101
1345.45	132
1344.91	131
1344.37	95
1343.83	124
1343.3	123
1342.76	105
1342.22	106
1341.68	118
1341.14	111
1340.6	107
1340.06	102
1339.52	105
1338.98	105
1338.45	100
1337.91	116
1337.37	94
1336.83	111
1336.29	105
1335.75	107
1335.21	106
1334.67	106
1334.13	109
1333.59	91
1333.05	119
1332.51	117
1331.97	139
1331.43	116
1330.89	112
1330.35	116
1329.81	92
1329.27	114
1328.73	97
1328.19	119
1327.65	111
1327.11	114
1326.57	103
1326.03	120
1325.49	117
1324.95	130
1324.41	105
1323.87	99
1323.33	115
1322.79	116
1322.25	108
1321.71	102
1321.16	99
1320.62	111
1320.08	121
1319.54	101
1319	118
1318.46	134
1317.92	115
1317.38	102
1316.84	125
1316.29	105
1315.75	119
1315.21	106
1314.67	95
1314.13	119
1313.59	125
1313.05	114
1312.5	110
1311.96	116
1311.42	117
1310.88	155
1310.34	371
1309.8	792
1309.25	2097
1308.71	1164
1308.17	556
1307.63	294
1307.09	125
1306.54	131
1306	123
1305.46	105
1304.92	112
1304.38	123
1303.83	107
1303.29	110
1302.75	109
1302.21	113
1301.66	110
1301.12	114
1300.58	122
1300.04	106
1299.49	121
1298.95	92
1298.41	110
1297.86	125
1297.32	145
1296.78	127
1296.23	108
1295.69	118
1295.15	98
1294.6	110
1294.06	107
1293.52	126
1292.97	109
1292.43	117
1291.89	87
1291.34	104
1290.8	104
1290.26	117
1289.71	120
1289.17	105
1288.63	155
1288.08	114
1287.54	108
1286.99	103
1286.45	95
1285.9	117
1285.36	111
1284.82	115
1284.27	101
1283.73	106
1283.19	102
1282.64	111
1282.1	106
1281.55	102
1281.01	110
1280.46	118
1279.92	113
1279.37	105
1278.83	117
1278.28	110
1277.74	117
1277.19	98
1276.65	101
1276.1	117
1275.56	114
1275.01	122
1274.47	102
1273.92	116
1273.38	100
1272.83	144
1272.29	109
1271.74	116
1271.2	107
1270.65	91
1270.11	106
1269.56	126
1269.01	107
1268.47	124
1267.92	123
1267.38	114
1266.83	108
1266.29	116
1265.74	116
1265.19	100
1264.65	110
1264.1	106
1263.55	104
1263.01	101
1262.46	117
1261.92	118
1261.37	103
1260.82	100
1260.28	129
1259.73	108
1259.18	104
1258.64	116
1258.09	107
1257.55	92
1257	111
1256.45	125
1255.9	111
1255.36	104
1254.81	106
1254.26	104
1253.72	116
1253.17	149
1252.62	208
1252.07	125
1251.53	122
1250.98	109
1250.43	97
1249.89	117
1249.34	110
1248.79	112
1248.24	84
1247.7	117
1247.15	117
1246.6	125
1246.05	120
1245.5	111
1244.96	94
1244.41	102
1243.86	101
1243.31	118
1242.77	106
1242.22	103
1241.67	116
1241.12	114
1240.57	111
1240.02	117
1239.48	118
1238.93	109
1238.38	111
1237.83	93
1237.28	116
1236.73	108
1236.18	119
1235.64	114
1235.09	106
1234.54	117
1233.99	105
1233.44	142
1232.89	100
1232.34	120
1231.79	116
1231.24	123
1230.69	115
1230.15	109
1229.6	110
1229.05	106
1228.5	107
1227.95	119
1227.4	123
1226.85	101
1226.3	104
1225.75	122
1225.2	108
1224.65	102
1224.1	127
1223.55	119
1223	105
1222.45	113
1221.9	108
1221.35	104
1220.8	126
1220.25	153
1219.7	270
1219.15	1710
1218.6	2847
1218.05	894
1217.5	200
1216.95	133
1216.4	123
1215.85	133
1215.3	121
1214.75	125
1214.2	112
1213.65	133
1213.09	115
1212.54	118
1211.99	117
1211.44	126
1210.89	141
1210.34	125
1209.79	129
1209.24	96
1208.69	131
1208.14	112
1207.58	106
1207.03	113
1206.48	118
1205.93	104
1205.38	121
1204.83	127
1204.27	109
1203.72	121
1203.17	123
1202.62	130
1202.07	109
1201.52	112
1200.96	112
1200.41	150
1199.86	183
1199.31	119
1198.76	122
1198.2	119
1197.65	135
1197.1	118
1196.55	120
1196	131
1195.44	112
1194.89	141
1194.34	470
1193.78	388
1193.23	135
1192.68	120
1192.13	125
1191.57	124
1191.02	112
1190.47	109
1189.91	110
1189.36	102
1188.81	131
1188.26	137
1187.7	130
1187.15	116
1186.6	113
1186.04	125
1185.49	121
1184.94	113
1184.38	122
1183.83	134
1183.28	112
1182.72	133
1182.17	144
1181.61	128
1181.06	116
1180.51	110
1179.95	130
1179.4	126
1178.85	111
1178.29	122
1177.74	134
1177.18	127
1176.63	128
1176.07	116
1175.52	129
1174.97	115
1174.41	125
1173.86	136
1173.3	136
1172.75	120
1172.19	121
1171.64	108
1171.09	133
1170.53	125
1169.97	125
1169.42	125
1168.86	145
1168.31	124
1167.76	122
1167.2	137
1166.65	126
1166.09	135
1165.53	140
1164.98	115
1164.42	108
1163.87	122
1163.31	131
1162.76	124
1162.2	124
1161.65	130
1161.09	109
1160.54	126
1159.98	98
1159.42	127
1158.87	132
1158.31	129
1157.76	122
1157.2	142
1156.65	129
1156.09	128
1155.53	149
1154.98	141
1154.42	131
1153.86	129
1153.31	133
1152.75	134
1152.19	137
1151.64	136
1151.08	130
1150.52	124
1149.97	128
1149.41	135
1148.86	145
1148.3	133
1147.74	131
1147.18	130
1146.63	123
1146.07	141
1145.51	126
1144.96	131
1144.4	141
1143.84	126
1143.28	147
1142.73	138
1142.17	130
1141.61	129
1141.06	115
1140.5	128
1139.94	141
1139.38	125
1138.83	140
1138.27	156
1137.71	130
1137.15	150
1136.59	133
1136.04	127
1135.48	155
1134.92	184
1134.36	840
1133.8	1239
1133.25	361
1132.69	165
1132.13	139
1131.57	150
1131.01	132
1130.45	137
1129.9	130
1129.34	135
1128.78	142
1128.22	165
1127.66	145
1127.1	147
1126.54	131
1125.98	155
1125.43	150
1124.87	170
1124.31	163
1123.75	242
1123.19	361
1122.63	200
1122.07	153
1121.51	165
1120.95	149
1120.39	148
1119.83	143
1119.27	146
1118.72	140
1118.15	161
1117.6	144
1117.04	167
1116.48	373
1115.92	3356
1115.36	3937
1114.8	588
1114.24	301
1113.68	769
1113.12	397
1112.56	169
1112	134
1111.44	148
1110.88	148
1110.32	147
1109.76	155
1109.19	142
1108.64	164
1108.07	146
1107.51	168
1106.95	146
1106.39	143
1105.83	166
1105.27	147
1104.71	154
1104.15	153
1103.59	221
1103.03	750
1102.47	661
1101.91	216
1101.34	171
1100.78	164
1100.22	155
1099.66	163
1099.1	151
1098.54	169
1097.98	184
1097.41	386
1096.85	854
1096.29	397
1095.73	193
1095.17	143
1094.61	167
1094.04	176
1093.48	173
1092.92	168
1092.36	139
1091.8	164
1091.23	168
1090.67	312
1090.11	250
1089.55	159
1088.99	164
1088.42	156
1087.86	157
1087.3	164
1086.74	153
1086.17	156
1085.61	191
1085.05	148
1084.49	135
1083.92	159
1083.36	156
1082.8	162
1082.23	156
1081.67	152
1081.11	166
1080.55	162
1079.98	157
1079.42	153
1078.86	134
1078.29	148
1077.73	164
1077.17	156
1076.6	164
1076.04	165
1075.48	150
1074.91	144
1074.35	185
1073.79	181
1073.22	171
1072.66	138
1072.09	172
1071.53	152
1070.97	167
1070.4	166
1069.84	133
1069.27	150
1068.71	137
1068.15	197
1067.58	295
1067.02	197
1066.45	162
1065.89	158
1065.32	137
1064.76	155
1064.19	161
1063.63	138
1063.07	158
1062.5	150
1061.94	130
1061.37	143
1060.81	203
1060.24	213
1059.68	151
1059.11	144
1058.55	152
1057.98	142
1057.42	153
1056.85	140
1056.29	151
1055.72	147
1055.16	182
1054.59	175
1054.03	162
1053.46	140
1052.89	152
1052.33	154
1051.76	155
1051.2	160
1050.63	147
1050.06	151
1049.5	256
1048.93	219
1048.37	157
1047.8	137
1047.24	164
1046.67	142
1046.1	157
1045.54	163
1044.97	147
1044.4	141
1043.84	162
1043.27	174
1042.7	127
1042.14	156
1041.57	154
1041.01	152
1040.44	123
1039.87	136
1039.3	161
1038.74	139
1038.17	150
1037.6	136
1037.04	155
1036.47	143
1035.9	149
1035.34	136
1034.77	141
1034.2	141
1033.63	126
1033.07	163
1032.5	142
1031.93	145
1031.36	128
1030.8	152
1030.23	134
1029.66	154
1029.09	144
1028.52	149
1027.96	143
1027.39	133
1026.82	126
1026.25	126
1025.68	147
1025.12	142
1024.55	144
1023.98	137
1023.41	145
1022.84	140
1022.28	152
1021.71	143
1021.14	154
1020.57	128
1020	148
1019.43	139
1018.86	158
1018.3	144
1017.73	140
1017.16	160
1016.59	127
1016.3	142