File: Testing/Hickernall_HORIBA/Ne4_01.txt
#Acq. time (s)=	45
#Accumulations=	2
#Range=	Off
#Autofocus=	Off
#Macrospot=	Off
#AutoExposure=	Off
#Spike filter=	Multiple accum.
#Delay time (s)=	0
#Binning=	1
#Readout mode=	Signal
#DeNoise=	Off
#ICS correction=	Off
#Dark correction=	Off
#Inst. Process=	Off
#Instrument=	LabRAM HR Evol
#Detector=	Andor CCD
#Objective=	x100 LWD
#Grating=	1800 gr/mm
#ND Filter=	100%
#Laser (nm)=	532
#Spectro (cm-¹)=	1240.02
#Hole=	49.98
#Range=	Visible
#AFM=	Off
#StageXY=	Marzhauser
#StageZ=	Marzhauser
#X (µm)=	-15857.5
#Y (µm)=	-1055.2
#Z (µm)=	-342
#Project=
#Sample=
#Site=
#Title=	Ne4
#Remark=
#Date=	06.05.2022 10:19
#Acquired=	06.05.2022 10:19:15
1454.81	140
1454.28	117
1453.75	137
1453.22	137
1452.69	119
1452.16	137
1451.64	167
1451.11	161
1450.58	141
1450.05	165
1449.52	187
1448.99	202
1448.46	263
1447.93	383
1447.4	771
1446.88	11897
1446.35	45842
1445.82	35318
1445.29	5499
1444.76	2030
1444.23	544
1443.7	296
1443.17	232
1442.64	220
1442.11	181
1441.58	184
1441.05	175
1440.52	159
1439.99	142
1439.46	134
1438.93	156
1438.4	157
1437.87	126
1437.34	149
1436.81	138
1436.28	128
1435.75	163
1435.22	692
1434.69	1438
1434.16	832
1433.63	186
1433.1	131
1432.57	140
1432.04	119
1431.51	110
1430.98	139
1430.45	108
1429.92	121
1429.39	117
1428.86	114
1428.33	111
1427.8	133
1427.26	115
1426.73	98
1426.2	123
1425.67	106
1425.14	106
1424.61	108
1424.08	120
1423.55	99
1423.02	105
1422.49	103
1421.95	123
1421.42	121
1420.89	116
1420.36	98
1419.83	111
1419.3	112
1418.76	109
1418.23	94
1417.7	97
1417.17	114
1416.64	116
1416.1	101
1415.57	111
1415.04	121
1414.51	103
1413.98	114
1413.44	108
1412.91	124
1412.38	115
1411.85	123
1411.32	142
1410.78	104
1410.25	112
1409.72	120
1409.18	118
1408.65	121
1408.12	123
1407.59	112
1407.05	114
1406.52	106
1405.99	117
1405.46	113
1404.92	116
1404.39	97
1403.86	114
1403.32	108
1402.79	136
1402.26	123
1401.72	123
1401.19	130
1400.66	136
1400.12	124
1399.59	189
1399.06	553
1398.52	1203
1397.99	7355
1397.46	10564
1396.92	2867
1396.39	322
1395.85	178
1395.32	135
1394.79	123
1394.25	136
1393.72	131
1393.18	125
1392.65	117
1392.12	118
1391.58	106
1391.05	107
1390.51	117
1389.98	125
1389.44	109
1388.91	128
1388.38	107
1387.84	102
1387.31	94
1386.77	120
1386.24	112
1385.7	97
1385.17	106
1384.63	127
1384.1	110
1383.56	98
1383.03	117
1382.49	116
1381.96	104
1381.42	110
1380.89	114
1380.35	122
1379.82	100
1379.28	87
1378.74	107
1378.21	94
1377.67	106
1377.14	112
1376.6	111
1376.07	102
1375.53	105
1374.99	97
1374.46	106
1373.92	122
1373.39	116
1372.85	136
1372.32	100
1371.78	221
1371.24	959
1370.71	1117
1370.17	308
1369.63	128
1369.1	129
1368.56	127
1368.03	159
1367.49	216
1366.95	174
1366.42	106
1365.88	143
1365.34	111
1364.81	93
1364.27	106
1363.73	116
1363.19	100
1362.66	121
1362.12	120
1361.58	105
1361.05	100
1360.51	108
1359.97	100
1359.44	105
1358.9	107
1358.36	105
1357.82	103
1357.29	106
1356.75	110
1356.21	110
1355.67	107
1355.14	92
1354.6	96
1354.06	101
1353.52	114
1352.99	111
1352.45	92
1351.91	109
1351.37	109
1350.83	81
1350.3	115
1349.76	114
1349.22	97
1348.68	109
1348.14	99
1347.6	104
1347.06	95
1346.53	105
1345.99	119
1345.45	98
1344.91	101
1344.37	98
1343.83	101
1343.3	86
1342.76	110
1342.22	104
1341.68	108
1341.14	97
1340.6	107
1340.06	102
1339.52	108
1338.98	104
1338.45	100
1337.91	107
1337.37	113
1336.83	109
1336.29	117
1335.75	122
1335.21	81
1334.67	85
1334.13	90
1333.59	134
1333.05	90
1332.51	97
1331.97	99
1331.43	90
1330.89	107
1330.35	112
1329.81	90
1329.27	102
1328.73	94
1328.19	90
1327.65	95
1327.11	89
1326.57	100
1326.03	82
1325.49	87
1324.95	92
1324.41	93
1323.87	91
1323.33	114
1322.79	87
1322.25	121
1321.71	95
1321.16	86
1320.62	101
1320.08	81
1319.54	95
1319	111
1318.46	122
1317.92	107
1317.38	94
1316.84	110
1316.29	103
1315.75	94
1315.21	98
1314.67	110
1314.13	90
1313.59	118
1313.05	100
1312.5	105
1311.96	116
1311.42	112
1310.88	142
1310.34	351
1309.8	829
1309.25	2192
1308.71	1398
1308.17	594
1307.63	364
1307.09	125
1306.54	112
1306	103
1305.46	85
1304.92	95
1304.38	96
1303.83	106
1303.29	92
1302.75	105
1302.21	100
1301.66	100
1301.12	106
1300.58	108
1300.04	93
1299.49	98
1298.95	88
1298.41	101
1297.86	106
1297.32	168
1296.78	133
1296.23	96
1295.69	106
1295.15	93
1294.6	107
1294.06	104
1293.52	105
1292.97	102
1292.43	102
1291.89	101
1291.34	87
1290.8	88
1290.26	95
1289.71	93
1289.17	102
1288.63	142
1288.08	122
1287.54	103
1286.99	95
1286.45	92
1285.9	98
1285.36	93
1284.82	90
1284.27	99
1283.73	112
1283.19	102
1282.64	104
1282.1	93
1281.55	112
1281.01	109
1280.46	95
1279.92	95
1279.37	99
1278.83	99
1278.28	93
1277.74	83
1277.19	91
1276.65	90
1276.1	102
1275.56	99
1275.01	103
1274.47	97
1273.92	87
1273.38	98
1272.83	118
1272.29	86
1271.74	99
1271.2	98
1270.65	89
1270.11	93
1269.56	102
1269.01	94
1268.47	106
1267.92	86
1267.38	100
1266.83	103
1266.29	102
1265.74	88
1265.19	92
1264.65	101
1264.1	108
1263.55	88
1263.01	97
1262.46	94
1261.92	92
1261.37	121
1260.82	102
1260.28	103
1259.73	98
1259.18	95
1258.64	103
1258.09	93
1257.55	105
1257	109
1256.45	95
1255.9	100
1255.36	92
1254.81	101
1254.26	100
1253.72	86
1253.17	146
1252.62	169
1252.07	120
1251.53	105
1250.98	115
1250.43	100
1249.89	102
1249.34	78
1248.79	111
1248.24	93
1247.7	86
1247.15	89
1246.6	96
1246.05	96
1245.5	87
1244.96	89
1244.41	101
1243.86	107
1243.31	108
1242.77	103
1242.22	93
1241.67	110
1241.12	89
1240.57	88
1240.02	87
1239.48	93
1238.93	112
1238.38	92
1237.83	110
1237.28	85
1236.73	103
1236.18	102
1235.64	105
1235.09	92
1234.54	112
1233.99	87
1233.44	123
1232.89	81
1232.34	110
1231.79	120
1231.24	82
1230.69	94
1230.15	94
1229.6	87
1229.05	106
1228.5	106
1227.95	115
1227.4	88
1226.85	111
1226.3	110
1225.75	96
1225.2	110
1224.65	94
1224.1	106
1223.55	102
1223	109
1222.45	89
1221.9	99
1221.35	92
1220.8	128
1220.25	133
1219.7	291
1219.15	1824
1218.6	3064
1218.05	1109
1217.5	232
1216.95	141
1216.4	103
1215.85	107
1215.3	118
1214.75	103
1214.2	116
1213.65	100
1213.09	107
1212.54	126
1211.99	115
1211.44	112
1210.89	140
1210.34	104
1209.79	106
1209.24	94
1208.69	108
1208.14	111
1207.58	93
1207.03	94
1206.48	109
1205.93	95
1205.38	100
1204.83	108
1204.27	85
1203.72	115
1203.17	120
1202.62	122
1202.07	113
1201.52	92
1200.96	105
1200.41	112
1199.86	163
1199.31	138
1198.76	103
1198.2	118
1197.65	104
1197.1	104
1196.55	112
1196	103
1195.44	113
1194.89	167
1194.34	465
1193.78	371
1193.23	140
1192.68	113
1192.13	103
1191.57	112
1191.02	102
1190.47	93
1189.91	95
1189.36	102
1188.81	100
1188.26	104
1187.7	99
1187.15	117
1186.6	103
1186.04	95
1185.49	98
1184.94	108
1184.38	98
1183.83	100
1183.28	123
1182.72	107
1182.17	93
1181.61	108
1181.06	105
1180.51	98
1179.95	112
1179.4	100
1178.85	100
1178.29	83
1177.74	92
1177.18	109
1176.63	104
1176.07	94
1175.52	117
1174.97	108
1174.41	103
1173.86	102
1173.3	92
1172.75	111
1172.19	107
1171.64	107
1171.09	114
1170.53	115
1169.97	99
1169.42	93
1168.86	104
1168.31	107
1167.76	114
1167.2	115
1166.65	119
1166.09	105
1165.53	93
1164.98	124
1164.42	93
1163.87	79
1163.31	112
1162.76	104
1162.2	99
1161.65	119
1161.09	89
1160.54	98
1159.98	106
1159.42	118
1158.87	104
1158.31	96
1157.76	108
1157.2	117
1156.65	101
1156.09	111
1155.53	103
1154.98	111
1154.42	100
1153.86	116
1153.31	94
1152.75	107
1152.19	89
1151.64	97
1151.08	107
1150.52	105
1149.97	100
1149.41	110
1148.86	103
1148.3	79
1147.74	113
1147.18	111
1146.63	115
1146.07	123
1145.51	133
1144.96	108
1144.4	115
1143.84	123
1143.28	121
1142.73	110
1142.17	123
1141.61	104
1141.06	105
1140.5	102
1139.94	118
1139.38	126
1138.83	112
1138.27	110
1137.71	128
1137.15	120
1136.59	111
1136.04	104
1135.48	117
1134.92	181
1134.36	985
1133.8	1315
1133.25	350
1132.69	150
1132.13	132
1131.57	122
1131.01	128
1130.45	119
1129.9	101
1129.34	126
1128.78	127
1128.22	120
1127.66	122
1127.1	124
1126.54	117
1125.98	112
1125.43	118
1124.87	119
1124.31	136
1123.75	213
1123.19	362
1122.63	195
1122.07	128
1121.51	117
1120.95	136
1120.39	131
1119.83	134
1119.27	111
1118.72	146
1118.15	147
1117.6	125
1117.04	160
1116.48	397
1115.92	3739
1115.36	4239
1114.8	737
1114.24	327
1113.68	720
1113.12	415
1112.56	147
1112	140
1111.44	125
1110.88	126
1110.32	130
1109.76	146
1109.19	135
1108.64	143
1108.07	104
1107.51	130
1106.95	111
1106.39	113
1105.83	134
1105.27	120
1104.71	131
1104.15	139
1103.59	197
1103.03	707
1102.47	682
1101.91	186
1101.34	145
1100.78	115
1100.22	120
1099.66	137
1099.1	137
1098.54	128
1097.98	158
1097.41	416
1096.85	848
1096.29	361
1095.73	139
1095.17	134
1094.61	110
1094.04	135
1093.48	137
1092.92	142
1092.36	157
1091.8	140
1091.23	150
1090.67	296
1090.11	211
1089.55	137
1088.99	129
1088.42	129
1087.86	136
1087.3	132
1086.74	113
1086.17	132
1085.61	116
1085.05	128
1084.49	133
1083.92	123
1083.36	144
1082.8	129
1082.23	120
1081.67	107
1081.11	128
1080.55	121
1079.98	129
1079.42	137
1078.86	137
1078.29	139
1077.73	110
1077.17	133
1076.6	140
1076.04	123
1075.48	138
1074.91	118
1074.35	131
1073.79	128
1073.22	128
1072.66	138
1072.09	127
1071.53	147
1070.97	137
1070.4	137
1069.84	121
1069.27	120
1068.71	140
1068.15	186
1067.58	290
1067.02	169
1066.45	125
1065.89	114
1065.32	123
1064.76	114
1064.19	145
1063.63	120
1063.07	129
1062.5	124
1061.94	132
1061.37	129
1060.81	161
1060.24	170
1059.68	126
1059.11	123
1058.55	122
1057.98	125
1057.42	109
1056.85	115
1056.29	138
1055.72	145
1055.16	173
1054.59	169
1054.03	137
1053.46	125
1052.89	131
1052.33	119
1051.76	122
1051.2	116
1050.63	143
1050.06	165
1049.5	232
1048.93	205
1048.37	126
1047.8	111
1047.24	117
1046.67	133
1046.1	121
1045.54	128
1044.97	123
1044.4	121
1043.84	123
1043.27	128
1042.7	137
1042.14	126
1041.57	121
1041.01	117
1040.44	117
1039.87	113
1039.3	115
1038.74	117
1038.17	135
1037.6	126
1037.04	127
1036.47	122
1035.9	121
1035.34	117
1034.77	121
1034.2	140
1033.63	135
1033.07	138
1032.5	128
1031.93	116
1031.36	116
1030.8	114
1030.23	128
1029.66	108
1029.09	106
1028.52	119
1027.96	109
1027.39	135
1026.82	119
1026.25	110
1025.68	123
1025.12	115
1024.55	115
1023.98	117
1023.41	114
1022.84	102
1022.28	136
1021.71	117
1021.14	105
1020.57	112
1020	114
1019.43	136
1018.86	117
1018.3	127
1017.73	119
1017.16	127
1016.59	112
1016.3	117