File: Testing/Hickernall_HORIBA/Ne6_01.txt
#Acq. time (s)=	55
#Accumulations=	2
#Range=	Off
#Autofocus=	Off
#Macrospot=	Off
#AutoExposure=	Off
#Spike filter=	Multiple accum.
#Delay time (s)=	0
#Binning=	1
#Readout mode=	Signal
#DeNoise=	Off
#ICS correction=	Off
#Dark correction=	Off
#Inst. Process=	Off
#Instrument=	LabRAM HR Evol
#Detector=	Andor CCD
#Objective=	x100 LWD
#Grating=	1800 gr/mm
#ND Filter=	100%
#Laser (nm)=	532
#Spectro (cm-¹)=	1240.02
#Hole=	49.98
#Range=	Visible
#AFM=	Off
#StageXY=	Marzhauser
#StageZ=	Marzhauser
#X (µm)=	-16206.4
#Y (µm)=	-737.9
#Z (µm)=	-344.3
#Project=
#Sample=
#Site=
#Title=	Ne6
#Remark=
#Date=	06.05.2022 11:38
#Acquired=	06.05.2022 11:38:58
1454.81	94
1454.28	101
1453.75	101
1453.22	91
1452.69	101
1452.16	115
1451.64	103
1451.11	123
1450.58	130
1450.05	125
1449.52	153
1448.99	180
1448.46	200
1447.93	325
1447.4	677
1446.88	12089
1446.35	47758
1445.82	32111
1445.29	4816
1444.76	1833
1444.23	492
1443.7	269
1443.17	210
1442.64	186
1442.11	181
1441.58	149
1441.05	132
1440.52	138
1439.99	133
1439.46	123
1438.93	144
1438.4	123
1437.87	111
1437.34	99
1436.81	115
1436.28	111
1435.75	122
1435.22	706
1434.69	1544
1434.16	741
1433.63	140
1433.1	112
1432.57	104
1432.04	86
1431.51	74
1430.98	96
1430.45	98
1429.92	89
1429.39	93
1428.86	85
1428.33	84
1427.8	83
1427.26	85
1426.73	89
1426.2	94
1425.67	100
1425.14	85
1424.61	92
1424.08	80
1423.55	80
1423.02	88
1422.49	89
1421.95	89
1421.42	100
1420.89	92
1420.36	101
1419.83	84
1419.3	85
1418.76	78
1418.23	77
1417.7	104
1417.17	73
1416.64	84
1416.1	74
1415.57	77
1415.04	80
1414.51	75
1413.98	80
1413.44	79
1412.91	76
1412.38	81
1411.85	78
1411.32	79
1410.78	87
1410.25	68
1409.72	89
1409.18	80
1408.65	65
1408.12	81
1407.59	79
1407.05	80
1406.52	77
1405.99	87
1405.46	89
1404.92	92
1404.39	80
1403.86	92
1403.32	84
1402.79	84
1402.26	78
1401.72	90
1401.19	101
1400.66	111
1400.12	96
1399.59	137
1399.06	546
1398.52	1038
1397.99	7412
1397.46	10362
1396.92	2519
1396.39	271
1395.85	126
1395.32	109
1394.79	96
1394.25	100
1393.72	92
1393.18	82
1392.65	79
1392.12	85
1391.58	89
1391.05	82
1390.51	81
1389.98	83
1389.44	89
1388.91	74
1388.38	66
1387.84	86
1387.31	95
1386.77	69
1386.24	78
1385.7	91
1385.17	65
1384.63	70
1384.1	88
1383.56	82
1383.03	84
1382.49	77
1381.96	59
1381.42	49
1380.89	83
1380.35	90
1379.82	81
1379.28	77
1378.74	63
1378.21	74
1377.67	85
1377.14	68
1376.6	83
1376.07	79
1375.53	87
1374.99	74
1374.46	84
1373.92	87
1373.39	70
1372.85	95
1372.32	90
1371.78	165
1371.24	1057
1370.71	1072
1370.17	245
1369.63	88
1369.1	87
1368.56	84
1368.03	132
1367.49	235
1366.95	129
1366.42	76
1365.88	121
1365.34	93
1364.81	76
1364.27	71
1363.73	72
1363.19	69
1362.66	58
1362.12	83
1361.58	66
1361.05	60
1360.51	68
1359.97	74
1359.44	79
1358.9	77
1358.36	79
1357.82	76
1357.29	70
1356.75	75
1356.21	91
1355.67	70
1355.14	88
1354.6	76
1354.06	68
1353.52	85
1352.99	77
1352.45	67
1351.91	83
1351.37	87
1350.83	66
1350.3	74
1349.76	73
1349.22	79
1348.68	74
1348.14	70
1347.6	95
1347.06	66
1346.53	64
1345.99	70
1345.45	67
1344.91	75
1344.37	71
1343.83	74
1343.3	66
1342.76	79
1342.22	72
1341.68	62
1341.14	78
1340.6	80
1340.06	85
1339.52	75
1338.98	73
1338.45	78
1337.91	62
1337.37	79
1336.83	87
1336.29	73
1335.75	68
1335.21	88
1334.67	69
1334.13	85
1333.59	53
1333.05	80
1332.51	75
1331.97	75
1331.43	75
1330.89	80
1330.35	78
1329.81	73
1329.27	74
1328.73	68
1328.19	91
1327.65	79
1327.11	58
1326.57	80
1326.03	68
1325.49	70
1324.95	65
1324.41	73
1323.87	80
1323.33	67
1322.79	61
1322.25	75
1321.71	69
1321.16	82
1320.62	65
1320.08	66
1319.54	87
1319	80
1318.46	69
1317.92	67
1317.38	83
1316.84	79
1316.29	79
1315.75	85
1315.21	72
1314.67	63
1314.13	75
1313.59	70
1313.05	71
1312.5	82
1311.96	83
1311.42	76
1310.88	90
1310.34	358
1309.8	797
1309.25	2113
1308.71	1362
1308.17	550
1307.63	325
1307.09	96
1306.54	84
1306	75
1305.46	85
1304.92	81
1304.38	57
1303.83	77
1303.29	70
1302.75	75
1302.21	66
1301.66	68
1301.12	61
1300.58	73
1300.04	75
1299.49	82
1298.95	73
1298.41	75
1297.86	102
1297.32	123
1296.78	113
1296.23	82
1295.69	69
1295.15	70
1294.6	70
1294.06	71
1293.52	74
1292.97	78
1292.43	62
1291.89	67
1291.34	62
1290.8	64
1290.26	73
1289.71	68
1289.17	80
1288.63	112
1288.08	95
1287.54	82
1286.99	68
1286.45	66
1285.9	64
1285.36	72
1284.82	60
1284.27	65
1283.73	65
1283.19	66
1282.64	66
1282.1	59
1281.55	78
1281.01	79
1280.46	70
1279.92	73
1279.37	66
1278.83	87
1278.28	66
1277.74	79
1277.19	73
1276.65	84
1276.1	78
1275.56	75
1275.01	69
1274.47	85
1273.92	91
1273.38	62
1272.83	92
1272.29	73
1271.74	79
1271.2	61
1270.65	67
1270.11	69
1269.56	74
1269.01	73
1268.47	72
1267.92	71
1267.38	73
1266.83	76
1266.29	55
1265.74	62
1265.19	66
1264.65	48
1264.1	72
1263.55	63
1263.01	66
1262.46	83
1261.92	71
1261.37	69
1260.82	67
1260.28	72
1259.73	67
1259.18	73
1258.64	82
1258.09	65
1257.55	72
1257	76
1256.45	80
1255.9	77
1255.36	58
1254.81	78
1254.26	78
1253.72	79
1253.17	144
1252.62	153
1252.07	91
1251.53	82
1250.98	67
1250.43	71
1249.89	77
1249.34	75
1248.79	57
1248.24	56
1247.7	75
1247.15	62
1246.6	82
1246.05	70
1245.5	74
1244.96	73
1244.41	66
1243.86	69
1243.31	53
1242.77	73
1242.22	64
1241.67	71
1241.12	77
1240.57	74
1240.02	79
1239.48	61
1238.93	73
1238.38	84
1237.83	69
1237.28	75
1236.73	70
1236.18	66
1235.64	70
1235.09	60
1234.54	89
1233.99	72
1233.44	112
1232.89	77
1232.34	62
1231.79	74
1231.24	71
1230.69	81
1230.15	59
1229.6	81
1229.05	65
1228.5	68
1227.95	69
1227.4	72
1226.85	67
1226.3	83
1225.75	78
1225.2	87
1224.65	71
1224.1	73
1223.55	66
1223	71
1222.45	80
1221.9	76
1221.35	58
1220.8	85
1220.25	101
1219.7	240
1219.15	1797
1218.6	3012
1218.05	1028
1217.5	205
1216.95	109
1216.4	94
1215.85	91
1215.3	90
1214.75	93
1214.2	88
1213.65	55
1213.09	74
1212.54	84
1211.99	86
1211.44	83
1210.89	84
1210.34	81
1209.79	85
1209.24	79
1208.69	63
1208.14	80
1207.58	83
1207.03	77
1206.48	71
1205.93	82
1205.38	86
1204.83	67
1204.27	74
1203.72	81
1203.17	85
1202.62	83
1202.07	84
1201.52	61
1200.96	82
1200.41	98
1199.86	141
1199.31	87
1198.76	72
1198.2	70
1197.65	70
1197.1	82
1196.55	81
1196	93
1195.44	71
1194.89	130
1194.34	449
1193.78	372
1193.23	102
1192.68	74
1192.13	67
1191.57	72
1191.02	78
1190.47	75
1189.91	73
1189.36	68
1188.81	77
1188.26	72
1187.7	56
1187.15	71
1186.6	83
1186.04	95
1185.49	80
1184.94	84
1184.38	78
1183.83	77
1183.28	83
1182.72	73
1182.17	69
1181.61	70
1181.06	61
1180.51	80
1179.95	80
1179.4	78
1178.85	71
1178.29	75
1177.74	87
1177.18	81
1176.63	78
1176.07	86
1175.52	76
1174.97	76
1174.41	75
1173.86	84
1173.3	82
1172.75	76
1172.19	66
1171.64	73
1171.09	78
1170.53	67
1169.97	70
1169.42	72
1168.86	77
1168.31	84
1167.76	83
1167.2	70
1166.65	71
1166.09	66
1165.53	72
1164.98	69
1164.42	81
1163.87	78
1163.31	77
1162.76	80
1162.2	91
1161.65	80
1161.09	74
1160.54	90
1159.98	83
1159.42	69
1158.87	62
1158.31	84
1157.76	80
1157.2	84
1156.65	73
1156.09	70
1155.53	61
1154.98	66
1154.42	74
1153.86	72
1153.31	71
1152.75	71
1152.19	83
1151.64	83
1151.08	72
1150.52	74
1149.97	87
1149.41	77
1148.86	78
1148.3	69
1147.74	84
1147.18	82
1146.63	80
1146.07	84
1145.51	69
1144.96	79
1144.4	89
1143.84	73
1143.28	84
1142.73	81
1142.17	79
1141.61	75
1141.06	73
1140.5	88
1139.94	81
1139.38	73
1138.83	65
1138.27	69
1137.71	85
1137.15	82
1136.59	96
1136.04	83
1135.48	83
1134.92	118
1134.36	861
1133.8	1287
1133.25	338
1132.69	113
1132.13	116
1131.57	91
1131.01	89
1130.45	81
1129.9	80
1129.34	63
1128.78	94
1128.22	75
1127.66	85
1127.1	77
1126.54	89
1125.98	67
1125.43	84
1124.87	88
1124.31	101
1123.75	168
1123.19	327
1122.63	162
1122.07	102
1121.51	67
1120.95	89
1120.39	86
1119.83	83
1119.27	86
1118.72	89
1118.15	122
1117.6	102
1117.04	115
1116.48	302
1115.92	3680
1115.36	4313
1114.8	631
1114.24	267
1113.68	725
1113.12	347
1112.56	93
1112	100
1111.44	101
1110.88	92
1110.32	93
1109.76	89
1109.19	84
1108.64	84
1108.07	81
1107.51	88
1106.95	88
1106.39	94
1105.83	86
1105.27	90
1104.71	92
1104.15	88
1103.59	144
1103.03	708
1102.47	604
1101.91	162
1101.34	81
1100.78	83
1100.22	78
1099.66	83
1099.1	93
1098.54	94
1097.98	107
1097.41	327
1096.85	889
1096.29	341
1095.73	89
1095.17	96
1094.61	91
1094.04	80
1093.48	90
1092.92	89
1092.36	83
1091.8	82
1091.23	127
1090.67	266
1090.11	187
1089.55	89
1088.99	87
1088.42	71
1087.86	65
1087.3	79
1086.74	83
1086.17	91
1085.61	77
1085.05	97
1084.49	80
1083.92	75
1083.36	94
1082.8	78
1082.23	78
1081.67	77
1081.11	93
1080.55	81
1079.98	78
1079.42	91
1078.86	105
1078.29	93
1077.73	70
1077.17	75
1076.6	91
1076.04	86
1075.48	82
1074.91	95
1074.35	107
1073.79	86
1073.22	97
1072.66	88
1072.09	82
1071.53	87
1070.97	94
1070.4	81
1069.84	89
1069.27	85
1068.71	78
1068.15	135
1067.58	253
1067.02	135
1066.45	80
1065.89	89
1065.32	83
1064.76	83
1064.19	84
1063.63	104
1063.07	77
1062.5	86
1061.94	89
1061.37	108
1060.81	145
1060.24	154
1059.68	86
1059.11	95
1058.55	70
1057.98	82
1057.42	85
1056.85	101
1056.29	90
1055.72	92
1055.16	116
1054.59	148
1054.03	98
1053.46	87
1052.89	92
1052.33	86
1051.76	86
1051.2	100
1050.63	96
1050.06	112
1049.5	218
1048.93	193
1048.37	97
1047.8	88
1047.24	98
1046.67	87
1046.1	85
1045.54	82
1044.97	83
1044.4	93
1043.84	90
1043.27	113
1042.7	76
1042.14	91
1041.57	85
1041.01	78
1040.44	87
1039.87	78
1039.3	81
1038.74	95
1038.17	87
1037.6	76
1037.04	98
1036.47	104
1035.9	89
1035.34	100
1034.77	88
1034.2	96
1033.63	92
1033.07	87
1032.5	107
1031.93	84
1031.36	91
1030.8	75
1030.23	94
1029.66	96
1029.09	103
1028.52	93
1027.96	100
1027.39	90
1026.82	95
1026.25	94
1025.68	73
1025.12	91
1024.55	86
1023.98	99
1023.41	83
1022.84	85
1022.28	87
1021.71	97
1021.14	90
1020.57	101
1020	96
1019.43	82
1018.86	88
1018.3	98
1017.73	89
1017.16	115
1016.59	77
1016.3	104