File: defunt_code/File_Formats/HORIBA_Ne_FileFormats.txt
#Acq. time (s)=	110
#Accumulations=	2
#Range=	Off
#Autofocus=	Off
#Macrospot=	Off
#AutoExposure=	Off
#Spike filter=	Multiple accum.
#Delay time (s)=	0
#Binning=	1
#Readout mode=	Signal
#DeNoise=	Off
#ICS correction=	Off
#Dark correction=	Off
#Inst. Process=	Off
#Instrument=	LabRAM HR Evol
#Detector=	Andor CCD
#Objective=	x100 LWD
#Grating=	1800 gr/mm
#ND Filter=	100%
#Laser (nm)=	532
#Spectro (cm-¹)=	1240.03
#Hole=	49.98
#Range=	Visible
#AFM=	Off
#StageXY=	Marzhauser
#StageZ=	Marzhauser
#X (µm)=	717.1
#Y (µm)=	-1004.6
#Z (µm)=	135.1
#Project=
#Sample=
#Site=
#Title=	Ne3
#Remark=
#Date=	28.03.2022 19:48
#Acquired=	28.03.2022 19:48:51
1454.82	131
1454.29	138
1453.76	138
1453.23	127
1452.7	144
1452.17	122
1451.65	148
1451.12	175
1450.59	164
1450.06	197
1449.53	237
1449	285
1448.47	540
1447.94	5220
1447.41	41926
1446.88	45175
1446.36	9436
1445.83	2523
1445.3	759
1444.77	318
1444.24	273
1443.71	217
1443.18	200
1442.65	179
1442.12	189
1441.59	165
1441.06	167
1440.53	145
1440	153
1439.47	140
1438.94	158
1438.41	143
1437.88	134
1437.35	140
1436.82	149
1436.29	445
1435.76	1437
1435.23	1045
1434.7	249
1434.17	125
1433.64	119
1433.11	123
1432.58	133
1432.05	123
1431.52	127
1430.99	107
1430.46	117
1429.93	120
1429.4	105
1428.87	96
1428.34	131
1427.81	115
1427.27	132
1426.74	117
1426.21	113
1425.68	129
1425.15	117
1424.62	118
1424.09	109
1423.56	126
1423.03	119
1422.49	113
1421.96	127
1421.43	113
1420.9	112
1420.37	122
1419.84	115
1419.3	128
1418.77	104
1418.24	102
1417.71	98
1417.18	104
1416.65	111
1416.11	111
1415.58	107
1415.05	104
1414.52	135
1413.99	110
1413.45	104
1412.92	117
1412.39	114
1411.86	130
1411.32	113
1410.79	132
1410.26	91
1409.73	116
1409.19	101
1408.66	114
1408.13	113
1407.6	122
1407.06	124
1406.53	108
1406	102
1405.46	113
1404.93	109
1404.4	112
1403.87	117
1403.33	113
1402.8	122
1402.27	123
1401.73	129
1401.2	162
1400.67	159
1400.13	441
1399.6	953
1399.07	5158
1398.53	11716
1398	5272
1397.46	480
1396.93	191
1396.4	143
1395.86	131
1395.33	128
1394.8	115
1394.26	122
1393.73	112
1393.19	128
1392.66	114
1392.13	111
1391.59	101
1391.06	110
1390.52	126
1389.99	108
1389.45	115
1388.92	95
1388.38	97
1387.85	116
1387.32	105
1386.78	112
1386.25	132
1385.71	115
1385.18	105
1384.64	112
1384.11	115
1383.57	122
1383.04	85
1382.5	87
1381.97	119
1381.43	111
1380.9	104
1380.36	103
1379.82	106
1379.29	118
1378.75	104
1378.22	103
1377.68	123
1377.15	102
1376.61	106
1376.08	100
1375.54	108
1375	127
1374.47	98
1373.93	107
1373.4	98
1372.86	151
1372.33	857
1371.79	1296
1371.25	533
1370.72	127
1370.18	130
1369.64	118
1369.11	133
1368.57	249
1368.03	209
1367.5	132
1366.96	113
1366.43	132
1365.89	144
1365.35	109
1364.82	123
1364.28	105
1363.74	110
1363.2	110
1362.67	101
1362.13	110
1361.59	106
1361.06	117
1360.52	107
1359.98	110
1359.45	100
1358.91	127
1358.37	121
1357.83	115
1357.3	101
1356.76	134
1356.22	107
1355.68	103
1355.15	123
1354.61	106
1354.07	133
1353.53	105
1352.99	115
1352.46	102
1351.92	113
1351.38	124
1350.84	114
1350.31	99
1349.77	111
1349.23	110
1348.69	114
1348.15	100
1347.61	106
1347.08	102
1346.54	123
1346	111
1345.46	105
1344.92	116
1344.38	94
1343.84	110
1343.3	100
1342.77	104
1342.23	109
1341.69	98
1341.15	108
1340.61	83
1340.07	107
1339.53	102
1338.99	108
1338.45	117
1337.92	90
1337.38	103
1336.84	100
1336.3	104
1335.76	98
1335.22	102
1334.68	120
1334.14	116
1333.6	110
1333.06	96
1332.52	107
1331.98	125
1331.44	109
1330.9	107
1330.36	104
1329.82	114
1329.28	100
1328.74	96
1328.2	101
1327.66	110
1327.12	97
1326.58	102
1326.04	118
1325.5	107
1324.96	108
1324.42	112
1323.88	102
1323.34	117
1322.8	111
1322.25	106
1321.71	107
1321.17	86
1320.63	124
1320.09	119
1319.55	100
1319.01	106
1318.47	117
1317.93	123
1317.39	112
1316.85	102
1316.3	116
1315.76	114
1315.22	109
1314.68	108
1314.14	104
1313.6	121
1313.06	127
1312.51	106
1311.97	104
1311.43	297
1310.89	594
1310.35	2050
1309.81	1754
1309.26	731
1308.72	468
1308.18	173
1307.64	117
1307.1	111
1306.55	112
1306.01	110
1305.47	105
1304.93	104
1304.39	87
1303.84	110
1303.3	107
1302.76	101
1302.22	99
1301.67	123
1301.13	123
1300.59	112
1300.04	116
1299.5	114
1298.96	115
1298.42	157
1297.87	156
1297.33	108
1296.79	114
1296.24	97
1295.7	119
1295.16	114
1294.61	113
1294.07	82
1293.53	98
1292.98	98
1292.44	97
1291.9	102
1291.35	118
1290.81	106
1290.27	92
1289.72	111
1289.18	157
1288.63	124
1288.09	111
1287.55	107
1287	97
1286.46	110
1285.92	102
1285.37	96
1284.83	105
1284.28	111
1283.74	109
1283.19	108
1282.65	91
1282.1	114
1281.56	94
1281.02	101
1280.47	95
1279.93	98
1279.38	101
1278.84	147
1278.29	99
1277.75	112
1277.2	100
1276.66	110
1276.11	110
1275.57	116
1275.02	122
1274.48	96
1273.93	106
1273.39	107
1272.84	123
1272.3	118
1271.75	104
1271.21	81
1270.66	90
1270.11	79
1269.57	94
1269.02	114
1268.48	96
1267.93	88
1267.39	103
1266.84	112
1266.3	95
1265.75	99
1265.2	101
1264.66	110
1264.11	87
1263.57	108
1263.02	110
1262.47	103
1261.93	99
1261.38	105
1260.83	105
1260.29	109
1259.74	102
1259.19	112
1258.65	84
1258.1	98
1257.55	109
1257.01	91
1256.46	101
1255.91	122
1255.37	99
1254.82	116
1254.27	154
1253.73	217
1253.18	151
1252.63	111
1252.08	116
1251.54	128
1250.99	108
1250.44	122
1249.9	99
1249.35	112
1248.8	89
1248.25	106
1247.71	98
1247.16	100
1246.61	116
1246.06	104
1245.51	100
1244.97	111
1244.42	105
1243.87	113
1243.32	130
1242.77	116
1242.23	127
1241.68	118
1241.13	128
1240.58	117
1240.03	134
1239.48	102
1238.94	105
1238.39	99
1237.84	103
1237.29	108
1236.74	102
1236.19	119
1235.65	121
1235.1	102
1234.55	114
1234	111
1233.45	161
1232.9	97
1232.35	98
1231.8	103
1231.25	101
1230.7	116
1230.16	113
1229.61	99
1229.06	112
1228.51	108
1227.96	109
1227.41	85
1226.86	97
1226.31	103
1225.76	103
1225.21	116
1224.66	103
1224.11	101
1223.56	115
1223.01	114
1222.46	118
1221.91	100
1221.36	112
1220.81	189
1220.26	1138
1219.71	3148
1219.16	1718
1218.61	313
1218.06	151
1217.51	111
1216.96	136
1216.41	109
1215.86	108
1215.31	117
1214.76	123
1214.21	115
1213.65	123
1213.1	114
1212.55	131
1212	129
1211.45	105
1210.9	105
1210.35	111
1209.8	104
1209.25	105
1208.7	106
1208.15	123
1207.59	110
1207.04	96
1206.49	127
1205.94	119
1205.39	106
1204.84	94
1204.29	126
1203.73	143
1203.18	112
1202.63	113
1202.08	108
1201.53	117
1200.97	203
1200.42	176
1199.87	123
1199.32	114
1198.77	120
1198.21	109
1197.66	113
1197.11	127
1196.56	107
1196	132
1195.45	443
1194.9	489
1194.35	196
1193.79	125
1193.24	92
1192.69	116
1192.14	104
1191.58	129
1191.03	101
1190.48	109
1189.92	101
1189.37	106
1188.82	107
1188.26	110
1187.71	113
1187.16	127
1186.61	129
1186.05	115
1185.5	115
1184.95	112
1184.39	116
1183.84	109
1183.28	106
1182.73	110
1182.18	122
1181.62	112
1181.07	105
1180.52	128
1179.96	114
1179.41	118
1178.86	118
1178.3	103
1177.75	118
1177.19	113
1176.64	112
1176.09	127
1175.53	111
1174.98	102
1174.42	106
1173.87	125
1173.31	128
1172.76	116
1172.2	108
1171.65	84
1171.09	113
1170.54	105
1169.99	112
1169.43	106
1168.87	117
1168.32	119
1167.76	102
1167.21	121
1166.66	115
1166.1	110
1165.55	116
1164.99	126
1164.43	126
1163.88	98
1163.32	121
1162.77	113
1162.21	114
1161.66	104
1161.1	126
1160.54	130
1159.99	128
1159.43	115
1158.88	103
1158.32	130
1157.77	122
1157.21	103
1156.65	121
1156.1	121
1155.54	108
1154.99	116
1154.43	146
1153.87	110
1153.32	110
1152.76	124
1152.2	128
1151.65	111
1151.09	126
1150.54	115
1149.98	132
1149.42	111
1148.86	113
1148.31	96
1147.75	114
1147.19	103
1146.64	134
1146.08	109
1145.52	120
1144.97	109
1144.41	104
1143.85	110
1143.29	116
1142.74	104
1142.18	125
1141.62	83
1141.06	102
1140.51	116
1139.95	114
1139.39	127
1138.83	123
1138.28	114
1137.72	114
1137.16	107
1136.6	134
1136.04	132
1135.49	625
1134.93	1445
1134.37	607
1133.81	181
1133.26	133
1132.7	127
1132.14	127
1131.58	110
1131.02	127
1130.46	127
1129.91	128
1129.35	106
1128.79	114
1128.23	130
1127.67	136
1127.11	118
1126.55	134
1125.99	127
1125.44	123
1124.88	178
1124.32	344
1123.76	229
1123.2	129
1122.64	127
1122.08	108
1121.52	137
1120.96	128
1120.4	110
1119.84	126
1119.28	126
1118.72	140
1118.16	140
1117.6	238
1117.05	2534
1116.49	4812
1115.93	1419
1115.37	283
1114.81	715
1114.25	561
1113.69	169
1113.13	143
1112.57	127
1112.01	122
1111.45	112
1110.89	128
1110.32	136
1109.77	129
1109.2	138
1108.64	143
1108.08	130
1107.52	116
1106.96	116
1106.4	114
1105.84	123
1105.28	138
1104.72	148
1104.16	562
1103.6	812
1103.04	275
1102.48	133
1101.92	133
1101.35	135
1100.79	131
1100.23	141
1099.67	129
1099.11	171
1098.55	277
1097.99	849
1097.42	574
1096.86	188
1096.3	148
1095.74	119
1095.18	139
1094.62	134
1094.05	138
1093.49	128
1092.93	136
1092.37	116
1091.81	266
1091.24	278
1090.68	159
1090.12	140
1089.56	126
1089	117
1088.43	122
1087.87	136
1087.31	119
1086.75	125
1086.18	126
1085.62	124
1085.06	144
1084.5	139
1083.93	138
1083.37	140
1082.81	124
1082.25	147
1081.68	150
1081.12	123
1080.56	130
1079.99	127
1079.43	129
1078.87	133
1078.3	156
1077.74	129
1077.18	131
1076.61	116
1076.05	145
1075.49	153
1074.92	125
1074.36	136
1073.8	126
1073.23	129
1072.67	122
1072.11	125
1071.54	118
1070.98	143
1070.41	131
1069.85	129
1069.28	138
1068.72	286
1068.16	236
1067.59	149
1067.03	136
1066.46	150
1065.9	137
1065.33	132
1064.77	153
1064.21	146
1063.64	109
1063.08	120
1062.51	123
1061.95	174
1061.38	230
1060.82	157
1060.25	130
1059.69	139
1059.12	132
1058.56	147
1057.99	149
1057.43	148
1056.86	134
1056.3	165
1055.73	173
1055.17	137
1054.6	142
1054.04	137
1053.47	147
1052.9	156
1052.34	157
1051.77	142
1051.21	148
1050.64	268
1050.07	304
1049.51	154
1048.94	145
1048.38	149
1047.81	141
1047.24	138
1046.68	139
1046.11	136
1045.55	151
1044.98	142
1044.41	131
1043.85	136
1043.28	241
1042.71	158
1042.15	135
1041.58	127
1041.02	132
1040.45	146
1039.88	153
1039.31	141
1038.75	142
1038.18	151
1037.61	126
1037.05	158
1036.48	167
1035.91	127
1035.34	149
1034.78	134
1034.21	141
1033.64	121
1033.08	131
1032.51	154
1031.94	131
1031.37	156
1030.81	146
1030.24	147
1029.67	159
1029.1	129
1028.53	133
1027.97	151
1027.4	149
1026.83	161
1026.26	141
1025.69	151
1025.13	137
1024.56	145
1023.99	140
1023.42	156
1022.85	151
1022.29	117
1021.72	137
1021.15	159
1020.58	153
1020.01	157
1019.44	151
1018.87	151
1018.31	159
1017.74	138
1017.17	175
1016.6	152
1016.31	164